Workbook

Sheet lc_detailed
B2: Asset Parameters (normalized by commodity feedstock) | Q2: Duals | AM2: LCOE for ethanol production ($/MWh-ethanol) | AO2: CI | AP2: CREDIT | AQ2: CI | AR2: CREDIT | BA2: NET CARBON INTENSITY + credit for capture | BD2: CREDIT for capture/storage + PAY for storage | BH2: Carbon Content | BL2: Carbon Inputs | BP2: Carbon Outputs | BW2: Sanity Checks
B3: id | C3: commodity | D3: elec_production (MWh/t-bio) | E3: elec_consumption (MWh/t-bio) | F3: ethanol_production (MWh-ethanol/t-bio) | G3: natgas_consumption (MWh/t-bio) | H3: co2_biomass_content (t-CO2/t-bio) | I3: process_capture_rate (t-CO2/t-bio) | J3: process_emission_rate (t-CO2/t-bio) | K3: fuel_capture_rate (t-CO2/t-bio) | L3: fuel_emission_rate (t-CO2/t-bio) | M3: investment_cost ($/yr per t-bio/hr) | N3: fixed_om_cost ($/yr per t-bio/hr) | O3: variable_om_cost ($/t-bio) | Q3: co2_sink ($/t) | R3: co2_captured ($/t) | S3: biocorn_supply ($/t) | T3: bioherb_supply ($/t) | U3: biowood_supply ($/t) | V3: bioagri_supply ($/t) | W3: ethanol_balance ($/MWh) | X3: ethanol_demand ($/MWh) | Y3: elec_demand ($/MWh) | Z3: h2_balance ($/MWh) | AA3: h2_demand ($/MWh) | AB3: gasoline_balance ($/MWh) | AC3: gasoline_demand ($/MWh) | AD3: diesel_balance ($/MWh) | AE3: diesel_demand ($/MWh) | AF3: jetfuel_balance ($/MWh) | AG3: jetfuel_demand ($/MWh) | AH3: ng_balance ($/MWh) | AI3: ng_demand ($/MWh) | AJ3: ethylene_balance ($/t) | AK3: ethylene_demand ($/t) | AM3: id_LC | AN3: commodity_LC | AO3: LCOE ($/MWh-ethanol) | AP3: LCOE ($/MWh-ethanol) | AQ3: LCOE ($/GJ-ethanol) | AR3: LCOE ($/GJ-ethanol) | AS3: Diff. Between Methods ($/MWh) | AT3: elec_production | AU3: elec_consumption | AV3: biomass_consumption | AW3: natgas_consumption | AX3: investment_cost | AY3: fixed_om_cost | AZ3: variable_om_cost | BA3: CI | BB3: modified capture cost | BC3: modified emissions cost | BD3: CI | BE3: modified capture cost | BF3: modified emissions cost | BH3: Biomass CO2 content (t-CO2/t-bio) | BI3: NG (t-CO2/MWh-NG) | BJ3: Ethanol (t-CO2/MWh-ethanol) | BL3: Biomass (t-CO2/MWh-ethanol) | BM3: NG (t-CO2/MWh-ethanol) | BN3: Total input (t-CO2/MWh-ethanol) | BP3: Ethanol (t-CO2/MWh-ethanol) | BQ3: Process Emissions (t-CO2/MWh-ethanol) | BR3: Fuel Emissions (t-CO2/MWh-ethanol) | BS3: Process Captured (t-CO2/MWh-ethanol) | BT3: Fuel Captured (t-CO2/MWh-ethanol) | BU3: Total Output (t-CO2/MWh-ethanol) | BW3: Carbon INPUT - OUTPUT
B4: CEN_Bio_Ethanol_Herb | C4: Biomass_Herb | D4: 0.2142 | E4: 0 | F4: 1.9848 | G4: 0 | H4: 1.723 | I4: 0 | J4: 1.2657602 | K4: 0 | L4: 0 | M4: 273134.22 | N4: 144062.46 | O4: 0.45 | Q4: 0 | R4: 6.223991 | S4: 100 | T4: 72.304369 | U4: 59.390495 | V4: 42.94088 | W4: 45.289647 | X4: 45.289647 | Y4: 22.958189 | Z4: 28.593352 | AB4: 51.059951 | AC4: 51.059951 | AD4: 107.87677 | AE4: 107.87677 | AF4: 96.945356 | AG4: 96.945356 | AH4: 14.066295 | AI4: 14.066295 | AJ4: 0 | AK4: 5000 | AM4: =B4 | AN4: =C4 | AO4: =SUM(AT4:AZ4)+BB4+BC4 | AP4: =SUM(AT4:AZ4)+BE4+BF4 | AQ4: =AO4/3.6 | AR4: =AP4/3.6 | AS4: =AO4-AP4 | AT4: =D4/F4*Y4*-1 | AU4: =E4/F4*Y4 | AV4: {=_xlfn.IFS(C4="Biomass_Corn", 1/F4*S4, C4="Biomass_Agri", 1/F4*V4, C4="Biomass_Wood", 1/F4*U4, C4="Biomass_Herb", 1/F4*T4)} | AW4: =G4/F4*AH4 | AX4: =M4/F4/(0.9*8760) | AY4: =N4/F4/(0.9*8760) | AZ4: =O4/F4 | BA4: =BP4+BQ4+BS4-BL4+BR4+BT4 | BB4: =(Q4+R4)*-1*(I4+K4)/F4 | BC4: =BA4*Q4 | BD4: =SUM(BP4:BR4)-BL4 | BE4: =(I4+K4)/F4*-1*R4 | BF4: =BD4*Q4 | BH4: =H4 | BI4: 0.18104824 | BJ4: 0.23037491 | BL4: =BH4/F4 | BM4: =BI4*G4/F4 | BN4: =SUM(BL4:BM4) | BP4: =BJ4 | BQ4: =J4/F4 | BR4: =L4/F4 | BS4: =I4/F4 | BT4: =K4/F4 | BU4: =SUM(BP4:BT4) | BW4: =BN4-BU4
B5: MIDAT_Bio_Ethanol_Herb | C5: Biomass_Herb | D5: 0.215 | E5: 0 | F5: 1.9924 | G5: 0 | H5: 1.736 | I5: 0 | J5: 1.2770045 | K5: 0 | L5: 0 | M5: 273134.22 | N5: 144062.46 | O5: 0.45 | Q5: 0 | R5: -14.741173 | S5: 100 | T5: 69.370717 | U5: 45.972292 | V5: 42.940257 | W5: 45.289647 | X5: 45.289647 | Y5: 35.672332 | Z5: 37.202448 | AB5: 51.059951 | AC5: 51.059951 | AD5: 107.87677 | AE5: 107.87677 | AF5: 96.945356 | AG5: 96.945356 | AH5: 15.046822 | AI5: 15.046822 | AJ5: 0 | AK5: 5000 | AM5: =B5 | AN5: =C5 | AO5: =SUM(AT5:AZ5)+BB5+BC5 | AP5: =SUM(AT5:AZ5)+BE5+BF5 | AQ5: =AO5/3.6 | AR5: =AP5/3.6 | AS5: =AO5-AP5 | AT5: =D5/F5*Y5*-1 | AU5: =E5/F5*Y5 | AV5: {=_xlfn.IFS(C5="Biomass_Corn", 1/F5*S5, C5="Biomass_Agri", 1/F5*V5, C5="Biomass_Wood", 1/F5*U5, C5="Biomass_Herb", 1/F5*T5)} | AW5: =G5/F5*AH5 | AX5: =M5/F5/(0.9*8760) | AY5: =N5/F5/(0.9*8760) | AZ5: =O5/F5 | BA5: =BP5+BQ5+BS5-BL5+BR5+BT5 | BB5: =(Q5+R5)*-1*(I5+K5)/F5 | BC5: =BA5*Q5 | BD5: =SUM(BP5:BR5)-BL5 | BE5: =(I5+K5)/F5*-1*R5 | BF5: =BD5*Q5 | BH5: =H5 | BI5: 0.18104824 | BJ5: 0.23037491 | BL5: =BH5/F5 | BM5: =BI5*G5/F5 | BN5: =SUM(BL5:BM5) | BP5: =BJ5 | BQ5: =J5/F5 | BR5: =L5/F5 | BS5: =I5/F5 | BT5: =K5/F5 | BU5: =SUM(BP5:BT5) | BW5: =BN5-BU5
B6: NCEN_Bio_Ethanol_Herb | C6: Biomass_Herb | D6: 0.2155 | E6: 0 | F6: 1.9967 | G6: 0 | H6: 1.74 | I6: 0 | J6: 1.2800012 | K6: 0 | L6: 0 | M6: 273134.22 | N6: 144062.46 | O6: 0.45 | Q6: 0 | R6: -0.911528 | S6: 100 | T6: 69.911137 | U6: 44.79442 | V6: 43.323942 | W6: 45.289647 | X6: 45.289647 | Y6: 29.249237 | Z6: 34.631601 | AB6: 51.059951 | AC6: 51.059951 | AD6: 107.87677 | AE6: 107.87677 | AF6: 96.945356 | AG6: 96.945356 | AH6: 14.089942 | AI6: 14.089942 | AJ6: 0 | AK6: 5000 | AM6: =B6 | AN6: =C6 | AO6: =SUM(AT6:AZ6)+BB6+BC6 | AP6: =SUM(AT6:AZ6)+BE6+BF6 | AQ6: =AO6/3.6 | AR6: =AP6/3.6 | AS6: =AO6-AP6 | AT6: =D6/F6*Y6*-1 | AU6: =E6/F6*Y6 | AV6: {=_xlfn.IFS(C6="Biomass_Corn", 1/F6*S6, C6="Biomass_Agri", 1/F6*V6, C6="Biomass_Wood", 1/F6*U6, C6="Biomass_Herb", 1/F6*T6)} | AW6: =G6/F6*AH6 | AX6: =M6/F6/(0.9*8760) | AY6: =N6/F6/(0.9*8760) | AZ6: =O6/F6 | BA6: =BP6+BQ6+BS6-BL6+BR6+BT6 | BB6: =(Q6+R6)*-1*(I6+K6)/F6 | BC6: =BA6*Q6 | BD6: =SUM(BP6:BR6)-BL6 | BE6: =(I6+K6)/F6*-1*R6 | BF6: =BD6*Q6 | BH6: =H6 | BI6: 0.18104824 | BJ6: 0.23037491 | BL6: =BH6/F6 | BM6: =BI6*G6/F6 | BN6: =SUM(BL6:BM6) | BP6: =BJ6 | BQ6: =J6/F6 | BR6: =L6/F6 | BS6: =I6/F6 | BT6: =K6/F6 | BU6: =SUM(BP6:BT6) | BW6: =BN6-BU6
B7: SE_Bio_Ethanol_Herb | C7: Biomass_Herb | D7: 0.2138 | E7: 0 | F7: 1.9815 | G7: 0 | H7: 1.717 | I7: 0 | J7: 1.2605127 | K7: 0 | L7: 0 | M7: 273134.22 | N7: 144062.46 | O7: 0.45 | Q7: 0 | R7: -5.914702 | S7: 100 | T7: 69.166622 | U7: 46.05675 | V7: 41.170372 | W7: 45.289647 | X7: 45.289647 | Y7: 33.298446 | Z7: 36.471022 | AB7: 51.059951 | AC7: 51.059951 | AD7: 107.87677 | AE7: 107.87677 | AF7: 96.945356 | AG7: 96.945356 | AH7: 14.089638 | AI7: 14.089638 | AJ7: 0 | AK7: 5000 | AM7: =B7 | AN7: =C7 | AO7: =SUM(AT7:AZ7)+BB7+BC7 | AP7: =SUM(AT7:AZ7)+BE7+BF7 | AQ7: =AO7/3.6 | AR7: =AP7/3.6 | AS7: =AO7-AP7 | AT7: =D7/F7*Y7*-1 | AU7: =E7/F7*Y7 | AV7: {=_xlfn.IFS(C7="Biomass_Corn", 1/F7*S7, C7="Biomass_Agri", 1/F7*V7, C7="Biomass_Wood", 1/F7*U7, C7="Biomass_Herb", 1/F7*T7)} | AW7: =G7/F7*AH7 | AX7: =M7/F7/(0.9*8760) | AY7: =N7/F7/(0.9*8760) | AZ7: =O7/F7 | BA7: =BP7+BQ7+BS7-BL7+BR7+BT7 | BB7: =(Q7+R7)*-1*(I7+K7)/F7 | BC7: =BA7*Q7 | BD7: =SUM(BP7:BR7)-BL7 | BE7: =(I7+K7)/F7*-1*R7 | BF7: =BD7*Q7 | BH7: =H7 | BI7: 0.18104824 | BJ7: 0.23037491 | BL7: =BH7/F7 | BM7: =BI7*G7/F7 | BN7: =SUM(BL7:BM7) | BP7: =BJ7 | BQ7: =J7/F7 | BR7: =L7/F7 | BS7: =I7/F7 | BT7: =K7/F7 | BU7: =SUM(BP7:BT7) | BW7: =BN7-BU7
B8: TX_Bio_Ethanol_Herb | C8: Biomass_Herb | D8: 0.2132 | E8: 0 | F8: 1.9761 | G8: 0 | H8: 1.714 | I8: 0 | J8: 1.2587667 | K8: 0 | L8: 0 | M8: 273134.22 | N8: 144062.46 | O8: 0.45 | Q8: 0 | R8: 14.732097 | S8: 100 | T8: 73.00646 | U8: 69.643664 | V8: 43.030303 | W8: 45.289647 | X8: 45.289647 | Y8: 19.019146 | Z8: 23.790747 | AB8: 51.059951 | AC8: 51.059951 | AD8: 107.87677 | AE8: 107.87677 | AF8: 96.945356 | AG8: 96.945356 | AH8: 13.326077 | AI8: 13.326077 | AJ8: 0 | AK8: 5000 | AM8: =B8 | AN8: =C8 | AO8: =SUM(AT8:AZ8)+BB8+BC8 | AP8: =SUM(AT8:AZ8)+BE8+BF8 | AQ8: =AO8/3.6 | AR8: =AP8/3.6 | AS8: =AO8-AP8 | AT8: =D8/F8*Y8*-1 | AU8: =E8/F8*Y8 | AV8: {=_xlfn.IFS(C8="Biomass_Corn", 1/F8*S8, C8="Biomass_Agri", 1/F8*V8, C8="Biomass_Wood", 1/F8*U8, C8="Biomass_Herb", 1/F8*T8)} | AW8: =G8/F8*AH8 | AX8: =M8/F8/(0.9*8760) | AY8: =N8/F8/(0.9*8760) | AZ8: =O8/F8 | BA8: =BP8+BQ8+BS8-BL8+BR8+BT8 | BB8: =(Q8+R8)*-1*(I8+K8)/F8 | BC8: =BA8*Q8 | BD8: =SUM(BP8:BR8)-BL8 | BE8: =(I8+K8)/F8*-1*R8 | BF8: =BD8*Q8 | BH8: =H8 | BI8: 0.18104824 | BJ8: 0.23037491 | BL8: =BH8/F8 | BM8: =BI8*G8/F8 | BN8: =SUM(BL8:BM8) | BP8: =BJ8 | BQ8: =J8/F8 | BR8: =L8/F8 | BS8: =I8/F8 | BT8: =K8/F8 | BU8: =SUM(BP8:BT8) | BW8: =BN8-BU8
B9: CEN_Bio_Ethanol_Wood | C9: Biomass_Wood | D9: 0.2241 | E9: 0 | F9: 2.0762 | G9: 0 | H9: 1.802 | I9: 0 | J9: 1.3236916 | K9: 0 | L9: 0 | M9: 273134.22 | N9: 144062.46 | O9: 0.45 | Q9: 0 | R9: 6.223991 | S9: 100 | T9: 72.304369 | U9: 59.390495 | V9: 42.94088 | W9: 45.289647 | X9: 45.289647 | Y9: 22.958189 | Z9: 28.593352 | AB9: 51.059951 | AC9: 51.059951 | AD9: 107.87677 | AE9: 107.87677 | AF9: 96.945356 | AG9: 96.945356 | AH9: 14.066295 | AI9: 14.066295 | AJ9: 0 | AK9: 5000 | AM9: =B9 | AN9: =C9 | AO9: =SUM(AT9:AZ9)+BB9+BC9 | AP9: =SUM(AT9:AZ9)+BE9+BF9 | AQ9: =AO9/3.6 | AR9: =AP9/3.6 | AS9: =AO9-AP9 | AT9: =D9/F9*Y9*-1 | AU9: =E9/F9*Y9 | AV9: {=_xlfn.IFS(C9="Biomass_Corn", 1/F9*S9, C9="Biomass_Agri", 1/F9*V9, C9="Biomass_Wood", 1/F9*U9, C9="Biomass_Herb", 1/F9*T9)} | AW9: =G9/F9*AH9 | AX9: =M9/F9/(0.9*8760) | AY9: =N9/F9/(0.9*8760) | AZ9: =O9/F9 | BA9: =BP9+BQ9+BS9-BL9+BR9+BT9 | BB9: =(Q9+R9)*-1*(I9+K9)/F9 | BC9: =BA9*Q9 | BD9: =SUM(BP9:BR9)-BL9 | BE9: =(I9+K9)/F9*-1*R9 | BF9: =BD9*Q9 | BH9: =H9 | BI9: 0.18104824 | BJ9: 0.23037491 | BL9: =BH9/F9 | BM9: =BI9*G9/F9 | BN9: =SUM(BL9:BM9) | BP9: =BJ9 | BQ9: =J9/F9 | BR9: =L9/F9 | BS9: =I9/F9 | BT9: =K9/F9 | BU9: =SUM(BP9:BT9) | BW9: =BN9-BU9
B10: MIDAT_Bio_Ethanol_Wood | C10: Biomass_Wood | D10: 0.2233 | E10: 0 | F10: 2.0697 | G10: 0 | H10: 1.806 | I10: 0 | J10: 1.3291965 | K10: 0 | L10: 0 | M10: 273134.22 | N10: 144062.46 | O10: 0.45 | Q10: 0 | R10: -14.741173 | S10: 100 | T10: 69.370717 | U10: 45.972292 | V10: 42.940257 | W10: 45.289647 | X10: 45.289647 | Y10: 35.672332 | Z10: 37.202448 | AB10: 51.059951 | AC10: 51.059951 | AD10: 107.87677 | AE10: 107.87677 | AF10: 96.945356 | AG10: 96.945356 | AH10: 15.046822 | AI10: 15.046822 | AJ10: 0 | AK10: 5000 | AM10: =B10 | AN10: =C10 | AO10: =SUM(AT10:AZ10)+BB10+BC10 | AP10: =SUM(AT10:AZ10)+BE10+BF10 | AQ10: =AO10/3.6 | AR10: =AP10/3.6 | AS10: =AO10-AP10 | AT10: =D10/F10*Y10*-1 | AU10: =E10/F10*Y10 | AV10: {=_xlfn.IFS(C10="Biomass_Corn", 1/F10*S10, C10="Biomass_Agri", 1/F10*V10, C10="Biomass_Wood", 1/F10*U10, C10="Biomass_Herb", 1/F10*T10)} | AW10: =G10/F10*AH10 | AX10: =M10/F10/(0.9*8760) | AY10: =N10/F10/(0.9*8760) | AZ10: =O10/F10 | BA10: =BP10+BQ10+BS10-BL10+BR10+BT10 | BB10: =(Q10+R10)*-1*(I10+K10)/F10 | BC10: =BA10*Q10 | BD10: =SUM(BP10:BR10)-BL10 | BE10: =(I10+K10)/F10*-1*R10 | BF10: =BD10*Q10 | BH10: =H10 | BI10: 0.18104824 | BJ10: 0.23037491 | BL10: =BH10/F10 | BM10: =BI10*G10/F10 | BN10: =SUM(BL10:BM10) | BP10: =BJ10 | BQ10: =J10/F10 | BR10: =L10/F10 | BS10: =I10/F10 | BT10: =K10/F10 | BU10: =SUM(BP10:BT10) | BW10: =BN10-BU10
B11: NCEN_Bio_Ethanol_Wood | C11: Biomass_Wood | D11: 0.2239 | E11: 0 | F11: 2.0751 | G11: 0 | H11: 1.802 | I11: 0 | J11: 1.3239424 | K11: 0 | L11: 0 | M11: 273134.22 | N11: 144062.46 | O11: 0.45 | Q11: 0 | R11: -0.911528 | S11: 100 | T11: 69.911137 | U11: 44.79442 | V11: 43.323942 | W11: 45.289647 | X11: 45.289647 | Y11: 29.249237 | Z11: 34.631601 | AB11: 51.059951 | AC11: 51.059951 | AD11: 107.87677 | AE11: 107.87677 | AF11: 96.945356 | AG11: 96.945356 | AH11: 14.089942 | AI11: 14.089942 | AJ11: 0 | AK11: 5000 | AM11: =B11 | AN11: =C11 | AO11: =SUM(AT11:AZ11)+BB11+BC11 | AP11: =SUM(AT11:AZ11)+BE11+BF11 | AQ11: =AO11/3.6 | AR11: =AP11/3.6 | AS11: =AO11-AP11 | AT11: =D11/F11*Y11*-1 | AU11: =E11/F11*Y11 | AV11: {=_xlfn.IFS(C11="Biomass_Corn", 1/F11*S11, C11="Biomass_Agri", 1/F11*V11, C11="Biomass_Wood", 1/F11*U11, C11="Biomass_Herb", 1/F11*T11)} | AW11: =G11/F11*AH11 | AX11: =M11/F11/(0.9*8760) | AY11: =N11/F11/(0.9*8760) | AZ11: =O11/F11 | BA11: =BP11+BQ11+BS11-BL11+BR11+BT11 | BB11: =(Q11+R11)*-1*(I11+K11)/F11 | BC11: =BA11*Q11 | BD11: =SUM(BP11:BR11)-BL11 | BE11: =(I11+K11)/F11*-1*R11 | BF11: =BD11*Q11 | BH11: =H11 | BI11: 0.18104824 | BJ11: 0.23037491 | BL11: =BH11/F11 | BM11: =BI11*G11/F11 | BN11: =SUM(BL11:BM11) | BP11: =BJ11 | BQ11: =J11/F11 | BR11: =L11/F11 | BS11: =I11/F11 | BT11: =K11/F11 | BU11: =SUM(BP11:BT11) | BW11: =BN11-BU11
B12: SE_Bio_Ethanol_Wood | C12: Biomass_Wood | D12: 0.2249 | E12: 0 | F12: 2.0838 | G12: 0 | H12: 1.821 | I12: 0 | J12: 1.3409358 | K12: 0 | L12: 0 | M12: 273134.22 | N12: 144062.46 | O12: 0.45 | Q12: 0 | R12: -5.914702 | S12: 100 | T12: 69.166622 | U12: 46.05675 | V12: 41.170372 | W12: 45.289647 | X12: 45.289647 | Y12: 33.298446 | Z12: 36.471022 | AB12: 51.059951 | AC12: 51.059951 | AD12: 107.87677 | AE12: 107.87677 | AF12: 96.945356 | AG12: 96.945356 | AH12: 14.089638 | AI12: 14.089638 | AJ12: 0 | AK12: 5000 | AM12: =B12 | AN12: =C12 | AO12: =SUM(AT12:AZ12)+BB12+BC12 | AP12: =SUM(AT12:AZ12)+BE12+BF12 | AQ12: =AO12/3.6 | AR12: =AP12/3.6 | AS12: =AO12-AP12 | AT12: =D12/F12*Y12*-1 | AU12: =E12/F12*Y12 | AV12: {=_xlfn.IFS(C12="Biomass_Corn", 1/F12*S12, C12="Biomass_Agri", 1/F12*V12, C12="Biomass_Wood", 1/F12*U12, C12="Biomass_Herb", 1/F12*T12)} | AW12: =G12/F12*AH12 | AX12: =M12/F12/(0.9*8760) | AY12: =N12/F12/(0.9*8760) | AZ12: =O12/F12 | BA12: =BP12+BQ12+BS12-BL12+BR12+BT12 | BB12: =(Q12+R12)*-1*(I12+K12)/F12 | BC12: =BA12*Q12 | BD12: =SUM(BP12:BR12)-BL12 | BE12: =(I12+K12)/F12*-1*R12 | BF12: =BD12*Q12 | BH12: =H12 | BI12: 0.18104824 | BJ12: 0.23037491 | BL12: =BH12/F12 | BM12: =BI12*G12/F12 | BN12: =SUM(BL12:BM12) | BP12: =BJ12 | BQ12: =J12/F12 | BR12: =L12/F12 | BS12: =I12/F12 | BT12: =K12/F12 | BU12: =SUM(BP12:BT12) | BW12: =BN12-BU12
B13: TX_Bio_Ethanol_Wood | C13: Biomass_Wood | D13: 0.2221 | E13: 0 | F13: 2.0577 | G13: 0 | H13: 1.821 | I13: 0 | J13: 1.3469554 | K13: 0 | L13: 0 | M13: 273134.22 | N13: 144062.46 | O13: 0.45 | Q13: 0 | R13: 14.732097 | S13: 100 | T13: 73.00646 | U13: 69.643664 | V13: 43.030303 | W13: 45.289647 | X13: 45.289647 | Y13: 19.019146 | Z13: 23.790747 | AB13: 51.059951 | AC13: 51.059951 | AD13: 107.87677 | AE13: 107.87677 | AF13: 96.945356 | AG13: 96.945356 | AH13: 13.326077 | AI13: 13.326077 | AJ13: 0 | AK13: 5000 | AM13: =B13 | AN13: =C13 | AO13: =SUM(AT13:AZ13)+BB13+BC13 | AP13: =SUM(AT13:AZ13)+BE13+BF13 | AQ13: =AO13/3.6 | AR13: =AP13/3.6 | AS13: =AO13-AP13 | AT13: =D13/F13*Y13*-1 | AU13: =E13/F13*Y13 | AV13: {=_xlfn.IFS(C13="Biomass_Corn", 1/F13*S13, C13="Biomass_Agri", 1/F13*V13, C13="Biomass_Wood", 1/F13*U13, C13="Biomass_Herb", 1/F13*T13)} | AW13: =G13/F13*AH13 | AX13: =M13/F13/(0.9*8760) | AY13: =N13/F13/(0.9*8760) | AZ13: =O13/F13 | BA13: =BP13+BQ13+BS13-BL13+BR13+BT13 | BB13: =(Q13+R13)*-1*(I13+K13)/F13 | BC13: =BA13*Q13 | BD13: =SUM(BP13:BR13)-BL13 | BE13: =(I13+K13)/F13*-1*R13 | BF13: =BD13*Q13 | BH13: =H13 | BI13: 0.18104824 | BJ13: 0.23037491 | BL13: =BH13/F13 | BM13: =BI13*G13/F13 | BN13: =SUM(BL13:BM13) | BP13: =BJ13 | BQ13: =J13/F13 | BR13: =L13/F13 | BS13: =I13/F13 | BT13: =K13/F13 | BU13: =SUM(BP13:BT13) | BW13: =BN13-BU13
B14: CEN_Bio_Ethanol_Agri | C14: Biomass_Agri | D14: 0.2017 | E14: 0 | F14: 1.8694 | G14: 0 | H14: 1.7 | I14: 0 | J14: 1.2693468 | K14: 0 | L14: 0 | M14: 273134.22 | N14: 144062.46 | O14: 0.45 | Q14: 0 | R14: 6.223991 | S14: 100 | T14: 72.304369 | U14: 59.390495 | V14: 42.94088 | W14: 45.289647 | X14: 45.289647 | Y14: 22.958189 | Z14: 28.593352 | AB14: 51.059951 | AC14: 51.059951 | AD14: 107.87677 | AE14: 107.87677 | AF14: 96.945356 | AG14: 96.945356 | AH14: 14.066295 | AI14: 14.066295 | AJ14: 0 | AK14: 5000 | AM14: =B14 | AN14: =C14 | AO14: =SUM(AT14:AZ14)+BB14+BC14 | AP14: =SUM(AT14:AZ14)+BE14+BF14 | AQ14: =AO14/3.6 | AR14: =AP14/3.6 | AS14: =AO14-AP14 | AT14: =D14/F14*Y14*-1 | AU14: =E14/F14*Y14 | AV14: {=_xlfn.IFS(C14="Biomass_Corn", 1/F14*S14, C14="Biomass_Agri", 1/F14*V14, C14="Biomass_Wood", 1/F14*U14, C14="Biomass_Herb", 1/F14*T14)} | AW14: =G14/F14*AH14 | AX14: =M14/F14/(0.9*8760) | AY14: =N14/F14/(0.9*8760) | AZ14: =O14/F14 | BA14: =BP14+BQ14+BS14-BL14+BR14+BT14 | BB14: =(Q14+R14)*-1*(I14+K14)/F14 | BC14: =BA14*Q14 | BD14: =SUM(BP14:BR14)-BL14 | BE14: =(I14+K14)/F14*-1*R14 | BF14: =BD14*Q14 | BH14: =H14 | BI14: 0.18104824 | BJ14: 0.23037491 | BL14: =BH14/F14 | BM14: =BI14*G14/F14 | BN14: =SUM(BL14:BM14) | BP14: =BJ14 | BQ14: =J14/F14 | BR14: =L14/F14 | BS14: =I14/F14 | BT14: =K14/F14 | BU14: =SUM(BP14:BT14) | BW14: =BN14-BU14
B15: MIDAT_Bio_Ethanol_Agri | C15: Biomass_Agri | D15: 0.203 | E15: 0 | F15: 1.8813 | G15: 0 | H15: 1.708 | I15: 0 | J15: 1.2745878 | K15: 0 | L15: 0 | M15: 273134.22 | N15: 144062.46 | O15: 0.45 | Q15: 0 | R15: -14.741173 | S15: 100 | T15: 69.370717 | U15: 45.972292 | V15: 42.940257 | W15: 45.289647 | X15: 45.289647 | Y15: 35.672332 | Z15: 37.202448 | AB15: 51.059951 | AC15: 51.059951 | AD15: 107.87677 | AE15: 107.87677 | AF15: 96.945356 | AG15: 96.945356 | AH15: 15.046822 | AI15: 15.046822 | AJ15: 0 | AK15: 5000 | AM15: =B15 | AN15: =C15 | AO15: =SUM(AT15:AZ15)+BB15+BC15 | AP15: =SUM(AT15:AZ15)+BE15+BF15 | AQ15: =AO15/3.6 | AR15: =AP15/3.6 | AS15: =AO15-AP15 | AT15: =D15/F15*Y15*-1 | AU15: =E15/F15*Y15 | AV15: {=_xlfn.IFS(C15="Biomass_Corn", 1/F15*S15, C15="Biomass_Agri", 1/F15*V15, C15="Biomass_Wood", 1/F15*U15, C15="Biomass_Herb", 1/F15*T15)} | AW15: =G15/F15*AH15 | AX15: =M15/F15/(0.9*8760) | AY15: =N15/F15/(0.9*8760) | AZ15: =O15/F15 | BA15: =BP15+BQ15+BS15-BL15+BR15+BT15 | BB15: =(Q15+R15)*-1*(I15+K15)/F15 | BC15: =BA15*Q15 | BD15: =SUM(BP15:BR15)-BL15 | BE15: =(I15+K15)/F15*-1*R15 | BF15: =BD15*Q15 | BH15: =H15 | BI15: 0.18104824 | BJ15: 0.23037491 | BL15: =BH15/F15 | BM15: =BI15*G15/F15 | BN15: =SUM(BL15:BM15) | BP15: =BJ15 | BQ15: =J15/F15 | BR15: =L15/F15 | BS15: =I15/F15 | BT15: =K15/F15 | BU15: =SUM(BP15:BT15) | BW15: =BN15-BU15
... B48: TX_Bio_Ethanol_CCS_86_Agri | C48: Biomass_Agri | D48: 0 | E48: 0.2632 | F48: 1.8062 | G48: 0 | H48: 1.633 | I48: 1.0492062 | J48: 0.16768802 | K48: 0 | L48: 0 | M48: 520155.64 | N48: 279265.62 | O48: 1.67 | Q48: 0 | R48: 14.732097 | S48: 100 | T48: 73.00646 | U48: 69.643664 | V48: 43.030303 | W48: 45.289647 | X48: 45.289647 | Y48: 19.019146 | Z48: 23.790747 | AB48: 51.059951 | AC48: 51.059951 | AD48: 107.87677 | AE48: 107.87677 | AF48: 96.945356 | AG48: 96.945356 | AH48: 13.326077 | AI48: 13.326077 | AJ48: 0 | AK48: 5000 | AM48: =B48 | AN48: =C48 | AO48: =SUM(AT48:AZ48)+BB48+BC48 | AP48: =SUM(AT48:AZ48)+BE48+BF48 | AQ48: =AO48/3.6 | AR48: =AP48/3.6 | AS48: =AO48-AP48 | AT48: =D48/F48*Y48*-1 | AU48: =E48/F48*Y48 | AV48: {=_xlfn.IFS(C48="Biomass_Corn", 1/F48*S48, C48="Biomass_Agri", 1/F48*V48, C48="Biomass_Wood", 1/F48*U48, C48="Biomass_Herb", 1/F48*T48)} | AW48: =G48/F48*AH48 | AX48: =M48/F48/(0.9*8760) | AY48: =N48/F48/(0.9*8760) | AZ48: =O48/F48 | BA48: =BP48+BQ48+BS48-BL48+BR48+BT48 | BB48: =(Q48+R48)*-1*(I48+K48)/F48 | BC48: =BA48*Q48 | BD48: =SUM(BP48:BR48)-BL48 | BE48: =(I48+K48)/F48*-1*R48 | BF48: =BD48*Q48 | BH48: =H48 | BI48: 0.18104824 | BJ48: 0.23037491 | BL48: =BH48/F48 | BM48: =BI48*G48/F48 | BN48: =SUM(BL48:BM48) | BP48: =BJ48 | BQ48: =J48/F48 | BR48: =L48/F48 | BS48: =I48/F48 | BT48: =K48/F48 | BU48: =SUM(BP48:BT48) | BW48: =BN48-BU48
B49: CA_DryMill_Existing_Non_CCS | C49: Biomass_Corn | D49: 0 | E49: 0.085342825 | F49: 3.104338 | G49: 1.0133975 | H49: 1.7588667 | I49: 0 | J49: 1.0437051 | K49: 0 | L49: 0.18534112 | M49: 322562.05 | N49: 176727.97 | O49: -25.41 | Q49: 0 | R49: -16.309543 | S49: 100 | U49: 39.347116 | V49: 34.413449 | W49: 45.289647 | X49: 45.289647 | Y49: 39.400687 | Z49: 35.007561 | AB49: 51.059951 | AC49: 51.059951 | AD49: 107.87677 | AE49: 107.87677 | AF49: 96.945356 | AG49: 96.945356 | AH49: 16.900485 | AI49: 16.900485 | AJ49: 0 | AK49: 5000 | AM49: =B49 | AN49: =C49 | AO49: =SUM(AT49:AZ49)+BB49+BC49 | AP49: =SUM(AT49:AZ49)+BE49+BF49 | AQ49: =AO49/3.6 | AR49: =AP49/3.6 | AS49: =AO49-AP49 | AT49: =D49/F49*Y49*-1 | AU49: =E49/F49*Y49 | AV49: {=_xlfn.IFS(C49="Biomass_Corn", 1/F49*S49, C49="Biomass_Agri", 1/F49*V49, C49="Biomass_Wood", 1/F49*U49, C49="Biomass_Herb", 1/F49*T49)} | AW49: =G49/F49*AH49 | AX49: =M49/F49/(0.9*8760) | AY49: =N49/F49/(0.9*8760) | AZ49: =O49/F49 | BA49: =BP49+BQ49+BS49-BL49+BR49+BT49 | BB49: =(Q49+R49)*-1*(I49+K49)/F49 | BC49: =BA49*Q49 | BD49: =SUM(BP49:BR49)-BL49 | BE49: =(I49+K49)/F49*-1*R49 | BF49: =BD49*Q49 | BH49: =H49 | BI49: 0.18104824 | BJ49: 0.23037491 | BL49: =BH49/F49 | BM49: =BI49*G49/F49 | BN49: =SUM(BL49:BM49) | BP49: =BJ49 | BQ49: =J49/F49 | BR49: =L49/F49 | BS49: =I49/F49 | BT49: =K49/F49 | BU49: =SUM(BP49:BT49) | BW49: =BN49-BU49
B50: NW_DryMill_Existing_Non_CCS | C50: Biomass_Corn | D50: 0 | E50: 0.085342825 | F50: 3.104338 | G50: 1.0133975 | H50: 1.7588667 | I50: 0 | J50: 1.0437051 | K50: 0 | L50: 0.18534112 | M50: 322562.05 | N50: 176727.97 | O50: -25.41 | Q50: 0 | R50: -3.557382 | S50: 100 | T50: 70.610863 | U50: 48.120714 | V50: 39.234002 | W50: 45.289647 | X50: 45.289647 | Y50: 28.009811 | Z50: 31.329838 | AB50: 51.059951 | AC50: 51.059951 | AD50: 107.87677 | AE50: 107.87677 | AF50: 96.945356 | AG50: 96.945356 | AH50: 15.780879 | AI50: 15.780879 | AJ50: 0 | AK50: 5000 | AM50: =B50 | AN50: =C50 | AO50: =SUM(AT50:AZ50)+BB50+BC50 | AP50: =SUM(AT50:AZ50)+BE50+BF50 | AQ50: =AO50/3.6 | AR50: =AP50/3.6 | AS50: =AO50-AP50 | AT50: =D50/F50*Y50*-1 | AU50: =E50/F50*Y50 | AV50: {=_xlfn.IFS(C50="Biomass_Corn", 1/F50*S50, C50="Biomass_Agri", 1/F50*V50, C50="Biomass_Wood", 1/F50*U50, C50="Biomass_Herb", 1/F50*T50)} | AW50: =G50/F50*AH50 | AX50: =M50/F50/(0.9*8760) | AY50: =N50/F50/(0.9*8760) | AZ50: =O50/F50 | BA50: =BP50+BQ50+BS50-BL50+BR50+BT50 | BB50: =(Q50+R50)*-1*(I50+K50)/F50 | BC50: =BA50*Q50 | BD50: =SUM(BP50:BR50)-BL50 | BE50: =(I50+K50)/F50*-1*R50 | BF50: =BD50*Q50 | BH50: =H50 | BI50: 0.18104824 | BJ50: 0.23037491 | BL50: =BH50/F50 | BM50: =BI50*G50/F50 | BN50: =SUM(BL50:BM50) | BP50: =BJ50 | BQ50: =J50/F50 | BR50: =L50/F50 | BS50: =I50/F50 | BT50: =K50/F50 | BU50: =SUM(BP50:BT50) | BW50: =BN50-BU50
B51: SW_DryMill_Existing_Non_CCS | C51: Biomass_Corn | D51: 0 | E51: 0.085342825 | F51: 3.104338 | G51: 1.0133975 | H51: 1.7588667 | I51: 0 | J51: 1.0437051 | K51: 0 | L51: 0.18534112 | M51: 322562.05 | N51: 176727.97 | O51: -25.41 | Q51: 0 | R51: -6.203351 | S51: 100 | T51: 67.594672 | U51: 47.542838 | V51: 39.757567 | W51: 45.289647 | X51: 45.289647 | Y51: 27.4329 | Z51: 29.313567 | AB51: 51.059951 | AC51: 51.059951 | AD51: 107.87677 | AE51: 107.87677 | AF51: 96.945356 | AG51: 96.945356 | AH51: 15.780712 | AI51: 15.780712 | AJ51: 0 | AK51: 5000 | AM51: =B51 | AN51: =C51 | AO51: =SUM(AT51:AZ51)+BB51+BC51 | AP51: =SUM(AT51:AZ51)+BE51+BF51 | AQ51: =AO51/3.6 | AR51: =AP51/3.6 | AS51: =AO51-AP51 | AT51: =D51/F51*Y51*-1 | AU51: =E51/F51*Y51 | AV51: {=_xlfn.IFS(C51="Biomass_Corn", 1/F51*S51, C51="Biomass_Agri", 1/F51*V51, C51="Biomass_Wood", 1/F51*U51, C51="Biomass_Herb", 1/F51*T51)} | AW51: =G51/F51*AH51 | AX51: =M51/F51/(0.9*8760) | AY51: =N51/F51/(0.9*8760) | AZ51: =O51/F51 | BA51: =BP51+BQ51+BS51-BL51+BR51+BT51 | BB51: =(Q51+R51)*-1*(I51+K51)/F51 | BC51: =BA51*Q51 | BD51: =SUM(BP51:BR51)-BL51 | BE51: =(I51+K51)/F51*-1*R51 | BF51: =BD51*Q51 | BH51: =H51 | BI51: 0.18104824 | BJ51: 0.23037491 | BL51: =BH51/F51 | BM51: =BI51*G51/F51 | BN51: =SUM(BL51:BM51) | BP51: =BJ51 | BQ51: =J51/F51 | BR51: =L51/F51 | BS51: =I51/F51 | BT51: =K51/F51 | BU51: =SUM(BP51:BT51) | BW51: =BN51-BU51
B52: TX_DryMill_Existing_Non_CCS | C52: Biomass_Corn | D52: 0 | E52: 0.085342825 | F52: 3.104338 | G52: 1.0133975 | H52: 1.7588667 | I52: 0 | J52: 1.0437051 | K52: 0 | L52: 0.18534112 | M52: 322562.05 | N52: 176727.97 | O52: -25.41 | Q52: 0 | R52: 14.732097 | S52: 100 | T52: 73.00646 | U52: 69.643664 | V52: 43.030303 | W52: 45.289647 | X52: 45.289647 | Y52: 19.019146 | Z52: 23.790747 | AB52: 51.059951 | AC52: 51.059951 | AD52: 107.87677 | AE52: 107.87677 | AF52: 96.945356 | AG52: 96.945356 | AH52: 13.326077 | AI52: 13.326077 | AJ52: 0 | AK52: 5000 | AM52: =B52 | AN52: =C52 | AO52: =SUM(AT52:AZ52)+BB52+BC52 | AP52: =SUM(AT52:AZ52)+BE52+BF52 | AQ52: =AO52/3.6 | AR52: =AP52/3.6 | AS52: =AO52-AP52 | AT52: =D52/F52*Y52*-1 | AU52: =E52/F52*Y52 | AV52: {=_xlfn.IFS(C52="Biomass_Corn", 1/F52*S52, C52="Biomass_Agri", 1/F52*V52, C52="Biomass_Wood", 1/F52*U52, C52="Biomass_Herb", 1/F52*T52)} | AW52: =G52/F52*AH52 | AX52: =M52/F52/(0.9*8760) | AY52: =N52/F52/(0.9*8760) | AZ52: =O52/F52 | BA52: =BP52+BQ52+BS52-BL52+BR52+BT52 | BB52: =(Q52+R52)*-1*(I52+K52)/F52 | BC52: =BA52*Q52 | BD52: =SUM(BP52:BR52)-BL52 | BE52: =(I52+K52)/F52*-1*R52 | BF52: =BD52*Q52 | BH52: =H52 | BI52: 0.18104824 | BJ52: 0.23037491 | BL52: =BH52/F52 | BM52: =BI52*G52/F52 | BN52: =SUM(BL52:BM52) | BP52: =BJ52 | BQ52: =J52/F52 | BR52: =L52/F52 | BS52: =I52/F52 | BT52: =K52/F52 | BU52: =SUM(BP52:BT52) | BW52: =BN52-BU52
B53: NCEN_DryMill_Existing_Non_CCS | C53: Biomass_Corn | D53: 0 | E53: 0.085342825 | F53: 3.104338 | G53: 1.0133975 | H53: 1.7588667 | I53: 0 | J53: 1.0437051 | K53: 0 | L53: 0.18534112 | M53: 322562.05 | N53: 176727.97 | O53: -25.41 | Q53: 0 | R53: -0.911528 | S53: 100 | T53: 69.911137 | U53: 44.79442 | V53: 43.323942 | W53: 45.289647 | X53: 45.289647 | Y53: 29.249237 | Z53: 34.631601 | AB53: 51.059951 | AC53: 51.059951 | AD53: 107.87677 | AE53: 107.87677 | AF53: 96.945356 | AG53: 96.945356 | AH53: 14.089942 | AI53: 14.089942 | AJ53: 0 | AK53: 5000 | AM53: =B53 | AN53: =C53 | AO53: =SUM(AT53:AZ53)+BB53+BC53 | AP53: =SUM(AT53:AZ53)+BE53+BF53 | AQ53: =AO53/3.6 | AR53: =AP53/3.6 | AS53: =AO53-AP53 | AT53: =D53/F53*Y53*-1 | AU53: =E53/F53*Y53 | AV53: {=_xlfn.IFS(C53="Biomass_Corn", 1/F53*S53, C53="Biomass_Agri", 1/F53*V53, C53="Biomass_Wood", 1/F53*U53, C53="Biomass_Herb", 1/F53*T53)} | AW53: =G53/F53*AH53 | AX53: =M53/F53/(0.9*8760) | AY53: =N53/F53/(0.9*8760) | AZ53: =O53/F53 | BA53: =BP53+BQ53+BS53-BL53+BR53+BT53 | BB53: =(Q53+R53)*-1*(I53+K53)/F53 | BC53: =BA53*Q53 | BD53: =SUM(BP53:BR53)-BL53 | BE53: =(I53+K53)/F53*-1*R53 | BF53: =BD53*Q53 | BH53: =H53 | BI53: 0.18104824 | BJ53: 0.23037491 | BL53: =BH53/F53 | BM53: =BI53*G53/F53 | BN53: =SUM(BL53:BM53) | BP53: =BJ53 | BQ53: =J53/F53 | BR53: =L53/F53 | BS53: =I53/F53 | BT53: =K53/F53 | BU53: =SUM(BP53:BT53) | BW53: =BN53-BU53
B54: CEN_DryMill_Existing_Non_CCS | C54: Biomass_Corn | D54: 0 | E54: 0.085342825 | F54: 3.104338 | G54: 1.0133975 | H54: 1.7588667 | I54: 0 | J54: 1.0437051 | K54: 0 | L54: 0.18534112 | M54: 322562.05 | N54: 176727.97 | O54: -25.41 | Q54: 0 | R54: 6.223991 | S54: 100 | T54: 72.304369 | U54: 59.390495 | V54: 42.94088 | W54: 45.289647 | X54: 45.289647 | Y54: 22.958189 | Z54: 28.593352 | AB54: 51.059951 | AC54: 51.059951 | AD54: 107.87677 | AE54: 107.87677 | AF54: 96.945356 | AG54: 96.945356 | AH54: 14.066295 | AI54: 14.066295 | AJ54: 0 | AK54: 5000 | AM54: =B54 | AN54: =C54 | AO54: =SUM(AT54:AZ54)+BB54+BC54 | AP54: =SUM(AT54:AZ54)+BE54+BF54 | AQ54: =AO54/3.6 | AR54: =AP54/3.6 | AS54: =AO54-AP54 | AT54: =D54/F54*Y54*-1 | AU54: =E54/F54*Y54 | AV54: {=_xlfn.IFS(C54="Biomass_Corn", 1/F54*S54, C54="Biomass_Agri", 1/F54*V54, C54="Biomass_Wood", 1/F54*U54, C54="Biomass_Herb", 1/F54*T54)} | AW54: =G54/F54*AH54 | AX54: =M54/F54/(0.9*8760) | AY54: =N54/F54/(0.9*8760) | AZ54: =O54/F54 | BA54: =BP54+BQ54+BS54-BL54+BR54+BT54 | BB54: =(Q54+R54)*-1*(I54+K54)/F54 | BC54: =BA54*Q54 | BD54: =SUM(BP54:BR54)-BL54 | BE54: =(I54+K54)/F54*-1*R54 | BF54: =BD54*Q54 | BH54: =H54 | BI54: 0.18104824 | BJ54: 0.23037491 | BL54: =BH54/F54 | BM54: =BI54*G54/F54 | BN54: =SUM(BL54:BM54) | BP54: =BJ54 | BQ54: =J54/F54 | BR54: =L54/F54 | BS54: =I54/F54 | BT54: =K54/F54 | BU54: =SUM(BP54:BT54) | BW54: =BN54-BU54
B55: SE_DryMill_Existing_Non_CCS | C55: Biomass_Corn | D55: 0 | E55: 0.085342825 | F55: 3.104338 | G55: 1.0133975 | H55: 1.7588667 | I55: 0 | J55: 1.0437051 | K55: 0 | L55: 0.18534112 | M55: 322562.05 | N55: 176727.97 | O55: -25.41 | Q55: 0 | R55: -5.914702 | S55: 100 | T55: 69.166622 | U55: 46.05675 | V55: 41.170372 | W55: 45.289647 | X55: 45.289647 | Y55: 33.298446 | Z55: 36.471022 | AB55: 51.059951 | AC55: 51.059951 | AD55: 107.87677 | AE55: 107.87677 | AF55: 96.945356 | AG55: 96.945356 | AH55: 14.089638 | AI55: 14.089638 | AJ55: 0 | AK55: 5000 | AM55: =B55 | AN55: =C55 | AO55: =SUM(AT55:AZ55)+BB55+BC55 | AP55: =SUM(AT55:AZ55)+BE55+BF55 | AQ55: =AO55/3.6 | AR55: =AP55/3.6 | AS55: =AO55-AP55 | AT55: =D55/F55*Y55*-1 | AU55: =E55/F55*Y55 | AV55: {=_xlfn.IFS(C55="Biomass_Corn", 1/F55*S55, C55="Biomass_Agri", 1/F55*V55, C55="Biomass_Wood", 1/F55*U55, C55="Biomass_Herb", 1/F55*T55)} | AW55: =G55/F55*AH55 | AX55: =M55/F55/(0.9*8760) | AY55: =N55/F55/(0.9*8760) | AZ55: =O55/F55 | BA55: =BP55+BQ55+BS55-BL55+BR55+BT55 | BB55: =(Q55+R55)*-1*(I55+K55)/F55 | BC55: =BA55*Q55 | BD55: =SUM(BP55:BR55)-BL55 | BE55: =(I55+K55)/F55*-1*R55 | BF55: =BD55*Q55 | BH55: =H55 | BI55: 0.18104824 | BJ55: 0.23037491 | BL55: =BH55/F55 | BM55: =BI55*G55/F55 | BN55: =SUM(BL55:BM55) | BP55: =BJ55 | BQ55: =J55/F55 | BR55: =L55/F55 | BS55: =I55/F55 | BT55: =K55/F55 | BU55: =SUM(BP55:BT55) | BW55: =BN55-BU55
B56: MIDAT_DryMill_Existing_Non_CCS | C56: Biomass_Corn | D56: 0 | E56: 0.085342825 | F56: 3.104338 | G56: 1.0133975 | H56: 1.7588667 | I56: 0 | J56: 1.0437051 | K56: 0 | L56: 0.18534112 | M56: 322562.05 | N56: 176727.97 | O56: -25.41 | Q56: 0 | R56: -14.741173 | S56: 100 | T56: 69.370717 | U56: 45.972292 | V56: 42.940257 | W56: 45.289647 | X56: 45.289647 | Y56: 35.672332 | Z56: 37.202448 | AB56: 51.059951 | AC56: 51.059951 | AD56: 107.87677 | AE56: 107.87677 | AF56: 96.945356 | AG56: 96.945356 | AH56: 15.046822 | AI56: 15.046822 | AJ56: 0 | AK56: 5000 | AM56: =B56 | AN56: =C56 | AO56: =SUM(AT56:AZ56)+BB56+BC56 | AP56: =SUM(AT56:AZ56)+BE56+BF56 | AQ56: =AO56/3.6 | AR56: =AP56/3.6 | AS56: =AO56-AP56 | AT56: =D56/F56*Y56*-1 | AU56: =E56/F56*Y56 | AV56: {=_xlfn.IFS(C56="Biomass_Corn", 1/F56*S56, C56="Biomass_Agri", 1/F56*V56, C56="Biomass_Wood", 1/F56*U56, C56="Biomass_Herb", 1/F56*T56)} | AW56: =G56/F56*AH56 | AX56: =M56/F56/(0.9*8760) | AY56: =N56/F56/(0.9*8760) | AZ56: =O56/F56 | BA56: =BP56+BQ56+BS56-BL56+BR56+BT56 | BB56: =(Q56+R56)*-1*(I56+K56)/F56 | BC56: =BA56*Q56 | BD56: =SUM(BP56:BR56)-BL56 | BE56: =(I56+K56)/F56*-1*R56 | BF56: =BD56*Q56 | BH56: =H56 | BI56: 0.18104824 | BJ56: 0.23037491 | BL56: =BH56/F56 | BM56: =BI56*G56/F56 | BN56: =SUM(BL56:BM56) | BP56: =BJ56 | BQ56: =J56/F56 | BR56: =L56/F56 | BS56: =I56/F56 | BT56: =K56/F56 | BU56: =SUM(BP56:BT56) | BW56: =BN56-BU56
B57: NE_DryMill_Existing_Non_CCS | C57: Biomass_Corn | D57: 0 | E57: 0.085342825 | F57: 3.104338 | G57: 1.0133975 | H57: 1.7588667 | I57: 0 | J57: 1.0437051 | K57: 0 | L57: 0.18534112 | M57: 322562.05 | N57: 176727.97 | O57: -25.41 | Q57: 0 | R57: -24.351161 | S57: 100 | T57: 69.16536 | U57: 35.638583 | V57: 39.351032 | W57: 45.289647 | X57: 45.289647 | Y57: 40.848462 | Z57: 42.811658 | AB57: 51.059951 | AC57: 51.059951 | AD57: 107.87677 | AE57: 107.87677 | AF57: 96.945356 | AG57: 96.945356 | AH57: 15.292119 | AI57: 15.292119 | AJ57: 0 | AK57: 5000 | AM57: =B57 | AN57: =C57 | AO57: =SUM(AT57:AZ57)+BB57+BC57 | AP57: =SUM(AT57:AZ57)+BE57+BF57 | AQ57: =AO57/3.6 | AR57: =AP57/3.6 | AS57: =AO57-AP57 | AT57: =D57/F57*Y57*-1 | AU57: =E57/F57*Y57 | AV57: {=_xlfn.IFS(C57="Biomass_Corn", 1/F57*S57, C57="Biomass_Agri", 1/F57*V57, C57="Biomass_Wood", 1/F57*U57, C57="Biomass_Herb", 1/F57*T57)} | AW57: =G57/F57*AH57 | AX57: =M57/F57/(0.9*8760) | AY57: =N57/F57/(0.9*8760) | AZ57: =O57/F57 | BA57: =BP57+BQ57+BS57-BL57+BR57+BT57 | BB57: =(Q57+R57)*-1*(I57+K57)/F57 | BC57: =BA57*Q57 | BD57: =SUM(BP57:BR57)-BL57 | BE57: =(I57+K57)/F57*-1*R57 | BF57: =BD57*Q57 | BH57: =H57 | BI57: 0.18104824 | BJ57: 0.23037491 | BL57: =BH57/F57 | BM57: =BI57*G57/F57 | BN57: =SUM(BL57:BM57) | BP57: =BJ57 | BQ57: =J57/F57 | BR57: =L57/F57 | BS57: =I57/F57 | BT57: =K57/F57 | BU57: =SUM(BP57:BT57) | BW57: =BN57-BU57
B58: CA_DryMill_CCS_Fermentation | C58: Biomass_Corn | D58: 0 | E58: 0.085342825 | F58: 3.104338 | G58: 1.0133975 | H58: 1.7588667 | I58: 0.35768767 | J58: 0.68601739 | K58: 0 | L58: 0.18534112 | M58: 27458.48 | N58: 191772.15 | O58: -25.37 | Q58: 0 | R58: -16.309543 | S58: 100 | U58: 39.347116 | V58: 34.413449 | W58: 45.289647 | X58: 45.289647 | Y58: 39.400687 | Z58: 35.007561 | AB58: 51.059951 | AC58: 51.059951 | AD58: 107.87677 | AE58: 107.87677 | AF58: 96.945356 | AG58: 96.945356 | AH58: 16.900485 | AI58: 16.900485 | AJ58: 0 | AK58: 5000 | AM58: =B58 | AN58: =C58 | AO58: =SUM(AT58:AZ58)+BB58+BC58 | AP58: =SUM(AT58:AZ58)+BE58+BF58 | AQ58: =AO58/3.6 | AR58: =AP58/3.6 | AS58: =AO58-AP58 | AT58: =D58/F58*Y58*-1 | AU58: =E58/F58*Y58 | AV58: {=_xlfn.IFS(C58="Biomass_Corn", 1/F58*S58, C58="Biomass_Agri", 1/F58*V58, C58="Biomass_Wood", 1/F58*U58, C58="Biomass_Herb", 1/F58*T58)} | AW58: =G58/F58*AH58 | AX58: =M58/F58/(0.9*8760) | AY58: =N58/F58/(0.9*8760) | AZ58: =O58/F58 | BA58: =BP58+BQ58+BS58-BL58+BR58+BT58 | BB58: =(Q58+R58)*-1*(I58+K58)/F58 | BC58: =BA58*Q58 | BD58: =SUM(BP58:BR58)-BL58 | BE58: =(I58+K58)/F58*-1*R58 | BF58: =BD58*Q58 | BH58: =H58 | BI58: 0.18104824 | BJ58: 0.23037491 | BL58: =BH58/F58 | BM58: =BI58*G58/F58 | BN58: =SUM(BL58:BM58) | BP58: =BJ58 | BQ58: =J58/F58 | BR58: =L58/F58 | BS58: =I58/F58 | BT58: =K58/F58 | BU58: =SUM(BP58:BT58) | BW58: =BN58-BU58
B59: NW_DryMill_CCS_Fermentation | C59: Biomass_Corn | D59: 0 | E59: 0.085342825 | F59: 3.104338 | G59: 1.0133975 | H59: 1.7588667 | I59: 0.35768767 | J59: 0.68601739 | K59: 0 | L59: 0.18534112 | M59: 27458.48 | N59: 191772.15 | O59: -25.37 | Q59: 0 | R59: -3.557382 | S59: 100 | T59: 70.610863 | U59: 48.120714 | V59: 39.234002 | W59: 45.289647 | X59: 45.289647 | Y59: 28.009811 | Z59: 31.329838 | AB59: 51.059951 | AC59: 51.059951 | AD59: 107.87677 | AE59: 107.87677 | AF59: 96.945356 | AG59: 96.945356 | AH59: 15.780879 | AI59: 15.780879 | AJ59: 0 | AK59: 5000 | AM59: =B59 | AN59: =C59 | AO59: =SUM(AT59:AZ59)+BB59+BC59 | AP59: =SUM(AT59:AZ59)+BE59+BF59 | AQ59: =AO59/3.6 | AR59: =AP59/3.6 | AS59: =AO59-AP59 | AT59: =D59/F59*Y59*-1 | AU59: =E59/F59*Y59 | AV59: {=_xlfn.IFS(C59="Biomass_Corn", 1/F59*S59, C59="Biomass_Agri", 1/F59*V59, C59="Biomass_Wood", 1/F59*U59, C59="Biomass_Herb", 1/F59*T59)} | AW59: =G59/F59*AH59 | AX59: =M59/F59/(0.9*8760) | AY59: =N59/F59/(0.9*8760) | AZ59: =O59/F59 | BA59: =BP59+BQ59+BS59-BL59+BR59+BT59 | BB59: =(Q59+R59)*-1*(I59+K59)/F59 | BC59: =BA59*Q59 | BD59: =SUM(BP59:BR59)-BL59 | BE59: =(I59+K59)/F59*-1*R59 | BF59: =BD59*Q59 | BH59: =H59 | BI59: 0.18104824 | BJ59: 0.23037491 | BL59: =BH59/F59 | BM59: =BI59*G59/F59 | BN59: =SUM(BL59:BM59) | BP59: =BJ59 | BQ59: =J59/F59 | BR59: =L59/F59 | BS59: =I59/F59 | BT59: =K59/F59 | BU59: =SUM(BP59:BT59) | BW59: =BN59-BU59
B60: SW_DryMill_CCS_Fermentation | C60: Biomass_Corn | D60: 0 | E60: 0.085342825 | F60: 3.104338 | G60: 1.0133975 | H60: 1.7588667 | I60: 0.35768767 | J60: 0.68601739 | K60: 0 | L60: 0.18534112 | M60: 27458.48 | N60: 191772.15 | O60: -25.37 | Q60: 0 | R60: -6.203351 | S60: 100 | T60: 67.594672 | U60: 47.542838 | V60: 39.757567 | W60: 45.289647 | X60: 45.289647 | Y60: 27.4329 | Z60: 29.313567 | AB60: 51.059951 | AC60: 51.059951 | AD60: 107.87677 | AE60: 107.87677 | AF60: 96.945356 | AG60: 96.945356 | AH60: 15.780712 | AI60: 15.780712 | AJ60: 0 | AK60: 5000 | AM60: =B60 | AN60: =C60 | AO60: =SUM(AT60:AZ60)+BB60+BC60 | AP60: =SUM(AT60:AZ60)+BE60+BF60 | AQ60: =AO60/3.6 | AR60: =AP60/3.6 | AS60: =AO60-AP60 | AT60: =D60/F60*Y60*-1 | AU60: =E60/F60*Y60 | AV60: {=_xlfn.IFS(C60="Biomass_Corn", 1/F60*S60, C60="Biomass_Agri", 1/F60*V60, C60="Biomass_Wood", 1/F60*U60, C60="Biomass_Herb", 1/F60*T60)} | AW60: =G60/F60*AH60 | AX60: =M60/F60/(0.9*8760) | AY60: =N60/F60/(0.9*8760) | AZ60: =O60/F60 | BA60: =BP60+BQ60+BS60-BL60+BR60+BT60 | BB60: =(Q60+R60)*-1*(I60+K60)/F60 | BC60: =BA60*Q60 | BD60: =SUM(BP60:BR60)-BL60 | BE60: =(I60+K60)/F60*-1*R60 | BF60: =BD60*Q60 | BH60: =H60 | BI60: 0.18104824 | BJ60: 0.23037491 | BL60: =BH60/F60 | BM60: =BI60*G60/F60 | BN60: =SUM(BL60:BM60) | BP60: =BJ60 | BQ60: =J60/F60 | BR60: =L60/F60 | BS60: =I60/F60 | BT60: =K60/F60 | BU60: =SUM(BP60:BT60) | BW60: =BN60-BU60
B61: TX_DryMill_CCS_Fermentation | C61: Biomass_Corn | D61: 0 | E61: 0.085342825 | F61: 3.104338 | G61: 1.0133975 | H61: 1.7588667 | I61: 0.35768767 | J61: 0.68601739 | K61: 0 | L61: 0.18534112 | M61: 27458.48 | N61: 191772.15 | O61: -25.37 | Q61: 0 | R61: 14.732097 | S61: 100 | T61: 73.00646 | U61: 69.643664 | V61: 43.030303 | W61: 45.289647 | X61: 45.289647 | Y61: 19.019146 | Z61: 23.790747 | AB61: 51.059951 | AC61: 51.059951 | AD61: 107.87677 | AE61: 107.87677 | AF61: 96.945356 | AG61: 96.945356 | AH61: 13.326077 | AI61: 13.326077 | AJ61: 0 | AK61: 5000 | AM61: =B61 | AN61: =C61 | AO61: =SUM(AT61:AZ61)+BB61+BC61 | AP61: =SUM(AT61:AZ61)+BE61+BF61 | AQ61: =AO61/3.6 | AR61: =AP61/3.6 | AS61: =AO61-AP61 | AT61: =D61/F61*Y61*-1 | AU61: =E61/F61*Y61 | AV61: {=_xlfn.IFS(C61="Biomass_Corn", 1/F61*S61, C61="Biomass_Agri", 1/F61*V61, C61="Biomass_Wood", 1/F61*U61, C61="Biomass_Herb", 1/F61*T61)} | AW61: =G61/F61*AH61 | AX61: =M61/F61/(0.9*8760) | AY61: =N61/F61/(0.9*8760) | AZ61: =O61/F61 | BA61: =BP61+BQ61+BS61-BL61+BR61+BT61 | BB61: =(Q61+R61)*-1*(I61+K61)/F61 | BC61: =BA61*Q61 | BD61: =SUM(BP61:BR61)-BL61 | BE61: =(I61+K61)/F61*-1*R61 | BF61: =BD61*Q61 | BH61: =H61 | BI61: 0.18104824 | BJ61: 0.23037491 | BL61: =BH61/F61 | BM61: =BI61*G61/F61 | BN61: =SUM(BL61:BM61) | BP61: =BJ61 | BQ61: =J61/F61 | BR61: =L61/F61 | BS61: =I61/F61 | BT61: =K61/F61 | BU61: =SUM(BP61:BT61) | BW61: =BN61-BU61
B62: NCEN_DryMill_CCS_Fermentation | C62: Biomass_Corn | D62: 0 | E62: 0.085342825 | F62: 3.104338 | G62: 1.0133975 | H62: 1.7588667 | I62: 0.35768767 | J62: 0.68601739 | K62: 0 | L62: 0.18534112 | M62: 27458.48 | N62: 191772.15 | O62: -25.37 | Q62: 0 | R62: -0.911528 | S62: 100 | T62: 69.911137 | U62: 44.79442 | V62: 43.323942 | W62: 45.289647 | X62: 45.289647 | Y62: 29.249237 | Z62: 34.631601 | AB62: 51.059951 | AC62: 51.059951 | AD62: 107.87677 | AE62: 107.87677 | AF62: 96.945356 | AG62: 96.945356 | AH62: 14.089942 | AI62: 14.089942 | AJ62: 0 | AK62: 5000 | AM62: =B62 | AN62: =C62 | AO62: =SUM(AT62:AZ62)+BB62+BC62 | AP62: =SUM(AT62:AZ62)+BE62+BF62 | AQ62: =AO62/3.6 | AR62: =AP62/3.6 | AS62: =AO62-AP62 | AT62: =D62/F62*Y62*-1 | AU62: =E62/F62*Y62 | AV62: {=_xlfn.IFS(C62="Biomass_Corn", 1/F62*S62, C62="Biomass_Agri", 1/F62*V62, C62="Biomass_Wood", 1/F62*U62, C62="Biomass_Herb", 1/F62*T62)} | AW62: =G62/F62*AH62 | AX62: =M62/F62/(0.9*8760) | AY62: =N62/F62/(0.9*8760) | AZ62: =O62/F62 | BA62: =BP62+BQ62+BS62-BL62+BR62+BT62 | BB62: =(Q62+R62)*-1*(I62+K62)/F62 | BC62: =BA62*Q62 | BD62: =SUM(BP62:BR62)-BL62 | BE62: =(I62+K62)/F62*-1*R62 | BF62: =BD62*Q62 | BH62: =H62 | BI62: 0.18104824 | BJ62: 0.23037491 | BL62: =BH62/F62 | BM62: =BI62*G62/F62 | BN62: =SUM(BL62:BM62) | BP62: =BJ62 | BQ62: =J62/F62 | BR62: =L62/F62 | BS62: =I62/F62 | BT62: =K62/F62 | BU62: =SUM(BP62:BT62) | BW62: =BN62-BU62
B63: CEN_DryMill_CCS_Fermentation | C63: Biomass_Corn | D63: 0 | E63: 0.085342825 | F63: 3.104338 | G63: 1.0133975 | H63: 1.7588667 | I63: 0.35768767 | J63: 0.68601739 | K63: 0 | L63: 0.18534112 | M63: 27458.48 | N63: 191772.15 | O63: -25.37 | Q63: 0 | R63: 6.223991 | S63: 100 | T63: 72.304369 | U63: 59.390495 | V63: 42.94088 | W63: 45.289647 | X63: 45.289647 | Y63: 22.958189 | Z63: 28.593352 | AB63: 51.059951 | AC63: 51.059951 | AD63: 107.87677 | AE63: 107.87677 | AF63: 96.945356 | AG63: 96.945356 | AH63: 14.066295 | AI63: 14.066295 | AJ63: 0 | AK63: 5000 | AM63: =B63 | AN63: =C63 | AO63: =SUM(AT63:AZ63)+BB63+BC63 | AP63: =SUM(AT63:AZ63)+BE63+BF63 | AQ63: =AO63/3.6 | AR63: =AP63/3.6 | AS63: =AO63-AP63 | AT63: =D63/F63*Y63*-1 | AU63: =E63/F63*Y63 | AV63: {=_xlfn.IFS(C63="Biomass_Corn", 1/F63*S63, C63="Biomass_Agri", 1/F63*V63, C63="Biomass_Wood", 1/F63*U63, C63="Biomass_Herb", 1/F63*T63)} | AW63: =G63/F63*AH63 | AX63: =M63/F63/(0.9*8760) | AY63: =N63/F63/(0.9*8760) | AZ63: =O63/F63 | BA63: =BP63+BQ63+BS63-BL63+BR63+BT63 | BB63: =(Q63+R63)*-1*(I63+K63)/F63 | BC63: =BA63*Q63 | BD63: =SUM(BP63:BR63)-BL63 | BE63: =(I63+K63)/F63*-1*R63 | BF63: =BD63*Q63 | BH63: =H63 | BI63: 0.18104824 | BJ63: 0.23037491 | BL63: =BH63/F63 | BM63: =BI63*G63/F63 | BN63: =SUM(BL63:BM63) | BP63: =BJ63 | BQ63: =J63/F63 | BR63: =L63/F63 | BS63: =I63/F63 | BT63: =K63/F63 | BU63: =SUM(BP63:BT63) | BW63: =BN63-BU63
B64: SE_DryMill_CCS_Fermentation | C64: Biomass_Corn | D64: 0 | E64: 0.085342825 | F64: 3.104338 | G64: 1.0133975 | H64: 1.7588667 | I64: 0.35768767 | J64: 0.68601739 | K64: 0 | L64: 0.18534112 | M64: 27458.48 | N64: 191772.15 | O64: -25.37 | Q64: 0 | R64: -5.914702 | S64: 100 | T64: 69.166622 | U64: 46.05675 | V64: 41.170372 | W64: 45.289647 | X64: 45.289647 | Y64: 33.298446 | Z64: 36.471022 | AB64: 51.059951 | AC64: 51.059951 | AD64: 107.87677 | AE64: 107.87677 | AF64: 96.945356 | AG64: 96.945356 | AH64: 14.089638 | AI64: 14.089638 | AJ64: 0 | AK64: 5000 | AM64: =B64 | AN64: =C64 | AO64: =SUM(AT64:AZ64)+BB64+BC64 | AP64: =SUM(AT64:AZ64)+BE64+BF64 | AQ64: =AO64/3.6 | AR64: =AP64/3.6 | AS64: =AO64-AP64 | AT64: =D64/F64*Y64*-1 | AU64: =E64/F64*Y64 | AV64: {=_xlfn.IFS(C64="Biomass_Corn", 1/F64*S64, C64="Biomass_Agri", 1/F64*V64, C64="Biomass_Wood", 1/F64*U64, C64="Biomass_Herb", 1/F64*T64)} | AW64: =G64/F64*AH64 | AX64: =M64/F64/(0.9*8760) | AY64: =N64/F64/(0.9*8760) | AZ64: =O64/F64 | BA64: =BP64+BQ64+BS64-BL64+BR64+BT64 | BB64: =(Q64+R64)*-1*(I64+K64)/F64 | BC64: =BA64*Q64 | BD64: =SUM(BP64:BR64)-BL64 | BE64: =(I64+K64)/F64*-1*R64 | BF64: =BD64*Q64 | BH64: =H64 | BI64: 0.18104824 | BJ64: 0.23037491 | BL64: =BH64/F64 | BM64: =BI64*G64/F64 | BN64: =SUM(BL64:BM64) | BP64: =BJ64 | BQ64: =J64/F64 | BR64: =L64/F64 | BS64: =I64/F64 | BT64: =K64/F64 | BU64: =SUM(BP64:BT64) | BW64: =BN64-BU64
B65: MIDAT_DryMill_CCS_Fermentation | C65: Biomass_Corn | D65: 0 | E65: 0.085342825 | F65: 3.104338 | G65: 1.0133975 | H65: 1.7588667 | I65: 0.35768767 | J65: 0.68601739 | K65: 0 | L65: 0.18534112 | M65: 27458.48 | N65: 191772.15 | O65: -25.37 | Q65: 0 | R65: -14.741173 | S65: 100 | T65: 69.370717 | U65: 45.972292 | V65: 42.940257 | W65: 45.289647 | X65: 45.289647 | Y65: 35.672332 | Z65: 37.202448 | AB65: 51.059951 | AC65: 51.059951 | AD65: 107.87677 | AE65: 107.87677 | AF65: 96.945356 | AG65: 96.945356 | AH65: 15.046822 | AI65: 15.046822 | AJ65: 0 | AK65: 5000 | AM65: =B65 | AN65: =C65 | AO65: =SUM(AT65:AZ65)+BB65+BC65 | AP65: =SUM(AT65:AZ65)+BE65+BF65 | AQ65: =AO65/3.6 | AR65: =AP65/3.6 | AS65: =AO65-AP65 | AT65: =D65/F65*Y65*-1 | AU65: =E65/F65*Y65 | AV65: {=_xlfn.IFS(C65="Biomass_Corn", 1/F65*S65, C65="Biomass_Agri", 1/F65*V65, C65="Biomass_Wood", 1/F65*U65, C65="Biomass_Herb", 1/F65*T65)} | AW65: =G65/F65*AH65 | AX65: =M65/F65/(0.9*8760) | AY65: =N65/F65/(0.9*8760) | AZ65: =O65/F65 | BA65: =BP65+BQ65+BS65-BL65+BR65+BT65 | BB65: =(Q65+R65)*-1*(I65+K65)/F65 | BC65: =BA65*Q65 | BD65: =SUM(BP65:BR65)-BL65 | BE65: =(I65+K65)/F65*-1*R65 | BF65: =BD65*Q65 | BH65: =H65 | BI65: 0.18104824 | BJ65: 0.23037491 | BL65: =BH65/F65 | BM65: =BI65*G65/F65 | BN65: =SUM(BL65:BM65) | BP65: =BJ65 | BQ65: =J65/F65 | BR65: =L65/F65 | BS65: =I65/F65 | BT65: =K65/F65 | BU65: =SUM(BP65:BT65) | BW65: =BN65-BU65
B66: NE_DryMill_CCS_Fermentation | C66: Biomass_Corn | D66: 0 | E66: 0.085342825 | F66: 3.104338 | G66: 1.0133975 | H66: 1.7588667 | I66: 0.35768767 | J66: 0.68601739 | K66: 0 | L66: 0.18534112 | M66: 27458.48 | N66: 191772.15 | O66: -25.37 | Q66: 0 | R66: -24.351161 | S66: 100 | T66: 69.16536 | U66: 35.638583 | V66: 39.351032 | W66: 45.289647 | X66: 45.289647 | Y66: 40.848462 | Z66: 42.811658 | AB66: 51.059951 | AC66: 51.059951 | AD66: 107.87677 | AE66: 107.87677 | AF66: 96.945356 | AG66: 96.945356 | AH66: 15.292119 | AI66: 15.292119 | AJ66: 0 | AK66: 5000 | AM66: =B66 | AN66: =C66 | AO66: =SUM(AT66:AZ66)+BB66+BC66 | AP66: =SUM(AT66:AZ66)+BE66+BF66 | AQ66: =AO66/3.6 | AR66: =AP66/3.6 | AS66: =AO66-AP66 | AT66: =D66/F66*Y66*-1 | AU66: =E66/F66*Y66 | AV66: {=_xlfn.IFS(C66="Biomass_Corn", 1/F66*S66, C66="Biomass_Agri", 1/F66*V66, C66="Biomass_Wood", 1/F66*U66, C66="Biomass_Herb", 1/F66*T66)} | AW66: =G66/F66*AH66 | AX66: =M66/F66/(0.9*8760) | AY66: =N66/F66/(0.9*8760) | AZ66: =O66/F66 | BA66: =BP66+BQ66+BS66-BL66+BR66+BT66 | BB66: =(Q66+R66)*-1*(I66+K66)/F66 | BC66: =BA66*Q66 | BD66: =SUM(BP66:BR66)-BL66 | BE66: =(I66+K66)/F66*-1*R66 | BF66: =BD66*Q66 | BH66: =H66 | BI66: 0.18104824 | BJ66: 0.23037491 | BL66: =BH66/F66 | BM66: =BI66*G66/F66 | BN66: =SUM(BL66:BM66) | BP66: =BJ66 | BQ66: =J66/F66 | BR66: =L66/F66 | BS66: =I66/F66 | BT66: =K66/F66 | BU66: =SUM(BP66:BT66) | BW66: =BN66-BU66
B67: CA_DryMill_CCS_Fermentation_Exhaust | C67: Biomass_Corn | D67: 0 | E67: 0.085342825 | F67: 3.104338 | G67: 1.0133975 | H67: 1.7588667 | I67: 0.35768767 | J67: 0.68601739 | K67: 0.15290642 | L67: 0.032434696 | M67: 45179.42 | N67: 201481.25 | O67: -25.28 | Q67: 0 | R67: -16.309543 | S67: 100 | U67: 39.347116 | V67: 34.413449 | W67: 45.289647 | X67: 45.289647 | Y67: 39.400687 | Z67: 35.007561 | AB67: 51.059951 | AC67: 51.059951 | AD67: 107.87677 | AE67: 107.87677 | AF67: 96.945356 | AG67: 96.945356 | AH67: 16.900485 | AI67: 16.900485 | AJ67: 0 | AK67: 5000 | AM67: =B67 | AN67: =C67 | AO67: =SUM(AT67:AZ67)+BB67+BC67 | AP67: =SUM(AT67:AZ67)+BE67+BF67 | AQ67: =AO67/3.6 | AR67: =AP67/3.6 | AS67: =AO67-AP67 | AT67: =D67/F67*Y67*-1 | AU67: =E67/F67*Y67 | AV67: {=_xlfn.IFS(C67="Biomass_Corn", 1/F67*S67, C67="Biomass_Agri", 1/F67*V67, C67="Biomass_Wood", 1/F67*U67, C67="Biomass_Herb", 1/F67*T67)} | AW67: =G67/F67*AH67 | AX67: =M67/F67/(0.9*8760) | AY67: =N67/F67/(0.9*8760) | AZ67: =O67/F67 | BA67: =BP67+BQ67+BS67-BL67+BR67+BT67 | BB67: =(Q67+R67)*-1*(I67+K67)/F67 | BC67: =BA67*Q67 | BD67: =SUM(BP67:BR67)-BL67 | BE67: =(I67+K67)/F67*-1*R67 | BF67: =BD67*Q67 | BH67: =H67 | BI67: 0.18104824 | BJ67: 0.23037491 | BL67: =BH67/F67 | BM67: =BI67*G67/F67 | BN67: =SUM(BL67:BM67) | BP67: =BJ67 | BQ67: =J67/F67 | BR67: =L67/F67 | BS67: =I67/F67 | BT67: =K67/F67 | BU67: =SUM(BP67:BT67) | BW67: =BN67-BU67
B68: NW_DryMill_CCS_Fermentation_Exhaust | C68: Biomass_Corn | D68: 0 | E68: 0.085342825 | F68: 3.104338 | G68: 1.0133975 | H68: 1.7588667 | I68: 0.35768767 | J68: 0.68601739 | K68: 0.15290642 | L68: 0.032434696 | M68: 45179.42 | N68: 201481.25 | O68: -25.28 | Q68: 0 | R68: -3.557382 | S68: 100 | T68: 70.610863 | U68: 48.120714 | V68: 39.234002 | W68: 45.289647 | X68: 45.289647 | Y68: 28.009811 | Z68: 31.329838 | AB68: 51.059951 | AC68: 51.059951 | AD68: 107.87677 | AE68: 107.87677 | AF68: 96.945356 | AG68: 96.945356 | AH68: 15.780879 | AI68: 15.780879 | AJ68: 0 | AK68: 5000 | AM68: =B68 | AN68: =C68 | AO68: =SUM(AT68:AZ68)+BB68+BC68 | AP68: =SUM(AT68:AZ68)+BE68+BF68 | AQ68: =AO68/3.6 | AR68: =AP68/3.6 | AS68: =AO68-AP68 | AT68: =D68/F68*Y68*-1 | AU68: =E68/F68*Y68 | AV68: {=_xlfn.IFS(C68="Biomass_Corn", 1/F68*S68, C68="Biomass_Agri", 1/F68*V68, C68="Biomass_Wood", 1/F68*U68, C68="Biomass_Herb", 1/F68*T68)} | AW68: =G68/F68*AH68 | AX68: =M68/F68/(0.9*8760) | AY68: =N68/F68/(0.9*8760) | AZ68: =O68/F68 | BA68: =BP68+BQ68+BS68-BL68+BR68+BT68 | BB68: =(Q68+R68)*-1*(I68+K68)/F68 | BC68: =BA68*Q68 | BD68: =SUM(BP68:BR68)-BL68 | BE68: =(I68+K68)/F68*-1*R68 | BF68: =BD68*Q68 | BH68: =H68 | BI68: 0.18104824 | BJ68: 0.23037491 | BL68: =BH68/F68 | BM68: =BI68*G68/F68 | BN68: =SUM(BL68:BM68) | BP68: =BJ68 | BQ68: =J68/F68 | BR68: =L68/F68 | BS68: =I68/F68 | BT68: =K68/F68 | BU68: =SUM(BP68:BT68) | BW68: =BN68-BU68
B69: SW_DryMill_CCS_Fermentation_Exhaust | C69: Biomass_Corn | D69: 0 | E69: 0.085342825 | F69: 3.104338 | G69: 1.0133975 | H69: 1.7588667 | I69: 0.35768767 | J69: 0.68601739 | K69: 0.15290642 | L69: 0.032434696 | M69: 45179.42 | N69: 201481.25 | O69: -25.28 | Q69: 0 | R69: -6.203351 | S69: 100 | T69: 67.594672 | U69: 47.542838 | V69: 39.757567 | W69: 45.289647 | X69: 45.289647 | Y69: 27.4329 | Z69: 29.313567 | AB69: 51.059951 | AC69: 51.059951 | AD69: 107.87677 | AE69: 107.87677 | AF69: 96.945356 | AG69: 96.945356 | AH69: 15.780712 | AI69: 15.780712 | AJ69: 0 | AK69: 5000 | AM69: =B69 | AN69: =C69 | AO69: =SUM(AT69:AZ69)+BB69+BC69 | AP69: =SUM(AT69:AZ69)+BE69+BF69 | AQ69: =AO69/3.6 | AR69: =AP69/3.6 | AS69: =AO69-AP69 | AT69: =D69/F69*Y69*-1 | AU69: =E69/F69*Y69 | AV69: {=_xlfn.IFS(C69="Biomass_Corn", 1/F69*S69, C69="Biomass_Agri", 1/F69*V69, C69="Biomass_Wood", 1/F69*U69, C69="Biomass_Herb", 1/F69*T69)} | AW69: =G69/F69*AH69 | AX69: =M69/F69/(0.9*8760) | AY69: =N69/F69/(0.9*8760) | AZ69: =O69/F69 | BA69: =BP69+BQ69+BS69-BL69+BR69+BT69 | BB69: =(Q69+R69)*-1*(I69+K69)/F69 | BC69: =BA69*Q69 | BD69: =SUM(BP69:BR69)-BL69 | BE69: =(I69+K69)/F69*-1*R69 | BF69: =BD69*Q69 | BH69: =H69 | BI69: 0.18104824 | BJ69: 0.23037491 | BL69: =BH69/F69 | BM69: =BI69*G69/F69 | BN69: =SUM(BL69:BM69) | BP69: =BJ69 | BQ69: =J69/F69 | BR69: =L69/F69 | BS69: =I69/F69 | BT69: =K69/F69 | BU69: =SUM(BP69:BT69) | BW69: =BN69-BU69
B70: TX_DryMill_CCS_Fermentation_Exhaust | C70: Biomass_Corn | D70: 0 | E70: 0.085342825 | F70: 3.104338 | G70: 1.0133975 | H70: 1.7588667 | I70: 0.35768767 | J70: 0.68601739 | K70: 0.15290642 | L70: 0.032434696 | M70: 45179.42 | N70: 201481.25 | O70: -25.28 | Q70: 0 | R70: 14.732097 | S70: 100 | T70: 73.00646 | U70: 69.643664 | V70: 43.030303 | W70: 45.289647 | X70: 45.289647 | Y70: 19.019146 | Z70: 23.790747 | AB70: 51.059951 | AC70: 51.059951 | AD70: 107.87677 | AE70: 107.87677 | AF70: 96.945356 | AG70: 96.945356 | AH70: 13.326077 | AI70: 13.326077 | AJ70: 0 | AK70: 5000 | AM70: =B70 | AN70: =C70 | AO70: =SUM(AT70:AZ70)+BB70+BC70 | AP70: =SUM(AT70:AZ70)+BE70+BF70 | AQ70: =AO70/3.6 | AR70: =AP70/3.6 | AS70: =AO70-AP70 | AT70: =D70/F70*Y70*-1 | AU70: =E70/F70*Y70 | AV70: {=_xlfn.IFS(C70="Biomass_Corn", 1/F70*S70, C70="Biomass_Agri", 1/F70*V70, C70="Biomass_Wood", 1/F70*U70, C70="Biomass_Herb", 1/F70*T70)} | AW70: =G70/F70*AH70 | AX70: =M70/F70/(0.9*8760) | AY70: =N70/F70/(0.9*8760) | AZ70: =O70/F70 | BA70: =BP70+BQ70+BS70-BL70+BR70+BT70 | BB70: =(Q70+R70)*-1*(I70+K70)/F70 | BC70: =BA70*Q70 | BD70: =SUM(BP70:BR70)-BL70 | BE70: =(I70+K70)/F70*-1*R70 | BF70: =BD70*Q70 | BH70: =H70 | BI70: 0.18104824 | BJ70: 0.23037491 | BL70: =BH70/F70 | BM70: =BI70*G70/F70 | BN70: =SUM(BL70:BM70) | BP70: =BJ70 | BQ70: =J70/F70 | BR70: =L70/F70 | BS70: =I70/F70 | BT70: =K70/F70 | BU70: =SUM(BP70:BT70) | BW70: =BN70-BU70
B71: NCEN_DryMill_CCS_Fermentation_Exhaust | C71: Biomass_Corn | D71: 0 | E71: 0.085342825 | F71: 3.104338 | G71: 1.0133975 | H71: 1.7588667 | I71: 0.35768767 | J71: 0.68601739 | K71: 0.15290642 | L71: 0.032434696 | M71: 45179.42 | N71: 201481.25 | O71: -25.28 | Q71: 0 | R71: -0.911528 | S71: 100 | T71: 69.911137 | U71: 44.79442 | V71: 43.323942 | W71: 45.289647 | X71: 45.289647 | Y71: 29.249237 | Z71: 34.631601 | AB71: 51.059951 | AC71: 51.059951 | AD71: 107.87677 | AE71: 107.87677 | AF71: 96.945356 | AG71: 96.945356 | AH71: 14.089942 | AI71: 14.089942 | AJ71: 0 | AK71: 5000 | AM71: =B71 | AN71: =C71 | AO71: =SUM(AT71:AZ71)+BB71+BC71 | AP71: =SUM(AT71:AZ71)+BE71+BF71 | AQ71: =AO71/3.6 | AR71: =AP71/3.6 | AS71: =AO71-AP71 | AT71: =D71/F71*Y71*-1 | AU71: =E71/F71*Y71 | AV71: {=_xlfn.IFS(C71="Biomass_Corn", 1/F71*S71, C71="Biomass_Agri", 1/F71*V71, C71="Biomass_Wood", 1/F71*U71, C71="Biomass_Herb", 1/F71*T71)} | AW71: =G71/F71*AH71 | AX71: =M71/F71/(0.9*8760) | AY71: =N71/F71/(0.9*8760) | AZ71: =O71/F71 | BA71: =BP71+BQ71+BS71-BL71+BR71+BT71 | BB71: =(Q71+R71)*-1*(I71+K71)/F71 | BC71: =BA71*Q71 | BD71: =SUM(BP71:BR71)-BL71 | BE71: =(I71+K71)/F71*-1*R71 | BF71: =BD71*Q71 | BH71: =H71 | BI71: 0.18104824 | BJ71: 0.23037491 | BL71: =BH71/F71 | BM71: =BI71*G71/F71 | BN71: =SUM(BL71:BM71) | BP71: =BJ71 | BQ71: =J71/F71 | BR71: =L71/F71 | BS71: =I71/F71 | BT71: =K71/F71 | BU71: =SUM(BP71:BT71) | BW71: =BN71-BU71
B72: CEN_DryMill_CCS_Fermentation_Exhaust | C72: Biomass_Corn | D72: 0 | E72: 0.085342825 | F72: 3.104338 | G72: 1.0133975 | H72: 1.7588667 | I72: 0.35768767 | J72: 0.68601739 | K72: 0.15290642 | L72: 0.032434696 | M72: 45179.42 | N72: 201481.25 | O72: -25.28 | Q72: 0 | R72: 6.223991 | S72: 100 | T72: 72.304369 | U72: 59.390495 | V72: 42.94088 | W72: 45.289647 | X72: 45.289647 | Y72: 22.958189 | Z72: 28.593352 | AB72: 51.059951 | AC72: 51.059951 | AD72: 107.87677 | AE72: 107.87677 | AF72: 96.945356 | AG72: 96.945356 | AH72: 14.066295 | AI72: 14.066295 | AJ72: 0 | AK72: 5000 | AM72: =B72 | AN72: =C72 | AO72: =SUM(AT72:AZ72)+BB72+BC72 | AP72: =SUM(AT72:AZ72)+BE72+BF72 | AQ72: =AO72/3.6 | AR72: =AP72/3.6 | AS72: =AO72-AP72 | AT72: =D72/F72*Y72*-1 | AU72: =E72/F72*Y72 | AV72: {=_xlfn.IFS(C72="Biomass_Corn", 1/F72*S72, C72="Biomass_Agri", 1/F72*V72, C72="Biomass_Wood", 1/F72*U72, C72="Biomass_Herb", 1/F72*T72)} | AW72: =G72/F72*AH72 | AX72: =M72/F72/(0.9*8760) | AY72: =N72/F72/(0.9*8760) | AZ72: =O72/F72 | BA72: =BP72+BQ72+BS72-BL72+BR72+BT72 | BB72: =(Q72+R72)*-1*(I72+K72)/F72 | BC72: =BA72*Q72 | BD72: =SUM(BP72:BR72)-BL72 | BE72: =(I72+K72)/F72*-1*R72 | BF72: =BD72*Q72 | BH72: =H72 | BI72: 0.18104824 | BJ72: 0.23037491 | BL72: =BH72/F72 | BM72: =BI72*G72/F72 | BN72: =SUM(BL72:BM72) | BP72: =BJ72 | BQ72: =J72/F72 | BR72: =L72/F72 | BS72: =I72/F72 | BT72: =K72/F72 | BU72: =SUM(BP72:BT72) | BW72: =BN72-BU72
B73: SE_DryMill_CCS_Fermentation_Exhaust | C73: Biomass_Corn | D73: 0 | E73: 0.085342825 | F73: 3.104338 | G73: 1.0133975 | H73: 1.7588667 | I73: 0.35768767 | J73: 0.68601739 | K73: 0.15290642 | L73: 0.032434696 | M73: 45179.42 | N73: 201481.25 | O73: -25.28 | Q73: 0 | R73: -5.914702 | S73: 100 | T73: 69.166622 | U73: 46.05675 | V73: 41.170372 | W73: 45.289647 | X73: 45.289647 | Y73: 33.298446 | Z73: 36.471022 | AB73: 51.059951 | AC73: 51.059951 | AD73: 107.87677 | AE73: 107.87677 | AF73: 96.945356 | AG73: 96.945356 | AH73: 14.089638 | AI73: 14.089638 | AJ73: 0 | AK73: 5000 | AM73: =B73 | AN73: =C73 | AO73: =SUM(AT73:AZ73)+BB73+BC73 | AP73: =SUM(AT73:AZ73)+BE73+BF73 | AQ73: =AO73/3.6 | AR73: =AP73/3.6 | AS73: =AO73-AP73 | AT73: =D73/F73*Y73*-1 | AU73: =E73/F73*Y73 | AV73: {=_xlfn.IFS(C73="Biomass_Corn", 1/F73*S73, C73="Biomass_Agri", 1/F73*V73, C73="Biomass_Wood", 1/F73*U73, C73="Biomass_Herb", 1/F73*T73)} | AW73: =G73/F73*AH73 | AX73: =M73/F73/(0.9*8760) | AY73: =N73/F73/(0.9*8760) | AZ73: =O73/F73 | BA73: =BP73+BQ73+BS73-BL73+BR73+BT73 | BB73: =(Q73+R73)*-1*(I73+K73)/F73 | BC73: =BA73*Q73 | BD73: =SUM(BP73:BR73)-BL73 | BE73: =(I73+K73)/F73*-1*R73 | BF73: =BD73*Q73 | BH73: =H73 | BI73: 0.18104824 | BJ73: 0.23037491 | BL73: =BH73/F73 | BM73: =BI73*G73/F73 | BN73: =SUM(BL73:BM73) | BP73: =BJ73 | BQ73: =J73/F73 | BR73: =L73/F73 | BS73: =I73/F73 | BT73: =K73/F73 | BU73: =SUM(BP73:BT73) | BW73: =BN73-BU73
...

Sheet lc_summary
B1: UNSORTED | O1: SORTED
B2: id | C2: elec_production | D2: elec_consumption | E2: biomass_consumption | F2: natgas_consumption | G2: investment_cost | H2: fixed_om_cost | I2: variable_om_cost | J2: modified capture cost | K2: modified emissions cost | L2: LCOE ($/MWh-ethanol) | M2: LCOE ($/GJ-ethanol) | O2: id | P2: elec_production | Q2: elec_consumption | R2: biomass_consumption | S2: natgas_consumption | T2: investment_cost | U2: fixed_om_cost | V2: variable_om_cost | W2: modified capture cost | X2: modified emissions cost | Y2: LCOE ($/MWh-ethanol) | Z2: LCOE ($/GJ-ethanol)
B3: =lc_detailed!B4 | C3: =lc_detailed!AT4 | D3: =lc_detailed!AU4 | E3: =lc_detailed!AV4 | F3: =lc_detailed!AW4 | G3: =lc_detailed!AX4 | H3: =lc_detailed!AY4 | I3: =lc_detailed!AZ4 | J3: =lc_detailed!BB4 | K3: =lc_detailed!BC4 | L3: =lc_detailed!AP4 | M3: =lc_detailed!AQ4 | O3: {=_xlfn._xlws.SORT(B3:M74, 11, 1)} | P3: 0 | Q3: 0.73605181 | R3: 54.762078 | S3: 4.465838 | T3: 1.8459717 | U3: 8.2322589 | V3: -8.1434432 | W3: -16.797273 | X3: 6.5363717 | Y3: 51.637854 | Z3: 14.343848
B4: =lc_detailed!B5 | C4: =lc_detailed!AT5 | D4: =lc_detailed!AU5 | E4: =lc_detailed!AV5 | F4: =lc_detailed!AW5 | G4: =lc_detailed!AX5 | H4: =lc_detailed!AY5 | I4: =lc_detailed!AZ5 | J4: =lc_detailed!BB5 | K4: =lc_detailed!BC5 | L4: =lc_detailed!AP5 | M4: =lc_detailed!AQ5 | O4: CA_DryMill_CCS_Fermentation_Exhaust | P4: 0 | Q4: 1.0048324 | R4: 54.762078 | S4: 4.4652582 | T4: 1.8459717 | U4: 8.2322589 | V4: -8.1434432 | W4: -16.93854 | X4: 6.5363717 | Y4: 51.764788 | Z4: 14.379108
B5: =lc_detailed!B6 | C5: =lc_detailed!AT6 | D5: =lc_detailed!AU6 | E5: =lc_detailed!AV6 | F5: =lc_detailed!AW6 | G5: =lc_detailed!AX6 | H5: =lc_detailed!AY6 | I5: =lc_detailed!AZ6 | J5: =lc_detailed!BB6 | K5: =lc_detailed!BC6 | L5: =lc_detailed!AP6 | M5: =lc_detailed!AQ6 | O5: SW_DryMill_CCS_Fermentation_Exhaust | P5: 0 | Q5: 0.76970088 | R5: 54.762078 | S5: 4.4657884 | T5: 1.8459717 | U5: 8.2322589 | V5: -8.1434432 | W5: -15.276872 | X5: 6.5363717 | Y5: 53.191854 | Z5: 14.775515
B6: =lc_detailed!B7 | C6: =lc_detailed!AT7 | D6: =lc_detailed!AU7 | E6: =lc_detailed!AV7 | F6: =lc_detailed!AW7 | G6: =lc_detailed!AX7 | H6: =lc_detailed!AY7 | I6: =lc_detailed!AZ7 | J6: =lc_detailed!BB7 | K6: =lc_detailed!BC7 | L6: =lc_detailed!AP7 | M6: =lc_detailed!AQ7 | O6: TX_DryMill_CCS_Fermentation_Exhaust | P6: 0 | Q6: 0.55615943 | R6: 54.762078 | S6: 4.3501973 | T6: 1.8459717 | U6: 8.2322589 | V6: -8.1434432 | W6: -14.469606 | X6: 6.5363717 | Y6: 53.669988 | Z6: 14.90833
B7: =lc_detailed!B8 | C7: =lc_detailed!AT8 | D7: =lc_detailed!AU8 | E7: =lc_detailed!AV8 | F7: =lc_detailed!AW8 | G7: =lc_detailed!AX8 | H7: =lc_detailed!AY8 | I7: =lc_detailed!AZ8 | J7: =lc_detailed!BB8 | K7: =lc_detailed!BC8 | L7: =lc_detailed!AP8 | M7: =lc_detailed!AQ8 | O7: NW_DryMill_CCS_Fermentation | P7: 0 | Q7: 0.73605181 | R7: 54.762078 | S7: 4.465838 | T7: 1.1219174 | U7: 7.8355578 | V7: -8.1724348 | W7: -11.767033 | X7: 6.5363717 | Y7: 55.518347 | Z7: 15.421763
B8: =lc_detailed!B9 | C8: =lc_detailed!AT9 | D8: =lc_detailed!AU9 | E8: =lc_detailed!AV9 | F8: =lc_detailed!AW9 | G8: =lc_detailed!AX9 | H8: =lc_detailed!AY9 | I8: =lc_detailed!AZ9 | J8: =lc_detailed!BB9 | K8: =lc_detailed!BC9 | L8: =lc_detailed!AP9 | M8: =lc_detailed!AQ9 | O8: CEN_DryMill_CCS_Fermentation_Exhaust | P8: 0 | Q8: 0.69621158 | R8: 54.762078 | S8: 4.3815246 | T8: 1.8459717 | U8: 8.2322589 | V8: -8.1434432 | W8: -12.792466 | X8: 6.5363717 | Y8: 55.518508 | Z8: 15.421808
B9: =lc_detailed!B10 | C9: =lc_detailed!AT10 | D9: =lc_detailed!AU10 | E9: =lc_detailed!AV10 | F9: =lc_detailed!AW10 | G9: =lc_detailed!AX10 | H9: =lc_detailed!AY10 | I9: =lc_detailed!AZ10 | J9: =lc_detailed!BB10 | K9: =lc_detailed!BC10 | L9: =lc_detailed!AP10 | M9: =lc_detailed!AQ10 | O9: CA_DryMill_CCS_Fermentation | P9: 0 | Q9: 1.0048324 | R9: 54.762078 | S9: 4.4652582 | T9: 1.1219174 | U9: 7.8355578 | V9: -8.1724348 | W9: -11.865995 | X9: 6.5363717 | Y9: 55.687586 | Z9: 15.468774
B10: =lc_detailed!B11 | C10: =lc_detailed!AT11 | D10: =lc_detailed!AU11 | E10: =lc_detailed!AV11 | F10: =lc_detailed!AW11 | G10: =lc_detailed!AX11 | H10: =lc_detailed!AY11 | I10: =lc_detailed!AZ11 | J10: =lc_detailed!BB11 | K10: =lc_detailed!BC11 | L10: =lc_detailed!AP11 | M10: =lc_detailed!AQ11 | O10: SW_DryMill_CCS_Fermentation | P10: 0 | Q10: 0.76970088 | R10: 54.762078 | S10: 4.4657884 | T10: 1.1219174 | U10: 7.8355578 | V10: -8.1724348 | W10: -10.701943 | X10: 6.5363717 | Y10: 56.617037 | Z10: 15.726955
B11: =lc_detailed!B12 | C11: =lc_detailed!AT12 | D11: =lc_detailed!AU12 | E11: =lc_detailed!AV12 | F11: =lc_detailed!AW12 | G11: =lc_detailed!AX12 | H11: =lc_detailed!AY12 | I11: =lc_detailed!AZ12 | J11: =lc_detailed!BB12 | K11: =lc_detailed!BC12 | L11: =lc_detailed!AP12 | M11: =lc_detailed!AQ12 | O11: TX_DryMill_CCS_Fermentation | P11: 0 | Q11: 0.55615943 | R11: 54.762078 | S11: 4.3501973 | T11: 1.1219174 | U11: 7.8355578 | V11: -8.1724348 | W11: -10.136427 | X11: 6.5363717 | Y11: 56.85342 | Z11: 15.792617
B12: =lc_detailed!B13 | C12: =lc_detailed!AT13 | D12: =lc_detailed!AU13 | E12: =lc_detailed!AV13 | F12: =lc_detailed!AW13 | G12: =lc_detailed!AX13 | H12: =lc_detailed!AY13 | I12: =lc_detailed!AZ13 | J12: =lc_detailed!BB13 | K12: =lc_detailed!BC13 | L12: =lc_detailed!AP13 | M12: =lc_detailed!AQ13 | O12: NCEN_DryMill_CCS_Fermentation_Exhaust | P12: 0 | Q12: 0.84421292 | R12: 54.762078 | S12: 4.381554 | T12: 1.8459717 | U12: 8.2322589 | V12: -8.1434432 | W12: -11.14544 | X12: 6.5363717 | Y12: 57.313564 | Z12: 15.920434
