Workbook

Sheet lc_detailed
B2: Asset Parameters (normalized by commodity feedstock) | P2: Duals | W2: LCOE for assets with ethane capacity ($/t-ethylene) | Y2: CI | Z2: CREDIT | AJ2: CARBON INTENSITY | AM2: CREDIT | AQ2: Carbon Content | AV2: Carbon Inputs | AX2: Carbon Outputs | BF2: Assumptions
B3: id | C3: commodity | D3: CCS | E3: h2_consumption (MWh/t-CO2Captured) | F3: elec_consumption (MWh/t-CO2Captured) | G3: ethylene_production (t-ethylene/t-CO2Captured) | H3: natgas_production (MWh/t-CO2Captured) | I3: gasoline_production (MWh/t-CO2Captured) | J3: emission_rate (t-CO2/t-CO2Captured) | K3: investment_cost ($/yr per t-CO2Captured/hr) | L3: fixed_om_cost ($/yr per t-CO2Captured/hr) | M3: variable_om_cost ($/t-CO2Captured) | N3: LPG production (t-LPG p t-ethylene) | P3: co2_sink ($/t) | Q3: co2_captured ($/t) | R3: elec_demand ($/MWh) | S3: h2_balance ($/MWh) | T3: gasoline_balance ($/MWh) | U3: ng_balance ($/MWh) | W3: id_LC | X3: commodity_LC | Y3: LCOE ($/t-ethylene) | Z3: LCOE ($/t-ethylene) | AA3: Diff. Between Methods | AB3: h2_consumption | AC3: elec_consumption | AD3: co2captured_consumption | AE3: natgas_production | AF3: gasoline_production | AG3: investment_cost | AH3: fixed_om_cost | AI3: variable_om_cost | AJ3: CI | AK3: modified capture cost | AL3: modified emissions cost | AM3: CI | AN3: modified capture cost | AO3: modified emissions cost | AQ3: Ethylene (t-CO2/t-ethylene) | AR3: Gasoline (t-CO2/MWh-gasoline) | AS3: LPG (t-CO2/t-LPG) | AT3: NG (t-CO2/MWh-NG) | AV3: CO2Captured (t-CO2/t-ethylene) | AX3: Ethylene (t-CO2/t-ethylene) | AY3: NG (t-CO2/t-ethylene) | AZ3: Emissions (t-CO2/t-ethylene) | BA3: LPG (t-CO2/t-ethylene) | BB3: Gasoline (t-CO2/t-ethylene) | BD3: INPUT - OUTPUT (diff LPG) | BF3: Ethylene Carbon Content | BG3: =22/7 -> 3.1428571 | BH3: t-CO2/t-ethylene
B4: CA_S-H2in | C4: CO2Captured | D4: 0 | E4: 5.5446014 | F4: 0.1763 | G4: 0.11376564 | H4: 0.15702624 | I4: 0.77706825 | J4: 0.063018887 | K4: 174237.66 | L4: 95841.65 | M4: -43.02 | N4: 1.01 | P4: 105.211 | Q4: -6.412213 | R4: 36.488698 | T4: 73.640341 | U4: 13.71857 | W4: =B4 -> CA_S-H2in | X4: =C4 -> CO2Captured | Y4: =SUM(AB4:AI4)+AK4+AL4 -> 1927.3066 | Z4: =SUM(AB4:AI4)+AN4+AO4 -> 1927.3066 | AA4: =Y4-Z4 -> 0 | AB4: =E4/G4*S4 -> 0 | AC4: =F4/G4*R4 -> 56.545696 | AD4: =1/G4*(P4+Q4) -> 868.44136 | AE4: =H4/G4*U4*-1 -> -18.935203 | AF4: =I4/G4*T4 -> 502.99519 | AG4: =K4/G4/(0.9*8760) -> 194.2604 | AH4: =L4/G4/(0.9*8760) -> 106.85542 | AI4: =M4 -> -43.02 | AJ4: =AY4+AZ4+BB4 -> 2.4727806 | AK4: 0 | AL4: =AJ4*P4 -> 260.16373 | AM4: =AY4+AZ4+BB4 -> 2.4727806 | AN4: 0 | AO4: =AM4*P4 -> 260.16373 | AQ4: =$BG$3 -> 3.1428571 | AR4: =$BG$4 -> 0.24396819 | AS4: 3.1429329 | AT4: =$BG$5 -> 0.18289084 | AV4: =1/G4 -> 8.79 | AX4: =AQ4 -> 3.1428571 | AY4: =AT4*H4/G4 -> 0.25243703 | AZ4: =J4/G4 -> 0.55393601 | BA4: =AS4*N4 -> 3.1743622 | BB4: =AR4*I4/G4 -> 1.6664076 | BD4: =AV4-SUM(AX4:BB4) -> -1.0935622e-08 | BF4: Gasoline Carbon Content | BG4: 0.24396819 | BH4: t-CO2/MWh-gasoline
B5: NW_S-H2in | C5: CO2Captured | D5: 0.9 | E5: 5.5446014 | F5: 0.1763 | G5: 0.11376564 | H5: 0.15702624 | I5: 0.77706825 | J5: 0.063018887 | K5: 174237.66 | L5: 95841.65 | M5: -43.02 | N5: 1.01 | P5: 105.211 | Q5: -7.379659 | R5: 26.787863 | T5: 73.640341 | U5: 13.71944 | W5: =B5 -> NW_S-H2in | X5: =C5 -> CO2Captured | Y5: =SUM(AB5:AI5)+AK5+AL5 -> 1903.7684 | Z5: =SUM(AB5:AI5)+AN5+AO5 -> 1903.7684 | AA5: =Y5-Z5 -> 0 | AB5: =E5/G5*S5 -> 0 | AC5: =F5/G5*R5 -> 41.512535 | AD5: =1/G5*(P5+Q5) -> 859.93751 | AE5: =H5/G5*U5*-1 -> -18.936403 | AF5: =I5/G5*T5 -> 502.99519 | AG5: =K5/G5/(0.9*8760) -> 194.2604 | AH5: =L5/G5/(0.9*8760) -> 106.85542 | AI5: =M5 -> -43.02 | AJ5: =AY5+AZ5+BB5 -> 2.4727806 | AK5: 0 | AL5: =AJ5*P5 -> 260.16373 | AM5: =AY5+AZ5+BB5 -> 2.4727806 | AN5: 0 | AO5: =AM5*P5 -> 260.16373 | AQ5: =$BG$3 -> 3.1428571 | AR5: =$BG$4 -> 0.24396819 | AS5: 3.1429329 | AT5: =$BG$5 -> 0.18289084 | AV5: =1/G5 -> 8.79 | AX5: =AQ5 -> 3.1428571 | AY5: =AT5*H5/G5 -> 0.25243703 | AZ5: =J5/G5 -> 0.55393601 | BA5: =AS5*N5 -> 3.1743622 | BB5: =AR5*I5/G5 -> 1.6664076 | BD5: =AV5-SUM(AX5:BB5) -> -1.0935622e-08 | BF5: Natural Gas Carbon Content | BG5: 0.18289084 | BH5: t-CO2/MWh-natgas
B6: SW_S-H2in | C6: CO2Captured | D6: 0 | E6: 5.5446014 | F6: 0.1763 | G6: 0.11376564 | H6: 0.15702624 | I6: 0.77706825 | J6: 0.063018887 | K6: 174237.66 | L6: 95841.65 | M6: -43.02 | N6: 1.01 | P6: 105.211 | Q6: -14.567418 | R6: 27.957547 | T6: 73.640341 | U6: 13.719351 | W6: =B6 -> SW_S-H2in | X6: =C6 -> CO2Captured | Y6: =SUM(AB6:AI6)+AK6+AL6 -> 1842.4007 | Z6: =SUM(AB6:AI6)+AN6+AO6 -> 1842.4007 | AA6: =Y6-Z6 -> 0 | AB6: =E6/G6*S6 -> 0 | AC6: =F6/G6*R6 -> 43.325168 | AD6: =1/G6*(P6+Q6) -> 796.75711 | AE6: =H6/G6*U6*-1 -> -18.936281 | AF6: =I6/G6*T6 -> 502.99519 | AG6: =K6/G6/(0.9*8760) -> 194.2604 | AH6: =L6/G6/(0.9*8760) -> 106.85542 | AI6: =M6 -> -43.02 | AJ6: =AY6+AZ6+BB6 -> 2.4727806 | AK6: 0 | AL6: =AJ6*P6 -> 260.16373 | AM6: =AY6+AZ6+BB6 -> 2.4727806 | AN6: 0 | AO6: =AM6*P6 -> 260.16373 | AQ6: =$BG$3 -> 3.1428571 | AR6: =$BG$4 -> 0.24396819 | AS6: 3.1429329 | AT6: =$BG$5 -> 0.18289084 | AV6: =1/G6 -> 8.79 | AX6: =AQ6 -> 3.1428571 | AY6: =AT6*H6/G6 -> 0.25243703 | AZ6: =J6/G6 -> 0.55393601 | BA6: =AS6*N6 -> 3.1743622 | BB6: =AR6*I6/G6 -> 1.6664076 | BD6: =AV6-SUM(AX6:BB6) -> -1.0935622e-08 | BF6: LPG Carbon Content | BG6: =0.22/14 -> 0.015714286 | BH6: t-CO2/t-LPG
B7: TX_S-H2in | C7: CO2Captured | D7: 0.9 | E7: 5.5446014 | F7: 0.1763 | G7: 0.11376564 | H7: 0.15702624 | I7: 0.77706825 | J7: 0.063018887 | K7: 174237.66 | L7: 95841.65 | M7: -43.02 | N7: 1.01 | P7: 105.211 | Q7: -19.477884 | R7: 20.174973 | T7: 73.640341 | U7: 13.326032 | W7: =B7 -> TX_S-H2in | X7: =C7 -> CO2Captured | Y7: =SUM(AB7:AI7)+AK7+AL7 -> 1787.7202 | Z7: =SUM(AB7:AI7)+AN7+AO7 -> 1787.7202 | AA7: =Y7-Z7 -> 0 | AB7: =E7/G7*S7 -> 0 | AC7: =F7/G7*R7 -> 31.264692 | AD7: =1/G7*(P7+Q7) -> 753.59412 | AE7: =H7/G7*U7*-1 -> -18.393398 | AF7: =I7/G7*T7 -> 502.99519 | AG7: =K7/G7/(0.9*8760) -> 194.2604 | AH7: =L7/G7/(0.9*8760) -> 106.85542 | AI7: =M7 -> -43.02 | AJ7: =AY7+AZ7+BB7 -> 2.4727806 | AK7: 0 | AL7: =AJ7*P7 -> 260.16373 | AM7: =AY7+AZ7+BB7 -> 2.4727806 | AN7: 0 | AO7: =AM7*P7 -> 260.16373 | AQ7: =$BG$3 -> 3.1428571 | AR7: =$BG$4 -> 0.24396819 | AS7: 3.1429329 | AT7: =$BG$5 -> 0.18289084 | AV7: =1/G7 -> 8.79 | AX7: =AQ7 -> 3.1428571 | AY7: =AT7*H7/G7 -> 0.25243703 | AZ7: =J7/G7 -> 0.55393601 | BA7: =AS7*N7 -> 3.1743622 | BB7: =AR7*I7/G7 -> 1.6664076 | BD7: =AV7-SUM(AX7:BB7) -> -1.0935622e-08 | BF7: Capacity Factor | BG7: 0.9 | BH7: %
B8: NCEN_S-H2in | C8: CO2Captured | D8: 0 | E8: 5.5446014 | F8: 0.1763 | G8: 0.11376564 | H8: 0.15702624 | I8: 0.77706825 | J8: 0.063018887 | K8: 174237.66 | L8: 95841.65 | M8: -43.02 | N8: 1.01 | P8: 105.211 | Q8: -39.686463 | R8: 30.71395 | T8: 73.640341 | U8: 13.425922 | W8: =B8 -> NCEN_S-H2in | X8: =C8 -> CO2Captured | Y8: =SUM(AB8:AI8)+AK8+AL8 -> 1626.2809 | Z8: =SUM(AB8:AI8)+AN8+AO8 -> 1626.2809 | AA8: =Y8-Z8 -> 0 | AB8: =E8/G8*S8 -> 0 | AC8: =F8/G8*R8 -> 47.596702 | AD8: =1/G8*(P8+Q8) -> 575.96071 | AE8: =H8/G8*U8*-1 -> -18.531272 | AF8: =I8/G8*T8 -> 502.99519 | AG8: =K8/G8/(0.9*8760) -> 194.2604 | AH8: =L8/G8/(0.9*8760) -> 106.85542 | AI8: =M8 -> -43.02 | AJ8: =AY8+AZ8+BB8 -> 2.4727806 | AK8: 0 | AL8: =AJ8*P8 -> 260.16373 | AM8: =AY8+AZ8+BB8 -> 2.4727806 | AN8: 0 | AO8: =AM8*P8 -> 260.16373 | AQ8: =$BG$3 -> 3.1428571 | AR8: =$BG$4 -> 0.24396819 | AS8: 3.1429329 | AT8: =$BG$5 -> 0.18289084 | AV8: =1/G8 -> 8.79 | AX8: =AQ8 -> 3.1428571 | AY8: =AT8*H8/G8 -> 0.25243703 | AZ8: =J8/G8 -> 0.55393601 | BA8: =AS8*N8 -> 3.1743622 | BB8: =AR8*I8/G8 -> 1.6664076 | BD8: =AV8-SUM(AX8:BB8) -> -1.0935622e-08
B9: CEN_S-H2in | C9: CO2Captured | D9: 0.9 | E9: 5.5446014 | F9: 0.1763 | G9: 0.11376564 | H9: 0.15702624 | I9: 0.77706825 | J9: 0.063018887 | K9: 174237.66 | L9: 95841.65 | M9: -43.02 | N9: 1.01 | P9: 105.211 | Q9: -29.672038 | R9: 25.118154 | T9: 73.640341 | U9: 13.425869 | W9: =B9 -> CEN_S-H2in | X9: =C9 -> CO2Captured | Y9: =SUM(AB9:AI9)+AK9+AL9 -> 1705.6361 | Z9: =SUM(AB9:AI9)+AN9+AO9 -> 1705.6361 | AA9: =Y9-Z9 -> 0 | AB9: =E9/G9*S9 -> 0 | AC9: =F9/G9*R9 -> 38.925026 | AD9: =1/G9*(P9+Q9) -> 663.9875 | AE9: =H9/G9*U9*-1 -> -18.531199 | AF9: =I9/G9*T9 -> 502.99519 | AG9: =K9/G9/(0.9*8760) -> 194.2604 | AH9: =L9/G9/(0.9*8760) -> 106.85542 | AI9: =M9 -> -43.02 | AJ9: =AY9+AZ9+BB9 -> 2.4727806 | AK9: 0 | AL9: =AJ9*P9 -> 260.16373 | AM9: =AY9+AZ9+BB9 -> 2.4727806 | AN9: 0 | AO9: =AM9*P9 -> 260.16373 | AQ9: =$BG$3 -> 3.1428571 | AR9: =$BG$4 -> 0.24396819 | AS9: 3.1429329 | AT9: =$BG$5 -> 0.18289084 | AV9: =1/G9 -> 8.79 | AX9: =AQ9 -> 3.1428571 | AY9: =AT9*H9/G9 -> 0.25243703 | AZ9: =J9/G9 -> 0.55393601 | BA9: =AS9*N9 -> 3.1743622 | BB9: =AR9*I9/G9 -> 1.6664076 | BD9: =AV9-SUM(AX9:BB9) -> -1.0935622e-08
B10: SE_S-H2in | C10: CO2Captured | D10: 0 | E10: 5.5446014 | F10: 0.1763 | G10: 0.11376564 | H10: 0.15702624 | I10: 0.77706825 | J10: 0.063018887 | K10: 174237.66 | L10: 95841.65 | M10: -43.02 | N10: 1.01 | P10: 105.211 | Q10: -45.510345 | R10: 38.099076 | T10: 73.640341 | U10: 13.425863 | W10: =B10 -> SE_S-H2in | X10: =C10 -> CO2Captured | Y10: =SUM(AB10:AI10)+AK10+AL10 -> 1586.5336 | Z10: =SUM(AB10:AI10)+AN10+AO10 -> 1586.5336 | AA10: =Y10-Z10 -> 0 | AB10: =E10/G10*S10 -> 0 | AC10: =F10/G10*R10 -> 59.041262 | AD10: =1/G10*(P10+Q10) -> 524.76878 | AE10: =H10/G10*U10*-1 -> -18.531191 | AF10: =I10/G10*T10 -> 502.99519 | AG10: =K10/G10/(0.9*8760) -> 194.2604 | AH10: =L10/G10/(0.9*8760) -> 106.85542 | AI10: =M10 -> -43.02 | AJ10: =AY10+AZ10+BB10 -> 2.4727806 | AK10: 0 | AL10: =AJ10*P10 -> 260.16373 | AM10: =AY10+AZ10+BB10 -> 2.4727806 | AN10: 0 | AO10: =AM10*P10 -> 260.16373 | AQ10: =$BG$3 -> 3.1428571 | AR10: =$BG$4 -> 0.24396819 | AS10: 3.1429329 | AT10: =$BG$5 -> 0.18289084 | AV10: =1/G10 -> 8.79 | AX10: =AQ10 -> 3.1428571 | AY10: =AT10*H10/G10 -> 0.25243703 | AZ10: =J10/G10 -> 0.55393601 | BA10: =AS10*N10 -> 3.1743622 | BB10: =AR10*I10/G10 -> 1.6664076 | BD10: =AV10-SUM(AX10:BB10) -> -1.0935622e-08
B11: MIDAT_S-H2in | C11: CO2Captured | D11: 0.9 | E11: 5.5446014 | F11: 0.1763 | G11: 0.11376564 | H11: 0.15702624 | I11: 0.77706825 | J11: 0.063018887 | K11: 174237.66 | L11: 95841.65 | M11: -43.02 | N11: 1.01 | P11: 105.211 | Q11: -50.334515 | R11: 39.29871 | T11: 73.640341 | U11: 13.42643 | W11: =B11 -> MIDAT_S-H2in | X11: =C11 -> CO2Captured | Y11: =SUM(AB11:AI11)+AK11+AL11 -> 1545.9874 | Z11: =SUM(AB11:AI11)+AN11+AO11 -> 1545.9874 | AA11: =Y11-Z11 -> 0 | AB11: =E11/G11*S11 -> 0 | AC11: =F11/G11*R11 -> 60.900307 | AD11: =1/G11*(P11+Q11) -> 482.36433 | AE11: =H11/G11*U11*-1 -> -18.531973 | AF11: =I11/G11*T11 -> 502.99519 | AG11: =K11/G11/(0.9*8760) -> 194.2604 | AH11: =L11/G11/(0.9*8760) -> 106.85542 | AI11: =M11 -> -43.02 | AJ11: =AY11+AZ11+BB11 -> 2.4727806 | AK11: 0 | AL11: =AJ11*P11 -> 260.16373 | AM11: =AY11+AZ11+BB11 -> 2.4727806 | AN11: 0 | AO11: =AM11*P11 -> 260.16373 | AQ11: =$BG$3 -> 3.1428571 | AR11: =$BG$4 -> 0.24396819 | AS11: 3.1429329 | AT11: =$BG$5 -> 0.18289084 | AV11: =1/G11 -> 8.79 | AX11: =AQ11 -> 3.1428571 | AY11: =AT11*H11/G11 -> 0.25243703 | AZ11: =J11/G11 -> 0.55393601 | BA11: =AS11*N11 -> 3.1743622 | BB11: =AR11*I11/G11 -> 1.6664076 | BD11: =AV11-SUM(AX11:BB11) -> -1.0935622e-08
B12: NE_S-H2in | C12: CO2Captured | D12: 0 | E12: 5.5446014 | F12: 0.1763 | G12: 0.11376564 | H12: 0.15702624 | I12: 0.77706825 | J12: 0.063018887 | K12: 174237.66 | L12: 95841.65 | M12: -43.02 | N12: 1.01 | P12: 105.211 | Q12: -58.833413 | R12: 47.365061 | T12: 73.640341 | U12: 13.426279 | W12: =B12 -> NE_S-H2in | X12: =C12 -> CO2Captured | Y12: =SUM(AB12:AI12)+AK12+AL12 -> 1483.7825 | Z12: =SUM(AB12:AI12)+AN12+AO12 -> 1483.7825 | AA12: =Y12-Z12 -> 0 | AB12: =E12/G12*S12 -> 0 | AC12: =F12/G12*R12 -> 73.400546 | AD12: =1/G12*(P12+Q12) -> 407.65902 | AE12: =H12/G12*U12*-1 -> -18.531765 | AF12: =I12/G12*T12 -> 502.99519 | AG12: =K12/G12/(0.9*8760) -> 194.2604 | AH12: =L12/G12/(0.9*8760) -> 106.85542 | AI12: =M12 -> -43.02 | AJ12: =AY12+AZ12+BB12 -> 2.4727806 | AK12: 0 | AL12: =AJ12*P12 -> 260.16373 | AM12: =AY12+AZ12+BB12 -> 2.4727806 | AN12: 0 | AO12: =AM12*P12 -> 260.16373 | AQ12: =$BG$3 -> 3.1428571 | AR12: =$BG$4 -> 0.24396819 | AS12: 3.1429329 | AT12: =$BG$5 -> 0.18289084 | AV12: =1/G12 -> 8.79 | AX12: =AQ12 -> 3.1428571 | AY12: =AT12*H12/G12 -> 0.25243703 | AZ12: =J12/G12 -> 0.55393601 | BA12: =AS12*N12 -> 3.1743622 | BB12: =AR12*I12/G12 -> 1.6664076 | BD12: =AV12-SUM(AX12:BB12) -> -1.0935622e-08
B13: CA_S-CC90-H2in | C13: CO2Captured | D13: 0.9 | E13: 5.8754727 | F13: 0.2382 | G13: 0.12055455 | H13: 0.1663967 | I13: 0.82343942 | J13: 0.0071050046 | K13: 203942.22 | L13: 112111.54 | M13: -45.26 | N13: 1.01 | P13: 105.211 | Q13: -6.412213 | R13: 36.488698 | T13: 73.640341 | U13: 13.71857 | W13: =B13 -> CA_S-CC90-H2in | X13: =C13 -> CO2Captured | Y13: =SUM(AB13:AI13)+AK13+AL13 -> 1871.047 | Z13: =SUM(AB13:AI13)+AN13+AO13 -> 1871.047 | AA13: =Y13-Z13 -> 0 | AB13: =E13/G13*S13 -> 0 | AC13: =F13/G13*R13 -> 72.096887 | AD13: =1/G13*(P13+Q13) -> 819.53596 | AE13: =H13/G13*U13*-1 -> -18.935203 | AF13: =I13/G13*T13 -> 502.99519 | AG13: =K13/G13/(0.9*8760) -> 214.57391 | AH13: =L13/G13/(0.9*8760) -> 117.95602 | AI13: =M13 -> -45.26 | AJ13: =AY13+AZ13+BB13 -> 1.9777806 | AK13: 0 | AL13: =AJ13*P13 -> 208.08428 | AM13: =AY13+AZ13+BB13 -> 1.9777806 | AN13: 0 | AO13: =AM13*P13 -> 208.08428 | AQ13: =$BG$3 -> 3.1428571 | AR13: =$BG$4 -> 0.24396819 | AS13: 3.1429329 | AT13: =$BG$5 -> 0.18289084 | AV13: =1/G13 -> 8.295 | AX13: =AQ13 -> 3.1428571 | AY13: =AT13*H13/G13 -> 0.25243703 | AZ13: =J13/G13 -> 0.058936013 | BA13: =AS13*N13 -> 3.1743622 | BB13: =AR13*I13/G13 -> 1.6664076 | BD13: =AV13-SUM(AX13:BB13) -> -1.0935626e-08
B14: NW_S-CC90-H2in | C14: CO2Captured | D14: 0 | E14: 5.8754727 | F14: 0.2382 | G14: 0.12055455 | H14: 0.1663967 | I14: 0.82343942 | J14: 0.0071050046 | K14: 203942.22 | L14: 112111.54 | M14: -45.26 | N14: 1.01 | P14: 105.211 | Q14: -7.379659 | R14: 26.787863 | T14: 73.640341 | U14: 13.71944 | W14: =B14 -> NW_S-CC90-H2in | X14: =C14 -> CO2Captured | Y14: =SUM(AB14:AI14)+AK14+AL14 -> 1843.8533 | Z14: =SUM(AB14:AI14)+AN14+AO14 -> 1843.8533 | AA14: =Y14-Z14 -> 0 | AB14: =E14/G14*S14 -> 0 | AC14: =F14/G14*R14 -> 52.929308 | AD14: =1/G14*(P14+Q14) -> 811.511 | AE14: =H14/G14*U14*-1 -> -18.936403 | AF14: =I14/G14*T14 -> 502.99519 | AG14: =K14/G14/(0.9*8760) -> 214.57391 | AH14: =L14/G14/(0.9*8760) -> 117.95602 | AI14: =M14 -> -45.26 | AJ14: =AY14+AZ14+BB14 -> 1.9777806 | AK14: 0 | AL14: =AJ14*P14 -> 208.08428 | AM14: =AY14+AZ14+BB14 -> 1.9777806 | AN14: 0 | AO14: =AM14*P14 -> 208.08428 | AQ14: =$BG$3 -> 3.1428571 | AR14: =$BG$4 -> 0.24396819 | AS14: 3.1429329 | AT14: =$BG$5 -> 0.18289084 | AV14: =1/G14 -> 8.295 | AX14: =AQ14 -> 3.1428571 | AY14: =AT14*H14/G14 -> 0.25243703 | AZ14: =J14/G14 -> 0.058936013 | BA14: =AS14*N14 -> 3.1743622 | BB14: =AR14*I14/G14 -> 1.6664076 | BD14: =AV14-SUM(AX14:BB14) -> -1.0935626e-08
B15: SW_S-CC90-H2in | C15: CO2Captured | D15: 0.9 | E15: 5.8754727 | F15: 0.2382 | G15: 0.12055455 | H15: 0.1663967 | I15: 0.82343942 | J15: 0.0071050046 | K15: 203942.22 | L15: 112111.54 | M15: -45.26 | N15: 1.01 | P15: 105.211 | Q15: -14.567418 | R15: 27.957547 | T15: 73.640341 | U15: 13.719351 | W15: =B15 -> SW_S-CC90-H2in | X15: =C15 -> CO2Captured | Y15: =SUM(AB15:AI15)+AK15+AL15 -> 1786.5421 | Z15: =SUM(AB15:AI15)+AN15+AO15 -> 1786.5421 | AA15: =Y15-Z15 -> 0 | AB15: =E15/G15*S15 -> 0 | AC15: =F15/G15*R15 -> 55.24045 | AD15: =1/G15*(P15+Q15) -> 751.88854 | AE15: =H15/G15*U15*-1 -> -18.936281 | AF15: =I15/G15*T15 -> 502.99519 | AG15: =K15/G15/(0.9*8760) -> 214.57391 | AH15: =L15/G15/(0.9*8760) -> 117.95602 | AI15: =M15 -> -45.26 | AJ15: =AY15+AZ15+BB15 -> 1.9777806 | AK15: 0 | AL15: =AJ15*P15 -> 208.08428 | AM15: =AY15+AZ15+BB15 -> 1.9777806 | AN15: 0 | AO15: =AM15*P15 -> 208.08428 | AQ15: =$BG$3 -> 3.1428571 | AR15: =$BG$4 -> 0.24396819 | AS15: 3.1429329 | AT15: =$BG$5 -> 0.18289084 | AV15: =1/G15 -> 8.295 | AX15: =AQ15 -> 3.1428571 | AY15: =AT15*H15/G15 -> 0.25243703 | AZ15: =J15/G15 -> 0.058936013 | BA15: =AS15*N15 -> 3.1743622 | BB15: =AR15*I15/G15 -> 1.6664076 | BD15: =AV15-SUM(AX15:BB15) -> -1.0935626e-08
B16: TX_S-CC90-H2in | C16: CO2Captured | D16: 0 | E16: 5.8754727 | F16: 0.2382 | G16: 0.12055455 | H16: 0.1663967 | I16: 0.82343942 | J16: 0.0071050046 | K16: 203942.22 | L16: 112111.54 | M16: -45.26 | N16: 1.01 | P16: 105.211 | Q16: -19.477884 | R16: 20.174973 | T16: 73.640341 | U16: 13.326032 | W16: =B16 -> TX_S-CC90-H2in | X16: =C16 -> CO2Captured | Y16: =SUM(AB16:AI16)+AK16+AL16 -> 1730.9753 | Z16: =SUM(AB16:AI16)+AN16+AO16 -> 1730.9753 | AA16: =Y16-Z16 -> 0 | AB16: =E16/G16*S16 -> 0 | AC16: =F16/G16*R16 -> 39.863104 | AD16: =1/G16*(P16+Q16) -> 711.15622 | AE16: =H16/G16*U16*-1 -> -18.393398 | AF16: =I16/G16*T16 -> 502.99519 | AG16: =K16/G16/(0.9*8760) -> 214.57391 | AH16: =L16/G16/(0.9*8760) -> 117.95602 | AI16: =M16 -> -45.26 | AJ16: =AY16+AZ16+BB16 -> 1.9777806 | AK16: 0 | AL16: =AJ16*P16 -> 208.08428 | AM16: =AY16+AZ16+BB16 -> 1.9777806 | AN16: 0 | AO16: =AM16*P16 -> 208.08428 | AQ16: =$BG$3 -> 3.1428571 | AR16: =$BG$4 -> 0.24396819 | AS16: 3.1429329 | AT16: =$BG$5 -> 0.18289084 | AV16: =1/G16 -> 8.295 | AX16: =AQ16 -> 3.1428571 | AY16: =AT16*H16/G16 -> 0.25243703 | AZ16: =J16/G16 -> 0.058936013 | BA16: =AS16*N16 -> 3.1743622 | BB16: =AR16*I16/G16 -> 1.6664076 | BD16: =AV16-SUM(AX16:BB16) -> -1.0935626e-08
B17: NCEN_S-CC90-H2in | C17: CO2Captured | D17: 0.9 | E17: 5.8754727 | F17: 0.2382 | G17: 0.12055455 | H17: 0.1663967 | I17: 0.82343942 | J17: 0.0071050046 | K17: 203942.22 | L17: 112111.54 | M17: -45.26 | N17: 1.01 | P17: 105.211 | Q17: -39.686463 | R17: 30.71395 | T17: 73.640341 | U17: 13.425922 | W17: =B17 -> NCEN_S-CC90-H2in | X17: =C17 -> CO2Captured | Y17: =SUM(AB17:AI17)+AK17+AL17 -> 1584.0309 | Z17: =SUM(AB17:AI17)+AN17+AO17 -> 1584.0309 | AA17: =Y17-Z17 -> 0 | AB17: =E17/G17*S17 -> 0 | AC17: =F17/G17*R17 -> 60.686742 | AD17: =1/G17*(P17+Q17) -> 543.52606 | AE17: =H17/G17*U17*-1 -> -18.531272 | AF17: =I17/G17*T17 -> 502.99519 | AG17: =K17/G17/(0.9*8760) -> 214.57391 | AH17: =L17/G17/(0.9*8760) -> 117.95602 | AI17: =M17 -> -45.26 | AJ17: =AY17+AZ17+BB17 -> 1.9777806 | AK17: 0 | AL17: =AJ17*P17 -> 208.08428 | AM17: =AY17+AZ17+BB17 -> 1.9777806 | AN17: 0 | AO17: =AM17*P17 -> 208.08428 | AQ17: =$BG$3 -> 3.1428571 | AR17: =$BG$4 -> 0.24396819 | AS17: 3.1429329 | AT17: =$BG$5 -> 0.18289084 | AV17: =1/G17 -> 8.295 | AX17: =AQ17 -> 3.1428571 | AY17: =AT17*H17/G17 -> 0.25243703 | AZ17: =J17/G17 -> 0.058936013 | BA17: =AS17*N17 -> 3.1743622 | BB17: =AR17*I17/G17 -> 1.6664076 | BD17: =AV17-SUM(AX17:BB17) -> -1.0935626e-08
B18: CEN_S-CC90-H2in | C18: CO2Captured | D18: 0 | E18: 5.8754727 | F18: 0.2382 | G18: 0.12055455 | H18: 0.1663967 | I18: 0.82343942 | J18: 0.0071050046 | K18: 203942.22 | L18: 112111.54 | M18: -45.26 | N18: 1.01 | P18: 105.211 | Q18: -29.672038 | R18: 25.118154 | T18: 73.640341 | U18: 13.425869 | W18: =B18 -> CEN_S-CC90-H2in | X18: =C18 -> CO2Captured | Y18: =SUM(AB18:AI18)+AK18+AL18 -> 1656.0441 | Z18: =SUM(AB18:AI18)+AN18+AO18 -> 1656.0441 | AA18: =Y18-Z18 -> 0 | AB18: =E18/G18*S18 -> 0 | AC18: =F18/G18*R18 -> 49.630182 | AD18: =1/G18*(P18+Q18) -> 626.59571 | AE18: =H18/G18*U18*-1 -> -18.531199 | AF18: =I18/G18*T18 -> 502.99519 | AG18: =K18/G18/(0.9*8760) -> 214.57391 | AH18: =L18/G18/(0.9*8760) -> 117.95602 | AI18: =M18 -> -45.26 | AJ18: =AY18+AZ18+BB18 -> 1.9777806 | AK18: 0 | AL18: =AJ18*P18 -> 208.08428 | AM18: =AY18+AZ18+BB18 -> 1.9777806 | AN18: 0 | AO18: =AM18*P18 -> 208.08428 | AQ18: =$BG$3 -> 3.1428571 | AR18: =$BG$4 -> 0.24396819 | AS18: 3.1429329 | AT18: =$BG$5 -> 0.18289084 | AV18: =1/G18 -> 8.295 | AX18: =AQ18 -> 3.1428571 | AY18: =AT18*H18/G18 -> 0.25243703 | AZ18: =J18/G18 -> 0.058936013 | BA18: =AS18*N18 -> 3.1743622 | BB18: =AR18*I18/G18 -> 1.6664076 | BD18: =AV18-SUM(AX18:BB18) -> -1.0935626e-08
B19: SE_S-CC90-H2in | C19: CO2Captured | D19: 0.9 | E19: 5.8754727 | F19: 0.2382 | G19: 0.12055455 | H19: 0.1663967 | I19: 0.82343942 | J19: 0.0071050046 | K19: 203942.22 | L19: 112111.54 | M19: -45.26 | N19: 1.01 | P19: 105.211 | Q19: -45.510345 | R19: 38.099076 | T19: 73.640341 | U19: 13.425863 | W19: =B19 -> SE_S-CC90-H2in | X19: =C19 -> CO2Captured | Y19: =SUM(AB19:AI19)+AK19+AL19 -> 1550.314 | Z19: =SUM(AB19:AI19)+AN19+AO19 -> 1550.314 | AA19: =Y19-Z19 -> 0 | AB19: =E19/G19*S19 -> 0 | AC19: =F19/G19*R19 -> 75.278783 | AD19: =1/G19*(P19+Q19) -> 495.21696 | AE19: =H19/G19*U19*-1 -> -18.531191 | AF19: =I19/G19*T19 -> 502.99519 | AG19: =K19/G19/(0.9*8760) -> 214.57391 | AH19: =L19/G19/(0.9*8760) -> 117.95602 | AI19: =M19 -> -45.26 | AJ19: =AY19+AZ19+BB19 -> 1.9777806 | AK19: 0 | AL19: =AJ19*P19 -> 208.08428 | AM19: =AY19+AZ19+BB19 -> 1.9777806 | AN19: 0 | AO19: =AM19*P19 -> 208.08428 | AQ19: =$BG$3 -> 3.1428571 | AR19: =$BG$4 -> 0.24396819 | AS19: 3.1429329 | AT19: =$BG$5 -> 0.18289084 | AV19: =1/G19 -> 8.295 | AX19: =AQ19 -> 3.1428571 | AY19: =AT19*H19/G19 -> 0.25243703 | AZ19: =J19/G19 -> 0.058936013 | BA19: =AS19*N19 -> 3.1743622 | BB19: =AR19*I19/G19 -> 1.6664076 | BD19: =AV19-SUM(AX19:BB19) -> -1.0935626e-08
... B21: NE_S-CC90-H2in | C21: CO2Captured | D21: 0.9 | E21: 5.8754727 | F21: 0.2382 | G21: 0.12055455 | H21: 0.1663967 | I21: 0.82343942 | J21: 0.0071050046 | K21: 203942.22 | L21: 112111.54 | M21: -45.26 | N21: 1.01 | P21: 105.211 | Q21: -58.833413 | R21: 47.365061 | T21: 73.640341 | U21: 13.426279 | W21: =B21 -> NE_S-CC90-H2in | X21: =C21 -> CO2Captured | Y21: =SUM(AB21:AI21)+AK21+AL21 -> 1458.1069 | Z21: =SUM(AB21:AI21)+AN21+AO21 -> 1458.1069 | AA21: =Y21-Z21 -> 0 | AB21: =E21/G21*S21 -> 0 | AC21: =F21/G21*R21 -> 93.587156 | AD21: =1/G21*(P21+Q21) -> 384.70211 | AE21: =H21/G21*U21*-1 -> -18.531765 | AF21: =I21/G21*T21 -> 502.99519 | AG21: =K21/G21/(0.9*8760) -> 214.57391 | AH21: =L21/G21/(0.9*8760) -> 117.95602 | AI21: =M21 -> -45.26 | AJ21: =AY21+AZ21+BB21 -> 1.9777806 | AK21: 0 | AL21: =AJ21*P21 -> 208.08428 | AM21: =AY21+AZ21+BB21 -> 1.9777806 | AN21: 0 | AO21: =AM21*P21 -> 208.08428 | AQ21: =$BG$3 -> 3.1428571 | AR21: =$BG$4 -> 0.24396819 | AS21: 3.1429329 | AT21: =$BG$5 -> 0.18289084 | AV21: =1/G21 -> 8.295 | AX21: =AQ21 -> 3.1428571 | AY21: =AT21*H21/G21 -> 0.25243703 | AZ21: =J21/G21 -> 0.058936013 | BA21: =AS21*N21 -> 3.1743622 | BB21: =AR21*I21/G21 -> 1.6664076 | BD21: =AV21-SUM(AX21:BB21) -> -1.0935626e-08
C22: CO2Captured | D22: 0.9 | N22: 1.01 | W22: =B22 -> 0 | X22: =C22 -> CO2Captured | Y22: =SUM(AB22:AI22)+AK22+AL22 -> #DIV/0! | Z22: =SUM(AB22:AI22)+AN22+AO22 -> #DIV/0! | AA22: =Y22-Z22 -> #DIV/0! | AB22: =E22/G22*S22 -> #DIV/0! | AC22: =F22/G22*R22 -> #DIV/0! | AD22: =1/G22*(P22+Q22) -> #DIV/0! | AE22: =H22/G22*U22*-1 -> #DIV/0! | AF22: =I22/G22*T22 -> #DIV/0! | AG22: =K22/G22/(0.9*8760) -> #DIV/0! | AH22: =L22/G22/(0.9*8760) -> #DIV/0! | AI22: =M22 -> 0 | AJ22: =AY22+AZ22+BB22 -> #DIV/0! | AK22: 0 | AL22: =AJ22*P22 -> #DIV/0! | AM22: =AY22+AZ22+BB22 -> #DIV/0! | AN22: 0 | AO22: =AM22*P22 -> #DIV/0! | AQ22: =$BG$3 -> 3.1428571 | AR22: =$BG$4 -> 0.24396819 | AS22: 3.1429329 | AT22: =$BG$5 -> 0.18289084 | AV22: =1/G22 -> #DIV/0! | AX22: =AQ22 -> 3.1428571 | AY22: =AT22*H22/G22 -> #DIV/0! | AZ22: =J22/G22 -> #DIV/0! | BA22: =AS22*N22 -> 3.1743622 | BB22: =AR22*I22/G22 -> #DIV/0! | BD22: =AV22-SUM(AX22:BB22) -> #DIV/0!
C23: CO2Captured | D23: 0.9 | N23: 1.01 | W23: =B23 -> 0 | X23: =C23 -> CO2Captured | Y23: =SUM(AB23:AI23)+AK23+AL23 -> #DIV/0! | Z23: =SUM(AB23:AI23)+AN23+AO23 -> #DIV/0! | AA23: =Y23-Z23 -> #DIV/0! | AB23: =E23/G23*S23 -> #DIV/0! | AC23: =F23/G23*R23 -> #DIV/0! | AD23: =1/G23*(P23+Q23) -> #DIV/0! | AE23: =H23/G23*U23*-1 -> #DIV/0! | AF23: =I23/G23*T23 -> #DIV/0! | AG23: =K23/G23/(0.9*8760) -> #DIV/0! | AH23: =L23/G23/(0.9*8760) -> #DIV/0! | AI23: =M23 -> 0 | AJ23: =AY23+AZ23+BB23 -> #DIV/0! | AK23: 0 | AL23: =AJ23*P23 -> #DIV/0! | AM23: =AY23+AZ23+BB23 -> #DIV/0! | AN23: 0 | AO23: =AM23*P23 -> #DIV/0! | AQ23: =$BG$3 -> 3.1428571 | AR23: =$BG$4 -> 0.24396819 | AS23: 3.1429329 | AT23: =$BG$5 -> 0.18289084 | AV23: =1/G23 -> #DIV/0! | AX23: =AQ23 -> 3.1428571 | AY23: =AT23*H23/G23 -> #DIV/0! | AZ23: =J23/G23 -> #DIV/0! | BA23: =AS23*N23 -> 3.1743622 | BB23: =AR23*I23/G23 -> #DIV/0! | BD23: =AV23-SUM(AX23:BB23) -> #DIV/0!
C24: CO2Captured | D24: 0.9 | N24: 1.01 | W24: =B24 -> 0 | X24: =C24 -> CO2Captured | Y24: =SUM(AB24:AI24)+AK24+AL24 -> #DIV/0! | Z24: =SUM(AB24:AI24)+AN24+AO24 -> #DIV/0! | AA24: =Y24-Z24 -> #DIV/0! | AB24: =E24/G24*S24 -> #DIV/0! | AC24: =F24/G24*R24 -> #DIV/0! | AD24: =1/G24*(P24+Q24) -> #DIV/0! | AE24: =H24/G24*U24*-1 -> #DIV/0! | AF24: =I24/G24*T24 -> #DIV/0! | AG24: =K24/G24/(0.9*8760) -> #DIV/0! | AH24: =L24/G24/(0.9*8760) -> #DIV/0! | AI24: =M24 -> 0 | AJ24: =AY24+AZ24+BB24 -> #DIV/0! | AK24: 0 | AL24: =AJ24*P24 -> #DIV/0! | AM24: =AY24+AZ24+BB24 -> #DIV/0! | AN24: 0 | AO24: =AM24*P24 -> #DIV/0! | AQ24: =$BG$3 -> 3.1428571 | AR24: =$BG$4 -> 0.24396819 | AS24: 3.1429329 | AT24: =$BG$5 -> 0.18289084 | AV24: =1/G24 -> #DIV/0! | AX24: =AQ24 -> 3.1428571 | AY24: =AT24*H24/G24 -> #DIV/0! | AZ24: =J24/G24 -> #DIV/0! | BA24: =AS24*N24 -> 3.1743622 | BB24: =AR24*I24/G24 -> #DIV/0! | BD24: =AV24-SUM(AX24:BB24) -> #DIV/0!
C25: CO2Captured | D25: 0.9 | N25: 1.01 | W25: =B25 -> 0 | X25: =C25 -> CO2Captured | Y25: =SUM(AB25:AI25)+AK25+AL25 -> #DIV/0! | Z25: =SUM(AB25:AI25)+AN25+AO25 -> #DIV/0! | AA25: =Y25-Z25 -> #DIV/0! | AB25: =E25/G25*S25 -> #DIV/0! | AC25: =F25/G25*R25 -> #DIV/0! | AD25: =1/G25*(P25+Q25) -> #DIV/0! | AE25: =H25/G25*U25*-1 -> #DIV/0! | AF25: =I25/G25*T25 -> #DIV/0! | AG25: =K25/G25/(0.9*8760) -> #DIV/0! | AH25: =L25/G25/(0.9*8760) -> #DIV/0! | AI25: =M25 -> 0 | AJ25: =AY25+AZ25+BB25 -> #DIV/0! | AK25: 0 | AL25: =AJ25*P25 -> #DIV/0! | AM25: =AY25+AZ25+BB25 -> #DIV/0! | AN25: 0 | AO25: =AM25*P25 -> #DIV/0! | AQ25: =$BG$3 -> 3.1428571 | AR25: =$BG$4 -> 0.24396819 | AS25: 3.1429329 | AT25: =$BG$5 -> 0.18289084 | AV25: =1/G25 -> #DIV/0! | AX25: =AQ25 -> 3.1428571 | AY25: =AT25*H25/G25 -> #DIV/0! | AZ25: =J25/G25 -> #DIV/0! | BA25: =AS25*N25 -> 3.1743622 | BB25: =AR25*I25/G25 -> #DIV/0! | BD25: =AV25-SUM(AX25:BB25) -> #DIV/0!
C26: CO2Captured | D26: 0.9 | N26: 1.01 | W26: =B26 -> 0 | X26: =C26 -> CO2Captured | Y26: =SUM(AB26:AI26)+AK26+AL26 -> #DIV/0! | Z26: =SUM(AB26:AI26)+AN26+AO26 -> #DIV/0! | AA26: =Y26-Z26 -> #DIV/0! | AB26: =E26/G26*S26 -> #DIV/0! | AC26: =F26/G26*R26 -> #DIV/0! | AD26: =1/G26*(P26+Q26) -> #DIV/0! | AE26: =H26/G26*U26*-1 -> #DIV/0! | AF26: =I26/G26*T26 -> #DIV/0! | AG26: =K26/G26/(0.9*8760) -> #DIV/0! | AH26: =L26/G26/(0.9*8760) -> #DIV/0! | AI26: =M26 -> 0 | AJ26: =AY26+AZ26+BB26 -> #DIV/0! | AK26: 0 | AL26: =AJ26*P26 -> #DIV/0! | AM26: =AY26+AZ26+BB26 -> #DIV/0! | AN26: 0 | AO26: =AM26*P26 -> #DIV/0! | AQ26: =$BG$3 -> 3.1428571 | AR26: =$BG$4 -> 0.24396819 | AS26: 3.1429329 | AT26: =$BG$5 -> 0.18289084 | AV26: =1/G26 -> #DIV/0! | AX26: =AQ26 -> 3.1428571 | AY26: =AT26*H26/G26 -> #DIV/0! | AZ26: =J26/G26 -> #DIV/0! | BA26: =AS26*N26 -> 3.1743622 | BB26: =AR26*I26/G26 -> #DIV/0! | BD26: =AV26-SUM(AX26:BB26) -> #DIV/0!
C27: CO2Captured | D27: 0.9 | N27: 1.01 | W27: =B27 -> 0 | X27: =C27 -> CO2Captured | Y27: =SUM(AB27:AI27)+AK27+AL27 -> #DIV/0! | Z27: =SUM(AB27:AI27)+AN27+AO27 -> #DIV/0! | AA27: =Y27-Z27 -> #DIV/0! | AB27: =E27/G27*S27 -> #DIV/0! | AC27: =F27/G27*R27 -> #DIV/0! | AD27: =1/G27*(P27+Q27) -> #DIV/0! | AE27: =H27/G27*U27*-1 -> #DIV/0! | AF27: =I27/G27*T27 -> #DIV/0! | AG27: =K27/G27/(0.9*8760) -> #DIV/0! | AH27: =L27/G27/(0.9*8760) -> #DIV/0! | AI27: =M27 -> 0 | AJ27: =AY27+AZ27+BB27 -> #DIV/0! | AK27: 0 | AL27: =AJ27*P27 -> #DIV/0! | AM27: =AY27+AZ27+BB27 -> #DIV/0! | AN27: 0 | AO27: =AM27*P27 -> #DIV/0! | AQ27: =$BG$3 -> 3.1428571 | AR27: =$BG$4 -> 0.24396819 | AS27: 3.1429329 | AT27: =$BG$5 -> 0.18289084 | AV27: =1/G27 -> #DIV/0! | AX27: =AQ27 -> 3.1428571 | AY27: =AT27*H27/G27 -> #DIV/0! | AZ27: =J27/G27 -> #DIV/0! | BA27: =AS27*N27 -> 3.1743622 | BB27: =AR27*I27/G27 -> #DIV/0! | BD27: =AV27-SUM(AX27:BB27) -> #DIV/0!
C28: CO2Captured | D28: 0.9 | N28: 1.01 | W28: =B28 -> 0 | X28: =C28 -> CO2Captured | Y28: =SUM(AB28:AI28)+AK28+AL28 -> #DIV/0! | Z28: =SUM(AB28:AI28)+AN28+AO28 -> #DIV/0! | AA28: =Y28-Z28 -> #DIV/0! | AB28: =E28/G28*S28 -> #DIV/0! | AC28: =F28/G28*R28 -> #DIV/0! | AD28: =1/G28*(P28+Q28) -> #DIV/0! | AE28: =H28/G28*U28*-1 -> #DIV/0! | AF28: =I28/G28*T28 -> #DIV/0! | AG28: =K28/G28/(0.9*8760) -> #DIV/0! | AH28: =L28/G28/(0.9*8760) -> #DIV/0! | AI28: =M28 -> 0 | AJ28: =AY28+AZ28+BB28 -> #DIV/0! | AK28: 0 | AL28: =AJ28*P28 -> #DIV/0! | AM28: =AY28+AZ28+BB28 -> #DIV/0! | AN28: 0 | AO28: =AM28*P28 -> #DIV/0! | AQ28: =$BG$3 -> 3.1428571 | AR28: =$BG$4 -> 0.24396819 | AS28: 3.1429329 | AT28: =$BG$5 -> 0.18289084 | AV28: =1/G28 -> #DIV/0! | AX28: =AQ28 -> 3.1428571 | AY28: =AT28*H28/G28 -> #DIV/0! | AZ28: =J28/G28 -> #DIV/0! | BA28: =AS28*N28 -> 3.1743622 | BB28: =AR28*I28/G28 -> #DIV/0! | BD28: =AV28-SUM(AX28:BB28) -> #DIV/0!
C29: CO2Captured | D29: 0.9 | N29: 1.01 | W29: =B29 -> 0 | X29: =C29 -> CO2Captured | Y29: =SUM(AB29:AI29)+AK29+AL29 -> #DIV/0! | Z29: =SUM(AB29:AI29)+AN29+AO29 -> #DIV/0! | AA29: =Y29-Z29 -> #DIV/0! | AB29: =E29/G29*S29 -> #DIV/0! | AC29: =F29/G29*R29 -> #DIV/0! | AD29: =1/G29*(P29+Q29) -> #DIV/0! | AE29: =H29/G29*U29*-1 -> #DIV/0! | AF29: =I29/G29*T29 -> #DIV/0! | AG29: =K29/G29/(0.9*8760) -> #DIV/0! | AH29: =L29/G29/(0.9*8760) -> #DIV/0! | AI29: =M29 -> 0 | AJ29: =AY29+AZ29+BB29 -> #DIV/0! | AK29: 0 | AL29: =AJ29*P29 -> #DIV/0! | AM29: =AY29+AZ29+BB29 -> #DIV/0! | AN29: 0 | AO29: =AM29*P29 -> #DIV/0! | AQ29: =$BG$3 -> 3.1428571 | AR29: =$BG$4 -> 0.24396819 | AS29: 3.1429329 | AT29: =$BG$5 -> 0.18289084 | AV29: =1/G29 -> #DIV/0! | AX29: =AQ29 -> 3.1428571 | AY29: =AT29*H29/G29 -> #DIV/0! | AZ29: =J29/G29 -> #DIV/0! | BA29: =AS29*N29 -> 3.1743622 | BB29: =AR29*I29/G29 -> #DIV/0! | BD29: =AV29-SUM(AX29:BB29) -> #DIV/0!
C30: CO2Captured | D30: 0.9 | N30: 1.01 | W30: =B30 -> 0 | X30: =C30 -> CO2Captured | Y30: =SUM(AB30:AI30)+AK30+AL30 -> #DIV/0! | Z30: =SUM(AB30:AI30)+AN30+AO30 -> #DIV/0! | AA30: =Y30-Z30 -> #DIV/0! | AB30: =E30/G30*S30 -> #DIV/0! | AC30: =F30/G30*R30 -> #DIV/0! | AD30: =1/G30*(P30+Q30) -> #DIV/0! | AE30: =H30/G30*U30*-1 -> #DIV/0! | AF30: =I30/G30*T30 -> #DIV/0! | AG30: =K30/G30/(0.9*8760) -> #DIV/0! | AH30: =L30/G30/(0.9*8760) -> #DIV/0! | AI30: =M30 -> 0 | AJ30: =AY30+AZ30+BB30 -> #DIV/0! | AK30: 0 | AL30: =AJ30*P30 -> #DIV/0! | AM30: =AY30+AZ30+BB30 -> #DIV/0! | AN30: 0 | AO30: =AM30*P30 -> #DIV/0! | AQ30: =$BG$3 -> 3.1428571 | AR30: =$BG$4 -> 0.24396819 | AS30: 3.1429329 | AT30: =$BG$5 -> 0.18289084 | AV30: =1/G30 -> #DIV/0! | AX30: =AQ30 -> 3.1428571 | AY30: =AT30*H30/G30 -> #DIV/0! | AZ30: =J30/G30 -> #DIV/0! | BA30: =AS30*N30 -> 3.1743622 | BB30: =AR30*I30/G30 -> #DIV/0! | BD30: =AV30-SUM(AX30:BB30) -> #DIV/0!
C31: CO2Captured | D31: 0.9 | N31: 1.01 | W31: =B31 -> 0 | X31: =C31 -> CO2Captured | Y31: =SUM(AB31:AI31)+AK31+AL31 -> #DIV/0! | Z31: =SUM(AB31:AI31)+AN31+AO31 -> #DIV/0! | AA31: =Y31-Z31 -> #DIV/0! | AB31: =E31/G31*S31 -> #DIV/0! | AC31: =F31/G31*R31 -> #DIV/0! | AD31: =1/G31*(P31+Q31) -> #DIV/0! | AE31: =H31/G31*U31*-1 -> #DIV/0! | AF31: =I31/G31*T31 -> #DIV/0! | AG31: =K31/G31/(0.9*8760) -> #DIV/0! | AH31: =L31/G31/(0.9*8760) -> #DIV/0! | AI31: =M31 -> 0 | AJ31: =AY31+AZ31+BB31 -> #DIV/0! | AK31: 0 | AL31: =AJ31*P31 -> #DIV/0! | AM31: =AY31+AZ31+BB31 -> #DIV/0! | AN31: 0 | AO31: =AM31*P31 -> #DIV/0! | AQ31: =$BG$3 -> 3.1428571 | AR31: =$BG$4 -> 0.24396819 | AS31: 3.1429329 | AT31: =$BG$5 -> 0.18289084 | AV31: =1/G31 -> #DIV/0! | AX31: =AQ31 -> 3.1428571 | AY31: =AT31*H31/G31 -> #DIV/0! | AZ31: =J31/G31 -> #DIV/0! | BA31: =AS31*N31 -> 3.1743622 | BB31: =AR31*I31/G31 -> #DIV/0! | BD31: =AV31-SUM(AX31:BB31) -> #DIV/0!
C32: CO2Captured | D32: 0.9 | N32: 1.01 | W32: =B32 -> 0 | X32: =C32 -> CO2Captured | Y32: =SUM(AB32:AI32)+AK32+AL32 -> #DIV/0! | Z32: =SUM(AB32:AI32)+AN32+AO32 -> #DIV/0! | AA32: =Y32-Z32 -> #DIV/0! | AB32: =E32/G32*S32 -> #DIV/0! | AC32: =F32/G32*R32 -> #DIV/0! | AD32: =1/G32*(P32+Q32) -> #DIV/0! | AE32: =H32/G32*U32*-1 -> #DIV/0! | AF32: =I32/G32*T32 -> #DIV/0! | AG32: =K32/G32/(0.9*8760) -> #DIV/0! | AH32: =L32/G32/(0.9*8760) -> #DIV/0! | AI32: =M32 -> 0 | AJ32: =AY32+AZ32+BB32 -> #DIV/0! | AK32: 0 | AL32: =AJ32*P32 -> #DIV/0! | AM32: =AY32+AZ32+BB32 -> #DIV/0! | AN32: 0 | AO32: =AM32*P32 -> #DIV/0! | AQ32: =$BG$3 -> 3.1428571 | AR32: =$BG$4 -> 0.24396819 | AS32: 3.1429329 | AT32: =$BG$5 -> 0.18289084 | AV32: =1/G32 -> #DIV/0! | AX32: =AQ32 -> 3.1428571 | AY32: =AT32*H32/G32 -> #DIV/0! | AZ32: =J32/G32 -> #DIV/0! | BA32: =AS32*N32 -> 3.1743622 | BB32: =AR32*I32/G32 -> #DIV/0! | BD32: =AV32-SUM(AX32:BB32) -> #DIV/0!
C33: CO2Captured | D33: 0.9 | N33: 1.01 | W33: =B33 -> 0 | X33: =C33 -> CO2Captured | Y33: =SUM(AB33:AI33)+AK33+AL33 -> #DIV/0! | Z33: =SUM(AB33:AI33)+AN33+AO33 -> #DIV/0! | AA33: =Y33-Z33 -> #DIV/0! | AB33: =E33/G33*S33 -> #DIV/0! | AC33: =F33/G33*R33 -> #DIV/0! | AD33: =1/G33*(P33+Q33) -> #DIV/0! | AE33: =H33/G33*U33*-1 -> #DIV/0! | AF33: =I33/G33*T33 -> #DIV/0! | AG33: =K33/G33/(0.9*8760) -> #DIV/0! | AH33: =L33/G33/(0.9*8760) -> #DIV/0! | AI33: =M33 -> 0 | AJ33: =AY33+AZ33+BB33 -> #DIV/0! | AK33: 0 | AL33: =AJ33*P33 -> #DIV/0! | AM33: =AY33+AZ33+BB33 -> #DIV/0! | AN33: 0 | AO33: =AM33*P33 -> #DIV/0! | AQ33: =$BG$3 -> 3.1428571 | AR33: =$BG$4 -> 0.24396819 | AS33: 3.1429329 | AT33: =$BG$5 -> 0.18289084 | AV33: =1/G33 -> #DIV/0! | AX33: =AQ33 -> 3.1428571 | AY33: =AT33*H33/G33 -> #DIV/0! | AZ33: =J33/G33 -> #DIV/0! | BA33: =AS33*N33 -> 3.1743622 | BB33: =AR33*I33/G33 -> #DIV/0! | BD33: =AV33-SUM(AX33:BB33) -> #DIV/0!
... C66: CO2Captured | D66: 0.9 | N66: 1.01 | W66: =B66 -> 0 | X66: =C66 -> CO2Captured | Y66: =SUM(AB66:AI66)+AK66+AL66 -> #DIV/0! | Z66: =SUM(AB66:AI66)+AN66+AO66 -> #DIV/0! | AA66: =Y66-Z66 -> #DIV/0! | AB66: =E66/G66*S66 -> #DIV/0! | AC66: =F66/G66*R66 -> #DIV/0! | AD66: =1/G66*(P66+Q66) -> #DIV/0! | AE66: =H66/G66*U66*-1 -> #DIV/0! | AF66: =I66/G66*T66 -> #DIV/0! | AG66: =K66/G66/(0.9*8760) -> #DIV/0! | AH66: =L66/G66/(0.9*8760) -> #DIV/0! | AI66: =M66 -> 0 | AJ66: =AY66+AZ66+BB66 -> #DIV/0! | AK66: 0 | AL66: =AJ66*P66 -> #DIV/0! | AM66: =AY66+AZ66+BB66 -> #DIV/0! | AN66: 0 | AO66: =AM66*P66 -> #DIV/0! | AQ66: =$BG$3 -> 3.1428571 | AR66: =$BG$4 -> 0.24396819 | AS66: 3.1429329 | AT66: =$BG$5 -> 0.18289084 | AV66: =1/G66 -> #DIV/0! | AX66: =AQ66 -> 3.1428571 | AY66: =AT66*H66/G66 -> #DIV/0! | AZ66: =J66/G66 -> #DIV/0! | BA66: =AS66*N66 -> 3.1743622 | BB66: =AR66*I66/G66 -> #DIV/0! | BD66: =AV66-SUM(AX66:BB66) -> #DIV/0!

Sheet lc_summary
A1: Levelized cost for Synthetic Ethylene Production - $/t-ethylene
A2: id_LC | B2: h2_consumption | C2: elec_consumption | D2: co2captured_consumption | E2: natgas_production | F2: gasoline_production | G2: investment_cost | H2: fixed_om_cost | I2: variable_om_cost | J2: modified capture cost | K2: modified emissions cost | L2: LCOE ($/t-ethylene) | N2: id_LC | O2: h2_consumption | P2: elec_consumption | Q2: co2captured_consumption | R2: natgas_production | S2: gasoline_production | T2: investment_cost | U2: fixed_om_cost | V2: variable_om_cost | W2: modified capture cost | X2: modified emissions cost | Y2: LCOE ($/t-ethylene)
A3: =lc_detailed!W4 -> CA_S-H2in | B3: =lc_detailed!AB4 -> 0 | C3: =lc_detailed!AC4 -> 56.545696 | D3: =lc_detailed!AD4 -> 868.44136 | E3: =lc_detailed!AE4 -> -18.935203 | F3: =lc_detailed!AF4 -> 502.99519 | G3: =lc_detailed!AG4 -> 194.2604 | H3: =lc_detailed!AH4 -> 106.85542 | I3: =lc_detailed!AI4 -> -43.02 | J3: =lc_detailed!AK4 -> 0 | K3: =lc_detailed!AL4 -> 260.16373 | L3: =lc_detailed!Y4 -> 1927.3066 | N3: {=_xlfn._xlws.SORT(A3:L70, 12, 1)} -> 0 | O3: 0 | P3: 0 | Q3: 0 | R3: 0 | S3: 0 | T3: 0 | U3: 0 | V3: 0 | W3: 0 | X3: 0 | Y3: 0
A4: =lc_detailed!W5 -> NW_S-H2in | B4: =lc_detailed!AB5 -> 0 | C4: =lc_detailed!AC5 -> 41.512535 | D4: =lc_detailed!AD5 -> 859.93751 | E4: =lc_detailed!AE5 -> -18.936403 | F4: =lc_detailed!AF5 -> 502.99519 | G4: =lc_detailed!AG5 -> 194.2604 | H4: =lc_detailed!AH5 -> 106.85542 | I4: =lc_detailed!AI5 -> -43.02 | J4: =lc_detailed!AK5 -> 0 | K4: =lc_detailed!AL5 -> 260.16373 | L4: =lc_detailed!Y5 -> 1903.7684 | N4: 0 | O4: 0 | P4: 0 | Q4: 0 | R4: 0 | S4: 0 | T4: 0 | U4: 0 | V4: 0 | W4: 0 | X4: 0 | Y4: 0
A5: =lc_detailed!W6 -> SW_S-H2in | B5: =lc_detailed!AB6 -> 0 | C5: =lc_detailed!AC6 -> 43.325168 | D5: =lc_detailed!AD6 -> 796.75711 | E5: =lc_detailed!AE6 -> -18.936281 | F5: =lc_detailed!AF6 -> 502.99519 | G5: =lc_detailed!AG6 -> 194.2604 | H5: =lc_detailed!AH6 -> 106.85542 | I5: =lc_detailed!AI6 -> -43.02 | J5: =lc_detailed!AK6 -> 0 | K5: =lc_detailed!AL6 -> 260.16373 | L5: =lc_detailed!Y6 -> 1842.4007 | N5: 0 | O5: 0 | P5: 0 | Q5: 0 | R5: 0 | S5: 0 | T5: 0 | U5: 0 | V5: 0 | W5: 0 | X5: 0 | Y5: 0
A6: =lc_detailed!W7 -> TX_S-H2in | B6: =lc_detailed!AB7 -> 0 | C6: =lc_detailed!AC7 -> 31.264692 | D6: =lc_detailed!AD7 -> 753.59412 | E6: =lc_detailed!AE7 -> -18.393398 | F6: =lc_detailed!AF7 -> 502.99519 | G6: =lc_detailed!AG7 -> 194.2604 | H6: =lc_detailed!AH7 -> 106.85542 | I6: =lc_detailed!AI7 -> -43.02 | J6: =lc_detailed!AK7 -> 0 | K6: =lc_detailed!AL7 -> 260.16373 | L6: =lc_detailed!Y7 -> 1787.7202 | N6: 0 | O6: 0 | P6: 0 | Q6: 0 | R6: 0 | S6: 0 | T6: 0 | U6: 0 | V6: 0 | W6: 0 | X6: 0 | Y6: 0
A7: =lc_detailed!W8 -> NCEN_S-H2in | B7: =lc_detailed!AB8 -> 0 | C7: =lc_detailed!AC8 -> 47.596702 | D7: =lc_detailed!AD8 -> 575.96071 | E7: =lc_detailed!AE8 -> -18.531272 | F7: =lc_detailed!AF8 -> 502.99519 | G7: =lc_detailed!AG8 -> 194.2604 | H7: =lc_detailed!AH8 -> 106.85542 | I7: =lc_detailed!AI8 -> -43.02 | J7: =lc_detailed!AK8 -> 0 | K7: =lc_detailed!AL8 -> 260.16373 | L7: =lc_detailed!Y8 -> 1626.2809 | N7: 0 | O7: 0 | P7: 0 | Q7: 0 | R7: 0 | S7: 0 | T7: 0 | U7: 0 | V7: 0 | W7: 0 | X7: 0 | Y7: 0
A8: =lc_detailed!W9 -> CEN_S-H2in | B8: =lc_detailed!AB9 -> 0 | C8: =lc_detailed!AC9 -> 38.925026 | D8: =lc_detailed!AD9 -> 663.9875 | E8: =lc_detailed!AE9 -> -18.531199 | F8: =lc_detailed!AF9 -> 502.99519 | G8: =lc_detailed!AG9 -> 194.2604 | H8: =lc_detailed!AH9 -> 106.85542 | I8: =lc_detailed!AI9 -> -43.02 | J8: =lc_detailed!AK9 -> 0 | K8: =lc_detailed!AL9 -> 260.16373 | L8: =lc_detailed!Y9 -> 1705.6361 | N8: NE_S-CC90-H2in | O8: 0 | P8: 93.587156 | Q8: 384.70211 | R8: -18.531765 | S8: 502.99519 | T8: 214.57391 | U8: 117.95602 | V8: -45.26 | W8: 0 | X8: 208.08428 | Y8: 1458.1069
A9: =lc_detailed!W10 -> SE_S-H2in | B9: =lc_detailed!AB10 -> 0 | C9: =lc_detailed!AC10 -> 59.041262 | D9: =lc_detailed!AD10 -> 524.76878 | E9: =lc_detailed!AE10 -> -18.531191 | F9: =lc_detailed!AF10 -> 502.99519 | G9: =lc_detailed!AG10 -> 194.2604 | H9: =lc_detailed!AH10 -> 106.85542 | I9: =lc_detailed!AI10 -> -43.02 | J9: =lc_detailed!AK10 -> 0 | K9: =lc_detailed!AL10 -> 260.16373 | L9: =lc_detailed!Y10 -> 1586.5336 | N9: NE_S-H2in | O9: 0 | P9: 73.400546 | Q9: 407.65902 | R9: -18.531765 | S9: 502.99519 | T9: 194.2604 | U9: 106.85542 | V9: -43.02 | W9: 0 | X9: 260.16373 | Y9: 1483.7825
A10: =lc_detailed!W11 -> MIDAT_S-H2in | B10: =lc_detailed!AB11 -> 0 | C10: =lc_detailed!AC11 -> 60.900307 | D10: =lc_detailed!AD11 -> 482.36433 | E10: =lc_detailed!AE11 -> -18.531973 | F10: =lc_detailed!AF11 -> 502.99519 | G10: =lc_detailed!AG11 -> 194.2604 | H10: =lc_detailed!AH11 -> 106.85542 | I10: =lc_detailed!AI11 -> -43.02 | J10: =lc_detailed!AK11 -> 0 | K10: =lc_detailed!AL11 -> 260.16373 | L10: =lc_detailed!Y11 -> 1545.9874 | N10: MIDAT_S-CC90-H2in | O10: 0 | P10: 77.649103 | Q10: 455.20047 | R10: -18.531973 | S10: 502.99519 | T10: 214.57391 | U10: 117.95602 | V10: -45.26 | W10: 0 | X10: 208.08428 | Y10: 1512.667
A11: =lc_detailed!W12 -> NE_S-H2in | B11: =lc_detailed!AB12 -> 0 | C11: =lc_detailed!AC12 -> 73.400546 | D11: =lc_detailed!AD12 -> 407.65902 | E11: =lc_detailed!AE12 -> -18.531765 | F11: =lc_detailed!AF12 -> 502.99519 | G11: =lc_detailed!AG12 -> 194.2604 | H11: =lc_detailed!AH12 -> 106.85542 | I11: =lc_detailed!AI12 -> -43.02 | J11: =lc_detailed!AK12 -> 0 | K11: =lc_detailed!AL12 -> 260.16373 | L11: =lc_detailed!Y12 -> 1483.7825 | N11: MIDAT_S-H2in | O11: 0 | P11: 60.900307 | Q11: 482.36433 | R11: -18.531973 | S11: 502.99519 | T11: 194.2604 | U11: 106.85542 | V11: -43.02 | W11: 0 | X11: 260.16373 | Y11: 1545.9874
A12: =lc_detailed!W13 -> CA_S-CC90-H2in | B12: =lc_detailed!AB13 -> 0 | C12: =lc_detailed!AC13 -> 72.096887 | D12: =lc_detailed!AD13 -> 819.53596 | E12: =lc_detailed!AE13 -> -18.935203 | F12: =lc_detailed!AF13 -> 502.99519 | G12: =lc_detailed!AG13 -> 214.57391 | H12: =lc_detailed!AH13 -> 117.95602 | I12: =lc_detailed!AI13 -> -45.26 | J12: =lc_detailed!AK13 -> 0 | K12: =lc_detailed!AL13 -> 208.08428 | L12: =lc_detailed!Y13 -> 1871.047 | N12: SE_S-CC90-H2in | O12: 0 | P12: 75.278783 | Q12: 495.21696 | R12: -18.531191 | S12: 502.99519 | T12: 214.57391 | U12: 117.95602 | V12: -45.26 | W12: 0 | X12: 208.08428 | Y12: 1550.314
A13: =lc_detailed!W14 -> NW_S-CC90-H2in | B13: =lc_detailed!AB14 -> 0 | C13: =lc_detailed!AC14 -> 52.929308 | D13: =lc_detailed!AD14 -> 811.511 | E13: =lc_detailed!AE14 -> -18.936403 | F13: =lc_detailed!AF14 -> 502.99519 | G13: =lc_detailed!AG14 -> 214.57391 | H13: =lc_detailed!AH14 -> 117.95602 | I13: =lc_detailed!AI14 -> -45.26 | J13: =lc_detailed!AK14 -> 0 | K13: =lc_detailed!AL14 -> 208.08428 | L13: =lc_detailed!Y14 -> 1843.8533 | N13: NCEN_S-CC90-H2in | O13: 0 | P13: 60.686742 | Q13: 543.52606 | R13: -18.531272 | S13: 502.99519 | T13: 214.57391 | U13: 117.95602 | V13: -45.26 | W13: 0 | X13: 208.08428 | Y13: 1584.0309
A14: =lc_detailed!W15 -> SW_S-CC90-H2in | B14: =lc_detailed!AB15 -> 0 | C14: =lc_detailed!AC15 -> 55.24045 | D14: =lc_detailed!AD15 -> 751.88854 | E14: =lc_detailed!AE15 -> -18.936281 | F14: =lc_detailed!AF15 -> 502.99519 | G14: =lc_detailed!AG15 -> 214.57391 | H14: =lc_detailed!AH15 -> 117.95602 | I14: =lc_detailed!AI15 -> -45.26 | J14: =lc_detailed!AK15 -> 0 | K14: =lc_detailed!AL15 -> 208.08428 | L14: =lc_detailed!Y15 -> 1786.5421 | N14: SE_S-H2in | O14: 0 | P14: 59.041262 | Q14: 524.76878 | R14: -18.531191 | S14: 502.99519 | T14: 194.2604 | U14: 106.85542 | V14: -43.02 | W14: 0 | X14: 260.16373 | Y14: 1586.5336
A15: =lc_detailed!W16 -> TX_S-CC90-H2in | B15: =lc_detailed!AB16 -> 0 | C15: =lc_detailed!AC16 -> 39.863104 | D15: =lc_detailed!AD16 -> 711.15622 | E15: =lc_detailed!AE16 -> -18.393398 | F15: =lc_detailed!AF16 -> 502.99519 | G15: =lc_detailed!AG16 -> 214.57391 | H15: =lc_detailed!AH16 -> 117.95602 | I15: =lc_detailed!AI16 -> -45.26 | J15: =lc_detailed!AK16 -> 0 | K15: =lc_detailed!AL16 -> 208.08428 | L15: =lc_detailed!Y16 -> 1730.9753 | N15: NCEN_S-H2in | O15: 0 | P15: 47.596702 | Q15: 575.96071 | R15: -18.531272 | S15: 502.99519 | T15: 194.2604 | U15: 106.85542 | V15: -43.02 | W15: 0 | X15: 260.16373 | Y15: 1626.2809
A16: =lc_detailed!W17 -> NCEN_S-CC90-H2in | B16: =lc_detailed!AB17 -> 0 | C16: =lc_detailed!AC17 -> 60.686742 | D16: =lc_detailed!AD17 -> 543.52606 | E16: =lc_detailed!AE17 -> -18.531272 | F16: =lc_detailed!AF17 -> 502.99519 | G16: =lc_detailed!AG17 -> 214.57391 | H16: =lc_detailed!AH17 -> 117.95602 | I16: =lc_detailed!AI17 -> -45.26 | J16: =lc_detailed!AK17 -> 0 | K16: =lc_detailed!AL17 -> 208.08428 | L16: =lc_detailed!Y17 -> 1584.0309 | N16: CEN_S-CC90-H2in | O16: 0 | P16: 49.630182 | Q16: 626.59571 | R16: -18.531199 | S16: 502.99519 | T16: 214.57391 | U16: 117.95602 | V16: -45.26 | W16: 0 | X16: 208.08428 | Y16: 1656.0441
A17: =lc_detailed!W18 -> CEN_S-CC90-H2in | B17: =lc_detailed!AB18 -> 0 | C17: =lc_detailed!AC18 -> 49.630182 | D17: =lc_detailed!AD18 -> 626.59571 | E17: =lc_detailed!AE18 -> -18.531199 | F17: =lc_detailed!AF18 -> 502.99519 | G17: =lc_detailed!AG18 -> 214.57391 | H17: =lc_detailed!AH18 -> 117.95602 | I17: =lc_detailed!AI18 -> -45.26 | J17: =lc_detailed!AK18 -> 0 | K17: =lc_detailed!AL18 -> 208.08428 | L17: =lc_detailed!Y18 -> 1656.0441 | N17: CEN_S-H2in | O17: 0 | P17: 38.925026 | Q17: 663.9875 | R17: -18.531199 | S17: 502.99519 | T17: 194.2604 | U17: 106.85542 | V17: -43.02 | W17: 0 | X17: 260.16373 | Y17: 1705.6361
A18: =lc_detailed!W19 -> SE_S-CC90-H2in | B18: =lc_detailed!AB19 -> 0 | C18: =lc_detailed!AC19 -> 75.278783 | D18: =lc_detailed!AD19 -> 495.21696 | E18: =lc_detailed!AE19 -> -18.531191 | F18: =lc_detailed!AF19 -> 502.99519 | G18: =lc_detailed!AG19 -> 214.57391 | H18: =lc_detailed!AH19 -> 117.95602 | I18: =lc_detailed!AI19 -> -45.26 | J18: =lc_detailed!AK19 -> 0 | K18: =lc_detailed!AL19 -> 208.08428 | L18: =lc_detailed!Y19 -> 1550.314 | N18: TX_S-CC90-H2in | O18: 0 | P18: 39.863104 | Q18: 711.15622 | R18: -18.393398 | S18: 502.99519 | T18: 214.57391 | U18: 117.95602 | V18: -45.26 | W18: 0 | X18: 208.08428 | Y18: 1730.9753
A19: =lc_detailed!W20 -> MIDAT_S-CC90-H2in | B19: =lc_detailed!AB20 -> 0 | C19: =lc_detailed!AC20 -> 77.649103 | D19: =lc_detailed!AD20 -> 455.20047 | E19: =lc_detailed!AE20 -> -18.531973 | F19: =lc_detailed!AF20 -> 502.99519 | G19: =lc_detailed!AG20 -> 214.57391 | H19: =lc_detailed!AH20 -> 117.95602 | I19: =lc_detailed!AI20 -> -45.26 | J19: =lc_detailed!AK20 -> 0 | K19: =lc_detailed!AL20 -> 208.08428 | L19: =lc_detailed!Y20 -> 1512.667 | N19: SW_S-CC90-H2in | O19: 0 | P19: 55.24045 | Q19: 751.88854 | R19: -18.936281 | S19: 502.99519 | T19: 214.57391 | U19: 117.95602 | V19: -45.26 | W19: 0 | X19: 208.08428 | Y19: 1786.5421
... A25: =lc_detailed!W26 -> 0 | B25: =lc_detailed!AB26 -> #DIV/0! | C25: =lc_detailed!AC26 -> #DIV/0! | D25: =lc_detailed!AD26 -> #DIV/0! | E25: =lc_detailed!AE26 -> #DIV/0! | F25: =lc_detailed!AF26 -> #DIV/0! | G25: =lc_detailed!AG26 -> #DIV/0! | H25: =lc_detailed!AH26 -> #DIV/0! | I25: =lc_detailed!AI26 -> 0 | J25: =lc_detailed!AK26 -> 0 | K25: =lc_detailed!AL26 -> #DIV/0! | L25: =lc_detailed!Y26 -> #DIV/0! | N25: CA_S-H2in | O25: 0 | P25: 56.545696 | Q25: 868.44136 | R25: -18.935203 | S25: 502.99519 | T25: 194.2604 | U25: 106.85542 | V25: -43.02 | W25: 0 | X25: 260.16373 | Y25: 1927.3066
A26: =lc_detailed!W27 -> 0 | B26: =lc_detailed!AB27 -> #DIV/0! | C26: =lc_detailed!AC27 -> #DIV/0! | D26: =lc_detailed!AD27 -> #DIV/0! | E26: =lc_detailed!AE27 -> #DIV/0! | F26: =lc_detailed!AF27 -> #DIV/0! | G26: =lc_detailed!AG27 -> #DIV/0! | H26: =lc_detailed!AH27 -> #DIV/0! | I26: =lc_detailed!AI27 -> 0 | J26: =lc_detailed!AK27 -> 0 | K26: =lc_detailed!AL27 -> #DIV/0! | L26: =lc_detailed!Y27 -> #DIV/0! | N26: 0 | O26: #DIV/0! | P26: #DIV/0! | Q26: #DIV/0! | R26: #DIV/0! | S26: #DIV/0! | T26: #DIV/0! | U26: #DIV/0! | V26: 0 | W26: 0 | X26: #DIV/0! | Y26: #DIV/0!
A27: =lc_detailed!W28 -> 0 | B27: =lc_detailed!AB28 -> #DIV/0! | C27: =lc_detailed!AC28 -> #DIV/0! | D27: =lc_detailed!AD28 -> #DIV/0! | E27: =lc_detailed!AE28 -> #DIV/0! | F27: =lc_detailed!AF28 -> #DIV/0! | G27: =lc_detailed!AG28 -> #DIV/0! | H27: =lc_detailed!AH28 -> #DIV/0! | I27: =lc_detailed!AI28 -> 0 | J27: =lc_detailed!AK28 -> 0 | K27: =lc_detailed!AL28 -> #DIV/0! | L27: =lc_detailed!Y28 -> #DIV/0! | N27: 0 | O27: #DIV/0! | P27: #DIV/0! | Q27: #DIV/0! | R27: #DIV/0! | S27: #DIV/0! | T27: #DIV/0! | U27: #DIV/0! | V27: 0 | W27: 0 | X27: #DIV/0! | Y27: #DIV/0!
A28: =lc_detailed!W29 -> 0 | B28: =lc_detailed!AB29 -> #DIV/0! | C28: =lc_detailed!AC29 -> #DIV/0! | D28: =lc_detailed!AD29 -> #DIV/0! | E28: =lc_detailed!AE29 -> #DIV/0! | F28: =lc_detailed!AF29 -> #DIV/0! | G28: =lc_detailed!AG29 -> #DIV/0! | H28: =lc_detailed!AH29 -> #DIV/0! | I28: =lc_detailed!AI29 -> 0 | J28: =lc_detailed!AK29 -> 0 | K28: =lc_detailed!AL29 -> #DIV/0! | L28: =lc_detailed!Y29 -> #DIV/0! | N28: 0 | O28: #DIV/0! | P28: #DIV/0! | Q28: #DIV/0! | R28: #DIV/0! | S28: #DIV/0! | T28: #DIV/0! | U28: #DIV/0! | V28: 0 | W28: 0 | X28: #DIV/0! | Y28: #DIV/0!
A29: =lc_detailed!W30 -> 0 | B29: =lc_detailed!AB30 -> #DIV/0! | C29: =lc_detailed!AC30 -> #DIV/0! | D29: =lc_detailed!AD30 -> #DIV/0! | E29: =lc_detailed!AE30 -> #DIV/0! | F29: =lc_detailed!AF30 -> #DIV/0! | G29: =lc_detailed!AG30 -> #DIV/0! | H29: =lc_detailed!AH30 -> #DIV/0! | I29: =lc_detailed!AI30 -> 0 | J29: =lc_detailed!AK30 -> 0 | K29: =lc_detailed!AL30 -> #DIV/0! | L29: =lc_detailed!Y30 -> #DIV/0! | N29: 0 | O29: #DIV/0! | P29: #DIV/0! | Q29: #DIV/0! | R29: #DIV/0! | S29: #DIV/0! | T29: #DIV/0! | U29: #DIV/0! | V29: 0 | W29: 0 | X29: #DIV/0! | Y29: #DIV/0!
A30: =lc_detailed!W31 -> 0 | B30: =lc_detailed!AB31 -> #DIV/0! | C30: =lc_detailed!AC31 -> #DIV/0! | D30: =lc_detailed!AD31 -> #DIV/0! | E30: =lc_detailed!AE31 -> #DIV/0! | F30: =lc_detailed!AF31 -> #DIV/0! | G30: =lc_detailed!AG31 -> #DIV/0! | H30: =lc_detailed!AH31 -> #DIV/0! | I30: =lc_detailed!AI31 -> 0 | J30: =lc_detailed!AK31 -> 0 | K30: =lc_detailed!AL31 -> #DIV/0! | L30: =lc_detailed!Y31 -> #DIV/0! | N30: 0 | O30: #DIV/0! | P30: #DIV/0! | Q30: #DIV/0! | R30: #DIV/0! | S30: #DIV/0! | T30: #DIV/0! | U30: #DIV/0! | V30: 0 | W30: 0 | X30: #DIV/0! | Y30: #DIV/0!
A31: =lc_detailed!W32 -> 0 | B31: =lc_detailed!AB32 -> #DIV/0! | C31: =lc_detailed!AC32 -> #DIV/0! | D31: =lc_detailed!AD32 -> #DIV/0! | E31: =lc_detailed!AE32 -> #DIV/0! | F31: =lc_detailed!AF32 -> #DIV/0! | G31: =lc_detailed!AG32 -> #DIV/0! | H31: =lc_detailed!AH32 -> #DIV/0! | I31: =lc_detailed!AI32 -> 0 | J31: =lc_detailed!AK32 -> 0 | K31: =lc_detailed!AL32 -> #DIV/0! | L31: =lc_detailed!Y32 -> #DIV/0! | N31: 0 | O31: #DIV/0! | P31: #DIV/0! | Q31: #DIV/0! | R31: #DIV/0! | S31: #DIV/0! | T31: #DIV/0! | U31: #DIV/0! | V31: 0 | W31: 0 | X31: #DIV/0! | Y31: #DIV/0!
A32: =lc_detailed!W33 -> 0 | B32: =lc_detailed!AB33 -> #DIV/0! | C32: =lc_detailed!AC33 -> #DIV/0! | D32: =lc_detailed!AD33 -> #DIV/0! | E32: =lc_detailed!AE33 -> #DIV/0! | F32: =lc_detailed!AF33 -> #DIV/0! | G32: =lc_detailed!AG33 -> #DIV/0! | H32: =lc_detailed!AH33 -> #DIV/0! | I32: =lc_detailed!AI33 -> 0 | J32: =lc_detailed!AK33 -> 0 | K32: =lc_detailed!AL33 -> #DIV/0! | L32: =lc_detailed!Y33 -> #DIV/0! | N32: 0 | O32: #DIV/0! | P32: #DIV/0! | Q32: #DIV/0! | R32: #DIV/0! | S32: #DIV/0! | T32: #DIV/0! | U32: #DIV/0! | V32: 0 | W32: 0 | X32: #DIV/0! | Y32: #DIV/0!
A33: =lc_detailed!W34 -> 0 | B33: =lc_detailed!AB34 -> #DIV/0! | C33: =lc_detailed!AC34 -> #DIV/0! | D33: =lc_detailed!AD34 -> #DIV/0! | E33: =lc_detailed!AE34 -> #DIV/0! | F33: =lc_detailed!AF34 -> #DIV/0! | G33: =lc_detailed!AG34 -> #DIV/0! | H33: =lc_detailed!AH34 -> #DIV/0! | I33: =lc_detailed!AI34 -> 0 | J33: =lc_detailed!AK34 -> 0 | K33: =lc_detailed!AL34 -> #DIV/0! | L33: =lc_detailed!Y34 -> #DIV/0! | N33: 0 | O33: #DIV/0! | P33: #DIV/0! | Q33: #DIV/0! | R33: #DIV/0! | S33: #DIV/0! | T33: #DIV/0! | U33: #DIV/0! | V33: 0 | W33: 0 | X33: #DIV/0! | Y33: #DIV/0!
A34: =lc_detailed!W35 -> 0 | B34: =lc_detailed!AB35 -> #DIV/0! | C34: =lc_detailed!AC35 -> #DIV/0! | D34: =lc_detailed!AD35 -> #DIV/0! | E34: =lc_detailed!AE35 -> #DIV/0! | F34: =lc_detailed!AF35 -> #DIV/0! | G34: =lc_detailed!AG35 -> #DIV/0! | H34: =lc_detailed!AH35 -> #DIV/0! | I34: =lc_detailed!AI35 -> 0 | J34: =lc_detailed!AK35 -> 0 | K34: =lc_detailed!AL35 -> #DIV/0! | L34: =lc_detailed!Y35 -> #DIV/0! | N34: 0 | O34: #DIV/0! | P34: #DIV/0! | Q34: #DIV/0! | R34: #DIV/0! | S34: #DIV/0! | T34: #DIV/0! | U34: #DIV/0! | V34: 0 | W34: 0 | X34: #DIV/0! | Y34: #DIV/0!
A35: =lc_detailed!W36 -> 0 | B35: =lc_detailed!AB36 -> #DIV/0! | C35: =lc_detailed!AC36 -> #DIV/0! | D35: =lc_detailed!AD36 -> #DIV/0! | E35: =lc_detailed!AE36 -> #DIV/0! | F35: =lc_detailed!AF36 -> #DIV/0! | G35: =lc_detailed!AG36 -> #DIV/0! | H35: =lc_detailed!AH36 -> #DIV/0! | I35: =lc_detailed!AI36 -> 0 | J35: =lc_detailed!AK36 -> 0 | K35: =lc_detailed!AL36 -> #DIV/0! | L35: =lc_detailed!Y36 -> #DIV/0! | N35: 0 | O35: #DIV/0! | P35: #DIV/0! | Q35: #DIV/0! | R35: #DIV/0! | S35: #DIV/0! | T35: #DIV/0! | U35: #DIV/0! | V35: 0 | W35: 0 | X35: #DIV/0! | Y35: #DIV/0!
A36: =lc_detailed!W37 -> 0 | B36: =lc_detailed!AB37 -> #DIV/0! | C36: =lc_detailed!AC37 -> #DIV/0! | D36: =lc_detailed!AD37 -> #DIV/0! | E36: =lc_detailed!AE37 -> #DIV/0! | F36: =lc_detailed!AF37 -> #DIV/0! | G36: =lc_detailed!AG37 -> #DIV/0! | H36: =lc_detailed!AH37 -> #DIV/0! | I36: =lc_detailed!AI37 -> 0 | J36: =lc_detailed!AK37 -> 0 | K36: =lc_detailed!AL37 -> #DIV/0! | L36: =lc_detailed!Y37 -> #DIV/0! | N36: 0 | O36: #DIV/0! | P36: #DIV/0! | Q36: #DIV/0! | R36: #DIV/0! | S36: #DIV/0! | T36: #DIV/0! | U36: #DIV/0! | V36: 0 | W36: 0 | X36: #DIV/0! | Y36: #DIV/0!
A37: =lc_detailed!W38 -> 0 | B37: =lc_detailed!AB38 -> #DIV/0! | C37: =lc_detailed!AC38 -> #DIV/0! | D37: =lc_detailed!AD38 -> #DIV/0! | E37: =lc_detailed!AE38 -> #DIV/0! | F37: =lc_detailed!AF38 -> #DIV/0! | G37: =lc_detailed!AG38 -> #DIV/0! | H37: =lc_detailed!AH38 -> #DIV/0! | I37: =lc_detailed!AI38 -> 0 | J37: =lc_detailed!AK38 -> 0 | K37: =lc_detailed!AL38 -> #DIV/0! | L37: =lc_detailed!Y38 -> #DIV/0! | N37: 0 | O37: #DIV/0! | P37: #DIV/0! | Q37: #DIV/0! | R37: #DIV/0! | S37: #DIV/0! | T37: #DIV/0! | U37: #DIV/0! | V37: 0 | W37: 0 | X37: #DIV/0! | Y37: #DIV/0!
... A70: =lc_detailed!W71 -> 0 | B70: =lc_detailed!AB71 -> 0 | C70: =lc_detailed!AC71 -> 0 | D70: =lc_detailed!AD71 -> 0 | E70: =lc_detailed!AE71 -> 0 | F70: =lc_detailed!AF71 -> 0 | G70: =lc_detailed!AG71 -> 0 | H70: =lc_detailed!AH71 -> 0 | I70: =lc_detailed!AI71 -> 0 | J70: =lc_detailed!AK71 -> 0 | K70: =lc_detailed!AL71 -> 0 | L70: =lc_detailed!Y71 -> 0 | N70: 0 | O70: #DIV/0! | P70: #DIV/0! | Q70: #DIV/0! | R70: #DIV/0! | S70: #DIV/0! | T70: #DIV/0! | U70: #DIV/0! | V70: 0 | W70: 0 | X70: #DIV/0! | Y70: #DIV/0!
A71: =lc_detailed!W72 -> 0 | B71: =lc_detailed!AB72 -> 0 | C71: =lc_detailed!AC72 -> 0 | D71: =lc_detailed!AD72 -> 0 | E71: =lc_detailed!AE72 -> 0 | F71: =lc_detailed!AF72 -> 0 | G71: =lc_detailed!AG72 -> 0 | H71: =lc_detailed!AH72 -> 0 | I71: =lc_detailed!AI72 -> 0 | J71: =lc_detailed!AK72 -> 0 | K71: =lc_detailed!AL72 -> 0 | L71: =lc_detailed!Y72 -> 0
A72: =lc_detailed!W73 -> 0 | B72: =lc_detailed!AB73 -> 0 | C72: =lc_detailed!AC73 -> 0 | D72: =lc_detailed!AD73 -> 0 | E72: =lc_detailed!AE73 -> 0 | F72: =lc_detailed!AF73 -> 0 | G72: =lc_detailed!AG73 -> 0 | H72: =lc_detailed!AH73 -> 0 | I72: =lc_detailed!AI73 -> 0 | J72: =lc_detailed!AK73 -> 0 | K72: =lc_detailed!AL73 -> 0 | L72: =lc_detailed!Y73 -> 0
A73: =lc_detailed!W74 -> 0 | B73: =lc_detailed!AB74 -> 0 | C73: =lc_detailed!AC74 -> 0 | D73: =lc_detailed!AD74 -> 0 | E73: =lc_detailed!AE74 -> 0 | F73: =lc_detailed!AF74 -> 0 | G73: =lc_detailed!AG74 -> 0 | H73: =lc_detailed!AH74 -> 0 | I73: =lc_detailed!AI74 -> 0 | J73: =lc_detailed!AK74 -> 0 | K73: =lc_detailed!AL74 -> 0 | L73: =lc_detailed!Y74 -> 0
A74: =lc_detailed!W75 -> 0 | B74: =lc_detailed!AB75 -> 0 | C74: =lc_detailed!AC75 -> 0 | D74: =lc_detailed!AD75 -> 0 | E74: =lc_detailed!AE75 -> 0 | F74: =lc_detailed!AF75 -> 0 | G74: =lc_detailed!AG75 -> 0 | H74: =lc_detailed!AH75 -> 0 | I74: =lc_detailed!AI75 -> 0 | J74: =lc_detailed!AK75 -> 0 | K74: =lc_detailed!AL75 -> 0 | L74: =lc_detailed!Y75 -> 0
A75: =lc_detailed!W76 -> 0 | B75: =lc_detailed!AB76 -> 0 | C75: =lc_detailed!AC76 -> 0 | D75: =lc_detailed!AD76 -> 0 | E75: =lc_detailed!AE76 -> 0 | F75: =lc_detailed!AF76 -> 0 | G75: =lc_detailed!AG76 -> 0 | H75: =lc_detailed!AH76 -> 0 | I75: =lc_detailed!AI76 -> 0 | J75: =lc_detailed!AK76 -> 0 | K75: =lc_detailed!AL76 -> 0 | L75: =lc_detailed!Y76 -> 0
A76: =lc_detailed!W77 -> 0 | B76: =lc_detailed!AB77 -> 0 | C76: =lc_detailed!AC77 -> 0 | D76: =lc_detailed!AD77 -> 0 | E76: =lc_detailed!AE77 -> 0 | F76: =lc_detailed!AF77 -> 0 | G76: =lc_detailed!AG77 -> 0 | H76: =lc_detailed!AH77 -> 0 | I76: =lc_detailed!AI77 -> 0 | J76: =lc_detailed!AK77 -> 0 | K76: =lc_detailed!AL77 -> 0 | L76: =lc_detailed!Y77 -> 0
A77: =lc_detailed!W78 -> 0 | B77: =lc_detailed!AB78 -> 0 | C77: =lc_detailed!AC78 -> 0 | D77: =lc_detailed!AD78 -> 0 | E77: =lc_detailed!AE78 -> 0 | F77: =lc_detailed!AF78 -> 0 | G77: =lc_detailed!AG78 -> 0 | H77: =lc_detailed!AH78 -> 0 | I77: =lc_detailed!AI78 -> 0 | J77: =lc_detailed!AK78 -> 0 | K77: =lc_detailed!AL78 -> 0 | L77: =lc_detailed!Y78 -> 0
...
