Workbook

Sheet lc_detailed
B1: Asset Parameters (normalized by commodity feedstock) | S1: Duals | AP1: LCOE for assets with ethane capacity ($/t-ethylene) | AR1: SEQ - CI | AS1: SEQ - CREDIT | AU1: NO SEQ - CI | AV1: NO SEQ - CREDIT | BF1: CHEM SEQUESTRATION - CARBON INTENSITY | BI1: CHEM SEQUESTRATION - CREDIT | BL1: NO CHEM SEQUESTRATION - CARBON INTENSITY | BO1: NO CHEM SEQUESTRATION - CREDIT | BS1: Carbon Content | BX1: Carbon Inputs | CA1: Carbon Outputs | CI1: Assumptions
B2: id | C2: commodity | D2: CCS | E2: h2_consumption (MWh/t-CO2Captured) | F2: elec_consumption (MWh/t-CO2Captured) | G2: ethylene_production (t-ethylene/t-CO2Captured) | H2: natgas_production (MWh/t-CO2Captured) | I2: gasoline_production (MWh/t-CO2Captured) | J2: emission_rate (t-CO2/t-CO2Captured) | K2: calculated_emission_rate (t-CO2/t-CO2Captured) | L2: investment_cost ($/yr per t-CO2Captured/hr) | M2: fixed_om_cost ($/yr per t-CO2Captured/hr) | N2: variable_om_cost WITHOUT LPG REVENUE ($/t-CO2Captured) | O2: variable_om_cost ($/t-CO2Captured) | P2: LPG_production (t-LPG/t-ethylene) | Q2: LPG_production (t-LPG/t-CO2Captured) | S2: co2_sink ($/t) | T2: co2_captured ($/t) | U2: bioherb_supply ($/t) | V2: biowood_supply ($/t) | W2: bioagri_supply ($/t) | X2: LPG_demand ($/t-LPG) | Y2: ethane_supply ($/MWh) | Z2: ethanol_balance ($/MWh) | AA2: ethanol_demand ($/MWh) | AB2: elec_demand ($/MWh) | AC2: h2_balance ($/MWh) | AD2: h2_demand ($/MWh) | AE2: gasoline_balance ($/MWh) | AF2: gasoline_demand ($/MWh) | AG2: diesel_balance ($/MWh) | AH2: diesel_demand ($/MWh) | AI2: jetfuel_balance ($/MWh) | AJ2: jetfuel_demand ($/MWh) | AK2: ng_balance ($/MWh) | AL2: ng_demand ($/MWh) | AM2: ethylene_balance ($/t) | AN2: ethylene_demand ($/t) | AP2: id_LC | AQ2: commodity_LC | AR2: LCOE ($/t-ethylene) | AS2: LCOE ($/t-ethylene) | AT2: Diff. Between Methods | AU2: LCOE ($/t-ethylene) | AV2: LCOE ($/t-ethylene) | AW2: Diff. Between Methods | AX2: h2_consumption | AY2: elec_consumption | AZ2: co2captured_consumption | BA2: natgas_production | BB2: gasoline_production | BC2: investment_cost | BD2: fixed_om_cost | BE2: variable_om_cost | BF2: CI | BG2: modified capture cost | BH2: modified emissions cost | BI2: CI | BJ2: modified capture cost | BK2: modified emissions cost | BL2: CI | BM2: modified capture cost | BN2: modified emissions cost | BO2: CI | BP2: modified capture cost | BQ2: modified emissions cost | BS2: Ethylene (t-CO2/t-ethylene) | BT2: Gasoline (t-CO2/MWh-gasoline) | BU2: NG (t-CO2/MWh-NG) | BV2: LPG (t-CO2/t-LPG) | BX2: CO2Captured (t-CO2/t-CO2Captured) | BY2: CO2Captured - RECYCLE ADJUSTED (t-CO2/t-CO2Captured) | CA2: Ethylene (t-CO2/t-CO2Captured) | CB2: NG (t-CO2/t-CO2Captured) | CC2: Emissions (t-CO2/t-CO2Captured) | CD2: LPG (t-CO2/t-CO2Captured) | CE2: Captured (t-CO2/t-CO2Captured) | CF2: Gasoline (t-CO2/t-CO2Captured) | CG2: RECYCLED Output (t-CO2/t-CO2Captured) | CI2: Ethylene Carbon Content | CJ2: 3.14 | CK2: t-CO2/t-ethylene
B3: SE_Synthetic_Ethylene_Non_CCS | C3: CO2Captured | D3: 0 | E3: 5.4424707 | F3: 0.17633675 | G3: 0.11376564 | H3: 0.15787735 | I3: 0.76475308 | J3: 0.41383317 | K3: =BY3-SUM(CA3+CD3+CB3+CF3) -> 0.41383317 | L3: 174237.66 | M3: 95841.654 | N3: 2.9463017 | O3: =N3-(Q3*X3) -> -45.313084 | P3: 1.01 | Q3: =P3*G3 -> 0.1149033 | S3: 73.71884 | T3: -6.091002 | U3: 59.252833 | V3: 23.691089 | W3: 31.789762 | X3: 420 | Y3: 21.986353 | Z3: -8.00727 | AB3: 21.266241 | AC3: 7.267779 | AE3: -128.07763 | AF3: -128.07763 | AK3: 7.96358 | AL3: 0 | AM3: 822.26752 | AN3: 822.26752 | AP3: =B3 -> SE_Synthetic_Ethylene_Non_CCS | AQ3: =C3 -> CO2Captured | AR3: =SUM(AX3:BE3)+BG3+BH3 -> 331.3833 | AS3: =SUM(AX3:BE3)+BJ3+BK3 -> 331.3833 | AT3: =AR3-AS3 -> 0 | AU3: =SUM(AX3:BE3)+BM3+BN3 -> 358.88747 | AV3: =SUM(AX3:BE3)+BP3+BQ3 -> 358.88747 | AW3: =AU3-AV3 -> 0 | AX3: =E3/G3*AC3 -> 347.68558 | AY3: =F3/G3*AB3 -> 32.962674 | AZ3: =1/G3*(S3+T3) -> 594.4487 | BA3: =H3/G3*AK3*-1 -> -11.051394 | BB3: =I3/G3*AE3 -> -860.96083 | BC3: =L3/G3/(0.9*8760) -> 194.2604 | BD3: =M3/G3/(0.9*8760) -> 106.85542 | BE3: =O3 -> -45.313084 | BF3: =CG3-BY3-CA3-CD3 -> -0.37309555 | BG3: 0 | BH3: =BF3*S3 -> -27.504171 | BI3: =BY3-CG3-CA3-CD3 -> -0.37309555 | BJ3: 0 | BK3: =BI3*S3 -> -27.504171 | BL3: =BY3-CG3 -> 0 | BM3: 0 | BN3: =BL3*S3 -> 0 | BO3: =BY3-CG3 -> 0 | BP3: 0 | BQ3: =BO3*S3 -> 0 | BS3: =$CJ$2 -> 3.14 | BT3: =$CJ$3 -> 0.24123847 | BU3: =$CJ$4 -> 0.18104824 | BV3: =$CJ$5 -> 0.015714286 | BX3: 1 | BY3: =BX3-CE3 -> 1 | CA3: =BS3*G3 -> 0.35722412 | CB3: =BU3*H3 -> 0.028583416 | CC3: =(BX3-CA3-CB3-CF3-CD3)*(1-D3) -> 0.41383317 | CD3: =BV3*P3 -> 0.015871429 | CE3: =(BX3-CA3-CB3-CF3-CD3)*(D3) -> 0 | CF3: =BT3*I3 -> 0.18448786 | CG3: =SUM(CA3:CF3)-CE3 -> 1 | CI3: Gasoline Carbon Content | CJ3: 0.24123847 | CK3: t-CO2/MWh-gasoline
B4: SE_Synthetic_Ethylene_CCS_90 | C4: CO2Captured | D4: 0.9 | E4: 5.9243674 | F4: 0.24466847 | G4: 0.12383888 | H4: 0.1718564 | I4: 0.83246718 | J4: 0.036333708 | K4: =BY4-SUM(CA4+CD4+CB4+CF4) -> 0.036333708 | L4: 209498.32 | M4: 115165.85 | N4: 3.5425479 | O4: =N4-(Q4*X4) -> -48.989905 | P4: 1.01 | Q4: =P4*G4 -> 0.12507727 | S4: 73.71884 | T4: -6.091002 | U4: 59.252833 | V4: 23.691089 | W4: 31.789762 | X4: 420 | Y4: 21.986353 | Z4: -8.00727 | AB4: 21.266241 | AC4: 7.267779 | AE4: -128.07763 | AF4: -128.07763 | AK4: 7.96358 | AL4: 0 | AM4: 822.26752 | AN4: 822.26752 | AP4: =B4 -> SE_Synthetic_Ethylene_CCS_90 | AQ4: =C4 -> CO2Captured | AR4: =SUM(AX4:BE4)+BG4+BH4 -> 317.48856 | AS4: =SUM(AX4:BE4)+BJ4+BK4 -> 317.48856 | AT4: =AR4-AS4 -> 0 | AU4: =SUM(AX4:BE4)+BM4+BN4 -> 347.32446 | AV4: =SUM(AX4:BE4)+BP4+BQ4 -> 347.32446 | AW4: =AU4-AV4 -> 0 | AX4: =E4/G4*AC4 -> 347.68558 | AY4: =F4/G4*AB4 -> 42.015712 | AZ4: =1/G4*(S4+T4) -> 546.09536 | BA4: =H4/G4*AK4*-1 -> -11.051394 | BB4: =I4/G4*AE4 -> -860.96083 | BC4: =L4/G4/(0.9*8760) -> 214.57391 | BD4: =M4/G4/(0.9*8760) -> 117.95602 | BE4: =O4 -> -48.989905 | BF4: =CG4-BY4-CA4-CD4 -> -0.40472551 | BG4: 0 | BH4: =BF4*S4 -> -29.835895 | BI4: =BY4-CG4-CA4-CD4 -> -0.40472551 | BJ4: 0 | BK4: =BI4*S4 -> -29.835895 | BL4: =BY4-CG4 -> 0 | BM4: 0 | BN4: =BL4*S4 -> 0 | BO4: =BY4-CG4 -> 0 | BP4: 0 | BQ4: =BO4*S4 -> 0 | BS4: =$CJ$2 -> 3.14 | BT4: =$CJ$3 -> 0.24123847 | BU4: =$CJ$4 -> 0.18104824 | BV4: =$CJ$5 -> 0.015714286 | BX4: 1 | BY4: =BX4-CE4 -> 0.67299663 | CA4: =BS4*G4 -> 0.38885408 | CB4: =BU4*H4 -> 0.031114299 | CC4: =(BX4-CA4-CB4-CF4-CD4)*(1-D4) -> 0.036333708 | CD4: =BV4*P4 -> 0.015871429 | CE4: =(BX4-CA4-CB4-CF4-CD4)*(D4) -> 0.32700337 | CF4: =BT4*I4 -> 0.20082311 | CG4: =SUM(CA4:CF4)-CE4 -> 0.67299663 | CI4: Natural Gas Carbon Content | CJ4: 0.18104824 | CK4: t-CO2/MWh-natgas
B5: MIDAT_Synthetic_Ethylene_Non_CCS | C5: CO2Captured | D5: 0 | E5: 5.4424707 | F5: 0.17633675 | G5: 0.11376564 | H5: 0.15787735 | I5: 0.76475308 | J5: 0.41383317 | K5: =BY5-SUM(CA5+CD5+CB5+CF5) -> 0.41383317 | L5: 174237.66 | M5: 95841.654 | N5: 2.9463017 | O5: =N5-(Q5*X5) -> -45.313084 | P5: 1.01 | Q5: =P5*G5 -> 0.1149033 | S5: 73.71884 | T5: -16.179128 | U5: 58.461202 | V5: 19.647223 | W5: 40.820307 | X5: 420 | Y5: 21.986353 | Z5: -2.203044 | AB5: 21.500722 | AC5: 7.532437 | AE5: -140.74133 | AF5: -140.74133 | AK5: 5.407672 | AL5: 0 | AM5: 822.26752 | AN5: 822.26752 | AP5: =B5 -> MIDAT_Synthetic_Ethylene_Non_CCS | AQ5: =C5 -> CO2Captured | AR5: =SUM(AX5:BE5)+BG5+BH5 -> 174.15243 | AS5: =SUM(AX5:BE5)+BJ5+BK5 -> 174.15243 | AT5: =AR5-AS5 -> 0 | AU5: =SUM(AX5:BE5)+BM5+BN5 -> 201.6566 | AV5: =SUM(AX5:BE5)+BP5+BQ5 -> 201.6566 | AW5: =AU5-AV5 -> 0 | AX5: =E5/G5*AC5 -> 360.34664 | AY5: =F5/G5*AB5 -> 33.326119 | AZ5: =1/G5*(S5+T5) -> 505.77407 | BA5: =H5/G5*AK5*-1 -> -7.504453 | BB5: =I5/G5*AE5 -> -946.08852 | BC5: =L5/G5/(0.9*8760) -> 194.2604 | BD5: =M5/G5/(0.9*8760) -> 106.85542 | BE5: =O5 -> -45.313084 | BF5: =CG5-BY5-CA5-CD5 -> -0.37309555 | BG5: 0 | BH5: =BF5*S5 -> -27.504171 | BI5: =BY5-CG5-CA5-CD5 -> -0.37309555 | BJ5: 0 | BK5: =BI5*S5 -> -27.504171 | BL5: =BY5-CG5 -> 0 | BM5: 0 | BN5: =BL5*S5 -> 0 | BO5: =BY5-CG5 -> 0 | BP5: 0 | BQ5: =BO5*S5 -> 0 | BS5: =$CJ$2 -> 3.14 | BT5: =$CJ$3 -> 0.24123847 | BU5: =$CJ$4 -> 0.18104824 | BV5: =$CJ$5 -> 0.015714286 | BX5: 1 | BY5: =BX5-CE5 -> 1 | CA5: =BS5*G5 -> 0.35722412 | CB5: =BU5*H5 -> 0.028583416 | CC5: =(BX5-CA5-CB5-CF5-CD5)*(1-D5) -> 0.41383317 | CD5: =BV5*P5 -> 0.015871429 | CE5: =(BX5-CA5-CB5-CF5-CD5)*(D5) -> 0 | CF5: =BT5*I5 -> 0.18448786 | CG5: =SUM(CA5:CF5)-CE5 -> 1 | CI5: LPG Carbon Content | CJ5: =0.22/14 -> 0.015714286 | CK5: t-CO2/t-LPG
B6: MIDAT_Synthetic_Ethylene_CCS_90 | C6: CO2Captured | D6: 0.9 | E6: 5.9243674 | F6: 0.24466847 | G6: 0.12383888 | H6: 0.1718564 | I6: 0.83246718 | J6: 0.036333708 | K6: =BY6-SUM(CA6+CD6+CB6+CF6) -> 0.036333708 | L6: 209498.32 | M6: 115165.85 | N6: 3.5425479 | O6: =N6-(Q6*X6) -> -48.989905 | P6: 1.01 | Q6: =P6*G6 -> 0.12507727 | S6: 73.71884 | T6: -16.179128 | U6: 58.461202 | V6: 19.647223 | W6: 40.820307 | X6: 420 | Y6: 21.986353 | Z6: -2.203044 | AB6: 21.500722 | AC6: 7.532437 | AE6: -140.74133 | AF6: -140.74133 | AK6: 5.407672 | AL6: 0 | AM6: 822.26752 | AN6: 822.26752 | AP6: =B6 -> MIDAT_Synthetic_Ethylene_CCS_90 | AQ6: =C6 -> CO2Captured | AR6: =SUM(AX6:BE6)+BG6+BH6 -> 167.57043 | AS6: =SUM(AX6:BE6)+BJ6+BK6 -> 167.57043 | AT6: =AR6-AS6 -> 0 | AU6: =SUM(AX6:BE6)+BM6+BN6 -> 197.40633 | AV6: =SUM(AX6:BE6)+BP6+BQ6 -> 197.40633 | AW6: =AU6-AV6 -> 0 | AX6: =E6/G6*AC6 -> 360.34664 | AY6: =F6/G6*AB6 -> 42.478976 | AZ6: =1/G6*(S6+T6) -> 464.63366 | BA6: =H6/G6*AK6*-1 -> -7.504453 | BB6: =I6/G6*AE6 -> -946.08852 | BC6: =L6/G6/(0.9*8760) -> 214.57391 | BD6: =M6/G6/(0.9*8760) -> 117.95602 | BE6: =O6 -> -48.989905 | BF6: =CG6-BY6-CA6-CD6 -> -0.40472551 | BG6: 0 | BH6: =BF6*S6 -> -29.835895 | BI6: =BY6-CG6-CA6-CD6 -> -0.40472551 | BJ6: 0 | BK6: =BI6*S6 -> -29.835895 | BL6: =BY6-CG6 -> 0 | BM6: 0 | BN6: =BL6*S6 -> 0 | BO6: =BY6-CG6 -> 0 | BP6: 0 | BQ6: =BO6*S6 -> 0 | BS6: =$CJ$2 -> 3.14 | BT6: =$CJ$3 -> 0.24123847 | BU6: =$CJ$4 -> 0.18104824 | BV6: =$CJ$5 -> 0.015714286 | BX6: 1 | BY6: =BX6-CE6 -> 0.67299663 | CA6: =BS6*G6 -> 0.38885408 | CB6: =BU6*H6 -> 0.031114299 | CC6: =(BX6-CA6-CB6-CF6-CD6)*(1-D6) -> 0.036333708 | CD6: =BV6*P6 -> 0.015871429 | CE6: =(BX6-CA6-CB6-CF6-CD6)*(D6) -> 0.32700337 | CF6: =BT6*I6 -> 0.20082311 | CG6: =SUM(CA6:CF6)-CE6 -> 0.67299663 | CI6: Capacity Factor | CJ6: 0.9 | CK6: %
B7: NE_Synthetic_Ethylene_Non_CCS | C7: CO2Captured | D7: 0 | E7: 5.4424707 | F7: 0.17633675 | G7: 0.11376564 | H7: 0.15787735 | I7: 0.76475308 | J7: 0.41383317 | K7: =BY7-SUM(CA7+CD7+CB7+CF7) -> 0.41383317 | L7: 174237.66 | M7: 95841.654 | N7: 2.9463017 | O7: =N7-(Q7*X7) -> -45.313084 | P7: 1.01 | Q7: =P7*G7 -> 0.1149033 | S7: 73.71884 | T7: -23.276809 | U7: 60.47681 | V7: 28.904358 | W7: 39.957475 | X7: 420 | Y7: 21.986353 | Z7: -2.703157 | AB7: 20.789991 | AC7: 9.19598 | AE7: -150.75579 | AF7: -150.75579 | AK7: 8.960454 | AL7: 0 | AM7: 822.26752 | AN7: 0 | AP7: =B7 -> NE_Synthetic_Ethylene_Non_CCS | AQ7: =C7 -> CO2Captured | AR7: =SUM(AX7:BE7)+BG7+BH7 -> 117.99563 | AS7: =SUM(AX7:BE7)+BJ7+BK7 -> 117.99563 | AT7: =AR7-AS7 -> 0 | AU7: =SUM(AX7:BE7)+BM7+BN7 -> 145.4998 | AV7: =SUM(AX7:BE7)+BP7+BQ7 -> 145.4998 | AW7: =AU7-AV7 -> 0 | AX7: =E7/G7*AC7 -> 439.9294 | AY7: =F7/G7*AB7 -> 32.224486 | AZ7: =1/G7*(S7+T7) -> 443.38545 | BA7: =H7/G7*AK7*-1 -> -12.434797 | BB7: =I7/G7*AE7 -> -1013.4075 | BC7: =L7/G7/(0.9*8760) -> 194.2604 | BD7: =M7/G7/(0.9*8760) -> 106.85542 | BE7: =O7 -> -45.313084 | BF7: =CG7-BY7-CA7-CD7 -> -0.37309555 | BG7: 0 | BH7: =BF7*S7 -> -27.504171 | BI7: =BY7-CG7-CA7-CD7 -> -0.37309555 | BJ7: 0 | BK7: =BI7*S7 -> -27.504171 | BL7: =BY7-CG7 -> 0 | BM7: 0 | BN7: =BL7*S7 -> 0 | BO7: =BY7-CG7 -> 0 | BP7: 0 | BQ7: =BO7*S7 -> 0 | BS7: =$CJ$2 -> 3.14 | BT7: =$CJ$3 -> 0.24123847 | BU7: =$CJ$4 -> 0.18104824 | BV7: =$CJ$5 -> 0.015714286 | BX7: 1 | BY7: =BX7-CE7 -> 1 | CA7: =BS7*G7 -> 0.35722412 | CB7: =BU7*H7 -> 0.028583416 | CC7: =(BX7-CA7-CB7-CF7-CD7)*(1-D7) -> 0.41383317 | CD7: =BV7*P7 -> 0.015871429 | CE7: =(BX7-CA7-CB7-CF7-CD7)*(D7) -> 0 | CF7: =BT7*I7 -> 0.18448786 | CG7: =SUM(CA7:CF7)-CE7 -> 1
B8: NE_Synthetic_Ethylene_CCS_90 | C8: CO2Captured | D8: 0.9 | E8: 5.9243674 | F8: 0.24466847 | G8: 0.12383888 | H8: 0.1718564 | I8: 0.83246718 | J8: 0.036333708 | K8: =BY8-SUM(CA8+CD8+CB8+CF8) -> 0.036333708 | L8: 209498.32 | M8: 115165.85 | N8: 3.5425479 | O8: =N8-(Q8*X8) -> -48.989905 | P8: 1.01 | Q8: =P8*G8 -> 0.12507727 | S8: 73.71884 | T8: -23.276809 | U8: 60.47681 | V8: 28.904358 | W8: 39.957475 | X8: 420 | Y8: 21.986353 | Z8: -2.703157 | AB8: 20.789991 | AC8: 9.19598 | AE8: -150.75579 | AF8: -150.75579 | AK8: 8.960454 | AL8: 0 | AM8: 822.26752 | AN8: 0 | AP8: =B8 -> NE_Synthetic_Ethylene_CCS_90 | AQ8: =C8 -> CO2Captured | AR8: =SUM(AX8:BE8)+BG8+BH8 -> 116.18586 | AS8: =SUM(AX8:BE8)+BJ8+BK8 -> 116.18586 | AT8: =AR8-AS8 -> 0 | AU8: =SUM(AX8:BE8)+BM8+BN8 -> 146.02176 | AV8: =SUM(AX8:BE8)+BP8+BQ8 -> 146.02176 | AW8: =AU8-AV8 -> 0 | AX8: =E8/G8*AC8 -> 439.9294 | AY8: =F8/G8*AB8 -> 41.074785 | AZ8: =1/G8*(S8+T8) -> 407.31983 | BA8: =H8/G8*AK8*-1 -> -12.434797 | BB8: =I8/G8*AE8 -> -1013.4075 | BC8: =L8/G8/(0.9*8760) -> 214.57391 | BD8: =M8/G8/(0.9*8760) -> 117.95602 | BE8: =O8 -> -48.989905 | BF8: =CG8-BY8-CA8-CD8 -> -0.40472551 | BG8: 0 | BH8: =BF8*S8 -> -29.835895 | BI8: =BY8-CG8-CA8-CD8 -> -0.40472551 | BJ8: 0 | BK8: =BI8*S8 -> -29.835895 | BL8: =BY8-CG8 -> 0 | BM8: 0 | BN8: =BL8*S8 -> 0 | BO8: =BY8-CG8 -> 0 | BP8: 0 | BQ8: =BO8*S8 -> 0 | BS8: =$CJ$2 -> 3.14 | BT8: =$CJ$3 -> 0.24123847 | BU8: =$CJ$4 -> 0.18104824 | BV8: =$CJ$5 -> 0.015714286 | BX8: 1 | BY8: =BX8-CE8 -> 0.67299663 | CA8: =BS8*G8 -> 0.38885408 | CB8: =BU8*H8 -> 0.031114299 | CC8: =(BX8-CA8-CB8-CF8-CD8)*(1-D8) -> 0.036333708 | CD8: =BV8*P8 -> 0.015871429 | CE8: =(BX8-CA8-CB8-CF8-CD8)*(D8) -> 0.32700337 | CF8: =BT8*I8 -> 0.20082311 | CG8: =SUM(CA8:CF8)-CE8 -> 0.67299663
B9: CA_Synthetic_Ethylene_Non_CCS | C9: CO2Captured | D9: 0 | E9: 5.4424707 | F9: 0.17633675 | G9: 0.11376564 | H9: 0.15787735 | I9: 0.76475308 | J9: 0.41383317 | K9: =BY9-SUM(CA9+CD9+CB9+CF9) -> 0.41383317 | L9: 174237.66 | M9: 95841.654 | N9: 2.9463017 | O9: =N9-(Q9*X9) -> -45.313084 | P9: 1.01 | Q9: =P9*G9 -> 0.1149033 | S9: 73.71884 | T9: 3.828238 | U9: 70.666428 | V9: 35.61527 | W9: 32.098216 | X9: 420 | Y9: 21.986353 | Z9: -9.011429 | AB9: 20.274928 | AC9: 8.466452 | AE9: -116.15052 | AF9: -116.15052 | AK9: 12.963218 | AL9: 0 | AM9: 822.26752 | AN9: 0 | AP9: =B9 -> CA_Synthetic_Ethylene_Non_CCS | AQ9: =C9 -> CO2Captured | AR9: =SUM(AX9:BE9)+BG9+BH9 -> 547.61858 | AS9: =SUM(AX9:BE9)+BJ9+BK9 -> 547.61858 | AT9: =AR9-AS9 -> 0 | AU9: =SUM(AX9:BE9)+BM9+BN9 -> 575.12275 | AV9: =SUM(AX9:BE9)+BP9+BQ9 -> 575.12275 | AW9: =AU9-AV9 -> 0 | AX9: =E9/G9*AC9 -> 405.02928 | AY9: =F9/G9*AB9 -> 31.426138 | AZ9: =1/G9*(S9+T9) -> 681.63882 | BA9: =H9/G9*AK9*-1 -> -17.989601 | BB9: =I9/G9*AE9 -> -780.78462 | BC9: =L9/G9/(0.9*8760) -> 194.2604 | BD9: =M9/G9/(0.9*8760) -> 106.85542 | BE9: =O9 -> -45.313084 | BF9: =CG9-BY9-CA9-CD9 -> -0.37309555 | BG9: 0 | BH9: =BF9*S9 -> -27.504171 | BI9: =BY9-CG9-CA9-CD9 -> -0.37309555 | BJ9: 0 | BK9: =BI9*S9 -> -27.504171 | BL9: =BY9-CG9 -> 0 | BM9: 0 | BN9: =BL9*S9 -> 0 | BO9: =BY9-CG9 -> 0 | BP9: 0 | BQ9: =BO9*S9 -> 0 | BS9: =$CJ$2 -> 3.14 | BT9: =$CJ$3 -> 0.24123847 | BU9: =$CJ$4 -> 0.18104824 | BV9: =$CJ$5 -> 0.015714286 | BX9: 1 | BY9: =BX9-CE9 -> 1 | CA9: =BS9*G9 -> 0.35722412 | CB9: =BU9*H9 -> 0.028583416 | CC9: =(BX9-CA9-CB9-CF9-CD9)*(1-D9) -> 0.41383317 | CD9: =BV9*P9 -> 0.015871429 | CE9: =(BX9-CA9-CB9-CF9-CD9)*(D9) -> 0 | CF9: =BT9*I9 -> 0.18448786 | CG9: =SUM(CA9:CF9)-CE9 -> 1
B10: CA_Synthetic_Ethylene_CCS_90 | C10: CO2Captured | D10: 0.9 | E10: 5.9243674 | F10: 0.24466847 | G10: 0.12383888 | H10: 0.1718564 | I10: 0.83246718 | J10: 0.036333708 | K10: =BY10-SUM(CA10+CD10+CB10+CF10) -> 0.036333708 | L10: 209498.32 | M10: 115165.85 | N10: 3.5425479 | O10: =N10-(Q10*X10) -> -48.989905 | P10: 1.01 | Q10: =P10*G10 -> 0.12507727 | S10: 73.71884 | T10: 3.828238 | U10: 70.666428 | V10: 35.61527 | W10: 32.098216 | X10: 420 | Y10: 21.986353 | Z10: -9.011429 | AB10: 20.274928 | AC10: 8.466452 | AE10: -116.15052 | AF10: -116.15052 | AK10: 12.963218 | AL10: 0 | AM10: 822.26752 | AN10: 0 | AP10: =B10 -> CA_Synthetic_Ethylene_CCS_90 | AQ10: =C10 -> CO2Captured | AR10: =SUM(AX10:BE10)+BG10+BH10 -> 526.20967 | AS10: =SUM(AX10:BE10)+BJ10+BK10 -> 526.20967 | AT10: =AR10-AS10 -> 0 | AU10: =SUM(AX10:BE10)+BM10+BN10 -> 556.04556 | AV10: =SUM(AX10:BE10)+BP10+BQ10 -> 556.04556 | AW10: =AU10-AV10 -> 0 | AX10: =E10/G10*AC10 -> 405.02928 | AY10: =F10/G10*AB10 -> 40.057175 | AZ10: =1/G10*(S10+T10) -> 626.19331 | BA10: =H10/G10*AK10*-1 -> -17.989601 | BB10: =I10/G10*AE10 -> -780.78462 | BC10: =L10/G10/(0.9*8760) -> 214.57391 | BD10: =M10/G10/(0.9*8760) -> 117.95602 | BE10: =O10 -> -48.989905 | BF10: =CG10-BY10-CA10-CD10 -> -0.40472551 | BG10: 0 | BH10: =BF10*S10 -> -29.835895 | BI10: =BY10-CG10-CA10-CD10 -> -0.40472551 | BJ10: 0 | BK10: =BI10*S10 -> -29.835895 | BL10: =BY10-CG10 -> 0 | BM10: 0 | BN10: =BL10*S10 -> 0 | BO10: =BY10-CG10 -> 0 | BP10: 0 | BQ10: =BO10*S10 -> 0 | BS10: =$CJ$2 -> 3.14 | BT10: =$CJ$3 -> 0.24123847 | BU10: =$CJ$4 -> 0.18104824 | BV10: =$CJ$5 -> 0.015714286 | BX10: 1 | BY10: =BX10-CE10 -> 0.67299663 | CA10: =BS10*G10 -> 0.38885408 | CB10: =BU10*H10 -> 0.031114299 | CC10: =(BX10-CA10-CB10-CF10-CD10)*(1-D10) -> 0.036333708 | CD10: =BV10*P10 -> 0.015871429 | CE10: =(BX10-CA10-CB10-CF10-CD10)*(D10) -> 0.32700337 | CF10: =BT10*I10 -> 0.20082311 | CG10: =SUM(CA10:CF10)-CE10 -> 0.67299663
B11: NCEN_Synthetic_Ethylene_Non_CCS | C11: CO2Captured | D11: 0 | E11: 5.4424707 | F11: 0.17633675 | G11: 0.11376564 | H11: 0.15787735 | I11: 0.76475308 | J11: 0.41383317 | K11: =BY11-SUM(CA11+CD11+CB11+CF11) -> 0.41383317 | L11: 174237.66 | M11: 95841.654 | N11: 2.9463017 | O11: =N11-(Q11*X11) -> -45.313084 | P11: 1.01 | Q11: =P11*G11 -> 0.1149033 | S11: 73.71884 | T11: -6.097314 | U11: 61.343403 | V11: 33.004971 | W11: 42.19561 | X11: 420 | Y11: 21.986353 | Z11: 51.423576 | AB11: 22.90669 | AC11: 13.197062 | AE11: -129.52898 | AF11: -129.52898 | AK11: 14.953878 | AL11: 0 | AM11: 822.26752 | AN11: 822.26752 | AP11: =B11 -> NCEN_Synthetic_Ethylene_Non_CCS | AQ11: =C11 -> CO2Captured | AR11: =SUM(AX11:BE11)+BG11+BH11 -> 598.06642 | AS11: =SUM(AX11:BE11)+BJ11+BK11 -> 598.06642 | AT11: =AR11-AS11 -> 0 | AU11: =SUM(AX11:BE11)+BM11+BN11 -> 625.5706 | AV11: =SUM(AX11:BE11)+BP11+BQ11 -> 625.5706 | AW11: =AU11-AV11 -> 0 | AX11: =E11/G11*AC11 -> 631.33843 | AY11: =F11/G11*AB11 -> 35.505369 | AZ11: =1/G11*(S11+T11) -> 594.39321 | BA11: =H11/G11*AK11*-1 -> -20.752123 | BB11: =I11/G11*AE11 -> -870.71704 | BC11: =L11/G11/(0.9*8760) -> 194.2604 | BD11: =M11/G11/(0.9*8760) -> 106.85542 | BE11: =O11 -> -45.313084 | BF11: =CG11-BY11-CA11-CD11 -> -0.37309555 | BG11: 0 | BH11: =BF11*S11 -> -27.504171 | BI11: =BY11-CG11-CA11-CD11 -> -0.37309555 | BJ11: 0 | BK11: =BI11*S11 -> -27.504171 | BL11: =BY11-CG11 -> 0 | BM11: 0 | BN11: =BL11*S11 -> 0 | BO11: =BY11-CG11 -> 0 | BP11: 0 | BQ11: =BO11*S11 -> 0 | BS11: =$CJ$2 -> 3.14 | BT11: =$CJ$3 -> 0.24123847 | BU11: =$CJ$4 -> 0.18104824 | BV11: =$CJ$5 -> 0.015714286 | BX11: 1 | BY11: =BX11-CE11 -> 1 | CA11: =BS11*G11 -> 0.35722412 | CB11: =BU11*H11 -> 0.028583416 | CC11: =(BX11-CA11-CB11-CF11-CD11)*(1-D11) -> 0.41383317 | CD11: =BV11*P11 -> 0.015871429 | CE11: =(BX11-CA11-CB11-CF11-CD11)*(D11) -> 0 | CF11: =BT11*I11 -> 0.18448786 | CG11: =SUM(CA11:CF11)-CE11 -> 1
B12: NCEN_Synthetic_Ethylene_CCS_90 | C12: CO2Captured | D12: 0.9 | E12: 5.9243674 | F12: 0.24466847 | G12: 0.12383888 | H12: 0.1718564 | I12: 0.83246718 | J12: 0.036333708 | K12: =BY12-SUM(CA12+CD12+CB12+CF12) -> 0.036333708 | L12: 209498.32 | M12: 115165.85 | N12: 3.5425479 | O12: =N12-(Q12*X12) -> -48.989905 | P12: 1.01 | Q12: =P12*G12 -> 0.12507727 | S12: 73.71884 | T12: -6.097314 | U12: 61.343403 | V12: 33.004971 | W12: 42.19561 | X12: 420 | Y12: 21.986353 | Z12: 51.423576 | AB12: 22.90669 | AC12: 13.197062 | AE12: -129.52898 | AF12: -129.52898 | AK12: 14.953878 | AL12: 0 | AM12: 822.26752 | AN12: 822.26752 | AP12: =B12 -> NCEN_Synthetic_Ethylene_CCS_90 | AQ12: =C12 -> CO2Captured | AR12: =SUM(AX12:BE12)+BG12+BH12 -> 584.87454 | AS12: =SUM(AX12:BE12)+BJ12+BK12 -> 584.87454 | AT12: =AR12-AS12 -> 0 | AU12: =SUM(AX12:BE12)+BM12+BN12 -> 614.71043 | AV12: =SUM(AX12:BE12)+BP12+BQ12 -> 614.71043 | AW12: =AU12-AV12 -> 0 | AX12: =E12/G12*AC12 -> 631.33844 | AY12: =F12/G12*AB12 -> 45.256747 | AZ12: =1/G12*(S12+T12) -> 546.0444 | BA12: =H12/G12*AK12*-1 -> -20.752123 | BB12: =I12/G12*AE12 -> -870.71704 | BC12: =L12/G12/(0.9*8760) -> 214.57391 | BD12: =M12/G12/(0.9*8760) -> 117.95602 | BE12: =O12 -> -48.989905 | BF12: =CG12-BY12-CA12-CD12 -> -0.40472551 | BG12: 0 | BH12: =BF12*S12 -> -29.835895 | BI12: =BY12-CG12-CA12-CD12 -> -0.40472551 | BJ12: 0 | BK12: =BI12*S12 -> -29.835895 | BL12: =BY12-CG12 -> 0 | BM12: 0 | BN12: =BL12*S12 -> 0 | BO12: =BY12-CG12 -> 0 | BP12: 0 | BQ12: =BO12*S12 -> 0 | BS12: =$CJ$2 -> 3.14 | BT12: =$CJ$3 -> 0.24123847 | BU12: =$CJ$4 -> 0.18104824 | BV12: =$CJ$5 -> 0.015714286 | BX12: 1 | BY12: =BX12-CE12 -> 0.67299663 | CA12: =BS12*G12 -> 0.38885408 | CB12: =BU12*H12 -> 0.031114299 | CC12: =(BX12-CA12-CB12-CF12-CD12)*(1-D12) -> 0.036333708 | CD12: =BV12*P12 -> 0.015871429 | CE12: =(BX12-CA12-CB12-CF12-CD12)*(D12) -> 0.32700337 | CF12: =BT12*I12 -> 0.20082311 | CG12: =SUM(CA12:CF12)-CE12 -> 0.67299663
B13: CEN_Synthetic_Ethylene_Non_CCS | C13: CO2Captured | D13: 0 | E13: 5.4424707 | F13: 0.17633675 | G13: 0.11376564 | H13: 0.15787735 | I13: 0.76475308 | J13: 0.41383317 | K13: =BY13-SUM(CA13+CD13+CB13+CF13) -> 0.41383317 | L13: 174237.66 | M13: 95841.654 | N13: 2.9463017 | O13: =N13-(Q13*X13) -> -45.313084 | P13: 1.01 | Q13: =P13*G13 -> 0.1149033 | S13: 73.71884 | T13: -6.199254 | U13: 65.59151 | V13: 31.821489 | W13: 37.986239 | X13: 420 | Y13: 21.986353 | Z13: 51.417555 | AB13: 22.465142 | AC13: 13.285634 | AE13: -129.68145 | AF13: -129.68145 | AK13: 15.046749 | AL13: 0 | AM13: 822.26752 | AN13: 822.26752 | AP13: =B13 -> CEN_Synthetic_Ethylene_Non_CCS | AQ13: =C13 -> CO2Captured | AR13: =SUM(AX13:BE13)+BG13+BH13 -> 599.56938 | AS13: =SUM(AX13:BE13)+BJ13+BK13 -> 599.56938 | AT13: =AR13-AS13 -> 0 | AU13: =SUM(AX13:BE13)+BM13+BN13 -> 627.07355 | AV13: =SUM(AX13:BE13)+BP13+BQ13 -> 627.07355 | AW13: =AU13-AV13 -> 0 | AX13: =E13/G13*AC13 -> 635.57566 | AY13: =F13/G13*AB13 -> 34.82097 | AZ13: =1/G13*(S13+T13) -> 593.49716 | BA13: =H13/G13*AK13*-1 -> -20.881004 | BB13: =I13/G13*AE13 -> -871.74198 | BC13: =L13/G13/(0.9*8760) -> 194.2604 | BD13: =M13/G13/(0.9*8760) -> 106.85542 | BE13: =O13 -> -45.313084 | BF13: =CG13-BY13-CA13-CD13 -> -0.37309555 | BG13: 0 | BH13: =BF13*S13 -> -27.504171 | BI13: =BY13-CG13-CA13-CD13 -> -0.37309555 | BJ13: 0 | BK13: =BI13*S13 -> -27.504171 | BL13: =BY13-CG13 -> 0 | BM13: 0 | BN13: =BL13*S13 -> 0 | BO13: =BY13-CG13 -> 0 | BP13: 0 | BQ13: =BO13*S13 -> 0 | BS13: =$CJ$2 -> 3.14 | BT13: =$CJ$3 -> 0.24123847 | BU13: =$CJ$4 -> 0.18104824 | BV13: =$CJ$5 -> 0.015714286 | BX13: 1 | BY13: =BX13-CE13 -> 1 | CA13: =BS13*G13 -> 0.35722412 | CB13: =BU13*H13 -> 0.028583416 | CC13: =(BX13-CA13-CB13-CF13-CD13)*(1-D13) -> 0.41383317 | CD13: =BV13*P13 -> 0.015871429 | CE13: =(BX13-CA13-CB13-CF13-CD13)*(D13) -> 0 | CF13: =BT13*I13 -> 0.18448786 | CG13: =SUM(CA13:CF13)-CE13 -> 1
B14: CEN_Synthetic_Ethylene_CCS_90 | C14: CO2Captured | D14: 0.9 | E14: 5.9243674 | F14: 0.24466847 | G14: 0.12383888 | H14: 0.1718564 | I14: 0.83246718 | J14: 0.036333708 | K14: =BY14-SUM(CA14+CD14+CB14+CF14) -> 0.036333708 | L14: 209498.32 | M14: 115165.85 | N14: 3.5425479 | O14: =N14-(Q14*X14) -> -48.989905 | P14: 1.01 | Q14: =P14*G14 -> 0.12507727 | S14: 73.71884 | T14: -6.199254 | U14: 65.59151 | V14: 31.821489 | W14: 37.986239 | X14: 420 | Y14: 21.986353 | Z14: 51.417555 | AB14: 22.465142 | AC14: 13.285634 | AE14: -129.68145 | AF14: -129.68145 | AK14: 15.046749 | AL14: 0 | AM14: 822.26752 | AN14: 822.26752 | AP14: =B14 -> CEN_Synthetic_Ethylene_CCS_90 | AQ14: =C14 -> CO2Captured | AR14: =SUM(AX14:BE14)+BG14+BH14 -> 586.26241 | AS14: =SUM(AX14:BE14)+BJ14+BK14 -> 586.26241 | AT14: =AR14-AS14 -> 0 | AU14: =SUM(AX14:BE14)+BM14+BN14 -> 616.09831 | AV14: =SUM(AX14:BE14)+BP14+BQ14 -> 616.09831 | AW14: =AU14-AV14 -> 0 | AX14: =E14/G14*AC14 -> 635.57566 | AY14: =F14/G14*AB14 -> 44.384381 | AZ14: =1/G14*(S14+T14) -> 545.22123 | BA14: =H14/G14*AK14*-1 -> -20.881004 | BB14: =I14/G14*AE14 -> -871.74198 | BC14: =L14/G14/(0.9*8760) -> 214.57391 | BD14: =M14/G14/(0.9*8760) -> 117.95602 | BE14: =O14 -> -48.989905 | BF14: =CG14-BY14-CA14-CD14 -> -0.40472551 | BG14: 0 | BH14: =BF14*S14 -> -29.835895 | BI14: =BY14-CG14-CA14-CD14 -> -0.40472551 | BJ14: 0 | BK14: =BI14*S14 -> -29.835895 | BL14: =BY14-CG14 -> 0 | BM14: 0 | BN14: =BL14*S14 -> 0 | BO14: =BY14-CG14 -> 0 | BP14: 0 | BQ14: =BO14*S14 -> 0 | BS14: =$CJ$2 -> 3.14 | BT14: =$CJ$3 -> 0.24123847 | BU14: =$CJ$4 -> 0.18104824 | BV14: =$CJ$5 -> 0.015714286 | BX14: 1 | BY14: =BX14-CE14 -> 0.67299663 | CA14: =BS14*G14 -> 0.38885408 | CB14: =BU14*H14 -> 0.031114299 | CC14: =(BX14-CA14-CB14-CF14-CD14)*(1-D14) -> 0.036333708 | CD14: =BV14*P14 -> 0.015871429 | CE14: =(BX14-CA14-CB14-CF14-CD14)*(D14) -> 0.32700337 | CF14: =BT14*I14 -> 0.20082311 | CG14: =SUM(CA14:CF14)-CE14 -> 0.67299663
B15: TX_Synthetic_Ethylene_Non_CCS | C15: CO2Captured | D15: 0 | E15: 5.4424707 | F15: 0.17633675 | G15: 0.11376564 | H15: 0.15787735 | I15: 0.76475308 | J15: 0.41383317 | K15: =BY15-SUM(CA15+CD15+CB15+CF15) -> 0.41383317 | L15: 174237.66 | M15: 95841.654 | N15: 2.9463017 | O15: =N15-(Q15*X15) -> -45.313084 | P15: 1.01 | Q15: =P15*G15 -> 0.1149033 | S15: 73.71884 | T15: -5.000084 | U15: 62.617055 | V15: 37.705083 | W15: 30.684852 | X15: 420 | Y15: 21.986353 | Z15: -8.726944 | AB15: 21.357777 | AC15: 7.54831 | AE15: -126.78287 | AF15: -126.78287 | AK15: 8.60172 | AL15: 0 | AM15: 822.26752 | AN15: 822.26752 | AP15: =B15 -> TX_Synthetic_Ethylene_Non_CCS | AQ15: =C15 -> CO2Captured | AR15: =SUM(AX15:BE15)+BG15+BH15 -> 362.35278 | AS15: =SUM(AX15:BE15)+BJ15+BK15 -> 362.35278 | AT15: =AR15-AS15 -> 0 | AU15: =SUM(AX15:BE15)+BM15+BN15 -> 389.85695 | AV15: =SUM(AX15:BE15)+BP15+BQ15 -> 389.85695 | AW15: =AU15-AV15 -> 0 | AX15: =E15/G15*AC15 -> 361.106 | AY15: =F15/G15*AB15 -> 33.104554 | AZ15: =1/G15*(S15+T15) -> 604.03787 | BA15: =H15/G15*AK15*-1 -> -11.936967 | BB15: =I15/G15*AE15 -> -852.25724 | BC15: =L15/G15/(0.9*8760) -> 194.2604 | BD15: =M15/G15/(0.9*8760) -> 106.85542 | BE15: =O15 -> -45.313084 | BF15: =CG15-BY15-CA15-CD15 -> -0.37309555 | BG15: 0 | BH15: =BF15*S15 -> -27.504171 | BI15: =BY15-CG15-CA15-CD15 -> -0.37309555 | BJ15: 0 | BK15: =BI15*S15 -> -27.504171 | BL15: =BY15-CG15 -> 0 | BM15: 0 | BN15: =BL15*S15 -> 0 | BO15: =BY15-CG15 -> 0 | BP15: 0 | BQ15: =BO15*S15 -> 0 | BS15: =$CJ$2 -> 3.14 | BT15: =$CJ$3 -> 0.24123847 | BU15: =$CJ$4 -> 0.18104824 | BV15: =$CJ$5 -> 0.015714286 | BX15: 1 | BY15: =BX15-CE15 -> 1 | CA15: =BS15*G15 -> 0.35722412 | CB15: =BU15*H15 -> 0.028583416 | CC15: =(BX15-CA15-CB15-CF15-CD15)*(1-D15) -> 0.41383317 | CD15: =BV15*P15 -> 0.015871429 | CE15: =(BX15-CA15-CB15-CF15-CD15)*(D15) -> 0 | CF15: =BT15*I15 -> 0.18448786 | CG15: =SUM(CA15:CF15)-CE15 -> 1
B16: TX_Synthetic_Ethylene_CCS_90 | C16: CO2Captured | D16: 0.9 | E16: 5.9243674 | F16: 0.24466847 | G16: 0.12383888 | H16: 0.1718564 | I16: 0.83246718 | J16: 0.036333708 | K16: =BY16-SUM(CA16+CD16+CB16+CF16) -> 0.036333708 | L16: 209498.32 | M16: 115165.85 | N16: 3.5425479 | O16: =N16-(Q16*X16) -> -48.989905 | P16: 1.01 | Q16: =P16*G16 -> 0.12507727 | S16: 73.71884 | T16: -5.000084 | U16: 62.617055 | V16: 37.705083 | W16: 30.684852 | X16: 420 | Y16: 21.986353 | Z16: -8.726944 | AB16: 21.357777 | AC16: 7.54831 | AE16: -126.78287 | AF16: -126.78287 | AK16: 8.60172 | AL16: 0 | AM16: 822.26752 | AN16: 822.26752 | AP16: =B16 -> TX_Synthetic_Ethylene_CCS_90 | AQ16: =C16 -> CO2Captured | AR16: =SUM(AX16:BE16)+BG16+BH16 -> 347.71701 | AS16: =SUM(AX16:BE16)+BJ16+BK16 -> 347.71701 | AT16: =AR16-AS16 -> 0 | AU16: =SUM(AX16:BE16)+BM16+BN16 -> 377.55291 | AV16: =SUM(AX16:BE16)+BP16+BQ16 -> 377.55291 | AW16: =AU16-AV16 -> 0 | AX16: =E16/G16*AC16 -> 361.106 | AY16: =F16/G16*AB16 -> 42.19656 | AZ16: =1/G16*(S16+T16) -> 554.90454 | BA16: =H16/G16*AK16*-1 -> -11.936967 | BB16: =I16/G16*AE16 -> -852.25724 | BC16: =L16/G16/(0.9*8760) -> 214.57391 | BD16: =M16/G16/(0.9*8760) -> 117.95602 | BE16: =O16 -> -48.989905 | BF16: =CG16-BY16-CA16-CD16 -> -0.40472551 | BG16: 0 | BH16: =BF16*S16 -> -29.835895 | BI16: =BY16-CG16-CA16-CD16 -> -0.40472551 | BJ16: 0 | BK16: =BI16*S16 -> -29.835895 | BL16: =BY16-CG16 -> 0 | BM16: 0 | BN16: =BL16*S16 -> 0 | BO16: =BY16-CG16 -> 0 | BP16: 0 | BQ16: =BO16*S16 -> 0 | BS16: =$CJ$2 -> 3.14 | BT16: =$CJ$3 -> 0.24123847 | BU16: =$CJ$4 -> 0.18104824 | BV16: =$CJ$5 -> 0.015714286 | BX16: 1 | BY16: =BX16-CE16 -> 0.67299663 | CA16: =BS16*G16 -> 0.38885408 | CB16: =BU16*H16 -> 0.031114299 | CC16: =(BX16-CA16-CB16-CF16-CD16)*(1-D16) -> 0.036333708 | CD16: =BV16*P16 -> 0.015871429 | CE16: =(BX16-CA16-CB16-CF16-CD16)*(D16) -> 0.32700337 | CF16: =BT16*I16 -> 0.20082311 | CG16: =SUM(CA16:CF16)-CE16 -> 0.67299663
B17: NW_Synthetic_Ethylene_Non_CCS | C17: CO2Captured | D17: 0 | E17: 5.4424707 | F17: 0.17633675 | G17: 0.11376564 | H17: 0.15787735 | I17: 0.76475308 | J17: 0.41383317 | K17: =BY17-SUM(CA17+CD17+CB17+CF17) -> 0.41383317 | L17: 174237.66 | M17: 95841.654 | N17: 2.9463017 | O17: =N17-(Q17*X17) -> -45.313084 | P17: 1.01 | Q17: =P17*G17 -> 0.1149033 | S17: 73.71884 | T17: 6.341225 | U17: 64.329805 | V17: 37.86581 | W17: 42.137908 | X17: 420 | Y17: 21.986353 | Z17: -3.879455 | AB17: 20.232007 | AC17: 8.132036 | AE17: -112.98996 | AF17: -112.98996 | AK17: 12.309823 | AL17: 0 | AM17: 822.26752 | AN17: 0 | AP17: =B17 -> NW_Synthetic_Ethylene_Non_CCS | AQ17: =C17 -> CO2Captured | AR17: =SUM(AX17:BE17)+BG17+BH17 -> 575.79552 | AS17: =SUM(AX17:BE17)+BJ17+BK17 -> 575.79552 | AT17: =AR17-AS17 -> 0 | AU17: =SUM(AX17:BE17)+BM17+BN17 -> 603.29969 | AV17: =SUM(AX17:BE17)+BP17+BQ17 -> 603.29969 | AW17: =AU17-AV17 -> 0 | AX17: =E17/G17*AC17 -> 389.03105 | AY17: =F17/G17*AB17 -> 31.359611 | AZ17: =1/G17*(S17+T17) -> 703.72797 | BA17: =H17/G17*AK17*-1 -> -17.082857 | BB17: =I17/G17*AE17 -> -759.53883 | BC17: =L17/G17/(0.9*8760) -> 194.2604 | BD17: =M17/G17/(0.9*8760) -> 106.85542 | BE17: =O17 -> -45.313084 | BF17: =CG17-BY17-CA17-CD17 -> -0.37309555 | BG17: 0 | BH17: =BF17*S17 -> -27.504171 | BI17: =BY17-CG17-CA17-CD17 -> -0.37309555 | BJ17: 0 | BK17: =BI17*S17 -> -27.504171 | BL17: =BY17-CG17 -> 0 | BM17: 0 | BN17: =BL17*S17 -> 0 | BO17: =BY17-CG17 -> 0 | BP17: 0 | BQ17: =BO17*S17 -> 0 | BS17: =$CJ$2 -> 3.14 | BT17: =$CJ$3 -> 0.24123847 | BU17: =$CJ$4 -> 0.18104824 | BV17: =$CJ$5 -> 0.015714286 | BX17: 1 | BY17: =BX17-CE17 -> 1 | CA17: =BS17*G17 -> 0.35722412 | CB17: =BU17*H17 -> 0.028583416 | CC17: =(BX17-CA17-CB17-CF17-CD17)*(1-D17) -> 0.41383317 | CD17: =BV17*P17 -> 0.015871429 | CE17: =(BX17-CA17-CB17-CF17-CD17)*(D17) -> 0 | CF17: =BT17*I17 -> 0.18448786 | CG17: =SUM(CA17:CF17)-CE17 -> 1
B18: NW_Synthetic_Ethylene_CCS_90 | C18: CO2Captured | D18: 0.9 | E18: 5.9243674 | F18: 0.24466847 | G18: 0.12383888 | H18: 0.1718564 | I18: 0.83246718 | J18: 0.036333708 | K18: =BY18-SUM(CA18+CD18+CB18+CF18) -> 0.036333708 | L18: 209498.32 | M18: 115165.85 | N18: 3.5425479 | O18: =N18-(Q18*X18) -> -48.989905 | P18: 1.01 | Q18: =P18*G18 -> 0.12507727 | S18: 73.71884 | T18: 6.341225 | U18: 64.329805 | V18: 37.86581 | W18: 42.137908 | X18: 420 | Y18: 21.986353 | Z18: -3.879455 | AB18: 20.232007 | AC18: 8.132036 | AE18: -112.98996 | AF18: -112.98996 | AK18: 12.309823 | AL18: 0 | AM18: 822.26752 | AN18: 0 | AP18: =B18 -> NW_Synthetic_Ethylene_CCS_90 | AQ18: =C18 -> CO2Captured | AR18: =SUM(AX18:BE18)+BG18+BH18 -> 552.57157 | AS18: =SUM(AX18:BE18)+BJ18+BK18 -> 552.57157 | AT18: =AR18-AS18 -> 0 | AU18: =SUM(AX18:BE18)+BM18+BN18 -> 582.40747 | AV18: =SUM(AX18:BE18)+BP18+BQ18 -> 582.40747 | AW18: =AU18-AV18 -> 0 | AX18: =E18/G18*AC18 -> 389.03105 | AY18: =F18/G18*AB18 -> 39.972376 | AZ18: =1/G18*(S18+T18) -> 646.4857 | BA18: =H18/G18*AK18*-1 -> -17.082857 | BB18: =I18/G18*AE18 -> -759.53883 | BC18: =L18/G18/(0.9*8760) -> 214.57391 | BD18: =M18/G18/(0.9*8760) -> 117.95602 | BE18: =O18 -> -48.989905 | BF18: =CG18-BY18-CA18-CD18 -> -0.40472551 | BG18: 0 | BH18: =BF18*S18 -> -29.835895 | BI18: =BY18-CG18-CA18-CD18 -> -0.40472551 | BJ18: 0 | BK18: =BI18*S18 -> -29.835895 | BL18: =BY18-CG18 -> 0 | BM18: 0 | BN18: =BL18*S18 -> 0 | BO18: =BY18-CG18 -> 0 | BP18: 0 | BQ18: =BO18*S18 -> 0 | BS18: =$CJ$2 -> 3.14 | BT18: =$CJ$3 -> 0.24123847 | BU18: =$CJ$4 -> 0.18104824 | BV18: =$CJ$5 -> 0.015714286 | BX18: 1 | BY18: =BX18-CE18 -> 0.67299663 | CA18: =BS18*G18 -> 0.38885408 | CB18: =BU18*H18 -> 0.031114299 | CC18: =(BX18-CA18-CB18-CF18-CD18)*(1-D18) -> 0.036333708 | CD18: =BV18*P18 -> 0.015871429 | CE18: =(BX18-CA18-CB18-CF18-CD18)*(D18) -> 0.32700337 | CF18: =BT18*I18 -> 0.20082311 | CG18: =SUM(CA18:CF18)-CE18 -> 0.67299663
... B20: SW_Synthetic_Ethylene_CCS_90 | C20: CO2Captured | D20: 0.9 | E20: 5.9243674 | F20: 0.24466847 | G20: 0.12383888 | H20: 0.1718564 | I20: 0.83246718 | J20: 0.036333708 | K20: =BY20-SUM(CA20+CD20+CB20+CF20) -> 0.036333708 | L20: 209498.32 | M20: 115165.85 | N20: 3.5425479 | O20: =N20-(Q20*X20) -> -48.989905 | P20: 1.01 | Q20: =P20*G20 -> 0.12507727 | S20: 73.71884 | T20: -4.302149 | U20: 61.152787 | V20: 40.832246 | W20: 41.356795 | X20: 420 | Y20: 21.986353 | Z20: -1.819211 | AB20: 21.021514 | AC20: 9.044068 | AE20: -126.2252 | AF20: -126.2252 | AK20: 10.321106 | AL20: 0 | AM20: 822.26752 | AN20: 0 | AP20: =B20 -> SW_Synthetic_Ethylene_CCS_90 | AQ20: =C20 -> CO2Captured | AR20: =SUM(AX20:BE20)+BG20+BH20 -> 425.60725 | AS20: =SUM(AX20:BE20)+BJ20+BK20 -> 425.60725 | AT20: =AR20-AS20 -> 0 | AU20: =SUM(AX20:BE20)+BM20+BN20 -> 455.44315 | AV20: =SUM(AX20:BE20)+BP20+BQ20 -> 455.44315 | AW20: =AU20-AV20 -> 0 | AX20: =E20/G20*AC20 -> 432.66204 | AY20: =F20/G20*AB20 -> 41.532205 | AZ20: =1/G20*(S20+T20) -> 560.54037 | BA20: =H20/G20*AK20*-1 -> -14.323031 | BB20: =I20/G20*AE20 -> -848.50845 | BC20: =L20/G20/(0.9*8760) -> 214.57391 | BD20: =M20/G20/(0.9*8760) -> 117.95602 | BE20: =O20 -> -48.989905 | BF20: =CG20-BY20-CA20-CD20 -> -0.40472551 | BG20: 0 | BH20: =BF20*S20 -> -29.835895 | BI20: =BY20-CG20-CA20-CD20 -> -0.40472551 | BJ20: 0 | BK20: =BI20*S20 -> -29.835895 | BL20: =BY20-CG20 -> 0 | BM20: 0 | BN20: =BL20*S20 -> 0 | BO20: =BY20-CG20 -> 0 | BP20: 0 | BQ20: =BO20*S20 -> 0 | BS20: =$CJ$2 -> 3.14 | BT20: =$CJ$3 -> 0.24123847 | BU20: =$CJ$4 -> 0.18104824 | BV20: =$CJ$5 -> 0.015714286 | BX20: 1 | BY20: =BX20-CE20 -> 0.67299663 | CA20: =BS20*G20 -> 0.38885408 | CB20: =BU20*H20 -> 0.031114299 | CC20: =(BX20-CA20-CB20-CF20-CD20)*(1-D20) -> 0.036333708 | CD20: =BV20*P20 -> 0.015871429 | CE20: =(BX20-CA20-CB20-CF20-CD20)*(D20) -> 0.32700337 | CF20: =BT20*I20 -> 0.20082311 | CG20: =SUM(CA20:CF20)-CE20 -> 0.67299663
P21: 1.01 | X21: 420
P22: 1.01 | X22: 420
P23: 1.01 | X23: 420
P24: 1.01 | X24: 420
P25: 1.01 | X25: 420
P26: 1.01 | X26: 420
P27: 1.01 | X27: 420
P28: 1.01 | X28: 420
P29: 1.01 | X29: 420
P30: 1.01 | X30: 420
P31: 1.01 | X31: 420
P32: 1.01 | X32: 420
... P65: 1.01 | X65: 420

Sheet lc_summary_noseq
A1: Levelized cost for Synthetic Ethylene Production - $/GJ-ethylene - no chemicals CO2 sequestration | Q1: Assumptions | U1: Levelized cost for Synthetic Ethylene Production - $/GJ-ethylene - no chemicals CO2 sequestration - SORTED
A2: id_LC | B2: h2_consumption | C2: elec_consumption | D2: co2captured_consumption | E2: natgas_production | F2: gasoline_production | G2: investment_cost | H2: fixed_om_cost | I2: variable_om_cost | J2: modified capture cost | K2: modified emissions cost | L2: CI | M2: LCOE ($/t-ethylene) | N2: LCOE ($/GJ-ethylene) | O2: CHECK LCOE ($/GJ-ethylene) | Q2: Ethylene LHV | R2: 45.6 | S2: GJ/t-ethylene | U2: id_LC | V2: h2_consumption | W2: elec_consumption | X2: co2captured_consumption | Y2: natgas_production | Z2: gasoline_production | AA2: investment_cost | AB2: fixed_om_cost | AC2: variable_om_cost | AD2: modified capture cost | AE2: modified emissions cost | AF2: CI | AG2: LCOE ($/t-ethylene) | AH2: LCOE ($/GJ-ethylene) | AI2: CHECK LCOE ($/GJ-ethylene)
A3: =lc_detailed!AP3 -> SE_Synthetic_Ethylene_Non_CCS | B3: =lc_detailed!AX3/$R$2 -> 7.6246839 | C3: =lc_detailed!AY3/$R$2 -> 0.72286565 | D3: =lc_detailed!AZ3/$R$2 -> 13.036156 | E3: =lc_detailed!BA3/$R$2 -> -0.24235512 | F3: =lc_detailed!BB3/$R$2 -> -18.88072 | G3: =lc_detailed!BC3/$R$2 -> 4.2600966 | H3: =lc_detailed!BD3/$R$2 -> 2.3433206 | I3: =lc_detailed!BE3/$R$2 -> -0.99370798 | J3: =lc_detailed!BM3/$R$2 -> 0 | K3: =lc_detailed!BN3/$R$2 -> 0 | L3: =lc_detailed!BL3 -> 0 | M3: =lc_detailed!AU3 -> 358.88747 | N3: =M3/$R$2 -> 7.8703392 | O3: =SUM(B3:K3) -> 7.8703392 | U3: {=_xlfn._xlws.SORT(A3:O65, 13, 1)} -> NE_Synthetic_Ethylene_Non_CCS | V3: 9.6475747 | W3: 0.70667733 | X3: 9.7233652 | Y3: -0.27269293 | Z3: -22.223848 | AA3: 4.2600966 | AB3: 2.3433206 | AC3: -0.99370798 | AD3: 0 | AE3: 0 | AF3: 0 | AG3: 145.4998 | AH3: 3.1907852 | AI3: 3.1907852
A4: =lc_detailed!AP4 -> SE_Synthetic_Ethylene_CCS_90 | B4: =lc_detailed!AX4/$R$2 -> 7.6246839 | C4: =lc_detailed!AY4/$R$2 -> 0.9213972 | D4: =lc_detailed!AZ4/$R$2 -> 11.975776 | E4: =lc_detailed!BA4/$R$2 -> -0.24235512 | F4: =lc_detailed!BB4/$R$2 -> -18.88072 | G4: =lc_detailed!BC4/$R$2 -> 4.7055682 | H4: =lc_detailed!BD4/$R$2 -> 2.5867547 | I4: =lc_detailed!BE4/$R$2 -> -1.07434 | J4: =lc_detailed!BM4/$R$2 -> 0 | K4: =lc_detailed!BN4/$R$2 -> 0 | L4: =lc_detailed!BL4 -> 0 | M4: =lc_detailed!AU4 -> 347.32446 | N4: =M4/$R$2 -> 7.6167644 | O4: =SUM(B4:K4) -> 7.6167644 | U4: NE_Synthetic_Ethylene_CCS_90 | V4: 9.6475747 | W4: 0.90076283 | X4: 8.9324524 | Y4: -0.27269293 | Z4: -22.223848 | AA4: 4.7055682 | AB4: 2.5867547 | AC4: -1.07434 | AD4: 0 | AE4: 0 | AF4: 0 | AG4: 146.02176 | AH4: 3.2022315 | AI4: 3.2022315
A5: =lc_detailed!AP5 -> MIDAT_Synthetic_Ethylene_Non_CCS | B5: =lc_detailed!AX5/$R$2 -> 7.9023387 | C5: =lc_detailed!AY5/$R$2 -> 0.73083595 | D5: =lc_detailed!AZ5/$R$2 -> 11.091537 | E5: =lc_detailed!BA5/$R$2 -> -0.16457134 | F5: =lc_detailed!BB5/$R$2 -> -20.747555 | G5: =lc_detailed!BC5/$R$2 -> 4.2600966 | H5: =lc_detailed!BD5/$R$2 -> 2.3433206 | I5: =lc_detailed!BE5/$R$2 -> -0.99370798 | J5: =lc_detailed!BM5/$R$2 -> 0 | K5: =lc_detailed!BN5/$R$2 -> 0 | L5: =lc_detailed!BL5 -> 0 | M5: =lc_detailed!AU5 -> 201.6566 | N5: =M5/$R$2 -> 4.4222939 | O5: =SUM(B5:K5) -> 4.4222939 | U5: MIDAT_Synthetic_Ethylene_CCS_90 | V5: 7.9023387 | W5: 0.9315565 | X5: 10.189335 | Y5: -0.16457134 | Z5: -20.747555 | AA5: 4.7055682 | AB5: 2.5867547 | AC5: -1.07434 | AD5: 0 | AE5: 0 | AF5: 0 | AG5: 197.40633 | AH5: 4.3290862 | AI5: 4.3290862
A6: =lc_detailed!AP6 -> MIDAT_Synthetic_Ethylene_CCS_90 | B6: =lc_detailed!AX6/$R$2 -> 7.9023387 | C6: =lc_detailed!AY6/$R$2 -> 0.9315565 | D6: =lc_detailed!AZ6/$R$2 -> 10.189335 | E6: =lc_detailed!BA6/$R$2 -> -0.16457134 | F6: =lc_detailed!BB6/$R$2 -> -20.747555 | G6: =lc_detailed!BC6/$R$2 -> 4.7055682 | H6: =lc_detailed!BD6/$R$2 -> 2.5867547 | I6: =lc_detailed!BE6/$R$2 -> -1.07434 | J6: =lc_detailed!BM6/$R$2 -> 0 | K6: =lc_detailed!BN6/$R$2 -> 0 | L6: =lc_detailed!BL6 -> 0 | M6: =lc_detailed!AU6 -> 197.40633 | N6: =M6/$R$2 -> 4.3290862 | O6: =SUM(B6:K6) -> 4.3290862 | U6: MIDAT_Synthetic_Ethylene_Non_CCS | V6: 7.9023387 | W6: 0.73083595 | X6: 11.091537 | Y6: -0.16457134 | Z6: -20.747555 | AA6: 4.2600966 | AB6: 2.3433206 | AC6: -0.99370798 | AD6: 0 | AE6: 0 | AF6: 0 | AG6: 201.6566 | AH6: 4.4222939 | AI6: 4.4222939
A7: =lc_detailed!AP7 -> NE_Synthetic_Ethylene_Non_CCS | B7: =lc_detailed!AX7/$R$2 -> 9.6475747 | C7: =lc_detailed!AY7/$R$2 -> 0.70667733 | D7: =lc_detailed!AZ7/$R$2 -> 9.7233652 | E7: =lc_detailed!BA7/$R$2 -> -0.27269293 | F7: =lc_detailed!BB7/$R$2 -> -22.223848 | G7: =lc_detailed!BC7/$R$2 -> 4.2600966 | H7: =lc_detailed!BD7/$R$2 -> 2.3433206 | I7: =lc_detailed!BE7/$R$2 -> -0.99370798 | J7: =lc_detailed!BM7/$R$2 -> 0 | K7: =lc_detailed!BN7/$R$2 -> 0 | L7: =lc_detailed!BL7 -> 0 | M7: =lc_detailed!AU7 -> 145.4998 | N7: =M7/$R$2 -> 3.1907852 | O7: =SUM(B7:K7) -> 3.1907852 | U7: SE_Synthetic_Ethylene_CCS_90 | V7: 7.6246839 | W7: 0.9213972 | X7: 11.975776 | Y7: -0.24235512 | Z7: -18.88072 | AA7: 4.7055682 | AB7: 2.5867547 | AC7: -1.07434 | AD7: 0 | AE7: 0 | AF7: 0 | AG7: 347.32446 | AH7: 7.6167644 | AI7: 7.6167644
A8: =lc_detailed!AP8 -> NE_Synthetic_Ethylene_CCS_90 | B8: =lc_detailed!AX8/$R$2 -> 9.6475747 | C8: =lc_detailed!AY8/$R$2 -> 0.90076283 | D8: =lc_detailed!AZ8/$R$2 -> 8.9324524 | E8: =lc_detailed!BA8/$R$2 -> -0.27269293 | F8: =lc_detailed!BB8/$R$2 -> -22.223848 | G8: =lc_detailed!BC8/$R$2 -> 4.7055682 | H8: =lc_detailed!BD8/$R$2 -> 2.5867547 | I8: =lc_detailed!BE8/$R$2 -> -1.07434 | J8: =lc_detailed!BM8/$R$2 -> 0 | K8: =lc_detailed!BN8/$R$2 -> 0 | L8: =lc_detailed!BL8 -> 0 | M8: =lc_detailed!AU8 -> 146.02176 | N8: =M8/$R$2 -> 3.2022315 | O8: =SUM(B8:K8) -> 3.2022315 | U8: SE_Synthetic_Ethylene_Non_CCS | V8: 7.6246839 | W8: 0.72286565 | X8: 13.036156 | Y8: -0.24235512 | Z8: -18.88072 | AA8: 4.2600966 | AB8: 2.3433206 | AC8: -0.99370798 | AD8: 0 | AE8: 0 | AF8: 0 | AG8: 358.88747 | AH8: 7.8703392 | AI8: 7.8703392
A9: =lc_detailed!AP9 -> CA_Synthetic_Ethylene_Non_CCS | B9: =lc_detailed!AX9/$R$2 -> 8.8822211 | C9: =lc_detailed!AY9/$R$2 -> 0.6891697 | D9: =lc_detailed!AZ9/$R$2 -> 14.94822 | E9: =lc_detailed!BA9/$R$2 -> -0.39450879 | F9: =lc_detailed!BB9/$R$2 -> -17.12247 | G9: =lc_detailed!BC9/$R$2 -> 4.2600966 | H9: =lc_detailed!BD9/$R$2 -> 2.3433206 | I9: =lc_detailed!BE9/$R$2 -> -0.99370798 | J9: =lc_detailed!BM9/$R$2 -> 0 | K9: =lc_detailed!BN9/$R$2 -> 0 | L9: =lc_detailed!BL9 -> 0 | M9: =lc_detailed!AU9 -> 575.12275 | N9: =M9/$R$2 -> 12.612341 | O9: =SUM(B9:K9) -> 12.612341 | U9: TX_Synthetic_Ethylene_CCS_90 | V9: 7.9189912 | W9: 0.92536316 | X9: 12.168959 | Y9: -0.2617756 | Z9: -18.689852 | AA9: 4.7055682 | AB9: 2.5867547 | AC9: -1.07434 | AD9: 0 | AE9: 0 | AF9: 0 | AG9: 377.55291 | AH9: 8.2796691 | AI9: 8.2796691
A10: =lc_detailed!AP10 -> CA_Synthetic_Ethylene_CCS_90 | B10: =lc_detailed!AX10/$R$2 -> 8.8822211 | C10: =lc_detailed!AY10/$R$2 -> 0.87844683 | D10: =lc_detailed!AZ10/$R$2 -> 13.732309 | E10: =lc_detailed!BA10/$R$2 -> -0.39450879 | F10: =lc_detailed!BB10/$R$2 -> -17.12247 | G10: =lc_detailed!BC10/$R$2 -> 4.7055682 | H10: =lc_detailed!BD10/$R$2 -> 2.5867547 | I10: =lc_detailed!BE10/$R$2 -> -1.07434 | J10: =lc_detailed!BM10/$R$2 -> 0 | K10: =lc_detailed!BN10/$R$2 -> 0 | L10: =lc_detailed!BL10 -> 0 | M10: =lc_detailed!AU10 -> 556.04556 | N10: =M10/$R$2 -> 12.193982 | O10: =SUM(B10:K10) -> 12.193982 | U10: TX_Synthetic_Ethylene_Non_CCS | V10: 7.9189911 | W10: 0.72597707 | X10: 13.246444 | Y10: -0.2617756 | Z10: -18.689852 | AA10: 4.2600966 | AB10: 2.3433206 | AC10: -0.99370798 | AD10: 0 | AE10: 0 | AF10: 0 | AG10: 389.85695 | AH10: 8.5494946 | AI10: 8.5494946
A11: =lc_detailed!AP11 -> NCEN_Synthetic_Ethylene_Non_CCS | B11: =lc_detailed!AX11/$R$2 -> 13.845141 | C11: =lc_detailed!AY11/$R$2 -> 0.77862652 | D11: =lc_detailed!AZ11/$R$2 -> 13.034939 | E11: =lc_detailed!BA11/$R$2 -> -0.45509042 | F11: =lc_detailed!BB11/$R$2 -> -19.094672 | G11: =lc_detailed!BC11/$R$2 -> 4.2600966 | H11: =lc_detailed!BD11/$R$2 -> 2.3433206 | I11: =lc_detailed!BE11/$R$2 -> -0.99370798 | J11: =lc_detailed!BM11/$R$2 -> 0 | K11: =lc_detailed!BN11/$R$2 -> 0 | L11: =lc_detailed!BL11 -> 0 | M11: =lc_detailed!AU11 -> 625.5706 | N11: =M11/$R$2 -> 13.718653 | O11: =SUM(B11:K11) -> 13.718653 | U11: SW_Synthetic_Ethylene_CCS_90 | V11: 9.4882026 | W11: 0.91079397 | X11: 12.292552 | Y11: -0.31410156 | Z11: -18.607641 | AA11: 4.7055682 | AB11: 2.5867547 | AC11: -1.07434 | AD11: 0 | AE11: 0 | AF11: 0 | AG11: 455.44315 | AH11: 9.9877883 | AI11: 9.9877883
A12: =lc_detailed!AP12 -> NCEN_Synthetic_Ethylene_CCS_90 | B12: =lc_detailed!AX12/$R$2 -> 13.845141 | C12: =lc_detailed!AY12/$R$2 -> 0.99247253 | D12: =lc_detailed!AZ12/$R$2 -> 11.974658 | E12: =lc_detailed!BA12/$R$2 -> -0.45509042 | F12: =lc_detailed!BB12/$R$2 -> -19.094672 | G12: =lc_detailed!BC12/$R$2 -> 4.7055682 | H12: =lc_detailed!BD12/$R$2 -> 2.5867547 | I12: =lc_detailed!BE12/$R$2 -> -1.07434 | J12: =lc_detailed!BM12/$R$2 -> 0 | K12: =lc_detailed!BN12/$R$2 -> 0 | L12: =lc_detailed!BL12 -> 0 | M12: =lc_detailed!AU12 -> 614.71043 | N12: =M12/$R$2 -> 13.480492 | O12: =SUM(B12:K12) -> 13.480492 | U12: SW_Synthetic_Ethylene_Non_CCS | V12: 9.4882026 | W12: 0.71454708 | X12: 13.380981 | Y12: -0.31410156 | Z12: -18.607641 | AA12: 4.2600966 | AB12: 2.3433206 | AC12: -0.99370798 | AD12: 0 | AE12: 0 | AF12: 0 | AG12: 468.38936 | AH12: 10.271696 | AI12: 10.271696
A13: =lc_detailed!AP13 -> CEN_Synthetic_Ethylene_Non_CCS | B13: =lc_detailed!AX13/$R$2 -> 13.938063 | C13: =lc_detailed!AY13/$R$2 -> 0.76361777 | D13: =lc_detailed!AZ13/$R$2 -> 13.015289 | E13: =lc_detailed!BA13/$R$2 -> -0.45791676 | F13: =lc_detailed!BB13/$R$2 -> -19.117149 | G13: =lc_detailed!BC13/$R$2 -> 4.2600966 | H13: =lc_detailed!BD13/$R$2 -> 2.3433206 | I13: =lc_detailed!BE13/$R$2 -> -0.99370798 | J13: =lc_detailed!BM13/$R$2 -> 0 | K13: =lc_detailed!BN13/$R$2 -> 0 | L13: =lc_detailed!BL13 -> 0 | M13: =lc_detailed!AU13 -> 627.07355 | N13: =M13/$R$2 -> 13.751613 | O13: =SUM(B13:K13) -> 13.751613 | U13: CA_Synthetic_Ethylene_CCS_90 | V13: 8.8822211 | W13: 0.87844683 | X13: 13.732309 | Y13: -0.39450879 | Z13: -17.12247 | AA13: 4.7055682 | AB13: 2.5867547 | AC13: -1.07434 | AD13: 0 | AE13: 0 | AF13: 0 | AG13: 556.04556 | AH13: 12.193982 | AI13: 12.193982
A14: =lc_detailed!AP14 -> CEN_Synthetic_Ethylene_CCS_90 | B14: =lc_detailed!AX14/$R$2 -> 13.938063 | C14: =lc_detailed!AY14/$R$2 -> 0.97334169 | D14: =lc_detailed!AZ14/$R$2 -> 11.956606 | E14: =lc_detailed!BA14/$R$2 -> -0.45791676 | F14: =lc_detailed!BB14/$R$2 -> -19.117149 | G14: =lc_detailed!BC14/$R$2 -> 4.7055682 | H14: =lc_detailed!BD14/$R$2 -> 2.5867547 | I14: =lc_detailed!BE14/$R$2 -> -1.07434 | J14: =lc_detailed!BM14/$R$2 -> 0 | K14: =lc_detailed!BN14/$R$2 -> 0 | L14: =lc_detailed!BL14 -> 0 | M14: =lc_detailed!AU14 -> 616.09831 | N14: =M14/$R$2 -> 13.510928 | O14: =SUM(B14:K14) -> 13.510928 | U14: CA_Synthetic_Ethylene_Non_CCS | V14: 8.8822211 | W14: 0.6891697 | X14: 14.94822 | Y14: -0.39450879 | Z14: -17.12247 | AA14: 4.2600966 | AB14: 2.3433206 | AC14: -0.99370798 | AD14: 0 | AE14: 0 | AF14: 0 | AG14: 575.12275 | AH14: 12.612341 | AI14: 12.612341
A15: =lc_detailed!AP15 -> TX_Synthetic_Ethylene_Non_CCS | B15: =lc_detailed!AX15/$R$2 -> 7.9189911 | C15: =lc_detailed!AY15/$R$2 -> 0.72597707 | D15: =lc_detailed!AZ15/$R$2 -> 13.246444 | E15: =lc_detailed!BA15/$R$2 -> -0.2617756 | F15: =lc_detailed!BB15/$R$2 -> -18.689852 | G15: =lc_detailed!BC15/$R$2 -> 4.2600966 | H15: =lc_detailed!BD15/$R$2 -> 2.3433206 | I15: =lc_detailed!BE15/$R$2 -> -0.99370798 | J15: =lc_detailed!BM15/$R$2 -> 0 | K15: =lc_detailed!BN15/$R$2 -> 0 | L15: =lc_detailed!BL15 -> 0 | M15: =lc_detailed!AU15 -> 389.85695 | N15: =M15/$R$2 -> 8.5494946 | O15: =SUM(B15:K15) -> 8.5494946 | U15: NW_Synthetic_Ethylene_CCS_90 | V15: 8.5313827 | W15: 0.8765872 | X15: 14.177318 | Y15: -0.37462406 | Z15: -16.656553 | AA15: 4.7055682 | AB15: 2.5867547 | AC15: -1.07434 | AD15: 0 | AE15: 0 | AF15: 0 | AG15: 582.40747 | AH15: 12.772094 | AI15: 12.772094
... A20: =lc_detailed!AP20 -> SW_Synthetic_Ethylene_CCS_90 | B20: =lc_detailed!AX20/$R$2 -> 9.4882026 | C20: =lc_detailed!AY20/$R$2 -> 0.91079397 | D20: =lc_detailed!AZ20/$R$2 -> 12.292552 | E20: =lc_detailed!BA20/$R$2 -> -0.31410156 | F20: =lc_detailed!BB20/$R$2 -> -18.607641 | G20: =lc_detailed!BC20/$R$2 -> 4.7055682 | H20: =lc_detailed!BD20/$R$2 -> 2.5867547 | I20: =lc_detailed!BE20/$R$2 -> -1.07434 | J20: =lc_detailed!BM20/$R$2 -> 0 | K20: =lc_detailed!BN20/$R$2 -> 0 | L20: =lc_detailed!BL20 -> 0 | M20: =lc_detailed!AU20 -> 455.44315 | N20: =M20/$R$2 -> 9.9877883 | O20: =SUM(B20:K20) -> 9.9877883 | U20: CEN_Synthetic_Ethylene_Non_CCS | V20: 13.938063 | W20: 0.76361777 | X20: 13.015289 | Y20: -0.45791676 | Z20: -19.117149 | AA20: 4.2600966 | AB20: 2.3433206 | AC20: -0.99370798 | AD20: 0 | AE20: 0 | AF20: 0 | AG20: 627.07355 | AH20: 13.751613 | AI20: 13.751613
U21: 0 | V21: 0 | W21: 0 | X21: 0 | Y21: 0 | Z21: 0 | AA21: 0 | AB21: 0 | AC21: 0 | AD21: 0 | AE21: 0 | AF21: 0 | AG21: 0 | AH21: 0 | AI21: 0
U22: 0 | V22: 0 | W22: 0 | X22: 0 | Y22: 0 | Z22: 0 | AA22: 0 | AB22: 0 | AC22: 0 | AD22: 0 | AE22: 0 | AF22: 0 | AG22: 0 | AH22: 0 | AI22: 0
U23: 0 | V23: 0 | W23: 0 | X23: 0 | Y23: 0 | Z23: 0 | AA23: 0 | AB23: 0 | AC23: 0 | AD23: 0 | AE23: 0 | AF23: 0 | AG23: 0 | AH23: 0 | AI23: 0
U24: 0 | V24: 0 | W24: 0 | X24: 0 | Y24: 0 | Z24: 0 | AA24: 0 | AB24: 0 | AC24: 0 | AD24: 0 | AE24: 0 | AF24: 0 | AG24: 0 | AH24: 0 | AI24: 0
U25: 0 | V25: 0 | W25: 0 | X25: 0 | Y25: 0 | Z25: 0 | AA25: 0 | AB25: 0 | AC25: 0 | AD25: 0 | AE25: 0 | AF25: 0 | AG25: 0 | AH25: 0 | AI25: 0
U26: 0 | V26: 0 | W26: 0 | X26: 0 | Y26: 0 | Z26: 0 | AA26: 0 | AB26: 0 | AC26: 0 | AD26: 0 | AE26: 0 | AF26: 0 | AG26: 0 | AH26: 0 | AI26: 0
U27: 0 | V27: 0 | W27: 0 | X27: 0 | Y27: 0 | Z27: 0 | AA27: 0 | AB27: 0 | AC27: 0 | AD27: 0 | AE27: 0 | AF27: 0 | AG27: 0 | AH27: 0 | AI27: 0
U28: 0 | V28: 0 | W28: 0 | X28: 0 | Y28: 0 | Z28: 0 | AA28: 0 | AB28: 0 | AC28: 0 | AD28: 0 | AE28: 0 | AF28: 0 | AG28: 0 | AH28: 0 | AI28: 0
U29: 0 | V29: 0 | W29: 0 | X29: 0 | Y29: 0 | Z29: 0 | AA29: 0 | AB29: 0 | AC29: 0 | AD29: 0 | AE29: 0 | AF29: 0 | AG29: 0 | AH29: 0 | AI29: 0
U30: 0 | V30: 0 | W30: 0 | X30: 0 | Y30: 0 | Z30: 0 | AA30: 0 | AB30: 0 | AC30: 0 | AD30: 0 | AE30: 0 | AF30: 0 | AG30: 0 | AH30: 0 | AI30: 0
U31: 0 | V31: 0 | W31: 0 | X31: 0 | Y31: 0 | Z31: 0 | AA31: 0 | AB31: 0 | AC31: 0 | AD31: 0 | AE31: 0 | AF31: 0 | AG31: 0 | AH31: 0 | AI31: 0
U32: 0 | V32: 0 | W32: 0 | X32: 0 | Y32: 0 | Z32: 0 | AA32: 0 | AB32: 0 | AC32: 0 | AD32: 0 | AE32: 0 | AF32: 0 | AG32: 0 | AH32: 0 | AI32: 0
... U65: 0 | V65: 0 | W65: 0 | X65: 0 | Y65: 0 | Z65: 0 | AA65: 0 | AB65: 0 | AC65: 0 | AD65: 0 | AE65: 0 | AF65: 0 | AG65: 0 | AH65: 0 | AI65: 0

Sheet lc_summary_seq
A1: Levelized cost for Synthetic Ethylene Production - $/GJ-ethylene - chemicals CO2 sequestration | Q1: Assumptions | U1: Levelized cost for Synthetic Ethylene Production - $/GJ-ethylene - chemicals CO2 sequestration - SORTED
A2: id_LC | B2: h2_consumption | C2: elec_consumption | D2: co2captured_consumption | E2: natgas_production | F2: gasoline_production | G2: investment_cost | H2: fixed_om_cost | I2: variable_om_cost | J2: modified capture cost | K2: modified emissions cost | L2: CI | M2: LCOE ($/t-ethylene) | N2: LCOE ($/GJ-ethylene) | O2: CHECK LCOE ($/GJ-ethylene) | Q2: Ethylene LHV | R2: 45.6 | S2: GJ/t-ethylene | U2: id_LC | V2: h2_consumption | W2: elec_consumption | X2: co2captured_consumption | Y2: natgas_production | Z2: gasoline_production | AA2: investment_cost | AB2: fixed_om_cost | AC2: variable_om_cost | AD2: modified capture cost | AE2: modified emissions cost | AF2: CI | AG2: LCOE ($/t-ethylene) | AH2: LCOE ($/GJ-ethylene) | AI2: CHECK LCOE ($/GJ-ethylene)
A3: =lc_detailed!AP3 -> SE_Synthetic_Ethylene_Non_CCS | B3: =lc_detailed!AX3/$R$2 -> 7.6246839 | C3: =lc_detailed!AY3/$R$2 -> 0.72286565 | D3: =lc_detailed!AZ3/$R$2 -> 13.036156 | E3: =lc_detailed!BA3/$R$2 -> -0.24235512 | F3: =lc_detailed!BB3/$R$2 -> -18.88072 | G3: =lc_detailed!BC3/$R$2 -> 4.2600966 | H3: =lc_detailed!BD3/$R$2 -> 2.3433206 | I3: =lc_detailed!BE3/$R$2 -> -0.99370798 | J3: =lc_detailed!BG3/$R$2 -> 0 | K3: =lc_detailed!BH3/$R$2 -> -0.60316164 | L3: =lc_detailed!BI3 -> -0.37309555 | M3: =lc_detailed!AR3 -> 331.3833 | N3: =M3/$R$2 -> 7.2671776 | O3: =SUM(B3:K3) -> 7.2671776 | U3: {=_xlfn._xlws.SORT(A3:O65, 13, 1)} -> NE_Synthetic_Ethylene_CCS_90 | V3: 9.6475747 | W3: 0.90076283 | X3: 8.9324524 | Y3: -0.27269293 | Z3: -22.223848 | AA3: 4.7055682 | AB3: 2.5867547 | AC3: -1.07434 | AD3: 0 | AE3: -0.65429595 | AF3: -0.40472551 | AG3: 116.18586 | AH3: 2.5479356 | AI3: 2.5479356
A4: =lc_detailed!AP4 -> SE_Synthetic_Ethylene_CCS_90 | B4: =lc_detailed!AX4/$R$2 -> 7.6246839 | C4: =lc_detailed!AY4/$R$2 -> 0.9213972 | D4: =lc_detailed!AZ4/$R$2 -> 11.975776 | E4: =lc_detailed!BA4/$R$2 -> -0.24235512 | F4: =lc_detailed!BB4/$R$2 -> -18.88072 | G4: =lc_detailed!BC4/$R$2 -> 4.7055682 | H4: =lc_detailed!BD4/$R$2 -> 2.5867547 | I4: =lc_detailed!BE4/$R$2 -> -1.07434 | J4: =lc_detailed!BG4/$R$2 -> 0 | K4: =lc_detailed!BH4/$R$2 -> -0.65429595 | L4: =lc_detailed!BI4 -> -0.40472551 | M4: =lc_detailed!AR4 -> 317.48856 | N4: =M4/$R$2 -> 6.9624684 | O4: =SUM(B4:K4) -> 6.9624684 | U4: NE_Synthetic_Ethylene_Non_CCS | V4: 9.6475747 | W4: 0.70667733 | X4: 9.7233652 | Y4: -0.27269293 | Z4: -22.223848 | AA4: 4.2600966 | AB4: 2.3433206 | AC4: -0.99370798 | AD4: 0 | AE4: -0.60316164 | AF4: -0.37309555 | AG4: 117.99563 | AH4: 2.5876235 | AI4: 2.5876235
A5: =lc_detailed!AP5 -> MIDAT_Synthetic_Ethylene_Non_CCS | B5: =lc_detailed!AX5/$R$2 -> 7.9023387 | C5: =lc_detailed!AY5/$R$2 -> 0.73083595 | D5: =lc_detailed!AZ5/$R$2 -> 11.091537 | E5: =lc_detailed!BA5/$R$2 -> -0.16457134 | F5: =lc_detailed!BB5/$R$2 -> -20.747555 | G5: =lc_detailed!BC5/$R$2 -> 4.2600966 | H5: =lc_detailed!BD5/$R$2 -> 2.3433206 | I5: =lc_detailed!BE5/$R$2 -> -0.99370798 | J5: =lc_detailed!BG5/$R$2 -> 0 | K5: =lc_detailed!BH5/$R$2 -> -0.60316164 | L5: =lc_detailed!BI5 -> -0.37309555 | M5: =lc_detailed!AR5 -> 174.15243 | N5: =M5/$R$2 -> 3.8191322 | O5: =SUM(B5:K5) -> 3.8191322 | U5: MIDAT_Synthetic_Ethylene_CCS_90 | V5: 7.9023387 | W5: 0.9315565 | X5: 10.189335 | Y5: -0.16457134 | Z5: -20.747555 | AA5: 4.7055682 | AB5: 2.5867547 | AC5: -1.07434 | AD5: 0 | AE5: -0.65429595 | AF5: -0.40472551 | AG5: 167.57043 | AH5: 3.6747902 | AI5: 3.6747902
A6: =lc_detailed!AP6 -> MIDAT_Synthetic_Ethylene_CCS_90 | B6: =lc_detailed!AX6/$R$2 -> 7.9023387 | C6: =lc_detailed!AY6/$R$2 -> 0.9315565 | D6: =lc_detailed!AZ6/$R$2 -> 10.189335 | E6: =lc_detailed!BA6/$R$2 -> -0.16457134 | F6: =lc_detailed!BB6/$R$2 -> -20.747555 | G6: =lc_detailed!BC6/$R$2 -> 4.7055682 | H6: =lc_detailed!BD6/$R$2 -> 2.5867547 | I6: =lc_detailed!BE6/$R$2 -> -1.07434 | J6: =lc_detailed!BG6/$R$2 -> 0 | K6: =lc_detailed!BH6/$R$2 -> -0.65429595 | L6: =lc_detailed!BI6 -> -0.40472551 | M6: =lc_detailed!AR6 -> 167.57043 | N6: =M6/$R$2 -> 3.6747902 | O6: =SUM(B6:K6) -> 3.6747902 | U6: MIDAT_Synthetic_Ethylene_Non_CCS | V6: 7.9023387 | W6: 0.73083595 | X6: 11.091537 | Y6: -0.16457134 | Z6: -20.747555 | AA6: 4.2600966 | AB6: 2.3433206 | AC6: -0.99370798 | AD6: 0 | AE6: -0.60316164 | AF6: -0.37309555 | AG6: 174.15243 | AH6: 3.8191322 | AI6: 3.8191322
A7: =lc_detailed!AP7 -> NE_Synthetic_Ethylene_Non_CCS | B7: =lc_detailed!AX7/$R$2 -> 9.6475747 | C7: =lc_detailed!AY7/$R$2 -> 0.70667733 | D7: =lc_detailed!AZ7/$R$2 -> 9.7233652 | E7: =lc_detailed!BA7/$R$2 -> -0.27269293 | F7: =lc_detailed!BB7/$R$2 -> -22.223848 | G7: =lc_detailed!BC7/$R$2 -> 4.2600966 | H7: =lc_detailed!BD7/$R$2 -> 2.3433206 | I7: =lc_detailed!BE7/$R$2 -> -0.99370798 | J7: =lc_detailed!BG7/$R$2 -> 0 | K7: =lc_detailed!BH7/$R$2 -> -0.60316164 | L7: =lc_detailed!BI7 -> -0.37309555 | M7: =lc_detailed!AR7 -> 117.99563 | N7: =M7/$R$2 -> 2.5876235 | O7: =SUM(B7:K7) -> 2.5876235 | U7: SE_Synthetic_Ethylene_CCS_90 | V7: 7.6246839 | W7: 0.9213972 | X7: 11.975776 | Y7: -0.24235512 | Z7: -18.88072 | AA7: 4.7055682 | AB7: 2.5867547 | AC7: -1.07434 | AD7: 0 | AE7: -0.65429595 | AF7: -0.40472551 | AG7: 317.48856 | AH7: 6.9624684 | AI7: 6.9624684
A8: =lc_detailed!AP8 -> NE_Synthetic_Ethylene_CCS_90 | B8: =lc_detailed!AX8/$R$2 -> 9.6475747 | C8: =lc_detailed!AY8/$R$2 -> 0.90076283 | D8: =lc_detailed!AZ8/$R$2 -> 8.9324524 | E8: =lc_detailed!BA8/$R$2 -> -0.27269293 | F8: =lc_detailed!BB8/$R$2 -> -22.223848 | G8: =lc_detailed!BC8/$R$2 -> 4.7055682 | H8: =lc_detailed!BD8/$R$2 -> 2.5867547 | I8: =lc_detailed!BE8/$R$2 -> -1.07434 | J8: =lc_detailed!BG8/$R$2 -> 0 | K8: =lc_detailed!BH8/$R$2 -> -0.65429595 | L8: =lc_detailed!BI8 -> -0.40472551 | M8: =lc_detailed!AR8 -> 116.18586 | N8: =M8/$R$2 -> 2.5479356 | O8: =SUM(B8:K8) -> 2.5479356 | U8: SE_Synthetic_Ethylene_Non_CCS | V8: 7.6246839 | W8: 0.72286565 | X8: 13.036156 | Y8: -0.24235512 | Z8: -18.88072 | AA8: 4.2600966 | AB8: 2.3433206 | AC8: -0.99370798 | AD8: 0 | AE8: -0.60316164 | AF8: -0.37309555 | AG8: 331.3833 | AH8: 7.2671776 | AI8: 7.2671776
A9: =lc_detailed!AP9 -> CA_Synthetic_Ethylene_Non_CCS | B9: =lc_detailed!AX9/$R$2 -> 8.8822211 | C9: =lc_detailed!AY9/$R$2 -> 0.6891697 | D9: =lc_detailed!AZ9/$R$2 -> 14.94822 | E9: =lc_detailed!BA9/$R$2 -> -0.39450879 | F9: =lc_detailed!BB9/$R$2 -> -17.12247 | G9: =lc_detailed!BC9/$R$2 -> 4.2600966 | H9: =lc_detailed!BD9/$R$2 -> 2.3433206 | I9: =lc_detailed!BE9/$R$2 -> -0.99370798 | J9: =lc_detailed!BG9/$R$2 -> 0 | K9: =lc_detailed!BH9/$R$2 -> -0.60316164 | L9: =lc_detailed!BI9 -> -0.37309555 | M9: =lc_detailed!AR9 -> 547.61858 | N9: =M9/$R$2 -> 12.009179 | O9: =SUM(B9:K9) -> 12.009179 | U9: TX_Synthetic_Ethylene_CCS_90 | V9: 7.9189912 | W9: 0.92536316 | X9: 12.168959 | Y9: -0.2617756 | Z9: -18.689852 | AA9: 4.7055682 | AB9: 2.5867547 | AC9: -1.07434 | AD9: 0 | AE9: -0.65429595 | AF9: -0.40472551 | AG9: 347.71701 | AH9: 7.6253731 | AI9: 7.6253731
A10: =lc_detailed!AP10 -> CA_Synthetic_Ethylene_CCS_90 | B10: =lc_detailed!AX10/$R$2 -> 8.8822211 | C10: =lc_detailed!AY10/$R$2 -> 0.87844683 | D10: =lc_detailed!AZ10/$R$2 -> 13.732309 | E10: =lc_detailed!BA10/$R$2 -> -0.39450879 | F10: =lc_detailed!BB10/$R$2 -> -17.12247 | G10: =lc_detailed!BC10/$R$2 -> 4.7055682 | H10: =lc_detailed!BD10/$R$2 -> 2.5867547 | I10: =lc_detailed!BE10/$R$2 -> -1.07434 | J10: =lc_detailed!BG10/$R$2 -> 0 | K10: =lc_detailed!BH10/$R$2 -> -0.65429595 | L10: =lc_detailed!BI10 -> -0.40472551 | M10: =lc_detailed!AR10 -> 526.20967 | N10: =M10/$R$2 -> 11.539686 | O10: =SUM(B10:K10) -> 11.539686 | U10: TX_Synthetic_Ethylene_Non_CCS | V10: 7.9189911 | W10: 0.72597707 | X10: 13.246444 | Y10: -0.2617756 | Z10: -18.689852 | AA10: 4.2600966 | AB10: 2.3433206 | AC10: -0.99370798 | AD10: 0 | AE10: -0.60316164 | AF10: -0.37309555 | AG10: 362.35278 | AH10: 7.9463329 | AI10: 7.9463329
A11: =lc_detailed!AP11 -> NCEN_Synthetic_Ethylene_Non_CCS | B11: =lc_detailed!AX11/$R$2 -> 13.845141 | C11: =lc_detailed!AY11/$R$2 -> 0.77862652 | D11: =lc_detailed!AZ11/$R$2 -> 13.034939 | E11: =lc_detailed!BA11/$R$2 -> -0.45509042 | F11: =lc_detailed!BB11/$R$2 -> -19.094672 | G11: =lc_detailed!BC11/$R$2 -> 4.2600966 | H11: =lc_detailed!BD11/$R$2 -> 2.3433206 | I11: =lc_detailed!BE11/$R$2 -> -0.99370798 | J11: =lc_detailed!BG11/$R$2 -> 0 | K11: =lc_detailed!BH11/$R$2 -> -0.60316164 | L11: =lc_detailed!BI11 -> -0.37309555 | M11: =lc_detailed!AR11 -> 598.06642 | N11: =M11/$R$2 -> 13.115492 | O11: =SUM(B11:K11) -> 13.115492 | U11: SW_Synthetic_Ethylene_CCS_90 | V11: 9.4882026 | W11: 0.91079397 | X11: 12.292552 | Y11: -0.31410156 | Z11: -18.607641 | AA11: 4.7055682 | AB11: 2.5867547 | AC11: -1.07434 | AD11: 0 | AE11: -0.65429595 | AF11: -0.40472551 | AG11: 425.60725 | AH11: 9.3334924 | AI11: 9.3334924
A12: =lc_detailed!AP12 -> NCEN_Synthetic_Ethylene_CCS_90 | B12: =lc_detailed!AX12/$R$2 -> 13.845141 | C12: =lc_detailed!AY12/$R$2 -> 0.99247253 | D12: =lc_detailed!AZ12/$R$2 -> 11.974658 | E12: =lc_detailed!BA12/$R$2 -> -0.45509042 | F12: =lc_detailed!BB12/$R$2 -> -19.094672 | G12: =lc_detailed!BC12/$R$2 -> 4.7055682 | H12: =lc_detailed!BD12/$R$2 -> 2.5867547 | I12: =lc_detailed!BE12/$R$2 -> -1.07434 | J12: =lc_detailed!BG12/$R$2 -> 0 | K12: =lc_detailed!BH12/$R$2 -> -0.65429595 | L12: =lc_detailed!BI12 -> -0.40472551 | M12: =lc_detailed!AR12 -> 584.87454 | N12: =M12/$R$2 -> 12.826196 | O12: =SUM(B12:K12) -> 12.826196 | U12: SW_Synthetic_Ethylene_Non_CCS | V12: 9.4882026 | W12: 0.71454708 | X12: 13.380981 | Y12: -0.31410156 | Z12: -18.607641 | AA12: 4.2600966 | AB12: 2.3433206 | AC12: -0.99370798 | AD12: 0 | AE12: -0.60316164 | AF12: -0.37309555 | AG12: 440.88519 | AH12: 9.6685348 | AI12: 9.6685348
