Workbook

Sheet lc_detailed
B1: Asset Parameters (normalized by commodity feedstock) | N1: doesn't include LPG | T1: Duals | AQ1: LCOE for assets with ethane capacity ($/t-ethylene) | AS1: SEQ - CI | AT1: SEQ - CREDIT | AV1: NO SEQ - CI | AW1: NO SEQ - CREDIT | BH1: CHEM SEQUESTRATION - CARBON INTENSITY | BK1: CHEM SEQUESTRATION - CREDIT | BN1: NO CHEM SEQUESTRATION - CARBON INTENSITY | BQ1: NO CHEM SEQUESTRATION - CREDIT | BU1: Carbon Content | BZ1: Carbon Inputs | CD1: Carbon Outputs | CK1: Sanity Checks
B2: id | C2: commodity | D2: CCS | E2: h2_consumption (MWh/MWh-ethane) | F2: h2_production (MWh/MWh-ethane) | G2: elec_consumption (MWh/MWh-ethane) | H2: ethylene_production (t-ethylene/MWh-ethane) | I2: natgas_consumption (MWh/MWh-ethane) | J2: natgas_production (MWh/MWh-ethane) | K2: ASSET_capture_rate (t-CO2/MWh-ethane) | L2: ASSET_emission_rate (t-CO2/MWh-ethane) | M2: capture_rate (t-CO2/MWh-ethane) | N2: emission_rate (t-CO2/MWh-ethane) | O2: investment_cost ($/yr per MW ethane) | P2: fixed_om_cost ($/yr per MW ethane) | Q2: variable_om_cost ($/MWh-ethane) | R2: LPG_production (t-LPG/t-ethylene) | T2: co2_sink ($/t) | U2: co2_captured ($/t) | V2: bioherb_supply ($/t) | W2: biowood_supply ($/t) | X2: bioagri_supply ($/t) | Y2: LPG_demand ($/t-LPG) | Z2: ethane_supply ($/MWh) | AA2: ethanol_balance ($/MWh) | AB2: ethanol_demand ($/MWh) | AC2: elec_demand ($/MWh) | AD2: h2_balance ($/MWh) | AE2: h2_demand ($/MWh) | AF2: gasoline_balance ($/MWh) | AG2: gasoline_demand ($/MWh) | AH2: diesel_balance ($/MWh) | AI2: diesel_demand ($/MWh) | AJ2: jetfuel_balance ($/MWh) | AK2: jetfuel_demand ($/MWh) | AL2: ng_balance ($/MWh) | AM2: ng_demand ($/MWh) | AN2: ethylene_balance ($/t) | AO2: ethylene_demand ($/t) | AQ2: id_LC | AR2: commodity_LC | AS2: LCOE ($/t-ethylene) | AT2: LCOE ($/t-ethylene) | AU2: Diff. Between Methods | AV2: LCOE ($/t-ethylene) | AW2: LCOE ($/t-ethylene) | AX2: Diff. Between Methods | AY2: h2_consumption | AZ2: h2_production | BA2: elec_consumption | BB2: ethane_consumption | BC2: natgas_consumption | BD2: natgas_production | BE2: investment_cost | BF2: fixed_om_cost | BG2: variable_om_cost | BH2: CI | BI2: modified capture cost | BJ2: modified emissions cost | BK2: CI | BL2: modified capture cost | BM2: modified emissions cost | BN2: CI | BO2: modified capture cost | BP2: modified emissions cost | BQ2: CI | BR2: modified capture cost | BS2: modified emissions cost | BU2: Ethylene (t-CO2/t-ethylene) | BV2: Ethane (t-CO2/MWh-ethane) | BW2: NG (t-CO2/MWh-NG) | BX2: LPG (t-CO2/t-LPG) | BZ2: Ethane (t-CO2/t-ethylene) | CA2: NG (t-CO2/t-ethylene) | CB2: Total input (t-CO2/t-ethylene) | CD2: Ethylene (t-CO2/t-ethylene) | CE2: Methane (t-CO2/t-ethylene) | CF2: Emissions (t-CO2/t-ethylene) | CG2: Captured (t-CO2/t-ethylene) | CH2: LPG (t-CO2/t-ethylene) | CI2: Total Output (t-CO2/t-ethylene) | CK2: Diff. Between Input and Output CO2 (t-CO2/t-ethylene)
B3: SW_TSC | C3: Ethane | D3: 0 | E3: 0 | F3: 0 | G3: 0 | H3: 0.053101897 | I3: 0.022701699 | J3: 0 | K3: 0 | L3: 0.059012541 | M3: =CG3*H3 -> 0 | N3: =CF3*H3 -> 0.059012541 | O3: 99124.32 | P3: 54251.998 | Q3: 1.6761598 | R3: 0.2020556 | T3: 73.71884 | U3: -4.302149 | V3: 61.152787 | W3: 40.832246 | X3: 41.356795 | Y3: 420 | Z3: 21.986353 | AA3: -1.819211 | AC3: 21.021514 | AD3: 9.044068 | AF3: -126.2252 | AG3: -126.2252 | AL3: 10.321106 | AM3: 0 | AN3: 822.26752 | AO3: 0 | AQ3: =B3 -> SW_TSC | AR3: =C3 -> Ethane | AS3: =SUM(AY3:BG3)+BI3+BJ3 -> 898.2971 | AT3: =SUM(AY3:BG3)+BL3+BM3 -> 898.2971 | AU3: =AS3-AT3 -> 0 | AV3: =SUM(AY3:BG3)+BO3+BP3 -> 1130.0083 | AW3: =SUM(AY3:BG3)+BR3+BS3 -> 1130.0083 | AX3: =AV3-AW3 -> 0 | AY3: =E3/H3*AD3 -> 0 | AZ3: =F3/H3*AD3*-1 -> 0 | BA3: =G3/H3*AC3 -> 0 | BB3: =1/H3*Z3 -> 414.04082 | BC3: =I3/H3*AL3 -> 4.4123968 | BD3: =J3/H3*AL3*-1 -> 0 | BE3: =O3/H3/(0.9*8760) -> 236.76831 | BF3: =P3/H3/(0.9*8760) -> 129.5863 | BG3: =Q3/H3 -> 31.564969 | BH3: =CE3+CF3+CG3 -> 1.1113076 | BI3: =(T3+U3)*-1*M3/H3 -> 0 | BJ3: =BH3*T3 -> 81.924305 | BK3: =CE3+CF3 -> 1.1113076 | BL3: =U3*M3*-1/H3 -> 0 | BM3: =BK3*T3 -> 81.924305 | BN3: =SUM(CD3:CH3) -> 4.2544827 | BO3: =(T3+U3)*-1*M3/H3 -> 0 | BP3: =BN3*T3 -> 313.63553 | BQ3: =CD3+CE3+CF3+CH3 -> 4.2544827 | BR3: =M3/H3*U3*-1 -> 0 | BS3: =T3*BQ3 -> 313.63553 | BU3: 3.14 | BV3: 0.221811 | BW3: 0.18104824 | BX3: 0.015714286 | BZ3: =1/H3*BV3 -> 4.1770824 | CA3: =I3/H3*BW3 -> 0.077400297 | CB3: =BZ3+CA3 -> 4.2544827 | CD3: =BU3 -> 3.14 | CE3: =J3/H3*BW3 -> 0 | CF3: =(CB3-CD3-CE3-CH3)*(1-D3) -> 1.1113076 | CG3: =(CB3-CD3-CE3-CH3)*D3 -> 0 | CH3: =BX3*R3 -> 0.0031751595 | CI3: =SUM(CD3:CH3) -> 4.2544827 | CK3: =CI3-CB3 -> 0
B4: TX_TSC | C4: Ethane | D4: 0 | E4: 0 | F4: 0 | G4: 0 | H4: 0.053101897 | I4: 0.022701699 | J4: 0 | K4: 0 | L4: 0.059012541 | M4: =CG4*H4 -> 0 | N4: =CF4*H4 -> 0.059012541 | O4: 99124.32 | P4: 54251.998 | Q4: 1.6761598 | R4: 0.2020556 | T4: 73.71884 | U4: -5.000084 | V4: 62.617055 | W4: 37.705083 | X4: 30.684852 | Y4: 420 | Z4: 21.986353 | AA4: -8.726944 | AC4: 21.357777 | AD4: 7.54831 | AF4: -126.78287 | AG4: -126.78287 | AL4: 8.60172 | AM4: 0 | AN4: 822.26752 | AO4: 822.26752 | AQ4: =B4 -> TX_TSC | AR4: =C4 -> Ethane | AS4: =SUM(AY4:BG4)+BI4+BJ4 -> 897.56204 | AT4: =SUM(AY4:BG4)+BL4+BM4 -> 897.56204 | AU4: =AS4-AT4 -> 0 | AV4: =SUM(AY4:BG4)+BO4+BP4 -> 1129.2733 | AW4: =SUM(AY4:BG4)+BR4+BS4 -> 1129.2733 | AX4: =AV4-AW4 -> 0 | AY4: =E4/H4*AD4 -> 0 | AZ4: =F4/H4*AD4*-1 -> 0 | BA4: =G4/H4*AC4 -> 0 | BB4: =1/H4*Z4 -> 414.04082 | BC4: =I4/H4*AL4 -> 3.6773386 | BD4: =J4/H4*AL4*-1 -> 0 | BE4: =O4/H4/(0.9*8760) -> 236.76831 | BF4: =P4/H4/(0.9*8760) -> 129.5863 | BG4: =Q4/H4 -> 31.564969 | BH4: =CE4+CF4+CG4 -> 1.1113076 | BI4: =(T4+U4)*-1*M4/H4 -> 0 | BJ4: =BH4*T4 -> 81.924305 | BK4: =CE4+CF4 -> 1.1113076 | BL4: =U4*M4*-1/H4 -> 0 | BM4: =BK4*T4 -> 81.924305 | BN4: =SUM(CD4:CH4) -> 4.2544827 | BO4: =(T4+U4)*-1*M4/H4 -> 0 | BP4: =BN4*T4 -> 313.63553 | BQ4: =CD4+CE4+CF4+CH4 -> 4.2544827 | BR4: =M4/H4*U4*-1 -> 0 | BS4: =T4*BQ4 -> 313.63553 | BU4: 3.14 | BV4: 0.221811 | BW4: 0.18104824 | BX4: 0.015714286 | BZ4: =1/H4*BV4 -> 4.1770824 | CA4: =I4/H4*BW4 -> 0.077400297 | CB4: =BZ4+CA4 -> 4.2544827 | CD4: =BU4 -> 3.14 | CE4: =J4/H4*BW4 -> 0 | CF4: =(CB4-CD4-CE4-CH4)*(1-D4) -> 1.1113076 | CG4: =(CB4-CD4-CE4-CH4)*D4 -> 0 | CH4: =BX4*R4 -> 0.0031751595 | CI4: =SUM(CD4:CH4) -> 4.2544827 | CK4: =CI4-CB4 -> 0
B5: NCEN_TSC | C5: Ethane | D5: 0 | E5: 0 | F5: 0 | G5: 0 | H5: 0.053101897 | I5: 0.022701699 | J5: 0 | K5: 0 | L5: 0.059012541 | M5: =CG5*H5 -> 0 | N5: =CF5*H5 -> 0.059012541 | O5: 99124.32 | P5: 54251.998 | Q5: 1.6761598 | R5: 0.2020556 | T5: 73.71884 | U5: -6.097314 | V5: 61.343403 | W5: 33.004971 | X5: 42.19561 | Y5: 420 | Z5: 21.986353 | AA5: 51.423576 | AC5: 22.90669 | AD5: 13.197062 | AF5: -129.52898 | AG5: -129.52898 | AL5: 14.953878 | AM5: 0 | AN5: 822.26752 | AO5: 822.26752 | AQ5: =B5 -> NCEN_TSC | AR5: =C5 -> Ethane | AS5: =SUM(AY5:BG5)+BI5+BJ5 -> 900.27767 | AT5: =SUM(AY5:BG5)+BL5+BM5 -> 900.27767 | AU5: =AS5-AT5 -> 0 | AV5: =SUM(AY5:BG5)+BO5+BP5 -> 1131.9889 | AW5: =SUM(AY5:BG5)+BR5+BS5 -> 1131.9889 | AX5: =AV5-AW5 -> 0 | AY5: =E5/H5*AD5 -> 0 | AZ5: =F5/H5*AD5*-1 -> 0 | BA5: =G5/H5*AC5 -> 0 | BB5: =1/H5*Z5 -> 414.04082 | BC5: =I5/H5*AL5 -> 6.3929624 | BD5: =J5/H5*AL5*-1 -> 0 | BE5: =O5/H5/(0.9*8760) -> 236.76831 | BF5: =P5/H5/(0.9*8760) -> 129.5863 | BG5: =Q5/H5 -> 31.564969 | BH5: =CE5+CF5+CG5 -> 1.1113076 | BI5: =(T5+U5)*-1*M5/H5 -> 0 | BJ5: =BH5*T5 -> 81.924305 | BK5: =CE5+CF5 -> 1.1113076 | BL5: =U5*M5*-1/H5 -> 0 | BM5: =BK5*T5 -> 81.924305 | BN5: =SUM(CD5:CH5) -> 4.2544827 | BO5: =(T5+U5)*-1*M5/H5 -> 0 | BP5: =BN5*T5 -> 313.63553 | BQ5: =CD5+CE5+CF5+CH5 -> 4.2544827 | BR5: =M5/H5*U5*-1 -> 0 | BS5: =T5*BQ5 -> 313.63553 | BU5: 3.14 | BV5: 0.221811 | BW5: 0.18104824 | BX5: 0.015714286 | BZ5: =1/H5*BV5 -> 4.1770824 | CA5: =I5/H5*BW5 -> 0.077400297 | CB5: =BZ5+CA5 -> 4.2544827 | CD5: =BU5 -> 3.14 | CE5: =J5/H5*BW5 -> 0 | CF5: =(CB5-CD5-CE5-CH5)*(1-D5) -> 1.1113076 | CG5: =(CB5-CD5-CE5-CH5)*D5 -> 0 | CH5: =BX5*R5 -> 0.0031751595 | CI5: =SUM(CD5:CH5) -> 4.2544827 | CK5: =CI5-CB5 -> 0
B6: CEN_TSC | C6: Ethane | D6: 0 | E6: 0 | F6: 0 | G6: 0 | H6: 0.053101897 | I6: 0.022701699 | J6: 0 | K6: 0 | L6: 0.059012541 | M6: =CG6*H6 -> 0 | N6: =CF6*H6 -> 0.059012541 | O6: 99124.32 | P6: 54251.998 | Q6: 1.6761598 | R6: 0.2020556 | T6: 73.71884 | U6: -6.199254 | V6: 65.59151 | W6: 31.821489 | X6: 37.986239 | Y6: 420 | Z6: 21.986353 | AA6: 51.417555 | AC6: 22.465142 | AD6: 13.285634 | AF6: -129.68145 | AG6: -129.68145 | AL6: 15.046749 | AM6: 0 | AN6: 822.26752 | AO6: 822.26752 | AQ6: =B6 -> CEN_TSC | AR6: =C6 -> Ethane | AS6: =SUM(AY6:BG6)+BI6+BJ6 -> 900.31737 | AT6: =SUM(AY6:BG6)+BL6+BM6 -> 900.31737 | AU6: =AS6-AT6 -> 0 | AV6: =SUM(AY6:BG6)+BO6+BP6 -> 1132.0286 | AW6: =SUM(AY6:BG6)+BR6+BS6 -> 1132.0286 | AX6: =AV6-AW6 -> 0 | AY6: =E6/H6*AD6 -> 0 | AZ6: =F6/H6*AD6*-1 -> 0 | BA6: =G6/H6*AC6 -> 0 | BB6: =1/H6*Z6 -> 414.04082 | BC6: =I6/H6*AL6 -> 6.4326659 | BD6: =J6/H6*AL6*-1 -> 0 | BE6: =O6/H6/(0.9*8760) -> 236.76831 | BF6: =P6/H6/(0.9*8760) -> 129.5863 | BG6: =Q6/H6 -> 31.564969 | BH6: =CE6+CF6+CG6 -> 1.1113076 | BI6: =(T6+U6)*-1*M6/H6 -> 0 | BJ6: =BH6*T6 -> 81.924305 | BK6: =CE6+CF6 -> 1.1113076 | BL6: =U6*M6*-1/H6 -> 0 | BM6: =BK6*T6 -> 81.924305 | BN6: =SUM(CD6:CH6) -> 4.2544827 | BO6: =(T6+U6)*-1*M6/H6 -> 0 | BP6: =BN6*T6 -> 313.63553 | BQ6: =CD6+CE6+CF6+CH6 -> 4.2544827 | BR6: =M6/H6*U6*-1 -> 0 | BS6: =T6*BQ6 -> 313.63553 | BU6: 3.14 | BV6: 0.221811 | BW6: 0.18104824 | BX6: 0.015714286 | BZ6: =1/H6*BV6 -> 4.1770824 | CA6: =I6/H6*BW6 -> 0.077400297 | CB6: =BZ6+CA6 -> 4.2544827 | CD6: =BU6 -> 3.14 | CE6: =J6/H6*BW6 -> 0 | CF6: =(CB6-CD6-CE6-CH6)*(1-D6) -> 1.1113076 | CG6: =(CB6-CD6-CE6-CH6)*D6 -> 0 | CH6: =BX6*R6 -> 0.0031751595 | CI6: =SUM(CD6:CH6) -> 4.2544827 | CK6: =CI6-CB6 -> 0
B7: SE_TSC | C7: Ethane | D7: 0 | E7: 0 | F7: 0 | G7: 0 | H7: 0.053101897 | I7: 0.022701699 | J7: 0 | K7: 0 | L7: 0.059012541 | M7: =CG7*H7 -> 0 | N7: =CF7*H7 -> 0.059012541 | O7: 99124.32 | P7: 54251.998 | Q7: 1.6761598 | R7: 0.2020556 | T7: 73.71884 | U7: -6.091002 | V7: 59.252833 | W7: 23.691089 | X7: 31.789762 | Y7: 420 | Z7: 21.986353 | AA7: -8.00727 | AC7: 21.266241 | AD7: 7.267779 | AF7: -128.07763 | AG7: -128.07763 | AL7: 7.96358 | AM7: 0 | AN7: 822.26752 | AO7: 822.26752 | AQ7: =B7 -> SE_TSC | AR7: =C7 -> Ethane | AS7: =SUM(AY7:BG7)+BI7+BJ7 -> 897.28923 | AT7: =SUM(AY7:BG7)+BL7+BM7 -> 897.28923 | AU7: =AS7-AT7 -> 0 | AV7: =SUM(AY7:BG7)+BO7+BP7 -> 1129.0005 | AW7: =SUM(AY7:BG7)+BR7+BS7 -> 1129.0005 | AX7: =AV7-AW7 -> 0 | AY7: =E7/H7*AD7 -> 0 | AZ7: =F7/H7*AD7*-1 -> 0 | BA7: =G7/H7*AC7 -> 0 | BB7: =1/H7*Z7 -> 414.04082 | BC7: =I7/H7*AL7 -> 3.4045261 | BD7: =J7/H7*AL7*-1 -> 0 | BE7: =O7/H7/(0.9*8760) -> 236.76831 | BF7: =P7/H7/(0.9*8760) -> 129.5863 | BG7: =Q7/H7 -> 31.564969 | BH7: =CE7+CF7+CG7 -> 1.1113076 | BI7: =(T7+U7)*-1*M7/H7 -> 0 | BJ7: =BH7*T7 -> 81.924305 | BK7: =CE7+CF7 -> 1.1113076 | BL7: =U7*M7*-1/H7 -> 0 | BM7: =BK7*T7 -> 81.924305 | BN7: =SUM(CD7:CH7) -> 4.2544827 | BO7: =(T7+U7)*-1*M7/H7 -> 0 | BP7: =BN7*T7 -> 313.63553 | BQ7: =CD7+CE7+CF7+CH7 -> 4.2544827 | BR7: =M7/H7*U7*-1 -> 0 | BS7: =T7*BQ7 -> 313.63553 | BU7: 3.14 | BV7: 0.221811 | BW7: 0.18104824 | BX7: 0.015714286 | BZ7: =1/H7*BV7 -> 4.1770824 | CA7: =I7/H7*BW7 -> 0.077400297 | CB7: =BZ7+CA7 -> 4.2544827 | CD7: =BU7 -> 3.14 | CE7: =J7/H7*BW7 -> 0 | CF7: =(CB7-CD7-CE7-CH7)*(1-D7) -> 1.1113076 | CG7: =(CB7-CD7-CE7-CH7)*D7 -> 0 | CH7: =BX7*R7 -> 0.0031751595 | CI7: =SUM(CD7:CH7) -> 4.2544827 | CK7: =CI7-CB7 -> 0
B8: MIDAT_TSC | C8: Ethane | D8: 0 | E8: 0 | F8: 0 | G8: 0 | H8: 0.053101897 | I8: 0.022701699 | J8: 0 | K8: 0 | L8: 0.059012541 | M8: =CG8*H8 -> 0 | N8: =CF8*H8 -> 0.059012541 | O8: 99124.32 | P8: 54251.998 | Q8: 1.6761598 | R8: 0.2020556 | T8: 73.71884 | U8: -16.179128 | V8: 58.461202 | W8: 19.647223 | X8: 40.820307 | Y8: 420 | Z8: 21.986353 | AA8: -2.203044 | AC8: 21.500722 | AD8: 7.532437 | AF8: -140.74133 | AG8: -140.74133 | AL8: 5.407672 | AM8: 0 | AN8: 822.26752 | AO8: 822.26752 | AQ8: =B8 -> MIDAT_TSC | AR8: =C8 -> Ethane | AS8: =SUM(AY8:BG8)+BI8+BJ8 -> 896.19655 | AT8: =SUM(AY8:BG8)+BL8+BM8 -> 896.19655 | AU8: =AS8-AT8 -> 0 | AV8: =SUM(AY8:BG8)+BO8+BP8 -> 1127.9078 | AW8: =SUM(AY8:BG8)+BR8+BS8 -> 1127.9078 | AX8: =AV8-AW8 -> 0 | AY8: =E8/H8*AD8 -> 0 | AZ8: =F8/H8*AD8*-1 -> 0 | BA8: =G8/H8*AC8 -> 0 | BB8: =1/H8*Z8 -> 414.04082 | BC8: =I8/H8*AL8 -> 2.3118447 | BD8: =J8/H8*AL8*-1 -> 0 | BE8: =O8/H8/(0.9*8760) -> 236.76831 | BF8: =P8/H8/(0.9*8760) -> 129.5863 | BG8: =Q8/H8 -> 31.564969 | BH8: =CE8+CF8+CG8 -> 1.1113076 | BI8: =(T8+U8)*-1*M8/H8 -> 0 | BJ8: =BH8*T8 -> 81.924305 | BK8: =CE8+CF8 -> 1.1113076 | BL8: =U8*M8*-1/H8 -> 0 | BM8: =BK8*T8 -> 81.924305 | BN8: =SUM(CD8:CH8) -> 4.2544827 | BO8: =(T8+U8)*-1*M8/H8 -> 0 | BP8: =BN8*T8 -> 313.63553 | BQ8: =CD8+CE8+CF8+CH8 -> 4.2544827 | BR8: =M8/H8*U8*-1 -> 0 | BS8: =T8*BQ8 -> 313.63553 | BU8: 3.14 | BV8: 0.221811 | BW8: 0.18104824 | BX8: 0.015714286 | BZ8: =1/H8*BV8 -> 4.1770824 | CA8: =I8/H8*BW8 -> 0.077400297 | CB8: =BZ8+CA8 -> 4.2544827 | CD8: =BU8 -> 3.14 | CE8: =J8/H8*BW8 -> 0 | CF8: =(CB8-CD8-CE8-CH8)*(1-D8) -> 1.1113076 | CG8: =(CB8-CD8-CE8-CH8)*D8 -> 0 | CH8: =BX8*R8 -> 0.0031751595 | CI8: =SUM(CD8:CH8) -> 4.2544827 | CK8: =CI8-CB8 -> 0
B9: NE_TSC | C9: Ethane | D9: 0 | E9: 0 | F9: 0 | G9: 0 | H9: 0.053101897 | I9: 0.022701699 | J9: 0 | K9: 0 | L9: 0.059012541 | M9: =CG9*H9 -> 0 | N9: =CF9*H9 -> 0.059012541 | O9: 99124.32 | P9: 54251.998 | Q9: 1.6761598 | R9: 0.2020556 | T9: 73.71884 | U9: -23.276809 | V9: 60.47681 | W9: 28.904358 | X9: 39.957475 | Y9: 420 | Z9: 21.986353 | AA9: -2.703157 | AC9: 20.789991 | AD9: 9.19598 | AF9: -150.75579 | AG9: -150.75579 | AL9: 8.960454 | AM9: 0 | AN9: 822.26752 | AO9: 0 | AQ9: =B9 -> NE_TSC | AR9: =C9 -> Ethane | AS9: =SUM(AY9:BG9)+BI9+BJ9 -> 897.7154 | AT9: =SUM(AY9:BG9)+BL9+BM9 -> 897.7154 | AU9: =AS9-AT9 -> 0 | AV9: =SUM(AY9:BG9)+BO9+BP9 -> 1129.4266 | AW9: =SUM(AY9:BG9)+BR9+BS9 -> 1129.4266 | AX9: =AV9-AW9 -> 0 | AY9: =E9/H9*AD9 -> 0 | AZ9: =F9/H9*AD9*-1 -> 0 | BA9: =G9/H9*AC9 -> 0 | BB9: =1/H9*Z9 -> 414.04082 | BC9: =I9/H9*AL9 -> 3.8307017 | BD9: =J9/H9*AL9*-1 -> 0 | BE9: =O9/H9/(0.9*8760) -> 236.76831 | BF9: =P9/H9/(0.9*8760) -> 129.5863 | BG9: =Q9/H9 -> 31.564969 | BH9: =CE9+CF9+CG9 -> 1.1113076 | BI9: =(T9+U9)*-1*M9/H9 -> 0 | BJ9: =BH9*T9 -> 81.924305 | BK9: =CE9+CF9 -> 1.1113076 | BL9: =U9*M9*-1/H9 -> 0 | BM9: =BK9*T9 -> 81.924305 | BN9: =SUM(CD9:CH9) -> 4.2544827 | BO9: =(T9+U9)*-1*M9/H9 -> 0 | BP9: =BN9*T9 -> 313.63553 | BQ9: =CD9+CE9+CF9+CH9 -> 4.2544827 | BR9: =M9/H9*U9*-1 -> 0 | BS9: =T9*BQ9 -> 313.63553 | BU9: 3.14 | BV9: 0.221811 | BW9: 0.18104824 | BX9: 0.015714286 | BZ9: =1/H9*BV9 -> 4.1770824 | CA9: =I9/H9*BW9 -> 0.077400297 | CB9: =BZ9+CA9 -> 4.2544827 | CD9: =BU9 -> 3.14 | CE9: =J9/H9*BW9 -> 0 | CF9: =(CB9-CD9-CE9-CH9)*(1-D9) -> 1.1113076 | CG9: =(CB9-CD9-CE9-CH9)*D9 -> 0 | CH9: =BX9*R9 -> 0.0031751595 | CI9: =SUM(CD9:CH9) -> 4.2544827 | CK9: =CI9-CB9 -> 0
B10: SW_TSC+CC90 | C10: Ethane | D10: 0.9 | E10: 0 | F10: 0 | G10: 0.0080529664 | H10: 0.053101897 | I10: 0.022701699 | J10: 0 | K10: 0.053111287 | L10: 0.005901254 | M10: =CG10*H10 -> 0.053111287 | N10: =CF10*H10 -> 0.0059012541 | O10: 106875.17 | P10: 58496.387 | Q10: 1.8072241 | R10: 0.2020556 | T10: 73.71884 | U10: -4.302149 | V10: 61.152787 | W10: 40.832246 | X10: 41.356795 | Y10: 420 | Z10: 21.986353 | AA10: -1.819211 | AC10: 21.021514 | AD10: 9.044068 | AF10: -126.2252 | AG10: -126.2252 | AL10: 10.321106 | AM10: 0 | AN10: 822.26752 | AO10: 0 | AQ10: =B10 -> SW_TSC+CC90 | AR10: =C10 -> Ethane | AS10: =SUM(AY10:BG10)+BI10+BJ10 -> 863.17606 | AT10: =SUM(AY10:BG10)+BL10+BM10 -> 863.17606 | AU10: =AS10-AT10 -> 0 | AV10: =SUM(AY10:BG10)+BO10+BP10 -> 1094.8873 | AW10: =SUM(AY10:BG10)+BR10+BS10 -> 1094.8873 | AX10: =AV10-AW10 -> 0 | AY10: =E10/H10*AD10 -> 0 | AZ10: =F10/H10*AD10*-1 -> 0 | BA10: =G10/H10*AC10 -> 3.1879378 | BB10: =1/H10*Z10 -> 414.04082 | BC10: =I10/H10*AL10 -> 4.4123968 | BD10: =J10/H10*AL10*-1 -> 0 | BE10: =O10/H10/(0.9*8760) -> 255.28198 | BF10: =P10/H10/(0.9*8760) -> 139.72444 | BG10: =Q10/H10 -> 34.033136 | BH10: =CE10+CF10+CG10 -> 1.1113076 | BI10: =(T10+U10)*-1*M10/H10 -> -69.428965 | BJ10: =BH10*T10 -> 81.924305 | BK10: =CE10+CF10 -> 0.11113076 | BL10: =U10*M10*-1/H10 -> 4.3029097 | BM10: =BK10*T10 -> 8.1924305 | BN10: =SUM(CD10:CH10) -> 4.2544827 | BO10: =(T10+U10)*-1*M10/H10 -> -69.428965 | BP10: =BN10*T10 -> 313.63553 | BQ10: =CD10+CE10+CF10+CH10 -> 3.2543059 | BR10: =M10/H10*U10*-1 -> 4.3029097 | BS10: =T10*BQ10 -> 239.90366 | BU10: 3.14 | BV10: 0.221811 | BW10: 0.18104824 | BX10: 0.015714286 | BZ10: =1/H10*BV10 -> 4.1770824 | CA10: =I10/H10*BW10 -> 0.077400297 | CB10: =BZ10+CA10 -> 4.2544827 | CD10: =BU10 -> 3.14 | CE10: =J10/H10*BW10 -> 0 | CF10: =(CB10-CD10-CE10-CH10)*(1-D10) -> 0.11113076 | CG10: =(CB10-CD10-CE10-CH10)*D10 -> 1.0001768 | CH10: =BX10*R10 -> 0.0031751595 | CI10: =SUM(CD10:CH10) -> 4.2544827 | CK10: =CI10-CB10 -> 0
B11: SW_TSC:H2 | C11: Ethane | D11: 0 | E11: 0 | F11: 0.15985314 | G11: 0 | H11: 0.053101897 | I11: 0.13183229 | J11: 0 | K11: 0 | L11: 0.078770441 | M11: =CG11*H11 -> 0 | N11: =CF11*H11 -> 0.078770441 | O11: 99124.32 | P11: 54251.998 | Q11: 1.6761598 | R11: 0.2020556 | T11: 73.71884 | U11: -4.302149 | V11: 61.152787 | W11: 40.832246 | X11: 41.356795 | Y11: 420 | Z11: 21.986353 | AA11: -1.819211 | AC11: 21.021514 | AD11: 9.044068 | AF11: -126.2252 | AG11: -126.2252 | AL11: 10.321106 | AM11: 0 | AN11: 822.26752 | AO11: 0 | AQ11: =B11 -> SW_TSC:H2 | AR11: =C11 -> Ethane | AS11: =SUM(AY11:BG11)+BI11+BJ11 -> 919.71169 | AT11: =SUM(AY11:BG11)+BL11+BM11 -> 919.71169 | AU11: =AS11-AT11 -> 0 | AV11: =SUM(AY11:BG11)+BO11+BP11 -> 1151.4229 | AW11: =SUM(AY11:BG11)+BR11+BS11 -> 1151.4229 | AX11: =AV11-AW11 -> 0 | AY11: =E11/H11*AD11 -> 0 | AZ11: =F11/H11*AD11*-1 -> -27.225443 | BA11: =G11/H11*AC11 -> 0 | BB11: =1/H11*Z11 -> 414.04082 | BC11: =I11/H11*AL11 -> 25.623472 | BD11: =J11/H11*AL11*-1 -> 0 | BE11: =O11/H11/(0.9*8760) -> 236.76831 | BF11: =P11/H11/(0.9*8760) -> 129.5863 | BG11: =Q11/H11 -> 31.564969 | BH11: =CE11+CF11+CG11 -> 1.4833828 | BI11: =(T11+U11)*-1*M11/H11 -> 0 | BJ11: =BH11*T11 -> 109.35326 | BK11: =CE11+CF11 -> 1.4833828 | BL11: =U11*M11*-1/H11 -> 0 | BM11: =BK11*T11 -> 109.35326 | BN11: =SUM(CD11:CH11) -> 4.626558 | BO11: =(T11+U11)*-1*M11/H11 -> 0 | BP11: =BN11*T11 -> 341.06449 | BQ11: =CD11+CE11+CF11+CH11 -> 4.626558 | BR11: =M11/H11*U11*-1 -> 0 | BS11: =T11*BQ11 -> 341.06449 | BU11: 3.14 | BV11: 0.221811 | BW11: 0.18104824 | BX11: 0.015714286 | BZ11: =1/H11*BV11 -> 4.1770824 | CA11: =I11/H11*BW11 -> 0.44947553 | CB11: =BZ11+CA11 -> 4.626558 | CD11: =BU11 -> 3.14 | CE11: =J11/H11*BW11 -> 0 | CF11: =(CB11-CD11-CE11-CH11)*(1-D11) -> 1.4833828 | CG11: =(CB11-CD11-CE11-CH11)*D11 -> 0 | CH11: =BX11*R11 -> 0.0031751595 | CI11: =SUM(CD11:CH11) -> 4.626558 | CK11: =CI11-CB11 -> 0
B12: SW_TSC+CC90:H2 | C12: Ethane | D12: 0.9 | E12: 0 | F12: 0.15985314 | G12: 0.0093887367 | H12: 0.053101897 | I12: 0.13183229 | J12: 0 | K12: 0.070893397 | L12: 0.007877044 | M12: =CG12*H12 -> 0.070893397 | N12: =CF12*H12 -> 0.0078770441 | O12: 106900.97 | P12: 58510.186 | Q12: 1.8076604 | R12: 0.2020556 | T12: 73.71884 | U12: -4.302149 | V12: 61.152787 | W12: 40.832246 | X12: 41.356795 | Y12: 420 | Z12: 21.986353 | AA12: -1.819211 | AC12: 21.021514 | AD12: 9.044068 | AF12: -126.2252 | AG12: -126.2252 | AL12: 10.321106 | AM12: 0 | AN12: 822.26752 | AO12: 0 | AQ12: =B12 -> SW_TSC+CC90:H2 | AR12: =C12 -> Ethane | AS12: =SUM(AY12:BG12)+BI12+BJ12 -> 861.97685 | AT12: =SUM(AY12:BG12)+BL12+BM12 -> 861.97685 | AU12: =AS12-AT12 -> 0 | AV12: =SUM(AY12:BG12)+BO12+BP12 -> 1093.6881 | AW12: =SUM(AY12:BG12)+BR12+BS12 -> 1093.6881 | AX12: =AV12-AW12 -> 0 | AY12: =E12/H12*AD12 -> 0 | AZ12: =F12/H12*AD12*-1 -> -27.225443 | BA12: =G12/H12*AC12 -> 3.7167309 | BB12: =1/H12*Z12 -> 414.04082 | BC12: =I12/H12*AL12 -> 25.623472 | BD12: =J12/H12*AL12*-1 -> 0 | BE12: =O12/H12/(0.9*8760) -> 255.34362 | BF12: =P12/H12/(0.9*8760) -> 139.7574 | BG12: =Q12/H12 -> 34.041353 | BH12: =CE12+CF12+CG12 -> 1.4833828 | BI12: =(T12+U12)*-1*M12/H12 -> -92.674373 | BJ12: =BH12*T12 -> 109.35326 | BK12: =CE12+CF12 -> 0.14833828 | BL12: =U12*M12*-1/H12 -> 5.7435605 | BM12: =BK12*T12 -> 10.935326 | BN12: =SUM(CD12:CH12) -> 4.626558 | BO12: =(T12+U12)*-1*M12/H12 -> -92.674373 | BP12: =BN12*T12 -> 341.06449 | BQ12: =CD12+CE12+CF12+CH12 -> 3.2915134 | BR12: =M12/H12*U12*-1 -> 5.7435605 | BS12: =T12*BQ12 -> 242.64655 | BU12: 3.14 | BV12: 0.221811 | BW12: 0.18104824 | BX12: 0.015714286 | BZ12: =1/H12*BV12 -> 4.1770824 | CA12: =I12/H12*BW12 -> 0.44947553 | CB12: =BZ12+CA12 -> 4.626558 | CD12: =BU12 -> 3.14 | CE12: =J12/H12*BW12 -> 0 | CF12: =(CB12-CD12-CE12-CH12)*(1-D12) -> 0.14833828 | CG12: =(CB12-CD12-CE12-CH12)*D12 -> 1.3350445 | CH12: =BX12*R12 -> 0.0031751595 | CI12: =SUM(CD12:CH12) -> 4.626558 | CK12: =CI12-CB12 -> 0
B13: SW_TSC+H2in | C13: Ethane | D13: 0 | E13: 0.022266442 | F13: 0 | G13: 0 | H13: 0.053101897 | I13: 0 | J13: 0 | K13: 0 | L13: 0.054902438 | M13: =CG13*H13 -> 0 | N13: =CF13*H13 -> 0.054902438 | O13: 99124.32 | P13: 54251.998 | Q13: 1.6761598 | R13: 0.2020556 | T13: 73.71884 | U13: -4.302149 | V13: 61.152787 | W13: 40.832246 | X13: 41.356795 | Y13: 420 | Z13: 21.986353 | AA13: -1.819211 | AC13: 21.021514 | AD13: 9.044068 | AF13: -126.2252 | AG13: -126.2252 | AL13: 10.321106 | AM13: 0 | AN13: 822.26752 | AO13: 0 | AQ13: =B13 -> SW_TSC+H2in | AR13: =C13 -> Ethane | AS13: =SUM(AY13:BG13)+BI13+BJ13 -> 891.97116 | AT13: =SUM(AY13:BG13)+BL13+BM13 -> 891.97116 | AU13: =AS13-AT13 -> 0 | AV13: =SUM(AY13:BG13)+BO13+BP13 -> 1123.6824 | AW13: =SUM(AY13:BG13)+BR13+BS13 -> 1123.6824 | AX13: =AV13-AW13 -> 0 | AY13: =E13/H13*AD13 -> 3.7923167 | AZ13: =F13/H13*AD13*-1 -> 0 | BA13: =G13/H13*AC13 -> 0 | BB13: =1/H13*Z13 -> 414.04082 | BC13: =I13/H13*AL13 -> 0 | BD13: =J13/H13*AL13*-1 -> 0 | BE13: =O13/H13/(0.9*8760) -> 236.76831 | BF13: =P13/H13/(0.9*8760) -> 129.5863 | BG13: =Q13/H13 -> 31.564969 | BH13: =CE13+CF13+CG13 -> 1.0339073 | BI13: =(T13+U13)*-1*M13/H13 -> 0 | BJ13: =BH13*T13 -> 76.218445 | BK13: =CE13+CF13 -> 1.0339073 | BL13: =U13*M13*-1/H13 -> 0 | BM13: =BK13*T13 -> 76.218445 | BN13: =SUM(CD13:CH13) -> 4.1770824 | BO13: =(T13+U13)*-1*M13/H13 -> 0 | BP13: =BN13*T13 -> 307.92967 | BQ13: =CD13+CE13+CF13+CH13 -> 4.1770824 | BR13: =M13/H13*U13*-1 -> 0 | BS13: =T13*BQ13 -> 307.92967 | BU13: 3.14 | BV13: 0.221811 | BW13: 0.18104824 | BX13: 0.015714286 | BZ13: =1/H13*BV13 -> 4.1770824 | CA13: =I13/H13*BW13 -> 0 | CB13: =BZ13+CA13 -> 4.1770824 | CD13: =BU13 -> 3.14 | CE13: =J13/H13*BW13 -> 0 | CF13: =(CB13-CD13-CE13-CH13)*(1-D13) -> 1.0339073 | CG13: =(CB13-CD13-CE13-CH13)*D13 -> 0 | CH13: =BX13*R13 -> 0.0031751595 | CI13: =SUM(CD13:CH13) -> 4.1770824 | CK13: =CI13-CB13 -> 0
B14: SW_TSC+H2in:CH4 | C14: Ethane | D14: 0 | E14: 0.1375867 | F14: 0 | G14: 0 | H14: 0.053101897 | I14: 0 | J14: 0.1181425 | K14: 0 | L14: 0.033512947 | M14: =CG14*H14 -> 0 | N14: =CF14*H14 -> 0.033512947 | O14: 99124.32 | P14: 54251.998 | Q14: 1.6761598 | R14: 0.2020556 | T14: 73.71884 | U14: -4.302149 | V14: 61.152787 | W14: 40.832246 | X14: 41.356795 | Y14: 420 | Z14: 21.986353 | AA14: -1.819211 | AC14: 21.021514 | AD14: 9.044068 | AF14: -126.2252 | AG14: -126.2252 | AL14: 10.321106 | AM14: 0 | AN14: 822.26752 | AO14: 0 | AQ14: =B14 -> SW_TSC+H2in:CH4 | AR14: =C14 -> Ethane | AS14: =SUM(AY14:BG14)+BI14+BJ14 -> 888.6493 | AT14: =SUM(AY14:BG14)+BL14+BM14 -> 888.6493 | AU14: =AS14-AT14 -> 0 | AV14: =SUM(AY14:BG14)+BO14+BP14 -> 1120.3605 | AW14: =SUM(AY14:BG14)+BR14+BS14 -> 1120.3605 | AX14: =AV14-AW14 -> 0 | AY14: =E14/H14*AD14 -> 23.433127 | AZ14: =F14/H14*AD14*-1 -> 0 | BA14: =G14/H14*AC14 -> 0 | BB14: =1/H14*Z14 -> 414.04082 | BC14: =I14/H14*AL14 -> 0 | BD14: =J14/H14*AL14*-1 -> -22.962668 | BE14: =O14/H14/(0.9*8760) -> 236.76831 | BF14: =P14/H14/(0.9*8760) -> 129.5863 | BG14: =Q14/H14 -> 31.564969 | BH14: =CE14+CF14+CG14 -> 1.0339073 | BI14: =(T14+U14)*-1*M14/H14 -> 0 | BJ14: =BH14*T14 -> 76.218445 | BK14: =CE14+CF14 -> 1.0339073 | BL14: =U14*M14*-1/H14 -> 0 | BM14: =BK14*T14 -> 76.218445 | BN14: =SUM(CD14:CH14) -> 4.1770824 | BO14: =(T14+U14)*-1*M14/H14 -> 0 | BP14: =BN14*T14 -> 307.92967 | BQ14: =CD14+CE14+CF14+CH14 -> 4.1770824 | BR14: =M14/H14*U14*-1 -> 0 | BS14: =T14*BQ14 -> 307.92967 | BU14: 3.14 | BV14: 0.221811 | BW14: 0.18104824 | BX14: 0.015714286 | BZ14: =1/H14*BV14 -> 4.1770824 | CA14: =I14/H14*BW14 -> 0 | CB14: =BZ14+CA14 -> 4.1770824 | CD14: =BU14 -> 3.14 | CE14: =J14/H14*BW14 -> 0.40280088 | CF14: =(CB14-CD14-CE14-CH14)*(1-D14) -> 0.6311064 | CG14: =(CB14-CD14-CE14-CH14)*D14 -> 0 | CH14: =BX14*R14 -> 0.0031751595 | CI14: =SUM(CD14:CH14) -> 4.1770824 | CK14: =CI14-CB14 -> 0
... B51: NE_ESC | C51: Ethane | D51: 0 | E51: 0 | F51: 0.15985314 | G51: 0.19138279 | H51: 0.053101897 | I51: 0 | J51: 0.1181425 | K51: 0 | L51: 0.033512947 | M51: =CG51*H51 -> 0 | N51: =CF51*H51 -> 0.033512947 | O51: 131324.11 | P51: 71875.354 | Q51: 2.2206477 | R51: 0.2020556 | T51: 73.71884 | U51: -23.276809 | V51: 60.47681 | W51: 28.904358 | X51: 39.957475 | Y51: 420 | Z51: 21.986353 | AA51: -2.703157 | AC51: 20.789991 | AD51: 9.19598 | AF51: -150.75579 | AG51: -150.75579 | AL51: 8.960454 | AM51: 0 | AN51: 822.26752 | AO51: 0 | AQ51: =B51 -> NE_ESC | AR51: =C51 -> Ethane | AS51: =SUM(AY51:BG51)+BI51+BJ51 -> 1044.7504 | AT51: =SUM(AY51:BG51)+BL51+BM51 -> 1044.7504 | AU51: =AS51-AT51 -> 0 | AV51: =SUM(AY51:BG51)+BO51+BP51 -> 1276.4616 | AW51: =SUM(AY51:BG51)+BR51+BS51 -> 1276.4616 | AX51: =AV51-AW51 -> 0 | AY51: =E51/H51*AD51 -> 0 | AZ51: =F51/H51*AD51*-1 -> -27.682746 | BA51: =G51/H51*AC51 -> 74.92852 | BB51: =1/H51*Z51 -> 414.04082 | BC51: =I51/H51*AL51 -> 0 | BD51: =J51/H51*AL51*-1 -> -19.935454 | BE51: =O51/H51/(0.9*8760) -> 313.68072 | BF51: =P51/H51/(0.9*8760) -> 171.68144 | BG51: =Q51/H51 -> 41.818614 | BH51: =CE51+CF51+CG51 -> 1.0339073 | BI51: =(T51+U51)*-1*M51/H51 -> 0 | BJ51: =BH51*T51 -> 76.218445 | BK51: =CE51+CF51 -> 1.0339073 | BL51: =U51*M51*-1/H51 -> 0 | BM51: =BK51*T51 -> 76.218445 | BN51: =SUM(CD51:CH51) -> 4.1770824 | BO51: =(T51+U51)*-1*M51/H51 -> 0 | BP51: =BN51*T51 -> 307.92967 | BQ51: =CD51+CE51+CF51+CH51 -> 4.1770824 | BR51: =M51/H51*U51*-1 -> 0 | BS51: =T51*BQ51 -> 307.92967 | BU51: 3.14 | BV51: 0.221811 | BW51: 0.18104824 | BX51: 0.015714286 | BZ51: =1/H51*BV51 -> 4.1770824 | CA51: =I51/H51*BW51 -> 0 | CB51: =BZ51+CA51 -> 4.1770824 | CD51: =BU51 -> 3.14 | CE51: =J51/H51*BW51 -> 0.40280088 | CF51: =(CB51-CD51-CE51-CH51)*(1-D51) -> 0.6311064 | CG51: =(CB51-CD51-CE51-CH51)*D51 -> 0 | CH51: =BX51*R51 -> 0.0031751595 | CI51: =SUM(CD51:CH51) -> 4.1770824 | CK51: =CI51-CB51 -> 0
M52: =CG52*H52 -> #DIV/0! | N52: =CF52*H52 -> #DIV/0! | R52: 0.2020556 | Y52: 420 | Z52: 21.986353 | AQ52: =B52 -> 0 | AR52: =C52 -> 0 | AS52: =SUM(AY52:BG52)+BI52+BJ52 -> #DIV/0! | AT52: =SUM(AY52:BG52)+BL52+BM52 -> #DIV/0! | AU52: =AS52-AT52 -> #DIV/0! | AV52: =SUM(AY52:BG52)+BO52+BP52 -> #DIV/0! | AW52: =SUM(AY52:BG52)+BR52+BS52 -> #DIV/0! | AX52: =AV52-AW52 -> #DIV/0! | AY52: =E52/H52*AD52 -> #DIV/0! | AZ52: =F52/H52*AD52*-1 -> #DIV/0! | BA52: =G52/H52*AC52 -> #DIV/0! | BB52: =1/H52*Z52 -> #DIV/0! | BC52: =I52/H52*AL52 -> #DIV/0! | BD52: =J52/H52*AL52*-1 -> #DIV/0! | BE52: =O52/H52/(0.9*8760) -> #DIV/0! | BF52: =P52/H52/(0.9*8760) -> #DIV/0! | BG52: =Q52/H52 -> #DIV/0! | BH52: =CE52+CF52+CG52 -> #DIV/0! | BI52: =(T52+U52)*-1*M52/H52 -> #DIV/0! | BJ52: =BH52*T52 -> #DIV/0! | BK52: =CE52+CF52 -> #DIV/0! | BL52: =U52*M52*-1/H52 -> #DIV/0! | BM52: =BK52*T52 -> #DIV/0! | BN52: =SUM(CD52:CH52) -> #DIV/0! | BO52: =(T52+U52)*-1*M52/H52 -> #DIV/0! | BP52: =BN52*T52 -> #DIV/0! | BQ52: =CD52+CE52+CF52+CH52 -> #DIV/0! | BR52: =M52/H52*U52*-1 -> #DIV/0! | BS52: =T52*BQ52 -> #DIV/0! | BU52: 3.14 | BV52: 0.221811 | BW52: 0.18104824 | BX52: 0.015714286 | BZ52: =1/H52*BV52 -> #DIV/0! | CA52: =I52/H52*BW52 -> #DIV/0! | CB52: =BZ52+CA52 -> #DIV/0! | CD52: =BU52 -> 3.14 | CE52: =J52/H52*BW52 -> #DIV/0! | CF52: =(CB52-CD52-CE52-CH52)*(1-D52) -> #DIV/0! | CG52: =(CB52-CD52-CE52-CH52)*D52 -> #DIV/0! | CH52: =BX52*R52 -> 0.0031751595 | CI52: =SUM(CD52:CH52) -> #DIV/0! | CK52: =CI52-CB52 -> #DIV/0!
M53: =CG53*H53 -> #DIV/0! | N53: =CF53*H53 -> #DIV/0! | R53: 0.2020556 | Y53: 420 | Z53: 21.986353 | AQ53: =B53 -> 0 | AR53: =C53 -> 0 | AS53: =SUM(AY53:BG53)+BI53+BJ53 -> #DIV/0! | AT53: =SUM(AY53:BG53)+BL53+BM53 -> #DIV/0! | AU53: =AS53-AT53 -> #DIV/0! | AV53: =SUM(AY53:BG53)+BO53+BP53 -> #DIV/0! | AW53: =SUM(AY53:BG53)+BR53+BS53 -> #DIV/0! | AX53: =AV53-AW53 -> #DIV/0! | AY53: =E53/H53*AD53 -> #DIV/0! | AZ53: =F53/H53*AD53*-1 -> #DIV/0! | BA53: =G53/H53*AC53 -> #DIV/0! | BB53: =1/H53*Z53 -> #DIV/0! | BC53: =I53/H53*AL53 -> #DIV/0! | BD53: =J53/H53*AL53*-1 -> #DIV/0! | BE53: =O53/H53/(0.9*8760) -> #DIV/0! | BF53: =P53/H53/(0.9*8760) -> #DIV/0! | BG53: =Q53/H53 -> #DIV/0! | BH53: =CE53+CF53+CG53 -> #DIV/0! | BI53: =(T53+U53)*-1*M53/H53 -> #DIV/0! | BJ53: =BH53*T53 -> #DIV/0! | BK53: =CE53+CF53 -> #DIV/0! | BL53: =U53*M53*-1/H53 -> #DIV/0! | BM53: =BK53*T53 -> #DIV/0! | BN53: =SUM(CD53:CH53) -> #DIV/0! | BO53: =(T53+U53)*-1*M53/H53 -> #DIV/0! | BP53: =BN53*T53 -> #DIV/0! | BQ53: =CD53+CE53+CF53+CH53 -> #DIV/0! | BR53: =M53/H53*U53*-1 -> #DIV/0! | BS53: =T53*BQ53 -> #DIV/0! | BU53: 3.14 | BV53: 0.221811 | BW53: 0.18104824 | BX53: 0.015714286 | BZ53: =1/H53*BV53 -> #DIV/0! | CA53: =I53/H53*BW53 -> #DIV/0! | CB53: =BZ53+CA53 -> #DIV/0! | CD53: =BU53 -> 3.14 | CE53: =J53/H53*BW53 -> #DIV/0! | CF53: =(CB53-CD53-CE53-CH53)*(1-D53) -> #DIV/0! | CG53: =(CB53-CD53-CE53-CH53)*D53 -> #DIV/0! | CH53: =BX53*R53 -> 0.0031751595 | CI53: =SUM(CD53:CH53) -> #DIV/0! | CK53: =CI53-CB53 -> #DIV/0!
M54: =CG54*H54 -> #DIV/0! | N54: =CF54*H54 -> #DIV/0! | R54: 0.2020556 | Y54: 420 | Z54: 21.986353 | AQ54: =B54 -> 0 | AR54: =C54 -> 0 | AS54: =SUM(AY54:BG54)+BI54+BJ54 -> #DIV/0! | AT54: =SUM(AY54:BG54)+BL54+BM54 -> #DIV/0! | AU54: =AS54-AT54 -> #DIV/0! | AV54: =SUM(AY54:BG54)+BO54+BP54 -> #DIV/0! | AW54: =SUM(AY54:BG54)+BR54+BS54 -> #DIV/0! | AX54: =AV54-AW54 -> #DIV/0! | AY54: =E54/H54*AD54 -> #DIV/0! | AZ54: =F54/H54*AD54*-1 -> #DIV/0! | BA54: =G54/H54*AC54 -> #DIV/0! | BB54: =1/H54*Z54 -> #DIV/0! | BC54: =I54/H54*AL54 -> #DIV/0! | BD54: =J54/H54*AL54*-1 -> #DIV/0! | BE54: =O54/H54/(0.9*8760) -> #DIV/0! | BF54: =P54/H54/(0.9*8760) -> #DIV/0! | BG54: =Q54/H54 -> #DIV/0! | BH54: =CE54+CF54+CG54 -> #DIV/0! | BI54: =(T54+U54)*-1*M54/H54 -> #DIV/0! | BJ54: =BH54*T54 -> #DIV/0! | BK54: =CE54+CF54 -> #DIV/0! | BL54: =U54*M54*-1/H54 -> #DIV/0! | BM54: =BK54*T54 -> #DIV/0! | BN54: =SUM(CD54:CH54) -> #DIV/0! | BO54: =(T54+U54)*-1*M54/H54 -> #DIV/0! | BP54: =BN54*T54 -> #DIV/0! | BQ54: =CD54+CE54+CF54+CH54 -> #DIV/0! | BR54: =M54/H54*U54*-1 -> #DIV/0! | BS54: =T54*BQ54 -> #DIV/0! | BU54: 3.14 | BV54: 0.221811 | BW54: 0.18104824 | BX54: 0.015714286 | BZ54: =1/H54*BV54 -> #DIV/0! | CA54: =I54/H54*BW54 -> #DIV/0! | CB54: =BZ54+CA54 -> #DIV/0! | CD54: =BU54 -> 3.14 | CE54: =J54/H54*BW54 -> #DIV/0! | CF54: =(CB54-CD54-CE54-CH54)*(1-D54) -> #DIV/0! | CG54: =(CB54-CD54-CE54-CH54)*D54 -> #DIV/0! | CH54: =BX54*R54 -> 0.0031751595 | CI54: =SUM(CD54:CH54) -> #DIV/0! | CK54: =CI54-CB54 -> #DIV/0!
M55: =CG55*H55 -> #DIV/0! | N55: =CF55*H55 -> #DIV/0! | R55: 0.2020556 | Y55: 420 | Z55: 21.986353 | AQ55: =B55 -> 0 | AR55: =C55 -> 0 | AS55: =SUM(AY55:BG55)+BI55+BJ55 -> #DIV/0! | AT55: =SUM(AY55:BG55)+BL55+BM55 -> #DIV/0! | AU55: =AS55-AT55 -> #DIV/0! | AV55: =SUM(AY55:BG55)+BO55+BP55 -> #DIV/0! | AW55: =SUM(AY55:BG55)+BR55+BS55 -> #DIV/0! | AX55: =AV55-AW55 -> #DIV/0! | AY55: =E55/H55*AD55 -> #DIV/0! | AZ55: =F55/H55*AD55*-1 -> #DIV/0! | BA55: =G55/H55*AC55 -> #DIV/0! | BB55: =1/H55*Z55 -> #DIV/0! | BC55: =I55/H55*AL55 -> #DIV/0! | BD55: =J55/H55*AL55*-1 -> #DIV/0! | BE55: =O55/H55/(0.9*8760) -> #DIV/0! | BF55: =P55/H55/(0.9*8760) -> #DIV/0! | BG55: =Q55/H55 -> #DIV/0! | BH55: =CE55+CF55+CG55 -> #DIV/0! | BI55: =(T55+U55)*-1*M55/H55 -> #DIV/0! | BJ55: =BH55*T55 -> #DIV/0! | BK55: =CE55+CF55 -> #DIV/0! | BL55: =U55*M55*-1/H55 -> #DIV/0! | BM55: =BK55*T55 -> #DIV/0! | BN55: =SUM(CD55:CH55) -> #DIV/0! | BO55: =(T55+U55)*-1*M55/H55 -> #DIV/0! | BP55: =BN55*T55 -> #DIV/0! | BQ55: =CD55+CE55+CF55+CH55 -> #DIV/0! | BR55: =M55/H55*U55*-1 -> #DIV/0! | BS55: =T55*BQ55 -> #DIV/0! | BU55: 3.14 | BV55: 0.221811 | BW55: 0.18104824 | BX55: 0.015714286 | BZ55: =1/H55*BV55 -> #DIV/0! | CA55: =I55/H55*BW55 -> #DIV/0! | CB55: =BZ55+CA55 -> #DIV/0! | CD55: =BU55 -> 3.14 | CE55: =J55/H55*BW55 -> #DIV/0! | CF55: =(CB55-CD55-CE55-CH55)*(1-D55) -> #DIV/0! | CG55: =(CB55-CD55-CE55-CH55)*D55 -> #DIV/0! | CH55: =BX55*R55 -> 0.0031751595 | CI55: =SUM(CD55:CH55) -> #DIV/0! | CK55: =CI55-CB55 -> #DIV/0!
M56: =CG56*H56 -> #DIV/0! | N56: =CF56*H56 -> #DIV/0! | R56: 0.2020556 | Y56: 420 | Z56: 21.986353 | AQ56: =B56 -> 0 | AR56: =C56 -> 0 | AS56: =SUM(AY56:BG56)+BI56+BJ56 -> #DIV/0! | AT56: =SUM(AY56:BG56)+BL56+BM56 -> #DIV/0! | AU56: =AS56-AT56 -> #DIV/0! | AV56: =SUM(AY56:BG56)+BO56+BP56 -> #DIV/0! | AW56: =SUM(AY56:BG56)+BR56+BS56 -> #DIV/0! | AX56: =AV56-AW56 -> #DIV/0! | AY56: =E56/H56*AD56 -> #DIV/0! | AZ56: =F56/H56*AD56*-1 -> #DIV/0! | BA56: =G56/H56*AC56 -> #DIV/0! | BB56: =1/H56*Z56 -> #DIV/0! | BC56: =I56/H56*AL56 -> #DIV/0! | BD56: =J56/H56*AL56*-1 -> #DIV/0! | BE56: =O56/H56/(0.9*8760) -> #DIV/0! | BF56: =P56/H56/(0.9*8760) -> #DIV/0! | BG56: =Q56/H56 -> #DIV/0! | BH56: =CE56+CF56+CG56 -> #DIV/0! | BI56: =(T56+U56)*-1*M56/H56 -> #DIV/0! | BJ56: =BH56*T56 -> #DIV/0! | BK56: =CE56+CF56 -> #DIV/0! | BL56: =U56*M56*-1/H56 -> #DIV/0! | BM56: =BK56*T56 -> #DIV/0! | BN56: =SUM(CD56:CH56) -> #DIV/0! | BO56: =(T56+U56)*-1*M56/H56 -> #DIV/0! | BP56: =BN56*T56 -> #DIV/0! | BQ56: =CD56+CE56+CF56+CH56 -> #DIV/0! | BR56: =M56/H56*U56*-1 -> #DIV/0! | BS56: =T56*BQ56 -> #DIV/0! | BU56: 3.14 | BV56: 0.221811 | BW56: 0.18104824 | BX56: 0.015714286 | BZ56: =1/H56*BV56 -> #DIV/0! | CA56: =I56/H56*BW56 -> #DIV/0! | CB56: =BZ56+CA56 -> #DIV/0! | CD56: =BU56 -> 3.14 | CE56: =J56/H56*BW56 -> #DIV/0! | CF56: =(CB56-CD56-CE56-CH56)*(1-D56) -> #DIV/0! | CG56: =(CB56-CD56-CE56-CH56)*D56 -> #DIV/0! | CH56: =BX56*R56 -> 0.0031751595 | CI56: =SUM(CD56:CH56) -> #DIV/0! | CK56: =CI56-CB56 -> #DIV/0!
M57: =CG57*H57 -> #DIV/0! | N57: =CF57*H57 -> #DIV/0! | R57: 0.2020556 | Y57: 420 | Z57: 21.986353 | AQ57: =B57 -> 0 | AR57: =C57 -> 0 | AS57: =SUM(AY57:BG57)+BI57+BJ57 -> #DIV/0! | AT57: =SUM(AY57:BG57)+BL57+BM57 -> #DIV/0! | AU57: =AS57-AT57 -> #DIV/0! | AV57: =SUM(AY57:BG57)+BO57+BP57 -> #DIV/0! | AW57: =SUM(AY57:BG57)+BR57+BS57 -> #DIV/0! | AX57: =AV57-AW57 -> #DIV/0! | AY57: =E57/H57*AD57 -> #DIV/0! | AZ57: =F57/H57*AD57*-1 -> #DIV/0! | BA57: =G57/H57*AC57 -> #DIV/0! | BB57: =1/H57*Z57 -> #DIV/0! | BC57: =I57/H57*AL57 -> #DIV/0! | BD57: =J57/H57*AL57*-1 -> #DIV/0! | BE57: =O57/H57/(0.9*8760) -> #DIV/0! | BF57: =P57/H57/(0.9*8760) -> #DIV/0! | BG57: =Q57/H57 -> #DIV/0! | BH57: =CE57+CF57+CG57 -> #DIV/0! | BI57: =(T57+U57)*-1*M57/H57 -> #DIV/0! | BJ57: =BH57*T57 -> #DIV/0! | BK57: =CE57+CF57 -> #DIV/0! | BL57: =U57*M57*-1/H57 -> #DIV/0! | BM57: =BK57*T57 -> #DIV/0! | BN57: =SUM(CD57:CH57) -> #DIV/0! | BO57: =(T57+U57)*-1*M57/H57 -> #DIV/0! | BP57: =BN57*T57 -> #DIV/0! | BQ57: =CD57+CE57+CF57+CH57 -> #DIV/0! | BR57: =M57/H57*U57*-1 -> #DIV/0! | BS57: =T57*BQ57 -> #DIV/0! | BU57: 3.14 | BV57: 0.221811 | BW57: 0.18104824 | BX57: 0.015714286 | BZ57: =1/H57*BV57 -> #DIV/0! | CA57: =I57/H57*BW57 -> #DIV/0! | CB57: =BZ57+CA57 -> #DIV/0! | CD57: =BU57 -> 3.14 | CE57: =J57/H57*BW57 -> #DIV/0! | CF57: =(CB57-CD57-CE57-CH57)*(1-D57) -> #DIV/0! | CG57: =(CB57-CD57-CE57-CH57)*D57 -> #DIV/0! | CH57: =BX57*R57 -> 0.0031751595 | CI57: =SUM(CD57:CH57) -> #DIV/0! | CK57: =CI57-CB57 -> #DIV/0!
M58: =CG58*H58 -> #DIV/0! | N58: =CF58*H58 -> #DIV/0! | R58: 0.2020556 | Y58: 420 | Z58: 21.986353 | AQ58: =B58 -> 0 | AR58: =C58 -> 0 | AS58: =SUM(AY58:BG58)+BI58+BJ58 -> #DIV/0! | AT58: =SUM(AY58:BG58)+BL58+BM58 -> #DIV/0! | AU58: =AS58-AT58 -> #DIV/0! | AV58: =SUM(AY58:BG58)+BO58+BP58 -> #DIV/0! | AW58: =SUM(AY58:BG58)+BR58+BS58 -> #DIV/0! | AX58: =AV58-AW58 -> #DIV/0! | AY58: =E58/H58*AD58 -> #DIV/0! | AZ58: =F58/H58*AD58*-1 -> #DIV/0! | BA58: =G58/H58*AC58 -> #DIV/0! | BB58: =1/H58*Z58 -> #DIV/0! | BC58: =I58/H58*AL58 -> #DIV/0! | BD58: =J58/H58*AL58*-1 -> #DIV/0! | BE58: =O58/H58/(0.9*8760) -> #DIV/0! | BF58: =P58/H58/(0.9*8760) -> #DIV/0! | BG58: =Q58/H58 -> #DIV/0! | BH58: =CE58+CF58+CG58 -> #DIV/0! | BI58: =(T58+U58)*-1*M58/H58 -> #DIV/0! | BJ58: =BH58*T58 -> #DIV/0! | BK58: =CE58+CF58 -> #DIV/0! | BL58: =U58*M58*-1/H58 -> #DIV/0! | BM58: =BK58*T58 -> #DIV/0! | BN58: =SUM(CD58:CH58) -> #DIV/0! | BO58: =(T58+U58)*-1*M58/H58 -> #DIV/0! | BP58: =BN58*T58 -> #DIV/0! | BQ58: =CD58+CE58+CF58+CH58 -> #DIV/0! | BR58: =M58/H58*U58*-1 -> #DIV/0! | BS58: =T58*BQ58 -> #DIV/0! | BU58: 3.14 | BV58: 0.221811 | BW58: 0.18104824 | BX58: 0.015714286 | BZ58: =1/H58*BV58 -> #DIV/0! | CA58: =I58/H58*BW58 -> #DIV/0! | CB58: =BZ58+CA58 -> #DIV/0! | CD58: =BU58 -> 3.14 | CE58: =J58/H58*BW58 -> #DIV/0! | CF58: =(CB58-CD58-CE58-CH58)*(1-D58) -> #DIV/0! | CG58: =(CB58-CD58-CE58-CH58)*D58 -> #DIV/0! | CH58: =BX58*R58 -> 0.0031751595 | CI58: =SUM(CD58:CH58) -> #DIV/0! | CK58: =CI58-CB58 -> #DIV/0!
M59: =CG59*H59 -> #DIV/0! | N59: =CF59*H59 -> #DIV/0! | R59: 0.2020556 | Y59: 420 | Z59: 21.986353 | AQ59: =B59 -> 0 | AR59: =C59 -> 0 | AS59: =SUM(AY59:BG59)+BI59+BJ59 -> #DIV/0! | AT59: =SUM(AY59:BG59)+BL59+BM59 -> #DIV/0! | AU59: =AS59-AT59 -> #DIV/0! | AV59: =SUM(AY59:BG59)+BO59+BP59 -> #DIV/0! | AW59: =SUM(AY59:BG59)+BR59+BS59 -> #DIV/0! | AX59: =AV59-AW59 -> #DIV/0! | AY59: =E59/H59*AD59 -> #DIV/0! | AZ59: =F59/H59*AD59*-1 -> #DIV/0! | BA59: =G59/H59*AC59 -> #DIV/0! | BB59: =1/H59*Z59 -> #DIV/0! | BC59: =I59/H59*AL59 -> #DIV/0! | BD59: =J59/H59*AL59*-1 -> #DIV/0! | BE59: =O59/H59/(0.9*8760) -> #DIV/0! | BF59: =P59/H59/(0.9*8760) -> #DIV/0! | BG59: =Q59/H59 -> #DIV/0! | BH59: =CE59+CF59+CG59 -> #DIV/0! | BI59: =(T59+U59)*-1*M59/H59 -> #DIV/0! | BJ59: =BH59*T59 -> #DIV/0! | BK59: =CE59+CF59 -> #DIV/0! | BL59: =U59*M59*-1/H59 -> #DIV/0! | BM59: =BK59*T59 -> #DIV/0! | BN59: =SUM(CD59:CH59) -> #DIV/0! | BO59: =(T59+U59)*-1*M59/H59 -> #DIV/0! | BP59: =BN59*T59 -> #DIV/0! | BQ59: =CD59+CE59+CF59+CH59 -> #DIV/0! | BR59: =M59/H59*U59*-1 -> #DIV/0! | BS59: =T59*BQ59 -> #DIV/0! | BU59: 3.14 | BV59: 0.221811 | BW59: 0.18104824 | BX59: 0.015714286 | BZ59: =1/H59*BV59 -> #DIV/0! | CA59: =I59/H59*BW59 -> #DIV/0! | CB59: =BZ59+CA59 -> #DIV/0! | CD59: =BU59 -> 3.14 | CE59: =J59/H59*BW59 -> #DIV/0! | CF59: =(CB59-CD59-CE59-CH59)*(1-D59) -> #DIV/0! | CG59: =(CB59-CD59-CE59-CH59)*D59 -> #DIV/0! | CH59: =BX59*R59 -> 0.0031751595 | CI59: =SUM(CD59:CH59) -> #DIV/0! | CK59: =CI59-CB59 -> #DIV/0!
M60: =CG60*H60 -> #DIV/0! | N60: =CF60*H60 -> #DIV/0! | R60: 0.2020556 | Y60: 420 | Z60: 21.986353 | AQ60: =B60 -> 0 | AR60: =C60 -> 0 | AS60: =SUM(AY60:BG60)+BI60+BJ60 -> #DIV/0! | AT60: =SUM(AY60:BG60)+BL60+BM60 -> #DIV/0! | AU60: =AS60-AT60 -> #DIV/0! | AV60: =SUM(AY60:BG60)+BO60+BP60 -> #DIV/0! | AW60: =SUM(AY60:BG60)+BR60+BS60 -> #DIV/0! | AX60: =AV60-AW60 -> #DIV/0! | AY60: =E60/H60*AD60 -> #DIV/0! | AZ60: =F60/H60*AD60*-1 -> #DIV/0! | BA60: =G60/H60*AC60 -> #DIV/0! | BB60: =1/H60*Z60 -> #DIV/0! | BC60: =I60/H60*AL60 -> #DIV/0! | BD60: =J60/H60*AL60*-1 -> #DIV/0! | BE60: =O60/H60/(0.9*8760) -> #DIV/0! | BF60: =P60/H60/(0.9*8760) -> #DIV/0! | BG60: =Q60/H60 -> #DIV/0! | BH60: =CE60+CF60+CG60 -> #DIV/0! | BI60: =(T60+U60)*-1*M60/H60 -> #DIV/0! | BJ60: =BH60*T60 -> #DIV/0! | BK60: =CE60+CF60 -> #DIV/0! | BL60: =U60*M60*-1/H60 -> #DIV/0! | BM60: =BK60*T60 -> #DIV/0! | BN60: =SUM(CD60:CH60) -> #DIV/0! | BO60: =(T60+U60)*-1*M60/H60 -> #DIV/0! | BP60: =BN60*T60 -> #DIV/0! | BQ60: =CD60+CE60+CF60+CH60 -> #DIV/0! | BR60: =M60/H60*U60*-1 -> #DIV/0! | BS60: =T60*BQ60 -> #DIV/0! | BU60: 3.14 | BV60: 0.221811 | BW60: 0.18104824 | BX60: 0.015714286 | BZ60: =1/H60*BV60 -> #DIV/0! | CA60: =I60/H60*BW60 -> #DIV/0! | CB60: =BZ60+CA60 -> #DIV/0! | CD60: =BU60 -> 3.14 | CE60: =J60/H60*BW60 -> #DIV/0! | CF60: =(CB60-CD60-CE60-CH60)*(1-D60) -> #DIV/0! | CG60: =(CB60-CD60-CE60-CH60)*D60 -> #DIV/0! | CH60: =BX60*R60 -> 0.0031751595 | CI60: =SUM(CD60:CH60) -> #DIV/0! | CK60: =CI60-CB60 -> #DIV/0!
M61: =CG61*H61 -> #DIV/0! | N61: =CF61*H61 -> #DIV/0! | R61: 0.2020556 | Y61: 420 | Z61: 21.986353 | AQ61: =B61 -> 0 | AR61: =C61 -> 0 | AS61: =SUM(AY61:BG61)+BI61+BJ61 -> #DIV/0! | AT61: =SUM(AY61:BG61)+BL61+BM61 -> #DIV/0! | AU61: =AS61-AT61 -> #DIV/0! | AV61: =SUM(AY61:BG61)+BO61+BP61 -> #DIV/0! | AW61: =SUM(AY61:BG61)+BR61+BS61 -> #DIV/0! | AX61: =AV61-AW61 -> #DIV/0! | AY61: =E61/H61*AD61 -> #DIV/0! | AZ61: =F61/H61*AD61*-1 -> #DIV/0! | BA61: =G61/H61*AC61 -> #DIV/0! | BB61: =1/H61*Z61 -> #DIV/0! | BC61: =I61/H61*AL61 -> #DIV/0! | BD61: =J61/H61*AL61*-1 -> #DIV/0! | BE61: =O61/H61/(0.9*8760) -> #DIV/0! | BF61: =P61/H61/(0.9*8760) -> #DIV/0! | BG61: =Q61/H61 -> #DIV/0! | BH61: =CE61+CF61+CG61 -> #DIV/0! | BI61: =(T61+U61)*-1*M61/H61 -> #DIV/0! | BJ61: =BH61*T61 -> #DIV/0! | BK61: =CE61+CF61 -> #DIV/0! | BL61: =U61*M61*-1/H61 -> #DIV/0! | BM61: =BK61*T61 -> #DIV/0! | BN61: =SUM(CD61:CH61) -> #DIV/0! | BO61: =(T61+U61)*-1*M61/H61 -> #DIV/0! | BP61: =BN61*T61 -> #DIV/0! | BQ61: =CD61+CE61+CF61+CH61 -> #DIV/0! | BR61: =M61/H61*U61*-1 -> #DIV/0! | BS61: =T61*BQ61 -> #DIV/0! | BU61: 3.14 | BV61: 0.221811 | BW61: 0.18104824 | BX61: 0.015714286 | BZ61: =1/H61*BV61 -> #DIV/0! | CA61: =I61/H61*BW61 -> #DIV/0! | CB61: =BZ61+CA61 -> #DIV/0! | CD61: =BU61 -> 3.14 | CE61: =J61/H61*BW61 -> #DIV/0! | CF61: =(CB61-CD61-CE61-CH61)*(1-D61) -> #DIV/0! | CG61: =(CB61-CD61-CE61-CH61)*D61 -> #DIV/0! | CH61: =BX61*R61 -> 0.0031751595 | CI61: =SUM(CD61:CH61) -> #DIV/0! | CK61: =CI61-CB61 -> #DIV/0!
M62: =CG62*H62 -> #DIV/0! | N62: =CF62*H62 -> #DIV/0! | R62: 0.2020556 | Y62: 420 | Z62: 21.986353 | AQ62: =B62 -> 0 | AR62: =C62 -> 0 | AS62: =SUM(AY62:BG62)+BI62+BJ62 -> #DIV/0! | AT62: =SUM(AY62:BG62)+BL62+BM62 -> #DIV/0! | AU62: =AS62-AT62 -> #DIV/0! | AV62: =SUM(AY62:BG62)+BO62+BP62 -> #DIV/0! | AW62: =SUM(AY62:BG62)+BR62+BS62 -> #DIV/0! | AX62: =AV62-AW62 -> #DIV/0! | AY62: =E62/H62*AD62 -> #DIV/0! | AZ62: =F62/H62*AD62*-1 -> #DIV/0! | BA62: =G62/H62*AC62 -> #DIV/0! | BB62: =1/H62*Z62 -> #DIV/0! | BC62: =I62/H62*AL62 -> #DIV/0! | BD62: =J62/H62*AL62*-1 -> #DIV/0! | BE62: =O62/H62/(0.9*8760) -> #DIV/0! | BF62: =P62/H62/(0.9*8760) -> #DIV/0! | BG62: =Q62/H62 -> #DIV/0! | BH62: =CE62+CF62+CG62 -> #DIV/0! | BI62: =(T62+U62)*-1*M62/H62 -> #DIV/0! | BJ62: =BH62*T62 -> #DIV/0! | BK62: =CE62+CF62 -> #DIV/0! | BL62: =U62*M62*-1/H62 -> #DIV/0! | BM62: =BK62*T62 -> #DIV/0! | BN62: =SUM(CD62:CH62) -> #DIV/0! | BO62: =(T62+U62)*-1*M62/H62 -> #DIV/0! | BP62: =BN62*T62 -> #DIV/0! | BQ62: =CD62+CE62+CF62+CH62 -> #DIV/0! | BR62: =M62/H62*U62*-1 -> #DIV/0! | BS62: =T62*BQ62 -> #DIV/0! | BU62: 3.14 | BV62: 0.221811 | BW62: 0.18104824 | BX62: 0.015714286 | BZ62: =1/H62*BV62 -> #DIV/0! | CA62: =I62/H62*BW62 -> #DIV/0! | CB62: =BZ62+CA62 -> #DIV/0! | CD62: =BU62 -> 3.14 | CE62: =J62/H62*BW62 -> #DIV/0! | CF62: =(CB62-CD62-CE62-CH62)*(1-D62) -> #DIV/0! | CG62: =(CB62-CD62-CE62-CH62)*D62 -> #DIV/0! | CH62: =BX62*R62 -> 0.0031751595 | CI62: =SUM(CD62:CH62) -> #DIV/0! | CK62: =CI62-CB62 -> #DIV/0!
M63: =CG63*H63 -> #DIV/0! | N63: =CF63*H63 -> #DIV/0! | R63: 0.2020556 | Y63: 420 | Z63: 21.986353 | AQ63: =B63 -> 0 | AR63: =C63 -> 0 | AS63: =SUM(AY63:BG63)+BI63+BJ63 -> #DIV/0! | AT63: =SUM(AY63:BG63)+BL63+BM63 -> #DIV/0! | AU63: =AS63-AT63 -> #DIV/0! | AV63: =SUM(AY63:BG63)+BO63+BP63 -> #DIV/0! | AW63: =SUM(AY63:BG63)+BR63+BS63 -> #DIV/0! | AX63: =AV63-AW63 -> #DIV/0! | AY63: =E63/H63*AD63 -> #DIV/0! | AZ63: =F63/H63*AD63*-1 -> #DIV/0! | BA63: =G63/H63*AC63 -> #DIV/0! | BB63: =1/H63*Z63 -> #DIV/0! | BC63: =I63/H63*AL63 -> #DIV/0! | BD63: =J63/H63*AL63*-1 -> #DIV/0! | BE63: =O63/H63/(0.9*8760) -> #DIV/0! | BF63: =P63/H63/(0.9*8760) -> #DIV/0! | BG63: =Q63/H63 -> #DIV/0! | BH63: =CE63+CF63+CG63 -> #DIV/0! | BI63: =(T63+U63)*-1*M63/H63 -> #DIV/0! | BJ63: =BH63*T63 -> #DIV/0! | BK63: =CE63+CF63 -> #DIV/0! | BL63: =U63*M63*-1/H63 -> #DIV/0! | BM63: =BK63*T63 -> #DIV/0! | BN63: =SUM(CD63:CH63) -> #DIV/0! | BO63: =(T63+U63)*-1*M63/H63 -> #DIV/0! | BP63: =BN63*T63 -> #DIV/0! | BQ63: =CD63+CE63+CF63+CH63 -> #DIV/0! | BR63: =M63/H63*U63*-1 -> #DIV/0! | BS63: =T63*BQ63 -> #DIV/0! | BU63: 3.14 | BV63: 0.221811 | BW63: 0.18104824 | BX63: 0.015714286 | BZ63: =1/H63*BV63 -> #DIV/0! | CA63: =I63/H63*BW63 -> #DIV/0! | CB63: =BZ63+CA63 -> #DIV/0! | CD63: =BU63 -> 3.14 | CE63: =J63/H63*BW63 -> #DIV/0! | CF63: =(CB63-CD63-CE63-CH63)*(1-D63) -> #DIV/0! | CG63: =(CB63-CD63-CE63-CH63)*D63 -> #DIV/0! | CH63: =BX63*R63 -> 0.0031751595 | CI63: =SUM(CD63:CH63) -> #DIV/0! | CK63: =CI63-CB63 -> #DIV/0!
... M65: =CG65*H65 -> #DIV/0! | N65: =CF65*H65 -> #DIV/0! | R65: 0.2020556 | Y65: 420 | Z65: 21.986353 | AQ65: =B65 -> 0 | AR65: =C65 -> 0 | AS65: =SUM(AY65:BG65)+BI65+BJ65 -> #DIV/0! | AT65: =SUM(AY65:BG65)+BL65+BM65 -> #DIV/0! | AU65: =AS65-AT65 -> #DIV/0! | AV65: =SUM(AY65:BG65)+BO65+BP65 -> #DIV/0! | AW65: =SUM(AY65:BG65)+BR65+BS65 -> #DIV/0! | AX65: =AV65-AW65 -> #DIV/0! | AY65: =E65/H65*AD65 -> #DIV/0! | AZ65: =F65/H65*AD65*-1 -> #DIV/0! | BA65: =G65/H65*AC65 -> #DIV/0! | BB65: =1/H65*Z65 -> #DIV/0! | BC65: =I65/H65*AL65 -> #DIV/0! | BD65: =J65/H65*AL65*-1 -> #DIV/0! | BE65: =O65/H65/(0.9*8760) -> #DIV/0! | BF65: =P65/H65/(0.9*8760) -> #DIV/0! | BG65: =Q65/H65 -> #DIV/0! | BH65: =CE65+CF65+CG65 -> #DIV/0! | BI65: =(T65+U65)*-1*M65/H65 -> #DIV/0! | BJ65: =BH65*T65 -> #DIV/0! | BK65: =CE65+CF65 -> #DIV/0! | BL65: =U65*M65*-1/H65 -> #DIV/0! | BM65: =BK65*T65 -> #DIV/0! | BN65: =SUM(CD65:CH65) -> #DIV/0! | BO65: =(T65+U65)*-1*M65/H65 -> #DIV/0! | BP65: =BN65*T65 -> #DIV/0! | BQ65: =CD65+CE65+CF65+CH65 -> #DIV/0! | BR65: =M65/H65*U65*-1 -> #DIV/0! | BS65: =T65*BQ65 -> #DIV/0! | BU65: 3.14 | BV65: 0.221811 | BW65: 0.18104824 | BX65: 0.015714286 | BZ65: =1/H65*BV65 -> #DIV/0! | CA65: =I65/H65*BW65 -> #DIV/0! | CB65: =BZ65+CA65 -> #DIV/0! | CD65: =BU65 -> 3.14 | CE65: =J65/H65*BW65 -> #DIV/0! | CF65: =(CB65-CD65-CE65-CH65)*(1-D65) -> #DIV/0! | CG65: =(CB65-CD65-CE65-CH65)*D65 -> #DIV/0! | CH65: =BX65*R65 -> 0.0031751595 | CI65: =SUM(CD65:CH65) -> #DIV/0! | CK65: =CI65-CB65 -> #DIV/0!

Sheet lc_summary_seq
A1: LCOE for steam/electric cracker ($/GJ-ethylene) - CHEMICALS SEQUESTRATION | R1: Assumptions | V1: LCOE for steam/electric cracker ($/GJ-ethylene) - CHEMICALS SEQUESTRATION - SORTED
A2: id_LC | B2: h2_consumption | C2: h2_production | D2: elec_consumption | E2: ethane_consumption | F2: natgas_consumption | G2: natgas_production | H2: investment_cost | I2: fixed_om_cost | J2: variable_om_cost | K2: modified capture cost | L2: modified emissions cost | M2: CI | N2: LCOE ($/t-ethylene) | O2: LCOE ($/GJ-ethylene) | P2: CHECK LCOE ($/GJ-ethylene) | R2: Ethylene LHV | S2: 45.6 | T2: GJ/t-ethylene | V2: id_LC | W2: h2_consumption | X2: h2_production | Y2: elec_consumption | Z2: ethane_consumption | AA2: natgas_consumption | AB2: natgas_production | AC2: investment_cost | AD2: fixed_om_cost | AE2: variable_om_cost | AF2: modified capture cost | AG2: modified emissions cost | AH2: CI | AI2: LCOE ($/t-ethylene) | AJ2: LCOE ($/GJ-ethylene) | AK2: CHECK LCOE ($/GJ-ethylene)
A3: =lc_detailed!AQ3 -> SW_TSC | B3: =lc_detailed!AY3/$S$2 -> 0 | C3: =lc_detailed!AZ3/$S$2 -> 0 | D3: =lc_detailed!BA3/$S$2 -> 0 | E3: =lc_detailed!BB3/$S$2 -> 9.0798426 | F3: =lc_detailed!BC3/$S$2 -> 0.096763087 | G3: =lc_detailed!BD3/$S$2 -> 0 | H3: =lc_detailed!BE3/$S$2 -> 5.1922874 | I3: =lc_detailed!BF3/$S$2 -> 2.8418048 | J3: =lc_detailed!BG3/$S$2 -> 0.69221424 | K3: =lc_detailed!BI3/$S$2 -> 0 | L3: =lc_detailed!BJ3/$S$2 -> 1.7965856 | M3: =lc_detailed!BH3 -> 1.1113076 | N3: =lc_detailed!AS3 -> 898.2971 | O3: =N3/$S$2 -> 19.699498 | P3: =SUM(B3:L3) -> 19.699498 | V3: {=_xlfn._xlws.SORT(A3:P65, 14, 1)} -> SW_TSC+CC90:H2 | W3: 0 | X3: -0.5970492 | Y3: 0.081507256 | Z3: 9.0798426 | AA3: 0.56191825 | AB3: 0 | AC3: 5.5996408 | AD3: 3.0648553 | AE3: 0.7465209 | AF3: -2.0323327 | AG3: 2.3980978 | AH3: 1.4833828 | AI3: 861.97685 | AJ3: 18.903001 | AK3: 18.903001
A4: =lc_detailed!AQ4 -> TX_TSC | B4: =lc_detailed!AY4/$S$2 -> 0 | C4: =lc_detailed!AZ4/$S$2 -> 0 | D4: =lc_detailed!BA4/$S$2 -> 0 | E4: =lc_detailed!BB4/$S$2 -> 9.0798426 | F4: =lc_detailed!BC4/$S$2 -> 0.08064339 | G4: =lc_detailed!BD4/$S$2 -> 0 | H4: =lc_detailed!BE4/$S$2 -> 5.1922874 | I4: =lc_detailed!BF4/$S$2 -> 2.8418048 | J4: =lc_detailed!BG4/$S$2 -> 0.69221424 | K4: =lc_detailed!BI4/$S$2 -> 0 | L4: =lc_detailed!BJ4/$S$2 -> 1.7965856 | M4: =lc_detailed!BH4 -> 1.1113076 | N4: =lc_detailed!AS4 -> 897.56204 | O4: =N4/$S$2 -> 19.683378 | P4: =SUM(B4:L4) -> 19.683378 | V4: SW_TSC+CC90 | W4: 0 | X4: 0 | Y4: 0.069910917 | Z4: 9.0798426 | AA4: 0.096763087 | AB4: 0 | AC4: 5.5982891 | AD4: 3.0641326 | AE4: 0.7463407 | AF4: -1.522565 | AG4: 1.7965856 | AH4: 1.1113076 | AI4: 863.17606 | AJ4: 18.9293 | AK4: 18.9293
A5: =lc_detailed!AQ5 -> NCEN_TSC | B5: =lc_detailed!AY5/$S$2 -> 0 | C5: =lc_detailed!AZ5/$S$2 -> 0 | D5: =lc_detailed!BA5/$S$2 -> 0 | E5: =lc_detailed!BB5/$S$2 -> 9.0798426 | F5: =lc_detailed!BC5/$S$2 -> 0.14019654 | G5: =lc_detailed!BD5/$S$2 -> 0 | H5: =lc_detailed!BE5/$S$2 -> 5.1922874 | I5: =lc_detailed!BF5/$S$2 -> 2.8418048 | J5: =lc_detailed!BG5/$S$2 -> 0.69221424 | K5: =lc_detailed!BI5/$S$2 -> 0 | L5: =lc_detailed!BJ5/$S$2 -> 1.7965856 | M5: =lc_detailed!BH5 -> 1.1113076 | N5: =lc_detailed!AS5 -> 900.27767 | O5: =N5/$S$2 -> 19.742931 | P5: =SUM(B5:L5) -> 19.742931 | V5: TX_TSC+CC90 | W5: 0 | X5: 0 | Y5: 0.071029222 | Z5: 9.0798426 | AA5: 0.08064339 | AB5: 0 | AC5: 5.5982891 | AD5: 3.0641326 | AE5: 0.7463407 | AF5: -1.5072567 | AG5: 1.7965856 | AH5: 1.1113076 | AI5: 863.19006 | AJ5: 18.929607 | AK5: 18.929607
A6: =lc_detailed!AQ6 -> CEN_TSC | B6: =lc_detailed!AY6/$S$2 -> 0 | C6: =lc_detailed!AZ6/$S$2 -> 0 | D6: =lc_detailed!BA6/$S$2 -> 0 | E6: =lc_detailed!BB6/$S$2 -> 9.0798426 | F6: =lc_detailed!BC6/$S$2 -> 0.14106723 | G6: =lc_detailed!BD6/$S$2 -> 0 | H6: =lc_detailed!BE6/$S$2 -> 5.1922874 | I6: =lc_detailed!BF6/$S$2 -> 2.8418048 | J6: =lc_detailed!BG6/$S$2 -> 0.69221424 | K6: =lc_detailed!BI6/$S$2 -> 0 | L6: =lc_detailed!BJ6/$S$2 -> 1.7965856 | M6: =lc_detailed!BH6 -> 1.1113076 | N6: =lc_detailed!AS6 -> 900.31737 | O6: =N6/$S$2 -> 19.743802 | P6: =SUM(B6:L6) -> 19.743802 | V6: TX_TSC+CC90:H2 | W6: 0 | X6: -0.4983059 | Y6: 0.082811057 | Z6: 9.0798426 | AA6: 0.46830868 | AB6: 0 | AC6: 5.5996408 | AD6: 3.0648553 | AE6: 0.7465209 | AF6: -2.0118991 | AG6: 2.3980978 | AH6: 1.4833828 | AI6: 863.20217 | AJ6: 18.929872 | AK6: 18.929872
A7: =lc_detailed!AQ7 -> SE_TSC | B7: =lc_detailed!AY7/$S$2 -> 0 | C7: =lc_detailed!AZ7/$S$2 -> 0 | D7: =lc_detailed!BA7/$S$2 -> 0 | E7: =lc_detailed!BB7/$S$2 -> 9.0798426 | F7: =lc_detailed!BC7/$S$2 -> 0.07466066 | G7: =lc_detailed!BD7/$S$2 -> 0 | H7: =lc_detailed!BE7/$S$2 -> 5.1922874 | I7: =lc_detailed!BF7/$S$2 -> 2.8418048 | J7: =lc_detailed!BG7/$S$2 -> 0.69221424 | K7: =lc_detailed!BI7/$S$2 -> 0 | L7: =lc_detailed!BJ7/$S$2 -> 1.7965856 | M7: =lc_detailed!BH7 -> 1.1113076 | N7: =lc_detailed!AS7 -> 897.28923 | O7: =N7/$S$2 -> 19.677395 | P7: =SUM(B7:L7) -> 19.677395 | V7: NCEN_TSC+CC90:H2 | W7: 0 | X7: -0.87121142 | Y7: 0.088816697 | Z7: 9.0798426 | AA7: 0.81414308 | AB7: 0 | AC7: 5.5996408 | AD7: 3.0648553 | AE7: 0.7465209 | AF7: -1.9797752 | AG7: 2.3980978 | AH7: 1.4833828 | AI7: 863.70644 | AJ7: 18.940931 | AK7: 18.940931
A8: =lc_detailed!AQ8 -> MIDAT_TSC | B8: =lc_detailed!AY8/$S$2 -> 0 | C8: =lc_detailed!AZ8/$S$2 -> 0 | D8: =lc_detailed!BA8/$S$2 -> 0 | E8: =lc_detailed!BB8/$S$2 -> 9.0798426 | F8: =lc_detailed!BC8/$S$2 -> 0.050698349 | G8: =lc_detailed!BD8/$S$2 -> 0 | H8: =lc_detailed!BE8/$S$2 -> 5.1922874 | I8: =lc_detailed!BF8/$S$2 -> 2.8418048 | J8: =lc_detailed!BG8/$S$2 -> 0.69221424 | K8: =lc_detailed!BI8/$S$2 -> 0 | L8: =lc_detailed!BJ8/$S$2 -> 1.7965856 | M8: =lc_detailed!BH8 -> 1.1113076 | N8: =lc_detailed!AS8 -> 896.19655 | O8: =N8/$S$2 -> 19.653433 | P8: =SUM(B8:L8) -> 19.653433 | V8: CEN_TSC+CC90:H2 | W8: 0 | X8: -0.87705855 | Y8: 0.087104671 | Z8: 9.0798426 | AA8: 0.81919931 | AB8: 0 | AC8: 5.5996408 | AD8: 3.0648553 | AE8: 0.7465209 | AF8: -1.9767907 | AG8: 2.3980978 | AH8: 1.4833828 | AI8: 863.7284 | AJ8: 18.941412 | AK8: 18.941412
A9: =lc_detailed!AQ9 -> NE_TSC | B9: =lc_detailed!AY9/$S$2 -> 0 | C9: =lc_detailed!AZ9/$S$2 -> 0 | D9: =lc_detailed!BA9/$S$2 -> 0 | E9: =lc_detailed!BB9/$S$2 -> 9.0798426 | F9: =lc_detailed!BC9/$S$2 -> 0.084006616 | G9: =lc_detailed!BD9/$S$2 -> 0 | H9: =lc_detailed!BE9/$S$2 -> 5.1922874 | I9: =lc_detailed!BF9/$S$2 -> 2.8418048 | J9: =lc_detailed!BG9/$S$2 -> 0.69221424 | K9: =lc_detailed!BI9/$S$2 -> 0 | L9: =lc_detailed!BJ9/$S$2 -> 1.7965856 | M9: =lc_detailed!BH9 -> 1.1113076 | N9: =lc_detailed!AS9 -> 897.7154 | O9: =N9/$S$2 -> 19.686741 | P9: =SUM(B9:L9) -> 19.686741 | V9: SE_TSC+CC90:H2 | W9: 0 | X9: -0.47978649 | Y9: 0.082456142 | Z9: 9.0798426 | AA9: 0.43356603 | AB9: 0 | AC9: 5.5996408 | AD9: 3.0648553 | AE9: 0.7465209 | AF9: -1.97996 | AG9: 2.3980978 | AH9: 1.4833828 | AI9: 863.90263 | AJ9: 18.945233 | AK9: 18.945233
A10: =lc_detailed!AQ10 -> SW_TSC+CC90 | B10: =lc_detailed!AY10/$S$2 -> 0 | C10: =lc_detailed!AZ10/$S$2 -> 0 | D10: =lc_detailed!BA10/$S$2 -> 0.069910917 | E10: =lc_detailed!BB10/$S$2 -> 9.0798426 | F10: =lc_detailed!BC10/$S$2 -> 0.096763087 | G10: =lc_detailed!BD10/$S$2 -> 0 | H10: =lc_detailed!BE10/$S$2 -> 5.5982891 | I10: =lc_detailed!BF10/$S$2 -> 3.0641326 | J10: =lc_detailed!BG10/$S$2 -> 0.7463407 | K10: =lc_detailed!BI10/$S$2 -> -1.522565 | L10: =lc_detailed!BJ10/$S$2 -> 1.7965856 | M10: =lc_detailed!BH10 -> 1.1113076 | N10: =lc_detailed!AS10 -> 863.17606 | O10: =N10/$S$2 -> 18.9293 | P10: =SUM(B10:L10) -> 18.9293 | V10: SE_TSC+CC90 | W10: 0 | X10: 0 | Y10: 0.070724802 | Z10: 9.0798426 | AA10: 0.07466066 | AB10: 0 | AC10: 5.5982891 | AD10: 3.0641326 | AE10: 0.7463407 | AF10: -1.4833289 | AG10: 1.7965856 | AH10: 1.1113076 | AI10: 863.99447 | AJ10: 18.947247 | AK10: 18.947247
A11: =lc_detailed!AQ11 -> SW_TSC:H2 | B11: =lc_detailed!AY11/$S$2 -> 0 | C11: =lc_detailed!AZ11/$S$2 -> -0.5970492 | D11: =lc_detailed!BA11/$S$2 -> 0 | E11: =lc_detailed!BB11/$S$2 -> 9.0798426 | F11: =lc_detailed!BC11/$S$2 -> 0.56191825 | G11: =lc_detailed!BD11/$S$2 -> 0 | H11: =lc_detailed!BE11/$S$2 -> 5.1922874 | I11: =lc_detailed!BF11/$S$2 -> 2.8418048 | J11: =lc_detailed!BG11/$S$2 -> 0.69221424 | K11: =lc_detailed!BI11/$S$2 -> 0 | L11: =lc_detailed!BJ11/$S$2 -> 2.3980978 | M11: =lc_detailed!BH11 -> 1.4833828 | N11: =lc_detailed!AS11 -> 919.71169 | O11: =N11/$S$2 -> 20.169116 | P11: =SUM(B11:L11) -> 20.169116 | V11: NCEN_TSC+CC90 | W11: 0 | X11: 0 | Y11: 0.076180417 | Z11: 9.0798426 | AA11: 0.14019654 | AB11: 0 | AC11: 5.5982891 | AD11: 3.0641326 | AE11: 0.7463407 | AF11: -1.4831904 | AG11: 1.7965856 | AH11: 1.1113076 | AI11: 867.238 | AJ11: 19.018377 | AK11: 19.018377
A12: =lc_detailed!AQ12 -> SW_TSC+CC90:H2 | B12: =lc_detailed!AY12/$S$2 -> 0 | C12: =lc_detailed!AZ12/$S$2 -> -0.5970492 | D12: =lc_detailed!BA12/$S$2 -> 0.081507256 | E12: =lc_detailed!BB12/$S$2 -> 9.0798426 | F12: =lc_detailed!BC12/$S$2 -> 0.56191825 | G12: =lc_detailed!BD12/$S$2 -> 0 | H12: =lc_detailed!BE12/$S$2 -> 5.5996408 | I12: =lc_detailed!BF12/$S$2 -> 3.0648553 | J12: =lc_detailed!BG12/$S$2 -> 0.7465209 | K12: =lc_detailed!BI12/$S$2 -> -2.0323327 | L12: =lc_detailed!BJ12/$S$2 -> 2.3980978 | M12: =lc_detailed!BH12 -> 1.4833828 | N12: =lc_detailed!AS12 -> 861.97685 | O12: =N12/$S$2 -> 18.903001 | P12: =SUM(B12:L12) -> 18.903001 | V12: CEN_TSC+CC90 | W12: 0 | X12: 0 | Y12: 0.074711968 | Z12: 9.0798426 | AA12: 0.14106723 | AB12: 0 | AC12: 5.5982891 | AD12: 3.0641326 | AE12: 0.7463407 | AF12: -1.4809545 | AG12: 1.7965856 | AH12: 1.1113076 | AI12: 867.3127 | AJ12: 19.020015 | AK12: 19.020015
A13: =lc_detailed!AQ13 -> SW_TSC+H2in | B13: =lc_detailed!AY13/$S$2 -> 0.08316484 | C13: =lc_detailed!AZ13/$S$2 -> 0 | D13: =lc_detailed!BA13/$S$2 -> 0 | E13: =lc_detailed!BB13/$S$2 -> 9.0798426 | F13: =lc_detailed!BC13/$S$2 -> 0 | G13: =lc_detailed!BD13/$S$2 -> 0 | H13: =lc_detailed!BE13/$S$2 -> 5.1922874 | I13: =lc_detailed!BF13/$S$2 -> 2.8418048 | J13: =lc_detailed!BG13/$S$2 -> 0.69221424 | K13: =lc_detailed!BI13/$S$2 -> 0 | L13: =lc_detailed!BJ13/$S$2 -> 1.6714571 | M13: =lc_detailed!BH13 -> 1.0339073 | N13: =lc_detailed!AS13 -> 891.97116 | O13: =N13/$S$2 -> 19.560771 | P13: =SUM(B13:L13) -> 19.560771 | V13: MIDAT_TSC+CC90:H2 | W13: 0 | X13: -0.49725803 | Y13: 0.083365301 | Z13: 9.0798426 | AA13: 0.29441318 | AB13: 0 | AC13: 5.5996408 | AD13: 3.0648553 | AE13: 0.7465209 | AF13: -1.684607 | AG13: 2.3980978 | AH13: 1.4833828 | AI13: 870.27011 | AJ13: 19.084871 | AK13: 19.084871
A14: =lc_detailed!AQ14 -> SW_TSC+H2in:CH4 | B14: =lc_detailed!AY14/$S$2 -> 0.51388436 | C14: =lc_detailed!AZ14/$S$2 -> 0 | D14: =lc_detailed!BA14/$S$2 -> 0 | E14: =lc_detailed!BB14/$S$2 -> 9.0798426 | F14: =lc_detailed!BC14/$S$2 -> 0 | G14: =lc_detailed!BD14/$S$2 -> -0.50356728 | H14: =lc_detailed!BE14/$S$2 -> 5.1922874 | I14: =lc_detailed!BF14/$S$2 -> 2.8418048 | J14: =lc_detailed!BG14/$S$2 -> 0.69221424 | K14: =lc_detailed!BI14/$S$2 -> 0 | L14: =lc_detailed!BJ14/$S$2 -> 1.6714571 | M14: =lc_detailed!BH14 -> 1.0339073 | N14: =lc_detailed!AS14 -> 888.6493 | O14: =N14/$S$2 -> 19.487923 | P14: =SUM(B14:L14) -> 19.487923 | V14: MIDAT_TSC+CC90 | W14: 0 | X14: 0 | Y14: 0.071504612 | Z14: 9.0798426 | AA14: 0.050698349 | AB14: 0 | AC14: 5.5982891 | AD14: 3.0641326 | AE14: 0.7463407 | AF14: -1.2620589 | AG14: 1.7965856 | AH14: 1.1113076 | AI14: 873.02726 | AJ14: 19.145335 | AK14: 19.145335
A15: =lc_detailed!AQ15 -> TX_TSC+CC90 | B15: =lc_detailed!AY15/$S$2 -> 0 | C15: =lc_detailed!AZ15/$S$2 -> 0 | D15: =lc_detailed!BA15/$S$2 -> 0.071029222 | E15: =lc_detailed!BB15/$S$2 -> 9.0798426 | F15: =lc_detailed!BC15/$S$2 -> 0.08064339 | G15: =lc_detailed!BD15/$S$2 -> 0 | H15: =lc_detailed!BE15/$S$2 -> 5.5982891 | I15: =lc_detailed!BF15/$S$2 -> 3.0641326 | J15: =lc_detailed!BG15/$S$2 -> 0.7463407 | K15: =lc_detailed!BI15/$S$2 -> -1.5072567 | L15: =lc_detailed!BJ15/$S$2 -> 1.7965856 | M15: =lc_detailed!BH15 -> 1.1113076 | N15: =lc_detailed!AS15 -> 863.19006 | O15: =N15/$S$2 -> 18.929607 | P15: =SUM(B15:L15) -> 18.929607 | V15: NE_TSC+CC90 | W15: 0 | X15: 0 | Y15: 0.069140945 | Z15: 9.0798426 | AA15: 0.084006616 | AB15: 0 | AC15: 5.5982891 | AD15: 3.0641326 | AE15: 0.7463407 | AF15: -1.1063805 | AG15: 1.7965856 | AH15: 1.1113076 | AI15: 881.53727 | AJ15: 19.331958 | AK15: 19.331958
... A51: =lc_detailed!AQ51 -> NE_ESC | B51: =lc_detailed!AY51/$S$2 -> 0 | C51: =lc_detailed!AZ51/$S$2 -> -0.60707775 | D51: =lc_detailed!BA51/$S$2 -> 1.6431693 | E51: =lc_detailed!BB51/$S$2 -> 9.0798426 | F51: =lc_detailed!BC51/$S$2 -> 0 | G51: =lc_detailed!BD51/$S$2 -> -0.437181 | H51: =lc_detailed!BE51/$S$2 -> 6.8789632 | I51: =lc_detailed!BF51/$S$2 -> 3.7649438 | J51: =lc_detailed!BG51/$S$2 -> 0.91707486 | K51: =lc_detailed!BI51/$S$2 -> 0 | L51: =lc_detailed!BJ51/$S$2 -> 1.6714571 | M51: =lc_detailed!BH51 -> 1.0339073 | N51: =lc_detailed!AS51 -> 1044.7504 | O51: =N51/$S$2 -> 22.911192 | P51: =SUM(B51:L51) -> 22.911192 | V51: MIDAT_ESC | W51: 0 | X51: -0.49725803 | Y51: 1.699343 | Z51: 9.0798426 | AA51: 0 | AB51: -0.26384059 | AC51: 6.8789632 | AD51: 3.7649438 | AE51: 0.91707486 | AF51: 0 | AG51: 1.6714571 | AH51: 1.0339073 | AI51: 1060.224 | AJ51: 23.250526 | AK51: 23.250526
