Workbook

Sheet lc_detailed
B2: Ethanol Upgrade Asset Parameters (normalized by MWh ethanol) | D2: Ethanol feedstock asset | AH2: Duals | AR2: LCOE for assets with ethane capacity ($/t-ethylene) | AT2: CI | AU2: CREDIT | BJ2: CHEM SEQUESTRATION - CARBON INTENSITY | BM2: CHEM SEQUESTRATION - CREDIT | BQ2: Ethanol Production LCOE parameters ($/MWh-fuel) | BZ2: Carbon Content | CG2: Carbon Inputs - Ethanol Production | CI2: Carbon Inputs - Ethanol Upgrade | CK2: Carbon Outputs - Ethanol Production | CM2: Carbon Outputs - Ethanol Upgrade | CR2: Sanity Checks | CT2: Asset Parameters (normalized by commodity feedstock)
B3: id | C3: commodity | D3: production_asset | E3: id_name | F3: h2_consumption (MWh/MWh-ethanol) | G3: elec_consumption (MWh/MWh-ethanol) | H3: elec_production (MWh/MWh-ethanol) | I3: gasoline_production (MWh-gasoline/MWh-ethanol) | J3: diesel_production (MWh-diesel/MWh-ethanol) | K3: jetfuel_production (MWh-jetfuel/MWh-ethanol) | L3: fuel_production (MWh-fuel/MWh-ethanol) | M3: process_capture_rate (t-CO2/MWh-ethanol) | N3: process_emission_rate (t-CO2/MWh-ethanol) | O3: investment_cost ($/yr per MW ethanol) | P3: fixed_om_cost ($/yr per MW ethanol) | Q3: variable_om_cost ($/MWh-ethanol) | S3: id_ethanol_prod_ref | T3: commodity_ethanol_prod_ref | U3: elec_production (MWh/t-bio) | V3: elec_consumption (MWh/t-bio) | W3: ethanol_production (MWh-ethanol/t-bio) | X3: natgas_consumption (MWh/t-bio) | Y3: co2_biomass_content (t-CO2/t-bio) | Z3: process_capture_rate (t-CO2/t-bio) | AA3: process_emission_rate (t-CO2/t-bio) | AB3: fuel_capture_rate (t-CO2/t-bio) | AC3: fuel_emission_rate (t-CO2/t-bio) | AD3: investment_cost ($/yr per t-bio/hr) | AE3: fixed_om_cost ($/yr per t-bio/hr) | AF3: variable_om_cost ($/t-bio) | AH3: co2_sink ($/t) | AI3: co2_captured ($/t) | AJ3: bioherb_supply ($/t) | AK3: biowood_supply ($/t) | AL3: bioagri_supply ($/t) | AM3: biocorn_supply ($/t) | AN3: elec_demand ($/MWh) | AO3: h2_balance ($/MWh) | AP3: ng_balance ($/MWh) | AR3: id_LC | AS3: commodity_LC | AT3: LCOE ($/t-ethylene) | AU3: LCOE ($/t-ethylene) | AV3: Diff. Between Methods | AW3: h2_consumption | AX3: elec_consumption | AY3: elec_consumption - ethanol | AZ3: elec_production | BA3: elec_production - ethanol | BB3: biomass_consumption - ethanol | BC3: natgas_consumption - ethanol | BD3: investment_cost | BE3: investment_cost - ethanol | BF3: fixed_om_cost | BG3: fixed_om_cost - ethanol | BH3: variable_om_cost | BI3: variable_om_cost - ethanol | BJ3: CI | BK3: modified capture cost | BL3: modified emissions cost | BM3: CI | BN3: modified capture cost | BO3: modified emissions cost | BQ3: id_LC_ethanol | BR3: elec_production | BS3: elec_consumption | BT3: biomass_consumption | BU3: natgas_consumption | BV3: investment_cost | BW3: fixed_om_cost | BX3: variable_om_cost | BZ3: Gasoline Avg (t-CO2/MWh-gasoline) | CA3: Diesel (t-CO2/MWh-diesel) | CB3: Jetfuel (t-CO2/MWh-jetfuel) | CC3: Biomass CO2 content (t-CO2/t-bio) | CD3: NG (t-CO2/MWh-NG) | CE3: Ethanol (t-CO2/MWh-ethanol) | CG3: Biomass (t-CO2/MWh-ethanol) | CH3: NG (t-CO2/MWh-ethanol) | CI3: Ethanol (t-CO2/MWh-ethanol) | CK3: Emissions (t-CO2/MWh-ethanol) | CL3: Captured (t-CO2/MWh-ethanol) | CM3: Gasoline (t-CO2/MWh-ethanol) | CN3: Diesel (t-CO2/MWh-ethanol) | CO3: JetFuel (t-CO2/MWh-ethanol) | CP3: Emissions (t-CO2/MWh-ethanol) | CR3: CARBON INPUT - OUTPUT | CT3: ethanol_production_asset | CU3: id_ethanol_prod_ref | CV3: commodity_ethanol_prod_ref | CW3: elec_production (MWh/t-bio) | CX3: elec_consumption (MWh/t-bio) | CY3: ethanol_production (MWh-ethanol/t-bio) | CZ3: natgas_consumption (MWh/t-bio) | DA3: co2_biomass_content (t-CO2/t-bio) | DB3: process_capture_rate (t-CO2/t-bio) | DC3: process_emission_rate (t-CO2/t-bio) | DD3: fuel_capture_rate (t-CO2/t-bio) | DE3: fuel_emission_rate (t-CO2/t-bio) | DF3: investment_cost ($/yr per t-bio/hr) | DG3: fixed_om_cost ($/yr per t-bio/hr) | DH3: variable_om_cost ($/t-bio)
B4: CA_Ethanol_to_Gasoline | C4: Ethanol | D4: 6 | E4: =S4 -> Drymill CCS Fermentation Exhaust | F4: 0 | G4: 0 | H4: 0 | I4: 0.94525743 | J4: 0 | K4: 0 | L4: =SUM(I4:K4) -> 0.94525743 | M4: 0 | N4: 0.00188639 | O4: 221829.88 | P4: 121538 | Q4: 5.38 | S4: {=_xlfn.XLOOKUP(D4, CT:CT, CU:DH)} -> Drymill CCS Fermentation Exhaust | T4: Biomass_Corn | U4: 0 | V4: 0.085342825 | W4: 3.104338 | X4: 1.0133975 | Y4: 1.7588667 | Z4: 0.35768767 | AA4: 0.68601739 | AB4: 0.15290642 | AC4: 0.032434696 | AD4: 45179.42 | AE4: 201481.25 | AF4: -25.28 | AH4: 105.211 | AI4: -6.412213 | AJ4: 313632.97 | AK4: 154.03698 | AL4: 132.85974 | AM4: 160 | AN4: 36.488698 | AO4: 29.796642 | AP4: 13.71857 | AR4: =B4 -> CA_Ethanol_to_Gasoline | AS4: =C4 -> Ethanol | AT4: =SUM(AW4:BI4)+BK4+BL4 -> 92.49031 | AU4: =SUM(AW4:BI4)+BN4+BO4 -> 92.849701 | AV4: =AT4-AU4 -> -0.35939129 | AW4: =F4/L4*AO4 -> 0 | AX4: =G4/L4*AN4 -> 0 | AY4: =BS4 -> 1.0612221 | AZ4: =H4/L4 -> 0 | BA4: =BR4 -> 0 | BB4: =BT4 -> 54.525654 | BC4: =BU4 -> 4.7377221 | BD4: =O4/L4/(0.9*8760) -> 29.766195 | BE4: =BV4 -> 6.6093692e-06 | BF4: =P4/L4/(0.9*8760) -> 16.30855 | BG4: =BW4 -> 1.4019874e-06 | BH4: =Q4/L4 -> 5.6915712 | BI4: =BX4 -> -8.6150533 | BJ4: =SUM(CK4:CP4)-CG4 -> 0.058983608 | BK4: =((AH4+AI4)*-1*CL4)/L4 -> -17.191284 | BL4: =BJ4*AH4 -> 6.2057246 | BM4: =(CK4+CM4+CN4+CO4+CP4-CG4)/L4 -> -0.11160346 | BN4: =(CL4*AI4*-1)/L4 -> 1.1157442 | BO4: =BM4*AH4 -> -11.741912 | BQ4: =S4 -> Drymill CCS Fermentation Exhaust | BR4: =U4/W4/L4*AN4*-1 -> 0 | BS4: =V4/W4/L4*AN4 -> 1.0612221 | BT4: {=_xlfn.IFS(T4="Biomass_Corn", 1/W4/L4*AM4, T4="Biomass_Agri", 1/W4/L4*AL4, T4="Biomass_Wood", 1/W4/L4*AK4, T4="Biomass_Herb", 1/W4/L4*AJ4)} -> 54.525654 | BU4: =X4/W4/L4*AP4 -> 4.7377221 | BV4: =AB4/W4/L4/(0.9*8760) -> 6.6093692e-06 | BW4: =AC4/W4/L4/(0.9*8760) -> 1.4019874e-06 | BX4: =AF4/W4/L4 -> -8.6150533 | BZ4: 0.24095893 | CA4: 0.24182836 | CB4: 0.24025514 | CC4: =Y4 -> 1.7588667 | CD4: 0.18289084 | CE4: 0.23037491 | CG4: =CC4/W4 -> 0.56658349 | CH4: =IF(X4=0, 0, CD4*X4/W4) -> 0.059703911 | CI4: =CE4 -> 0.23037491 | CK4: =(AA4+AC4)/W4 -> 0.23143488 | CL4: =(Z4+AB4)/W4 -> 0.16447761 | CM4: =BZ4*I4 -> 0.22776822 | CN4: =CA4*J4 -> 0 | CO4: =CB4*K4 -> 0 | CP4: =(N4) -> 0.00188639 | CR4: =SUM(CG4:CH4)-SUM(CK4:CP4) -> 0.00072030281 | CT4: 1 | CU4: DryMill_Existing_Non_CCS | CV4: Biomass_Corn | CW4: 0 | CX4: 0.085342825 | CY4: 3.104338 | CZ4: 1.0133975 | DA4: 1.7588667 | DB4: 0 | DC4: 1.0437051 | DD4: 0 | DE4: 0.18534112 | DF4: 322562.05 | DG4: 176727.97 | DH4: -25.41
B5: NW_Ethanol_to_Gasoline | C5: Ethanol | D5: 6 | E5: =S5 -> Drymill CCS Fermentation Exhaust | F5: 0 | G5: 0 | H5: 0 | I5: 0.94525743 | J5: 0 | K5: 0 | L5: =SUM(I5:K5) -> 0.94525743 | M5: 0 | N5: 0.00188639 | O5: 221829.88 | P5: 121538 | Q5: 5.38 | S5: {=_xlfn.XLOOKUP(D5, CT:CT, CU:DH)} -> Drymill CCS Fermentation Exhaust | T5: Biomass_Corn | U5: 0 | V5: 0.085342825 | W5: 3.104338 | X5: 1.0133975 | Y5: 1.7588667 | Z5: 0.35768767 | AA5: 0.68601739 | AB5: 0.15290642 | AC5: 0.032434696 | AD5: 45179.42 | AE5: 201481.25 | AF5: -25.28 | AH5: 105.211 | AI5: -7.379659 | AJ5: 130.9966 | AK5: 149.05667 | AL5: 112.26938 | AM5: 160 | AN5: 26.787863 | AO5: 27.898395 | AP5: 13.71944 | AR5: =B5 -> NW_Ethanol_to_Gasoline | AS5: =C5 -> Ethanol | AT5: =SUM(AW5:BI5)+BK5+BL5 -> 92.376814 | AU5: =SUM(AW5:BI5)+BN5+BO5 -> 92.736205 | AV5: =AT5-AU5 -> -0.35939129 | AW5: =F5/L5*AO5 -> 0 | AX5: =G5/L5*AN5 -> 0 | AY5: =BS5 -> 0.77908704 | AZ5: =H5/L5 -> 0 | BA5: =BR5 -> 0 | BB5: =BT5 -> 54.525654 | BC5: =BU5 -> 4.7380225 | BD5: =O5/L5/(0.9*8760) -> 29.766195 | BE5: =BV5 -> 6.6093692e-06 | BF5: =P5/L5/(0.9*8760) -> 16.30855 | BG5: =BW5 -> 1.4019874e-06 | BH5: =Q5/L5 -> 5.6915712 | BI5: =BX5 -> -8.6150533 | BJ5: =SUM(CK5:CP5)-CG5 -> 0.058983608 | BK5: =((AH5+AI5)*-1*CL5)/L5 -> -17.022945 | BL5: =BJ5*AH5 -> 6.2057246 | BM5: =(CK5+CM5+CN5+CO5+CP5-CG5)/L5 -> -0.11160346 | BN5: =(CL5*AI5*-1)/L5 -> 1.2840827 | BO5: =BM5*AH5 -> -11.741912 | BQ5: =S5 -> Drymill CCS Fermentation Exhaust | BR5: =U5/W5/L5*AN5*-1 -> 0 | BS5: =V5/W5/L5*AN5 -> 0.77908704 | BT5: {=_xlfn.IFS(T5="Biomass_Corn", 1/W5/L5*AM5, T5="Biomass_Agri", 1/W5/L5*AL5, T5="Biomass_Wood", 1/W5/L5*AK5, T5="Biomass_Herb", 1/W5/L5*AJ5)} -> 54.525654 | BU5: =X5/W5/L5*AP5 -> 4.7380225 | BV5: =AB5/W5/L5/(0.9*8760) -> 6.6093692e-06 | BW5: =AC5/W5/L5/(0.9*8760) -> 1.4019874e-06 | BX5: =AF5/W5/L5 -> -8.6150533 | BZ5: 0.24095893 | CA5: 0.24182836 | CB5: 0.24025514 | CC5: =Y5 -> 1.7588667 | CD5: 0.18289084 | CE5: 0.23037491 | CG5: =CC5/W5 -> 0.56658349 | CH5: =IF(X5=0, 0, CD5*X5/W5) -> 0.059703911 | CI5: =CE5 -> 0.23037491 | CK5: =(AA5+AC5)/W5 -> 0.23143488 | CL5: =(Z5+AB5)/W5 -> 0.16447761 | CM5: =BZ5*I5 -> 0.22776822 | CN5: =CA5*J5 -> 0 | CO5: =CB5*K5 -> 0 | CP5: =(N5) -> 0.00188639 | CR5: =SUM(CG5:CH5)-SUM(CK5:CP5) -> 0.00072030281 | CT5: 2 | CU5: Biochemical_Non_CCS | CV5: Biomass_Agri | CW5: 0.2142 | CX5: 0 | CY5: 1.9848 | CZ5: 0 | DA5: 1.723 | DB5: 0 | DC5: 1.2657602 | DD5: 0 | DE5: 0 | DF5: 273134.22 | DG5: 144062.46 | DH5: 0.45
B6: SW_Ethanol_to_Gasoline | C6: Ethanol | D6: 6 | E6: =S6 -> Drymill CCS Fermentation Exhaust | F6: 0 | G6: 0 | H6: 0 | I6: 0.94525743 | J6: 0 | K6: 0 | L6: =SUM(I6:K6) -> 0.94525743 | M6: 0 | N6: 0.00188639 | O6: 221829.88 | P6: 121538 | Q6: 5.38 | S6: {=_xlfn.XLOOKUP(D6, CT:CT, CU:DH)} -> Drymill CCS Fermentation Exhaust | T6: Biomass_Corn | U6: 0 | V6: 0.085342825 | W6: 3.104338 | X6: 1.0133975 | Y6: 1.7588667 | Z6: 0.35768767 | AA6: 0.68601739 | AB6: 0.15290642 | AC6: 0.032434696 | AD6: 45179.42 | AE6: 201481.25 | AF6: -25.28 | AH6: 105.211 | AI6: -14.567418 | AJ6: 120.28219 | AK6: 137.47503 | AL6: 107.55987 | AM6: 160 | AN6: 27.957547 | AO6: 26.470402 | AP6: 13.719351 | AR6: =B6 -> SW_Ethanol_to_Gasoline | AS6: =C6 -> Ethanol | AT6: =SUM(AW6:BI6)+BK6+BL6 -> 93.661493 | AU6: =SUM(AW6:BI6)+BN6+BO6 -> 94.020885 | AV6: =AT6-AU6 -> -0.35939129 | AW6: =F6/L6*AO6 -> 0 | AX6: =G6/L6*AN6 -> 0 | AY6: =BS6 -> 0.81310565 | AZ6: =H6/L6 -> 0 | BA6: =BR6 -> 0 | BB6: =BT6 -> 54.525654 | BC6: =BU6 -> 4.7379918 | BD6: =O6/L6/(0.9*8760) -> 29.766195 | BE6: =BV6 -> 6.6093692e-06 | BF6: =P6/L6/(0.9*8760) -> 16.30855 | BG6: =BW6 -> 1.4019874e-06 | BH6: =Q6/L6 -> 5.6915712 | BI6: =BX6 -> -8.6150533 | BJ6: =SUM(CK6:CP6)-CG6 -> 0.058983608 | BK6: =((AH6+AI6)*-1*CL6)/L6 -> -15.772254 | BL6: =BJ6*AH6 -> 6.2057246 | BM6: =(CK6+CM6+CN6+CO6+CP6-CG6)/L6 -> -0.11160346 | BN6: =(CL6*AI6*-1)/L6 -> 2.5347741 | BO6: =BM6*AH6 -> -11.741912 | BQ6: =S6 -> Drymill CCS Fermentation Exhaust | BR6: =U6/W6/L6*AN6*-1 -> 0 | BS6: =V6/W6/L6*AN6 -> 0.81310565 | BT6: {=_xlfn.IFS(T6="Biomass_Corn", 1/W6/L6*AM6, T6="Biomass_Agri", 1/W6/L6*AL6, T6="Biomass_Wood", 1/W6/L6*AK6, T6="Biomass_Herb", 1/W6/L6*AJ6)} -> 54.525654 | BU6: =X6/W6/L6*AP6 -> 4.7379918 | BV6: =AB6/W6/L6/(0.9*8760) -> 6.6093692e-06 | BW6: =AC6/W6/L6/(0.9*8760) -> 1.4019874e-06 | BX6: =AF6/W6/L6 -> -8.6150533 | BZ6: 0.24095893 | CA6: 0.24182836 | CB6: 0.24025514 | CC6: =Y6 -> 1.7588667 | CD6: 0.18289084 | CE6: 0.23037491 | CG6: =CC6/W6 -> 0.56658349 | CH6: =IF(X6=0, 0, CD6*X6/W6) -> 0.059703911 | CI6: =CE6 -> 0.23037491 | CK6: =(AA6+AC6)/W6 -> 0.23143488 | CL6: =(Z6+AB6)/W6 -> 0.16447761 | CM6: =BZ6*I6 -> 0.22776822 | CN6: =CA6*J6 -> 0 | CO6: =CB6*K6 -> 0 | CP6: =(N6) -> 0.00188639 | CR6: =SUM(CG6:CH6)-SUM(CK6:CP6) -> 0.00072030281 | CT6: 3 | CU6: Biochemical_CCS_20 | CV6: Biomass_Agri | CW6: 0 | CX6: 0 | CY6: 1.9848 | CZ6: 0 | DA6: 1.723 | DB6: 0.25912643 | DC6: 1.0066338 | DD6: 0 | DE6: 0 | DF6: 293026.95 | DG6: 154950.42 | DH6: 0.48
B7: TX_Ethanol_to_Gasoline | C7: Ethanol | D7: 6 | E7: =S7 -> Drymill CCS Fermentation Exhaust | F7: 0 | G7: 0 | H7: 0 | I7: 0.94525743 | J7: 0 | K7: 0 | L7: =SUM(I7:K7) -> 0.94525743 | M7: 0 | N7: 0.00188639 | O7: 221829.88 | P7: 121538 | Q7: 5.38 | S7: {=_xlfn.XLOOKUP(D7, CT:CT, CU:DH)} -> Drymill CCS Fermentation Exhaust | T7: Biomass_Corn | U7: 0 | V7: 0.085342825 | W7: 3.104338 | X7: 1.0133975 | Y7: 1.7588667 | Z7: 0.35768767 | AA7: 0.68601739 | AB7: 0.15290642 | AC7: 0.032434696 | AD7: 45179.42 | AE7: 201481.25 | AF7: -25.28 | AH7: 105.211 | AI7: -19.477884 | AJ7: 132.95548 | AK7: 152.57709 | AL7: 106.67489 | AM7: 160 | AN7: 20.174973 | AO7: 18.805643 | AP7: 13.326032 | AR7: =B7 -> TX_Ethanol_to_Gasoline | AS7: =C7 -> Ethanol | AT7: =SUM(AW7:BI7)+BK7+BL7 -> 94.153751 | AU7: =SUM(AW7:BI7)+BN7+BO7 -> 94.513142 | AV7: =AT7-AU7 -> -0.35939129 | AW7: =F7/L7*AO7 -> 0 | AX7: =G7/L7*AN7 -> 0 | AY7: =BS7 -> 0.58676051 | AZ7: =H7/L7 -> 0 | BA7: =BR7 -> 0 | BB7: =BT7 -> 54.525654 | BC7: =BU7 -> 4.6021587 | BD7: =O7/L7/(0.9*8760) -> 29.766195 | BE7: =BV7 -> 6.6093692e-06 | BF7: =P7/L7/(0.9*8760) -> 16.30855 | BG7: =BW7 -> 1.4019874e-06 | BH7: =Q7/L7 -> 5.6915712 | BI7: =BX7 -> -8.6150533 | BJ7: =SUM(CK7:CP7)-CG7 -> 0.058983608 | BK7: =((AH7+AI7)*-1*CL7)/L7 -> -14.917818 | BL7: =BJ7*AH7 -> 6.2057246 | BM7: =(CK7+CM7+CN7+CO7+CP7-CG7)/L7 -> -0.11160346 | BN7: =(CL7*AI7*-1)/L7 -> 3.3892099 | BO7: =BM7*AH7 -> -11.741912 | BQ7: =S7 -> Drymill CCS Fermentation Exhaust | BR7: =U7/W7/L7*AN7*-1 -> 0 | BS7: =V7/W7/L7*AN7 -> 0.58676051 | BT7: {=_xlfn.IFS(T7="Biomass_Corn", 1/W7/L7*AM7, T7="Biomass_Agri", 1/W7/L7*AL7, T7="Biomass_Wood", 1/W7/L7*AK7, T7="Biomass_Herb", 1/W7/L7*AJ7)} -> 54.525654 | BU7: =X7/W7/L7*AP7 -> 4.6021587 | BV7: =AB7/W7/L7/(0.9*8760) -> 6.6093692e-06 | BW7: =AC7/W7/L7/(0.9*8760) -> 1.4019874e-06 | BX7: =AF7/W7/L7 -> -8.6150533 | BZ7: 0.24095893 | CA7: 0.24182836 | CB7: 0.24025514 | CC7: =Y7 -> 1.7588667 | CD7: 0.18289084 | CE7: 0.23037491 | CG7: =CC7/W7 -> 0.56658349 | CH7: =IF(X7=0, 0, CD7*X7/W7) -> 0.059703911 | CI7: =CE7 -> 0.23037491 | CK7: =(AA7+AC7)/W7 -> 0.23143488 | CL7: =(Z7+AB7)/W7 -> 0.16447761 | CM7: =BZ7*I7 -> 0.22776822 | CN7: =CA7*J7 -> 0 | CO7: =CB7*K7 -> 0 | CP7: =(N7) -> 0.00188639 | CR7: =SUM(CG7:CH7)-SUM(CK7:CP7) -> 0.00072030281 | CT7: 4 | CU7: Biochemical_CCS_86 | CV7: Biomass_Agri | CW7: 0 | CX7: 0.2632 | CY7: 1.9848 | CZ7: 0 | DA7: 1.723 | DB7: 1.0913384 | DC7: 0.17442176 | DD7: 0 | DE7: 0 | DF7: 520155.64 | DG7: 279265.62 | DH7: 1.67
B8: NCEN_Ethanol_to_Gasoline | C8: Ethanol | D8: 6 | E8: =S8 -> Drymill CCS Fermentation Exhaust | F8: 0 | G8: 0 | H8: 0 | I8: 0.94525743 | J8: 0 | K8: 0 | L8: =SUM(I8:K8) -> 0.94525743 | M8: 0 | N8: 0.00188639 | O8: 221829.88 | P8: 121538 | Q8: 5.38 | S8: {=_xlfn.XLOOKUP(D8, CT:CT, CU:DH)} -> Drymill CCS Fermentation Exhaust | T8: Biomass_Corn | U8: 0 | V8: 0.085342825 | W8: 3.104338 | X8: 1.0133975 | Y8: 1.7588667 | Z8: 0.35768767 | AA8: 0.68601739 | AB8: 0.15290642 | AC8: 0.032434696 | AD8: 45179.42 | AE8: 201481.25 | AF8: -25.28 | AH8: 105.211 | AI8: -39.686463 | AJ8: 100.75765 | AK8: 111.99077 | AL8: 89.243782 | AM8: 160 | AN8: 30.71395 | AO8: 27.816395 | AP8: 13.425922 | AR8: =B8 -> NCEN_Ethanol_to_Gasoline | AS8: =C8 -> Ethanol | AT8: =SUM(AW8:BI8)+BK8+BL8 -> 98.011112 | AU8: =SUM(AW8:BI8)+BN8+BO8 -> 98.370503 | AV8: =AT8-AU8 -> -0.35939129 | AW8: =F8/L8*AO8 -> 0 | AX8: =G8/L8*AN8 -> 0 | AY8: =BS8 -> 0.89327172 | AZ8: =H8/L8 -> 0 | BA8: =BR8 -> 0 | BB8: =BT8 -> 54.525654 | BC8: =BU8 -> 4.6366558 | BD8: =O8/L8/(0.9*8760) -> 29.766195 | BE8: =BV8 -> 6.6093692e-06 | BF8: =P8/L8/(0.9*8760) -> 16.30855 | BG8: =BW8 -> 1.4019874e-06 | BH8: =Q8/L8 -> 5.6915712 | BI8: =BX8 -> -8.6150533 | BJ8: =SUM(CK8:CP8)-CG8 -> 0.058983608 | BK8: =((AH8+AI8)*-1*CL8)/L8 -> -11.401465 | BL8: =BJ8*AH8 -> 6.2057246 | BM8: =(CK8+CM8+CN8+CO8+CP8-CG8)/L8 -> -0.11160346 | BN8: =(CL8*AI8*-1)/L8 -> 6.9055628 | BO8: =BM8*AH8 -> -11.741912 | BQ8: =S8 -> Drymill CCS Fermentation Exhaust | BR8: =U8/W8/L8*AN8*-1 -> 0 | BS8: =V8/W8/L8*AN8 -> 0.89327172 | BT8: {=_xlfn.IFS(T8="Biomass_Corn", 1/W8/L8*AM8, T8="Biomass_Agri", 1/W8/L8*AL8, T8="Biomass_Wood", 1/W8/L8*AK8, T8="Biomass_Herb", 1/W8/L8*AJ8)} -> 54.525654 | BU8: =X8/W8/L8*AP8 -> 4.6366558 | BV8: =AB8/W8/L8/(0.9*8760) -> 6.6093692e-06 | BW8: =AC8/W8/L8/(0.9*8760) -> 1.4019874e-06 | BX8: =AF8/W8/L8 -> -8.6150533 | BZ8: 0.24095893 | CA8: 0.24182836 | CB8: 0.24025514 | CC8: =Y8 -> 1.7588667 | CD8: 0.18289084 | CE8: 0.23037491 | CG8: =CC8/W8 -> 0.56658349 | CH8: =IF(X8=0, 0, CD8*X8/W8) -> 0.059703911 | CI8: =CE8 -> 0.23037491 | CK8: =(AA8+AC8)/W8 -> 0.23143488 | CL8: =(Z8+AB8)/W8 -> 0.16447761 | CM8: =BZ8*I8 -> 0.22776822 | CN8: =CA8*J8 -> 0 | CO8: =CB8*K8 -> 0 | CP8: =(N8) -> 0.00188639 | CR8: =SUM(CG8:CH8)-SUM(CK8:CP8) -> 0.00072030281 | CT8: 5 | CU8: Drymill CCS Fermentation | CV8: Biomass_Corn | CW8: 0 | CX8: 0.08534283 | CY8: 3.104338 | CZ8: 1.0133975 | DA8: 1.7588667 | DB8: 0.35768767 | DC8: 0.68601739 | DD8: 0 | DE8: 0.18534112 | DF8: 27458.48 | DG8: 191772.15 | DH8: -25.37
B9: CEN_Ethanol_to_Gasoline | C9: Ethanol | D9: 6 | E9: =S9 -> Drymill CCS Fermentation Exhaust | F9: 0 | G9: 0 | H9: 0 | I9: 0.94525743 | J9: 0 | K9: 0 | L9: =SUM(I9:K9) -> 0.94525743 | M9: 0 | N9: 0.00188639 | O9: 221829.88 | P9: 121538 | Q9: 5.38 | S9: {=_xlfn.XLOOKUP(D9, CT:CT, CU:DH)} -> Drymill CCS Fermentation Exhaust | T9: Biomass_Corn | U9: 0 | V9: 0.085342825 | W9: 3.104338 | X9: 1.0133975 | Y9: 1.7588667 | Z9: 0.35768767 | AA9: 0.68601739 | AB9: 0.15290642 | AC9: 0.032434696 | AD9: 45179.42 | AE9: 201481.25 | AF9: -25.28 | AH9: 105.211 | AI9: -29.672038 | AJ9: 107.02715 | AK9: 122.86522 | AL9: 94.404421 | AM9: 160 | AN9: 25.118154 | AO9: 25.810506 | AP9: 13.425869 | AR9: =B9 -> CEN_Ethanol_to_Gasoline | AS9: =C9 -> Ethanol | AT9: =SUM(AW9:BI9)+BK9+BL9 -> 96.105808 | AU9: =SUM(AW9:BI9)+BN9+BO9 -> 96.465199 | AV9: =AT9-AU9 -> -0.35939129 | AW9: =F9/L9*AO9 -> 0 | AX9: =G9/L9*AN9 -> 0 | AY9: =BS9 -> 0.73052592 | AZ9: =H9/L9 -> 0 | BA9: =BR9 -> 0 | BB9: =BT9 -> 54.525654 | BC9: =BU9 -> 4.6366375 | BD9: =O9/L9/(0.9*8760) -> 29.766195 | BE9: =BV9 -> 6.6093692e-06 | BF9: =P9/L9/(0.9*8760) -> 16.30855 | BG9: =BW9 -> 1.4019874e-06 | BH9: =Q9/L9 -> 5.6915712 | BI9: =BX9 -> -8.6150533 | BJ9: =SUM(CK9:CP9)-CG9 -> 0.058983608 | BK9: =((AH9+AI9)*-1*CL9)/L9 -> -13.144005 | BL9: =BJ9*AH9 -> 6.2057246 | BM9: =(CK9+CM9+CN9+CO9+CP9-CG9)/L9 -> -0.11160346 | BN9: =(CL9*AI9*-1)/L9 -> 5.163023 | BO9: =BM9*AH9 -> -11.741912 | BQ9: =S9 -> Drymill CCS Fermentation Exhaust | BR9: =U9/W9/L9*AN9*-1 -> 0 | BS9: =V9/W9/L9*AN9 -> 0.73052592 | BT9: {=_xlfn.IFS(T9="Biomass_Corn", 1/W9/L9*AM9, T9="Biomass_Agri", 1/W9/L9*AL9, T9="Biomass_Wood", 1/W9/L9*AK9, T9="Biomass_Herb", 1/W9/L9*AJ9)} -> 54.525654 | BU9: =X9/W9/L9*AP9 -> 4.6366375 | BV9: =AB9/W9/L9/(0.9*8760) -> 6.6093692e-06 | BW9: =AC9/W9/L9/(0.9*8760) -> 1.4019874e-06 | BX9: =AF9/W9/L9 -> -8.6150533 | BZ9: 0.24095893 | CA9: 0.24182836 | CB9: 0.24025514 | CC9: =Y9 -> 1.7588667 | CD9: 0.18289084 | CE9: 0.23037491 | CG9: =CC9/W9 -> 0.56658349 | CH9: =IF(X9=0, 0, CD9*X9/W9) -> 0.059703911 | CI9: =CE9 -> 0.23037491 | CK9: =(AA9+AC9)/W9 -> 0.23143488 | CL9: =(Z9+AB9)/W9 -> 0.16447761 | CM9: =BZ9*I9 -> 0.22776822 | CN9: =CA9*J9 -> 0 | CO9: =CB9*K9 -> 0 | CP9: =(N9) -> 0.00188639 | CR9: =SUM(CG9:CH9)-SUM(CK9:CP9) -> 0.00072030281 | CT9: 6 | CU9: Drymill CCS Fermentation Exhaust | CV9: Biomass_Corn | CW9: 0 | CX9: 0.085342825 | CY9: 3.104338 | CZ9: 1.0133975 | DA9: 1.7588667 | DB9: 0.35768767 | DC9: 0.68601739 | DD9: 0.15290642 | DE9: 0.032434696 | DF9: 45179.42 | DG9: 201481.25 | DH9: -25.28
B10: SE_Ethanol_to_Gasoline | C10: Ethanol | D10: 6 | E10: =S10 -> Drymill CCS Fermentation Exhaust | F10: 0 | G10: 0 | H10: 0 | I10: 0.94525743 | J10: 0 | K10: 0 | L10: =SUM(I10:K10) -> 0.94525743 | M10: 0 | N10: 0.00188639 | O10: 221829.88 | P10: 121538 | Q10: 5.38 | S10: {=_xlfn.XLOOKUP(D10, CT:CT, CU:DH)} -> Drymill CCS Fermentation Exhaust | T10: Biomass_Corn | U10: 0 | V10: 0.085342825 | W10: 3.104338 | X10: 1.0133975 | Y10: 1.7588667 | Z10: 0.35768767 | AA10: 0.68601739 | AB10: 0.15290642 | AC10: 0.032434696 | AD10: 45179.42 | AE10: 201481.25 | AF10: -25.28 | AH10: 105.211 | AI10: -45.510345 | AJ10: 97.593262 | AK10: 109.79123 | AL10: 86.911507 | AM10: 160 | AN10: 38.099076 | AO10: 30.305277 | AP10: 13.425863 | AR10: =B10 -> SE_Ethanol_to_Gasoline | AS10: =C10 -> Ethanol | AT10: =SUM(AW10:BI10)+BK10+BL10 -> 99.23925 | AU10: =SUM(AW10:BI10)+BN10+BO10 -> 99.598642 | AV10: =AT10-AU10 -> -0.35939129 | AW10: =F10/L10*AO10 -> 0 | AX10: =G10/L10*AN10 -> 0 | AY10: =BS10 -> 1.1080576 | AZ10: =H10/L10 -> 0 | BA10: =BR10 -> 0 | BB10: =BT10 -> 54.525654 | BC10: =BU10 -> 4.6366354 | BD10: =O10/L10/(0.9*8760) -> 29.766195 | BE10: =BV10 -> 6.6093692e-06 | BF10: =P10/L10/(0.9*8760) -> 16.30855 | BG10: =BW10 -> 1.4019874e-06 | BH10: =Q10/L10 -> 5.6915712 | BI10: =BX10 -> -8.6150533 | BJ10: =SUM(CK10:CP10)-CG10 -> 0.058983608 | BK10: =((AH10+AI10)*-1*CL10)/L10 -> -10.388092 | BL10: =BJ10*AH10 -> 6.2057246 | BM10: =(CK10+CM10+CN10+CO10+CP10-CG10)/L10 -> -0.11160346 | BN10: =(CL10*AI10*-1)/L10 -> 7.9189357 | BO10: =BM10*AH10 -> -11.741912 | BQ10: =S10 -> Drymill CCS Fermentation Exhaust | BR10: =U10/W10/L10*AN10*-1 -> 0 | BS10: =V10/W10/L10*AN10 -> 1.1080576 | BT10: {=_xlfn.IFS(T10="Biomass_Corn", 1/W10/L10*AM10, T10="Biomass_Agri", 1/W10/L10*AL10, T10="Biomass_Wood", 1/W10/L10*AK10, T10="Biomass_Herb", 1/W10/L10*AJ10)} -> 54.525654 | BU10: =X10/W10/L10*AP10 -> 4.6366354 | BV10: =AB10/W10/L10/(0.9*8760) -> 6.6093692e-06 | BW10: =AC10/W10/L10/(0.9*8760) -> 1.4019874e-06 | BX10: =AF10/W10/L10 -> -8.6150533 | BZ10: 0.24095893 | CA10: 0.24182836 | CB10: 0.24025514 | CC10: =Y10 -> 1.7588667 | CD10: 0.18289084 | CE10: 0.23037491 | CG10: =CC10/W10 -> 0.56658349 | CH10: =IF(X10=0, 0, CD10*X10/W10) -> 0.059703911 | CI10: =CE10 -> 0.23037491 | CK10: =(AA10+AC10)/W10 -> 0.23143488 | CL10: =(Z10+AB10)/W10 -> 0.16447761 | CM10: =BZ10*I10 -> 0.22776822 | CN10: =CA10*J10 -> 0 | CO10: =CB10*K10 -> 0 | CP10: =(N10) -> 0.00188639 | CR10: =SUM(CG10:CH10)-SUM(CK10:CP10) -> 0.00072030281
B11: MIDAT_Ethanol_to_Gasoline | C11: Ethanol | D11: 6 | E11: =S11 -> Drymill CCS Fermentation Exhaust | F11: 0 | G11: 0 | H11: 0 | I11: 0.94525743 | J11: 0 | K11: 0 | L11: =SUM(I11:K11) -> 0.94525743 | M11: 0 | N11: 0.00188639 | O11: 221829.88 | P11: 121538 | Q11: 5.38 | S11: {=_xlfn.XLOOKUP(D11, CT:CT, CU:DH)} -> Drymill CCS Fermentation Exhaust | T11: Biomass_Corn | U11: 0 | V11: 0.085342825 | W11: 3.104338 | X11: 1.0133975 | Y11: 1.7588667 | Z11: 0.35768767 | AA11: 0.68601739 | AB11: 0.15290642 | AC11: 0.032434696 | AD11: 45179.42 | AE11: 201481.25 | AF11: -25.28 | AH11: 105.211 | AI11: -50.334515 | AJ11: 98.707491 | AK11: 106.53196 | AL11: 87.469328 | AM11: 160 | AN11: 39.29871 | AO11: 31.568805 | AP11: 13.42643 | AR11: =B11 -> MIDAT_Ethanol_to_Gasoline | AS11: =C11 -> Ethanol | AT11: =SUM(AW11:BI11)+BK11+BL11 -> 100.11376 | AU11: =SUM(AW11:BI11)+BN11+BO11 -> 100.47315 | AV11: =AT11-AU11 -> -0.35939129 | AW11: =F11/L11*AO11 -> 0 | AX11: =G11/L11*AN11 -> 0 | AY11: =BS11 -> 1.1429473 | AZ11: =H11/L11 -> 0 | BA11: =BR11 -> 0 | BB11: =BT11 -> 54.525654 | BC11: =BU11 -> 4.6368312 | BD11: =O11/L11/(0.9*8760) -> 29.766195 | BE11: =BV11 -> 6.6093692e-06 | BF11: =P11/L11/(0.9*8760) -> 16.30855 | BG11: =BW11 -> 1.4019874e-06 | BH11: =Q11/L11 -> 5.6915712 | BI11: =BX11 -> -8.6150533 | BJ11: =SUM(CK11:CP11)-CG11 -> 0.058983608 | BK11: =((AH11+AI11)*-1*CL11)/L11 -> -9.5486724 | BL11: =BJ11*AH11 -> 6.2057246 | BM11: =(CK11+CM11+CN11+CO11+CP11-CG11)/L11 -> -0.11160346 | BN11: =(CL11*AI11*-1)/L11 -> 8.7583556 | BO11: =BM11*AH11 -> -11.741912 | BQ11: =S11 -> Drymill CCS Fermentation Exhaust | BR11: =U11/W11/L11*AN11*-1 -> 0 | BS11: =V11/W11/L11*AN11 -> 1.1429473 | BT11: {=_xlfn.IFS(T11="Biomass_Corn", 1/W11/L11*AM11, T11="Biomass_Agri", 1/W11/L11*AL11, T11="Biomass_Wood", 1/W11/L11*AK11, T11="Biomass_Herb", 1/W11/L11*AJ11)} -> 54.525654 | BU11: =X11/W11/L11*AP11 -> 4.6368312 | BV11: =AB11/W11/L11/(0.9*8760) -> 6.6093692e-06 | BW11: =AC11/W11/L11/(0.9*8760) -> 1.4019874e-06 | BX11: =AF11/W11/L11 -> -8.6150533 | BZ11: 0.24095893 | CA11: 0.24182836 | CB11: 0.24025514 | CC11: =Y11 -> 1.7588667 | CD11: 0.18289084 | CE11: 0.23037491 | CG11: =CC11/W11 -> 0.56658349 | CH11: =IF(X11=0, 0, CD11*X11/W11) -> 0.059703911 | CI11: =CE11 -> 0.23037491 | CK11: =(AA11+AC11)/W11 -> 0.23143488 | CL11: =(Z11+AB11)/W11 -> 0.16447761 | CM11: =BZ11*I11 -> 0.22776822 | CN11: =CA11*J11 -> 0 | CO11: =CB11*K11 -> 0 | CP11: =(N11) -> 0.00188639 | CR11: =SUM(CG11:CH11)-SUM(CK11:CP11) -> 0.00072030281
B12: NE_Ethanol_to_Gasoline | C12: Ethanol | D12: 6 | E12: =S12 -> Drymill CCS Fermentation Exhaust | F12: 0 | G12: 0 | H12: 0 | I12: 0.94525743 | J12: 0 | K12: 0 | L12: =SUM(I12:K12) -> 0.94525743 | M12: 0 | N12: 0.00188639 | O12: 221829.88 | P12: 121538 | Q12: 5.38 | S12: {=_xlfn.XLOOKUP(D12, CT:CT, CU:DH)} -> Drymill CCS Fermentation Exhaust | T12: Biomass_Corn | U12: 0 | V12: 0.085342825 | W12: 3.104338 | X12: 1.0133975 | Y12: 1.7588667 | Z12: 0.35768767 | AA12: 0.68601739 | AB12: 0.15290642 | AC12: 0.032434696 | AD12: 45179.42 | AE12: 201481.25 | AF12: -25.28 | AH12: 105.211 | AI12: -58.833413 | AJ12: 99.493747 | AK12: 105.21396 | AL12: 89.700445 | AM12: 160 | AN12: 47.365061 | AO12: 33.373224 | AP12: 13.426279 | AR12: =B12 -> NE_Ethanol_to_Gasoline | AS12: =C12 -> Ethanol | AT12: =SUM(AW12:BI12)+BK12+BL12 -> 101.82714 | AU12: =SUM(AW12:BI12)+BN12+BO12 -> 102.18653 | AV12: =AT12-AU12 -> -0.35939129 | AW12: =F12/L12*AO12 -> 0 | AX12: =G12/L12*AN12 -> 0 | AY12: =BS12 -> 1.3775457 | AZ12: =H12/L12 -> 0 | BA12: =BR12 -> 0 | BB12: =BT12 -> 54.525654 | BC12: =BU12 -> 4.6367791 | BD12: =O12/L12/(0.9*8760) -> 29.766195 | BE12: =BV12 -> 6.6093692e-06 | BF12: =P12/L12/(0.9*8760) -> 16.30855 | BG12: =BW12 -> 1.4019874e-06 | BH12: =Q12/L12 -> 5.6915712 | BI12: =BX12 -> -8.6150533 | BJ12: =SUM(CK12:CP12)-CG12 -> 0.058983608 | BK12: =((AH12+AI12)*-1*CL12)/L12 -> -8.0698389 | BL12: =BJ12*AH12 -> 6.2057246 | BM12: =(CK12+CM12+CN12+CO12+CP12-CG12)/L12 -> -0.11160346 | BN12: =(CL12*AI12*-1)/L12 -> 10.237189 | BO12: =BM12*AH12 -> -11.741912 | BQ12: =S12 -> Drymill CCS Fermentation Exhaust | BR12: =U12/W12/L12*AN12*-1 -> 0 | BS12: =V12/W12/L12*AN12 -> 1.3775457 | BT12: {=_xlfn.IFS(T12="Biomass_Corn", 1/W12/L12*AM12, T12="Biomass_Agri", 1/W12/L12*AL12, T12="Biomass_Wood", 1/W12/L12*AK12, T12="Biomass_Herb", 1/W12/L12*AJ12)} -> 54.525654 | BU12: =X12/W12/L12*AP12 -> 4.6367791 | BV12: =AB12/W12/L12/(0.9*8760) -> 6.6093692e-06 | BW12: =AC12/W12/L12/(0.9*8760) -> 1.4019874e-06 | BX12: =AF12/W12/L12 -> -8.6150533 | BZ12: 0.24095893 | CA12: 0.24182836 | CB12: 0.24025514 | CC12: =Y12 -> 1.7588667 | CD12: 0.18289084 | CE12: 0.23037491 | CG12: =CC12/W12 -> 0.56658349 | CH12: =IF(X12=0, 0, CD12*X12/W12) -> 0.059703911 | CI12: =CE12 -> 0.23037491 | CK12: =(AA12+AC12)/W12 -> 0.23143488 | CL12: =(Z12+AB12)/W12 -> 0.16447761 | CM12: =BZ12*I12 -> 0.22776822 | CN12: =CA12*J12 -> 0 | CO12: =CB12*K12 -> 0 | CP12: =(N12) -> 0.00188639 | CR12: =SUM(CG12:CH12)-SUM(CK12:CP12) -> 0.00072030281
B13: CA_Ethanol_to_Diesel | C13: Ethanol | D13: 6 | E13: =S13 -> Drymill CCS Fermentation Exhaust | F13: 0.014253091 | G13: 0 | H13: 0 | I13: 0 | J13: 0.95046639 | K13: 0 | L13: =SUM(I13:K13) -> 0.95046639 | M13: 0 | N13: 0.0010795 | O13: 246863.86 | P13: 135253.82 | Q13: 10.05 | S13: {=_xlfn.XLOOKUP(D13, CT:CT, CU:DH)} -> Drymill CCS Fermentation Exhaust | T13: Biomass_Corn | U13: 0 | V13: 0.085342825 | W13: 3.104338 | X13: 1.0133975 | Y13: 1.7588667 | Z13: 0.35768767 | AA13: 0.68601739 | AB13: 0.15290642 | AC13: 0.032434696 | AD13: 45179.42 | AE13: 201481.25 | AF13: -25.28 | AH13: 105.211 | AI13: -6.412213 | AJ13: 313632.97 | AK13: 154.03698 | AL13: 132.85974 | AM13: 160 | AN13: 36.488698 | AO13: 29.796642 | AP13: 13.71857 | AR13: =B13 -> CA_Ethanol_to_Diesel | AS13: =C13 -> Ethanol | AT13: =SUM(AW13:BI13)+BK13+BL13 -> 102.68288 | AU13: =SUM(AW13:BI13)+BN13+BO13 -> 103.01328 | AV13: =AT13-AU13 -> -0.33040054 | AW13: =F13/L13*AO13 -> 0.44682722 | AX13: =G13/L13*AN13 -> 0 | AY13: =BS13 -> 1.0554061 | AZ13: =H13/L13 -> 0 | BA13: =BR13 -> 0 | BB13: =BT13 -> 54.22683 | BC13: =BU13 -> 4.7117573 | BD13: =O13/L13/(0.9*8760) -> 32.943834 | BE13: =BV13 -> 6.5731471e-06 | BF13: =P13/L13/(0.9*8760) -> 18.049541 | BG13: =BW13 -> 1.3943039e-06 | BH13: =Q13/L13 -> 10.573756 | BI13: =BX13 -> -8.5678392 | BJ13: =SUM(CK13:CP13)-CG13 -> 0.060258229 | BK13: =((AH13+AI13)*-1*CL13)/L13 -> -17.097068 | BL13: =BJ13*AH13 -> 6.3398287 | BM13: =(CK13+CM13+CN13+CO13+CP13-CG13)/L13 -> -0.10965078 | BN13: =(CL13*AI13*-1)/L13 -> 1.1096294 | BO13: =BM13*AH13 -> -11.536469 | BQ13: =S13 -> Drymill CCS Fermentation Exhaust | BR13: =U13/W13/L13*AN13*-1 -> 0 | BS13: =V13/W13/L13*AN13 -> 1.0554061 | BT13: {=_xlfn.IFS(T13="Biomass_Corn", 1/W13/L13*AM13, T13="Biomass_Agri", 1/W13/L13*AL13, T13="Biomass_Wood", 1/W13/L13*AK13, T13="Biomass_Herb", 1/W13/L13*AJ13)} -> 54.22683 | BU13: =X13/W13/L13*AP13 -> 4.7117573 | BV13: =AB13/W13/L13/(0.9*8760) -> 6.5731471e-06 | BW13: =AC13/W13/L13/(0.9*8760) -> 1.3943039e-06 | BX13: =AF13/W13/L13 -> -8.5678392 | BZ13: 0.24095893 | CA13: 0.24182836 | CB13: 0.24025514 | CC13: =Y13 -> 1.7588667 | CD13: 0.18289084 | CE13: 0.23037491 | CG13: =CC13/W13 -> 0.56658349 | CH13: =IF(X13=0, 0, CD13*X13/W13) -> 0.059703911 | CI13: =CE13 -> 0.23037491 | CK13: =(AA13+AC13)/W13 -> 0.23143488 | CL13: =(Z13+AB13)/W13 -> 0.16447761 | CM13: =BZ13*I13 -> 0 | CN13: =CA13*J13 -> 0.22984973 | CO13: =CB13*K13 -> 0 | CP13: =(N13) -> 0.0010795 | CR13: =SUM(CG13:CH13)-SUM(CK13:CP13) -> -0.00055431849
B14: NW_Ethanol_to_Diesel | C14: Ethanol | D14: 6 | E14: =S14 -> Drymill CCS Fermentation Exhaust | F14: 0.014253091 | G14: 0 | H14: 0 | I14: 0 | J14: 0.95046639 | K14: 0 | L14: =SUM(I14:K14) -> 0.95046639 | M14: 0 | N14: 0.0010795 | O14: 246863.86 | P14: 135253.82 | Q14: 10.05 | S14: {=_xlfn.XLOOKUP(D14, CT:CT, CU:DH)} -> Drymill CCS Fermentation Exhaust | T14: Biomass_Corn | U14: 0 | V14: 0.085342825 | W14: 3.104338 | X14: 1.0133975 | Y14: 1.7588667 | Z14: 0.35768767 | AA14: 0.68601739 | AB14: 0.15290642 | AC14: 0.032434696 | AD14: 45179.42 | AE14: 201481.25 | AF14: -25.28 | AH14: 105.211 | AI14: -7.379659 | AJ14: 130.9966 | AK14: 149.05667 | AL14: 112.26938 | AM14: 160 | AN14: 26.787863 | AO14: 27.898395 | AP14: 13.71944 | AR14: =B14 -> NW_Ethanol_to_Diesel | AS14: =C14 -> Ethanol | AT14: =SUM(AW14:BI14)+BK14+BL14 -> 102.54154 | AU14: =SUM(AW14:BI14)+BN14+BO14 -> 102.87194 | AV14: =AT14-AU14 -> -0.33040054 | AW14: =F14/L14*AO14 -> 0.41836131 | AX14: =G14/L14*AN14 -> 0 | AY14: =BS14 -> 0.77481732 | AZ14: =H14/L14 -> 0 | BA14: =BR14 -> 0 | BB14: =BT14 -> 54.22683 | BC14: =BU14 -> 4.7120562 | BD14: =O14/L14/(0.9*8760) -> 32.943834 | BE14: =BV14 -> 6.5731471e-06 | BF14: =P14/L14/(0.9*8760) -> 18.049541 | BG14: =BW14 -> 1.3943039e-06 | BH14: =Q14/L14 -> 10.573756 | BI14: =BX14 -> -8.5678392 | BJ14: =SUM(CK14:CP14)-CG14 -> 0.060258229 | BK14: =((AH14+AI14)*-1*CL14)/L14 -> -16.929652 | BL14: =BJ14*AH14 -> 6.3398287 | BM14: =(CK14+CM14+CN14+CO14+CP14-CG14)/L14 -> -0.10965078 | BN14: =(CL14*AI14*-1)/L14 -> 1.2770453 | BO14: =BM14*AH14 -> -11.536469 | BQ14: =S14 -> Drymill CCS Fermentation Exhaust | BR14: =U14/W14/L14*AN14*-1 -> 0 | BS14: =V14/W14/L14*AN14 -> 0.77481732 | BT14: {=_xlfn.IFS(T14="Biomass_Corn", 1/W14/L14*AM14, T14="Biomass_Agri", 1/W14/L14*AL14, T14="Biomass_Wood", 1/W14/L14*AK14, T14="Biomass_Herb", 1/W14/L14*AJ14)} -> 54.22683 | BU14: =X14/W14/L14*AP14 -> 4.7120562 | BV14: =AB14/W14/L14/(0.9*8760) -> 6.5731471e-06 | BW14: =AC14/W14/L14/(0.9*8760) -> 1.3943039e-06 | BX14: =AF14/W14/L14 -> -8.5678392 | BZ14: 0.24095893 | CA14: 0.24182836 | CB14: 0.24025514 | CC14: =Y14 -> 1.7588667 | CD14: 0.18289084 | CE14: 0.23037491 | CG14: =CC14/W14 -> 0.56658349 | CH14: =IF(X14=0, 0, CD14*X14/W14) -> 0.059703911 | CI14: =CE14 -> 0.23037491 | CK14: =(AA14+AC14)/W14 -> 0.23143488 | CL14: =(Z14+AB14)/W14 -> 0.16447761 | CM14: =BZ14*I14 -> 0 | CN14: =CA14*J14 -> 0.22984973 | CO14: =CB14*K14 -> 0 | CP14: =(N14) -> 0.0010795 | CR14: =SUM(CG14:CH14)-SUM(CK14:CP14) -> -0.00055431849
B15: SW_Ethanol_to_Diesel | C15: Ethanol | D15: 6 | E15: =S15 -> Drymill CCS Fermentation Exhaust | F15: 0.014253091 | G15: 0 | H15: 0 | I15: 0 | J15: 0.95046639 | K15: 0 | L15: =SUM(I15:K15) -> 0.95046639 | M15: 0 | N15: 0.0010795 | O15: 246863.86 | P15: 135253.82 | Q15: 10.05 | S15: {=_xlfn.XLOOKUP(D15, CT:CT, CU:DH)} -> Drymill CCS Fermentation Exhaust | T15: Biomass_Corn | U15: 0 | V15: 0.085342825 | W15: 3.104338 | X15: 1.0133975 | Y15: 1.7588667 | Z15: 0.35768767 | AA15: 0.68601739 | AB15: 0.15290642 | AC15: 0.032434696 | AD15: 45179.42 | AE15: 201481.25 | AF15: -25.28 | AH15: 105.211 | AI15: -14.567418 | AJ15: 120.28219 | AK15: 137.47503 | AL15: 107.55987 | AM15: 160 | AN15: 27.957547 | AO15: 26.470402 | AP15: 13.719351 | AR15: =B15 -> SW_Ethanol_to_Diesel | AS15: =C15 -> Ethanol | AT15: =SUM(AW15:BI15)+BK15+BL15 -> 103.79777 | AU15: =SUM(AW15:BI15)+BN15+BO15 -> 104.12817 | AV15: =AT15-AU15 -> -0.33040054 | AW15: =F15/L15*AO15 -> 0.39694728 | AX15: =G15/L15*AN15 -> 0 | AY15: =BS15 -> 0.80864948 | AZ15: =H15/L15 -> 0 | BA15: =BR15 -> 0 | BB15: =BT15 -> 54.22683 | BC15: =BU15 -> 4.7120256 | BD15: =O15/L15/(0.9*8760) -> 32.943834 | BE15: =BV15 -> 6.5731471e-06 | BF15: =P15/L15/(0.9*8760) -> 18.049541 | BG15: =BW15 -> 1.3943039e-06 | BH15: =Q15/L15 -> 10.573756 | BI15: =BX15 -> -8.5678392 | BJ15: =SUM(CK15:CP15)-CG15 -> 0.060258229 | BK15: =((AH15+AI15)*-1*CL15)/L15 -> -15.685815 | BL15: =BJ15*AH15 -> 6.3398287 | BM15: =(CK15+CM15+CN15+CO15+CP15-CG15)/L15 -> -0.10965078 | BN15: =(CL15*AI15*-1)/L15 -> 2.5208825 | BO15: =BM15*AH15 -> -11.536469 | BQ15: =S15 -> Drymill CCS Fermentation Exhaust | BR15: =U15/W15/L15*AN15*-1 -> 0 | BS15: =V15/W15/L15*AN15 -> 0.80864948 | BT15: {=_xlfn.IFS(T15="Biomass_Corn", 1/W15/L15*AM15, T15="Biomass_Agri", 1/W15/L15*AL15, T15="Biomass_Wood", 1/W15/L15*AK15, T15="Biomass_Herb", 1/W15/L15*AJ15)} -> 54.22683 | BU15: =X15/W15/L15*AP15 -> 4.7120256 | BV15: =AB15/W15/L15/(0.9*8760) -> 6.5731471e-06 | BW15: =AC15/W15/L15/(0.9*8760) -> 1.3943039e-06 | BX15: =AF15/W15/L15 -> -8.5678392 | BZ15: 0.24095893 | CA15: 0.24182836 | CB15: 0.24025514 | CC15: =Y15 -> 1.7588667 | CD15: 0.18289084 | CE15: 0.23037491 | CG15: =CC15/W15 -> 0.56658349 | CH15: =IF(X15=0, 0, CD15*X15/W15) -> 0.059703911 | CI15: =CE15 -> 0.23037491 | CK15: =(AA15+AC15)/W15 -> 0.23143488 | CL15: =(Z15+AB15)/W15 -> 0.16447761 | CM15: =BZ15*I15 -> 0 | CN15: =CA15*J15 -> 0.22984973 | CO15: =CB15*K15 -> 0 | CP15: =(N15) -> 0.0010795 | CR15: =SUM(CG15:CH15)-SUM(CK15:CP15) -> -0.00055431849
B16: TX_Ethanol_to_Diesel | C16: Ethanol | D16: 6 | E16: =S16 -> Drymill CCS Fermentation Exhaust | F16: 0.014253091 | G16: 0 | H16: 0 | I16: 0 | J16: 0.95046639 | K16: 0 | L16: =SUM(I16:K16) -> 0.95046639 | M16: 0 | N16: 0.0010795 | O16: 246863.86 | P16: 135253.82 | Q16: 10.05 | S16: {=_xlfn.XLOOKUP(D16, CT:CT, CU:DH)} -> Drymill CCS Fermentation Exhaust | T16: Biomass_Corn | U16: 0 | V16: 0.085342825 | W16: 3.104338 | X16: 1.0133975 | Y16: 1.7588667 | Z16: 0.35768767 | AA16: 0.68601739 | AB16: 0.15290642 | AC16: 0.032434696 | AD16: 45179.42 | AE16: 201481.25 | AF16: -25.28 | AH16: 105.211 | AI16: -19.477884 | AJ16: 132.95548 | AK16: 152.57709 | AL16: 106.67489 | AM16: 160 | AN16: 20.174973 | AO16: 18.805643 | AP16: 13.326032 | AR16: =B16 -> TX_Ethanol_to_Diesel | AS16: =C16 -> Ethanol | AT16: =SUM(AW16:BI16)+BK16+BL16 -> 104.17239 | AU16: =SUM(AW16:BI16)+BN16+BO16 -> 104.50279 | AV16: =AT16-AU16 -> -0.33040054 | AW16: =F16/L16*AO16 -> 0.28200739 | AX16: =G16/L16*AN16 -> 0 | AY16: =BS16 -> 0.58354481 | AZ16: =H16/L16 -> 0 | BA16: =BR16 -> 0 | BB16: =BT16 -> 54.22683 | BC16: =BU16 -> 4.5769369 | BD16: =O16/L16/(0.9*8760) -> 32.943834 | BE16: =BV16 -> 6.5731471e-06 | BF16: =P16/L16/(0.9*8760) -> 18.049541 | BG16: =BW16 -> 1.3943039e-06 | BH16: =Q16/L16 -> 10.573756 | BI16: =BX16 -> -8.5678392 | BJ16: =SUM(CK16:CP16)-CG16 -> 0.060258229 | BK16: =((AH16+AI16)*-1*CL16)/L16 -> -14.836062 | BL16: =BJ16*AH16 -> 6.3398287 | BM16: =(CK16+CM16+CN16+CO16+CP16-CG16)/L16 -> -0.10965078 | BN16: =(CL16*AI16*-1)/L16 -> 3.3706356 | BO16: =BM16*AH16 -> -11.536469 | BQ16: =S16 -> Drymill CCS Fermentation Exhaust | BR16: =U16/W16/L16*AN16*-1 -> 0 | BS16: =V16/W16/L16*AN16 -> 0.58354481 | BT16: {=_xlfn.IFS(T16="Biomass_Corn", 1/W16/L16*AM16, T16="Biomass_Agri", 1/W16/L16*AL16, T16="Biomass_Wood", 1/W16/L16*AK16, T16="Biomass_Herb", 1/W16/L16*AJ16)} -> 54.22683 | BU16: =X16/W16/L16*AP16 -> 4.5769369 | BV16: =AB16/W16/L16/(0.9*8760) -> 6.5731471e-06 | BW16: =AC16/W16/L16/(0.9*8760) -> 1.3943039e-06 | BX16: =AF16/W16/L16 -> -8.5678392 | BZ16: 0.24095893 | CA16: 0.24182836 | CB16: 0.24025514 | CC16: =Y16 -> 1.7588667 | CD16: 0.18289084 | CE16: 0.23037491 | CG16: =CC16/W16 -> 0.56658349 | CH16: =IF(X16=0, 0, CD16*X16/W16) -> 0.059703911 | CI16: =CE16 -> 0.23037491 | CK16: =(AA16+AC16)/W16 -> 0.23143488 | CL16: =(Z16+AB16)/W16 -> 0.16447761 | CM16: =BZ16*I16 -> 0 | CN16: =CA16*J16 -> 0.22984973 | CO16: =CB16*K16 -> 0 | CP16: =(N16) -> 0.0010795 | CR16: =SUM(CG16:CH16)-SUM(CK16:CP16) -> -0.00055431849
B17: NCEN_Ethanol_to_Diesel | C17: Ethanol | D17: 6 | E17: =S17 -> Drymill CCS Fermentation Exhaust | F17: 0.014253091 | G17: 0 | H17: 0 | I17: 0 | J17: 0.95046639 | K17: 0 | L17: =SUM(I17:K17) -> 0.95046639 | M17: 0 | N17: 0.0010795 | O17: 246863.86 | P17: 135253.82 | Q17: 10.05 | S17: {=_xlfn.XLOOKUP(D17, CT:CT, CU:DH)} -> Drymill CCS Fermentation Exhaust | T17: Biomass_Corn | U17: 0 | V17: 0.085342825 | W17: 3.104338 | X17: 1.0133975 | Y17: 1.7588667 | Z17: 0.35768767 | AA17: 0.68601739 | AB17: 0.15290642 | AC17: 0.032434696 | AD17: 45179.42 | AE17: 201481.25 | AF17: -25.28 | AH17: 105.211 | AI17: -39.686463 | AJ17: 100.75765 | AK17: 111.99077 | AL17: 89.243782 | AM17: 160 | AN17: 30.71395 | AO17: 27.816395 | AP17: 13.425922 | AR17: =B17 -> NCEN_Ethanol_to_Diesel | AS17: =C17 -> Ethanol | AT17: =SUM(AW17:BI17)+BK17+BL17 -> 108.14373 | AU17: =SUM(AW17:BI17)+BN17+BO17 -> 108.47413 | AV17: =AT17-AU17 -> -0.33040054 | AW17: =F17/L17*AO17 -> 0.41713165 | AX17: =G17/L17*AN17 -> 0 | AY17: =BS17 -> 0.88837622 | AZ17: =H17/L17 -> 0 | BA17: =BR17 -> 0 | BB17: =BT17 -> 54.22683 | BC17: =BU17 -> 4.6112449 | BD17: =O17/L17/(0.9*8760) -> 32.943834 | BE17: =BV17 -> 6.5731471e-06 | BF17: =P17/L17/(0.9*8760) -> 18.049541 | BG17: =BW17 -> 1.3943039e-06 | BH17: =Q17/L17 -> 10.573756 | BI17: =BX17 -> -8.5678392 | BJ17: =SUM(CK17:CP17)-CG17 -> 0.060258229 | BK17: =((AH17+AI17)*-1*CL17)/L17 -> -11.33898 | BL17: =BJ17*AH17 -> 6.3398287 | BM17: =(CK17+CM17+CN17+CO17+CP17-CG17)/L17 -> -0.10965078 | BN17: =(CL17*AI17*-1)/L17 -> 6.8677174 | BO17: =BM17*AH17 -> -11.536469 | BQ17: =S17 -> Drymill CCS Fermentation Exhaust | BR17: =U17/W17/L17*AN17*-1 -> 0 | BS17: =V17/W17/L17*AN17 -> 0.88837622 | BT17: {=_xlfn.IFS(T17="Biomass_Corn", 1/W17/L17*AM17, T17="Biomass_Agri", 1/W17/L17*AL17, T17="Biomass_Wood", 1/W17/L17*AK17, T17="Biomass_Herb", 1/W17/L17*AJ17)} -> 54.22683 | BU17: =X17/W17/L17*AP17 -> 4.6112449 | BV17: =AB17/W17/L17/(0.9*8760) -> 6.5731471e-06 | BW17: =AC17/W17/L17/(0.9*8760) -> 1.3943039e-06 | BX17: =AF17/W17/L17 -> -8.5678392 | BZ17: 0.24095893 | CA17: 0.24182836 | CB17: 0.24025514 | CC17: =Y17 -> 1.7588667 | CD17: 0.18289084 | CE17: 0.23037491 | CG17: =CC17/W17 -> 0.56658349 | CH17: =IF(X17=0, 0, CD17*X17/W17) -> 0.059703911 | CI17: =CE17 -> 0.23037491 | CK17: =(AA17+AC17)/W17 -> 0.23143488 | CL17: =(Z17+AB17)/W17 -> 0.16447761 | CM17: =BZ17*I17 -> 0 | CN17: =CA17*J17 -> 0.22984973 | CO17: =CB17*K17 -> 0 | CP17: =(N17) -> 0.0010795 | CR17: =SUM(CG17:CH17)-SUM(CK17:CP17) -> -0.00055431849
B18: CEN_Ethanol_to_Diesel | C18: Ethanol | D18: 6 | E18: =S18 -> Drymill CCS Fermentation Exhaust | F18: 0.014253091 | G18: 0 | H18: 0 | I18: 0 | J18: 0.95046639 | K18: 0 | L18: =SUM(I18:K18) -> 0.95046639 | M18: 0 | N18: 0.0010795 | O18: 246863.86 | P18: 135253.82 | Q18: 10.05 | S18: {=_xlfn.XLOOKUP(D18, CT:CT, CU:DH)} -> Drymill CCS Fermentation Exhaust | T18: Biomass_Corn | U18: 0 | V18: 0.085342825 | W18: 3.104338 | X18: 1.0133975 | Y18: 1.7588667 | Z18: 0.35768767 | AA18: 0.68601739 | AB18: 0.15290642 | AC18: 0.032434696 | AD18: 45179.42 | AE18: 201481.25 | AF18: -25.28 | AH18: 105.211 | AI18: -29.672038 | AJ18: 107.02715 | AK18: 122.86522 | AL18: 94.404421 | AM18: 160 | AN18: 25.118154 | AO18: 25.810506 | AP18: 13.425869 | AR18: =B18 -> CEN_Ethanol_to_Diesel | AS18: =C18 -> Ethanol | AT18: =SUM(AW18:BI18)+BK18+BL18 -> 106.21879 | AU18: =SUM(AW18:BI18)+BN18+BO18 -> 106.54919 | AV18: =AT18-AU18 -> -0.33040054 | AW18: =F18/L18*AO18 -> 0.38705155 | AX18: =G18/L18*AN18 -> 0 | AY18: =BS18 -> 0.72652233 | AZ18: =H18/L18 -> 0 | BA18: =BR18 -> 0 | BB18: =BT18 -> 54.22683 | BC18: =BU18 -> 4.6112267 | BD18: =O18/L18/(0.9*8760) -> 32.943834 | BE18: =BV18 -> 6.5731471e-06 | BF18: =P18/L18/(0.9*8760) -> 18.049541 | BG18: =BW18 -> 1.3943039e-06 | BH18: =Q18/L18 -> 10.573756 | BI18: =BX18 -> -8.5678392 | BJ18: =SUM(CK18:CP18)-CG18 -> 0.060258229 | BK18: =((AH18+AI18)*-1*CL18)/L18 -> -13.07197 | BL18: =BJ18*AH18 -> 6.3398287 | BM18: =(CK18+CM18+CN18+CO18+CP18-CG18)/L18 -> -0.10965078 | BN18: =(CL18*AI18*-1)/L18 -> 5.1347275 | BO18: =BM18*AH18 -> -11.536469 | BQ18: =S18 -> Drymill CCS Fermentation Exhaust | BR18: =U18/W18/L18*AN18*-1 -> 0 | BS18: =V18/W18/L18*AN18 -> 0.72652233 | BT18: {=_xlfn.IFS(T18="Biomass_Corn", 1/W18/L18*AM18, T18="Biomass_Agri", 1/W18/L18*AL18, T18="Biomass_Wood", 1/W18/L18*AK18, T18="Biomass_Herb", 1/W18/L18*AJ18)} -> 54.22683 | BU18: =X18/W18/L18*AP18 -> 4.6112267 | BV18: =AB18/W18/L18/(0.9*8760) -> 6.5731471e-06 | BW18: =AC18/W18/L18/(0.9*8760) -> 1.3943039e-06 | BX18: =AF18/W18/L18 -> -8.5678392 | BZ18: 0.24095893 | CA18: 0.24182836 | CB18: 0.24025514 | CC18: =Y18 -> 1.7588667 | CD18: 0.18289084 | CE18: 0.23037491 | CG18: =CC18/W18 -> 0.56658349 | CH18: =IF(X18=0, 0, CD18*X18/W18) -> 0.059703911 | CI18: =CE18 -> 0.23037491 | CK18: =(AA18+AC18)/W18 -> 0.23143488 | CL18: =(Z18+AB18)/W18 -> 0.16447761 | CM18: =BZ18*I18 -> 0 | CN18: =CA18*J18 -> 0.22984973 | CO18: =CB18*K18 -> 0 | CP18: =(N18) -> 0.0010795 | CR18: =SUM(CG18:CH18)-SUM(CK18:CP18) -> -0.00055431849
B19: SE_Ethanol_to_Diesel | C19: Ethanol | D19: 6 | E19: =S19 -> Drymill CCS Fermentation Exhaust | F19: 0.014253091 | G19: 0 | H19: 0 | I19: 0 | J19: 0.95046639 | K19: 0 | L19: =SUM(I19:K19) -> 0.95046639 | M19: 0 | N19: 0.0010795 | O19: 246863.86 | P19: 135253.82 | Q19: 10.05 | S19: {=_xlfn.XLOOKUP(D19, CT:CT, CU:DH)} -> Drymill CCS Fermentation Exhaust | T19: Biomass_Corn | U19: 0 | V19: 0.085342825 | W19: 3.104338 | X19: 1.0133975 | Y19: 1.7588667 | Z19: 0.35768767 | AA19: 0.68601739 | AB19: 0.15290642 | AC19: 0.032434696 | AD19: 45179.42 | AE19: 201481.25 | AF19: -25.28 | AH19: 105.211 | AI19: -45.510345 | AJ19: 97.593262 | AK19: 109.79123 | AL19: 86.911507 | AM19: 160 | AN19: 38.099076 | AO19: 30.305277 | AP19: 13.425863 | AR19: =B19 -> SE_Ethanol_to_Diesel | AS19: =C19 -> Ethanol | AT19: =SUM(AW19:BI19)+BK19+BL19 -> 109.40246 | AU19: =SUM(AW19:BI19)+BN19+BO19 -> 109.73286 | AV19: =AT19-AU19 -> -0.33040054 | AW19: =F19/L19*AO19 -> 0.45445465 | AX19: =G19/L19*AN19 -> 0 | AY19: =BS19 -> 1.101985 | AZ19: =H19/L19 -> 0 | BA19: =BR19 -> 0 | BB19: =BT19 -> 54.22683 | BC19: =BU19 -> 4.6112247 | BD19: =O19/L19/(0.9*8760) -> 32.943834 | BE19: =BV19 -> 6.5731471e-06 | BF19: =P19/L19/(0.9*8760) -> 18.049541 | BG19: =BW19 -> 1.3943039e-06 | BH19: =Q19/L19 -> 10.573756 | BI19: =BX19 -> -8.5678392 | BJ19: =SUM(CK19:CP19)-CG19 -> 0.060258229 | BK19: =((AH19+AI19)*-1*CL19)/L19 -> -10.331161 | BL19: =BJ19*AH19 -> 6.3398287 | BM19: =(CK19+CM19+CN19+CO19+CP19-CG19)/L19 -> -0.10965078 | BN19: =(CL19*AI19*-1)/L19 -> 7.8755366 | BO19: =BM19*AH19 -> -11.536469 | BQ19: =S19 -> Drymill CCS Fermentation Exhaust | BR19: =U19/W19/L19*AN19*-1 -> 0 | BS19: =V19/W19/L19*AN19 -> 1.101985 | BT19: {=_xlfn.IFS(T19="Biomass_Corn", 1/W19/L19*AM19, T19="Biomass_Agri", 1/W19/L19*AL19, T19="Biomass_Wood", 1/W19/L19*AK19, T19="Biomass_Herb", 1/W19/L19*AJ19)} -> 54.22683 | BU19: =X19/W19/L19*AP19 -> 4.6112247 | BV19: =AB19/W19/L19/(0.9*8760) -> 6.5731471e-06 | BW19: =AC19/W19/L19/(0.9*8760) -> 1.3943039e-06 | BX19: =AF19/W19/L19 -> -8.5678392 | BZ19: 0.24095893 | CA19: 0.24182836 | CB19: 0.24025514 | CC19: =Y19 -> 1.7588667 | CD19: 0.18289084 | CE19: 0.23037491 | CG19: =CC19/W19 -> 0.56658349 | CH19: =IF(X19=0, 0, CD19*X19/W19) -> 0.059703911 | CI19: =CE19 -> 0.23037491 | CK19: =(AA19+AC19)/W19 -> 0.23143488 | CL19: =(Z19+AB19)/W19 -> 0.16447761 | CM19: =BZ19*I19 -> 0 | CN19: =CA19*J19 -> 0.22984973 | CO19: =CB19*K19 -> 0 | CP19: =(N19) -> 0.0010795 | CR19: =SUM(CG19:CH19)-SUM(CK19:CP19) -> -0.00055431849
B20: MIDAT_Ethanol_to_Diesel | C20: Ethanol | D20: 6 | E20: =S20 -> Drymill CCS Fermentation Exhaust | F20: 0.014253091 | G20: 0 | H20: 0 | I20: 0 | J20: 0.95046639 | K20: 0 | L20: =SUM(I20:K20) -> 0.95046639 | M20: 0 | N20: 0.0010795 | O20: 246863.86 | P20: 135253.82 | Q20: 10.05 | S20: {=_xlfn.XLOOKUP(D20, CT:CT, CU:DH)} -> Drymill CCS Fermentation Exhaust | T20: Biomass_Corn | U20: 0 | V20: 0.085342825 | W20: 3.104338 | X20: 1.0133975 | Y20: 1.7588667 | Z20: 0.35768767 | AA20: 0.68601739 | AB20: 0.15290642 | AC20: 0.032434696 | AD20: 45179.42 | AE20: 201481.25 | AF20: -25.28 | AH20: 105.211 | AI20: -50.334515 | AJ20: 98.707491 | AK20: 106.53196 | AL20: 87.469328 | AM20: 160 | AN20: 39.29871 | AO20: 31.568805 | AP20: 13.42643 | AR20: =B20 -> MIDAT_Ethanol_to_Diesel | AS20: =C20 -> Ethanol | AT20: =SUM(AW20:BI20)+BK20+BL20 -> 110.29112 | AU20: =SUM(AW20:BI20)+BN20+BO20 -> 110.62152 | AV20: =AT20-AU20 -> -0.33040054 | AW20: =F20/L20*AO20 -> 0.47340238 | AX20: =G20/L20*AN20 -> 0 | AY20: =BS20 -> 1.1366835 | AZ20: =H20/L20 -> 0 | BA20: =BR20 -> 0 | BB20: =BT20 -> 54.22683 | BC20: =BU20 -> 4.6114194 | BD20: =O20/L20/(0.9*8760) -> 32.943834 | BE20: =BV20 -> 6.5731471e-06 | BF20: =P20/L20/(0.9*8760) -> 18.049541 | BG20: =BW20 -> 1.3943039e-06 | BH20: =Q20/L20 -> 10.573756 | BI20: =BX20 -> -8.5678392 | BJ20: =SUM(CK20:CP20)-CG20 -> 0.060258229 | BK20: =((AH20+AI20)*-1*CL20)/L20 -> -9.4963417 | BL20: =BJ20*AH20 -> 6.3398287 | BM20: =(CK20+CM20+CN20+CO20+CP20-CG20)/L20 -> -0.10965078 | BN20: =(CL20*AI20*-1)/L20 -> 8.7103561 | BO20: =BM20*AH20 -> -11.536469 | BQ20: =S20 -> Drymill CCS Fermentation Exhaust | BR20: =U20/W20/L20*AN20*-1 -> 0 | BS20: =V20/W20/L20*AN20 -> 1.1366835 | BT20: {=_xlfn.IFS(T20="Biomass_Corn", 1/W20/L20*AM20, T20="Biomass_Agri", 1/W20/L20*AL20, T20="Biomass_Wood", 1/W20/L20*AK20, T20="Biomass_Herb", 1/W20/L20*AJ20)} -> 54.22683 | BU20: =X20/W20/L20*AP20 -> 4.6114194 | BV20: =AB20/W20/L20/(0.9*8760) -> 6.5731471e-06 | BW20: =AC20/W20/L20/(0.9*8760) -> 1.3943039e-06 | BX20: =AF20/W20/L20 -> -8.5678392 | BZ20: 0.24095893 | CA20: 0.24182836 | CB20: 0.24025514 | CC20: =Y20 -> 1.7588667 | CD20: 0.18289084 | CE20: 0.23037491 | CG20: =CC20/W20 -> 0.56658349 | CH20: =IF(X20=0, 0, CD20*X20/W20) -> 0.059703911 | CI20: =CE20 -> 0.23037491 | CK20: =(AA20+AC20)/W20 -> 0.23143488 | CL20: =(Z20+AB20)/W20 -> 0.16447761 | CM20: =BZ20*I20 -> 0 | CN20: =CA20*J20 -> 0.22984973 | CO20: =CB20*K20 -> 0 | CP20: =(N20) -> 0.0010795 | CR20: =SUM(CG20:CH20)-SUM(CK20:CP20) -> -0.00055431849
B21: NE_Ethanol_to_Diesel | C21: Ethanol | D21: 6 | E21: =S21 -> Drymill CCS Fermentation Exhaust | F21: 0.014253091 | G21: 0 | H21: 0 | I21: 0 | J21: 0.95046639 | K21: 0 | L21: =SUM(I21:K21) -> 0.95046639 | M21: 0 | N21: 0.0010795 | O21: 246863.86 | P21: 135253.82 | Q21: 10.05 | S21: {=_xlfn.XLOOKUP(D21, CT:CT, CU:DH)} -> Drymill CCS Fermentation Exhaust | T21: Biomass_Corn | U21: 0 | V21: 0.085342825 | W21: 3.104338 | X21: 1.0133975 | Y21: 1.7588667 | Z21: 0.35768767 | AA21: 0.68601739 | AB21: 0.15290642 | AC21: 0.032434696 | AD21: 45179.42 | AE21: 201481.25 | AF21: -25.28 | AH21: 105.211 | AI21: -58.833413 | AJ21: 99.493747 | AK21: 105.21396 | AL21: 89.700445 | AM21: 160 | AN21: 47.365061 | AO21: 33.373224 | AP21: 13.426279 | AR21: =B21 -> NE_Ethanol_to_Diesel | AS21: =C21 -> Ethanol | AT21: =SUM(AW21:BI21)+BK21+BL21 -> 112.02217 | AU21: =SUM(AW21:BI21)+BN21+BO21 -> 112.35257 | AV21: =AT21-AU21 -> -0.33040054 | AW21: =F21/L21*AO21 -> 0.50046125 | AX21: =G21/L21*AN21 -> 0 | AY21: =BS21 -> 1.3699962 | AZ21: =H21/L21 -> 0 | BA21: =BR21 -> 0 | BB21: =BT21 -> 54.22683 | BC21: =BU21 -> 4.6113676 | BD21: =O21/L21/(0.9*8760) -> 32.943834 | BE21: =BV21 -> 6.5731471e-06 | BF21: =P21/L21/(0.9*8760) -> 18.049541 | BG21: =BW21 -> 1.3943039e-06 | BH21: =Q21/L21 -> 10.573756 | BI21: =BX21 -> -8.5678392 | BJ21: =SUM(CK21:CP21)-CG21 -> 0.060258229 | BK21: =((AH21+AI21)*-1*CL21)/L21 -> -8.0256128 | BL21: =BJ21*AH21 -> 6.3398287 | BM21: =(CK21+CM21+CN21+CO21+CP21-CG21)/L21 -> -0.10965078 | BN21: =(CL21*AI21*-1)/L21 -> 10.181085 | BO21: =BM21*AH21 -> -11.536469 | BQ21: =S21 -> Drymill CCS Fermentation Exhaust | BR21: =U21/W21/L21*AN21*-1 -> 0 | BS21: =V21/W21/L21*AN21 -> 1.3699962 | BT21: {=_xlfn.IFS(T21="Biomass_Corn", 1/W21/L21*AM21, T21="Biomass_Agri", 1/W21/L21*AL21, T21="Biomass_Wood", 1/W21/L21*AK21, T21="Biomass_Herb", 1/W21/L21*AJ21)} -> 54.22683 | BU21: =X21/W21/L21*AP21 -> 4.6113676 | BV21: =AB21/W21/L21/(0.9*8760) -> 6.5731471e-06 | BW21: =AC21/W21/L21/(0.9*8760) -> 1.3943039e-06 | BX21: =AF21/W21/L21 -> -8.5678392 | BZ21: 0.24095893 | CA21: 0.24182836 | CB21: 0.24025514 | CC21: =Y21 -> 1.7588667 | CD21: 0.18289084 | CE21: 0.23037491 | CG21: =CC21/W21 -> 0.56658349 | CH21: =IF(X21=0, 0, CD21*X21/W21) -> 0.059703911 | CI21: =CE21 -> 0.23037491 | CK21: =(AA21+AC21)/W21 -> 0.23143488 | CL21: =(Z21+AB21)/W21 -> 0.16447761 | CM21: =BZ21*I21 -> 0 | CN21: =CA21*J21 -> 0.22984973 | CO21: =CB21*K21 -> 0 | CP21: =(N21) -> 0.0010795 | CR21: =SUM(CG21:CH21)-SUM(CK21:CP21) -> -0.00055431849
... B39: NE_Ethanol_to_Gasoline_Diesel | C39: Ethanol | D39: 6 | E39: =S39 -> Drymill CCS Fermentation Exhaust | F39: 0 | G39: 0 | H39: 0 | I39: 0.87460153 | J39: 0.075453064 | K39: 0 | L39: =SUM(I39:K39) -> 0.9500546 | M39: 0 | N39: 0.00200763 | O39: 226211.7 | P39: 123938.75 | Q39: 6 | S39: {=_xlfn.XLOOKUP(D39, CT:CT, CU:DH)} -> Drymill CCS Fermentation Exhaust | T39: Biomass_Corn | U39: 0 | V39: 0.085342825 | W39: 3.104338 | X39: 1.0133975 | Y39: 1.7588667 | Z39: 0.35768767 | AA39: 0.68601739 | AB39: 0.15290642 | AC39: 0.032434696 | AD39: 45179.42 | AE39: 201481.25 | AF39: -25.28 | AH39: 105.211 | AI39: -58.833413 | AJ39: 99.493747 | AK39: 105.21396 | AL39: 89.700445 | AM39: 160 | AN39: 47.365061 | AO39: 33.373224 | AP39: 13.426279 | AR39: =B39 -> NE_Ethanol_to_Gasoline_Diesel | AS39: =C39 -> Ethanol | AT39: =SUM(AW39:BI39)+BK39+BL39 -> 103.0437 | AU39: =SUM(AW39:BI39)+BN39+BO39 -> 103.37737 | AV39: =AT39-AU39 -> -0.33366858 | AW39: =F39/L39*AO39 -> 0 | AX39: =G39/L39*AN39 -> 0 | AY39: =BS39 -> 1.37059 | AZ39: =H39/L39 -> 0 | BA39: =BR39 -> 0 | BB39: =BT39 -> 54.250334 | BC39: =BU39 -> 4.6133663 | BD39: =O39/L39/(0.9*8760) -> 30.200901 | BE39: =BV39 -> 6.5759961e-06 | BF39: =P39/L39/(0.9*8760) -> 16.54672 | BG39: =BW39 -> 1.3949083e-06 | BH39: =Q39/L39 -> 6.3154265 | BI39: =BX39 -> -8.5715528 | BJ39: =SUM(CK39:CP39)-CG39 -> 0.060326369 | BK39: =((AH39+AI39)*-1*CL39)/L39 -> -8.0290914 | BL39: =BJ39*AH39 -> 6.3469978 | BM39: =(CK39+CM39+CN39+CO39+CP39-CG39)/L39 -> -0.10962659 | BN39: =(CL39*AI39*-1)/L39 -> 10.185498 | BO39: =BM39*AH39 -> -11.533923 | BQ39: =S39 -> Drymill CCS Fermentation Exhaust | BR39: =U39/W39/L39*AN39*-1 -> 0 | BS39: =V39/W39/L39*AN39 -> 1.37059 | BT39: {=_xlfn.IFS(T39="Biomass_Corn", 1/W39/L39*AM39, T39="Biomass_Agri", 1/W39/L39*AL39, T39="Biomass_Wood", 1/W39/L39*AK39, T39="Biomass_Herb", 1/W39/L39*AJ39)} -> 54.250334 | BU39: =X39/W39/L39*AP39 -> 4.6133663 | BV39: =AB39/W39/L39/(0.9*8760) -> 6.5759961e-06 | BW39: =AC39/W39/L39/(0.9*8760) -> 1.3949083e-06 | BX39: =AF39/W39/L39 -> -8.5715528 | BZ39: 0.24095893 | CA39: 0.24182836 | CB39: 0.24025514 | CC39: =Y39 -> 1.7588667 | CD39: 0.18289084 | CE39: 0.23037491 | CG39: =CC39/W39 -> 0.56658349 | CH39: =IF(X39=0, 0, CD39*X39/W39) -> 0.059703911 | CI39: =CE39 -> 0.23037491 | CK39: =(AA39+AC39)/W39 -> 0.23143488 | CL39: =(Z39+AB39)/W39 -> 0.16447761 | CM39: =BZ39*I39 -> 0.21074305 | CN39: =CA39*J39 -> 0.018246691 | CO39: =CB39*K39 -> 0 | CP39: =(N39) -> 0.00200763 | CR39: =SUM(CG39:CH39)-SUM(CK39:CP39) -> -0.00062245783
D40: 6 | E40: =S40 -> Drymill CCS Fermentation Exhaust | L40: =SUM(I40:K40) -> 0 | S40: {=_xlfn.XLOOKUP(D40, CT:CT, CU:DH)} -> Drymill CCS Fermentation Exhaust | T40: Biomass_Corn | U40: 0 | V40: 0.085342825 | W40: 3.104338 | X40: 1.0133975 | Y40: 1.7588667 | Z40: 0.35768767 | AA40: 0.68601739 | AB40: 0.15290642 | AC40: 0.032434696 | AD40: 45179.42 | AE40: 201481.25 | AF40: -25.28 | AR40: =B40 -> 0 | AS40: =C40 -> 0 | AT40: =SUM(AW40:BI40)+BK40+BL40 -> #DIV/0! | AU40: =SUM(AW40:BI40)+BN40+BO40 -> #DIV/0! | AV40: =AT40-AU40 -> #DIV/0! | AW40: =F40/L40*AO40 -> #DIV/0! | AX40: =G40/L40*AN40 -> #DIV/0! | AY40: =BS40 -> #DIV/0! | AZ40: =H40/L40 -> #DIV/0! | BA40: =BR40 -> #DIV/0! | BB40: =BT40 -> #DIV/0! | BC40: =BU40 -> #DIV/0! | BD40: =O40/L40/(0.9*8760) -> #DIV/0! | BE40: =BV40 -> #DIV/0! | BF40: =P40/L40/(0.9*8760) -> #DIV/0! | BG40: =BW40 -> #DIV/0! | BH40: =Q40/L40 -> #DIV/0! | BI40: =BX40 -> #DIV/0! | BJ40: =SUM(CK40:CP40)-CG40 -> -0.170671 | BK40: =((AH40+AI40)*-1*CL40)/L40 -> #DIV/0! | BL40: =BJ40*AH40 -> 0 | BM40: =(CK40+CM40+CN40+CO40+CP40-CG40)/L40 -> #DIV/0! | BN40: =(CL40*AI40*-1)/L40 -> #DIV/0! | BO40: =BM40*AH40 -> #DIV/0! | BQ40: =S40 -> Drymill CCS Fermentation Exhaust | BR40: =U40/W40/L40*AN40*-1 -> #DIV/0! | BS40: =V40/W40/L40*AN40 -> #DIV/0! | BT40: {=_xlfn.IFS(T40="Biomass_Corn", 1/W40/L40*AM40, T40="Biomass_Agri", 1/W40/L40*AL40, T40="Biomass_Wood", 1/W40/L40*AK40, T40="Biomass_Herb", 1/W40/L40*AJ40)} -> #DIV/0! | BU40: =X40/W40/L40*AP40 -> #DIV/0! | BV40: =AB40/W40/L40/(0.9*8760) -> #DIV/0! | BW40: =AC40/W40/L40/(0.9*8760) -> #DIV/0! | BX40: =AF40/W40/L40 -> #DIV/0! | BZ40: 0.24095893 | CA40: 0.24182836 | CB40: 0.24025514 | CC40: =Y40 -> 1.7588667 | CD40: 0.18289084 | CE40: 0.23037491 | CG40: =CC40/W40 -> 0.56658349 | CH40: =IF(X40=0, 0, CD40*X40/W40) -> 0.059703911 | CI40: =CE40 -> 0.23037491 | CK40: =(AA40+AC40)/W40 -> 0.23143488 | CL40: =(Z40+AB40)/W40 -> 0.16447761 | CM40: =BZ40*I40 -> 0 | CN40: =CA40*J40 -> 0 | CO40: =CB40*K40 -> 0 | CP40: =(N40) -> 0 | CR40: =SUM(CG40:CH40)-SUM(CK40:CP40) -> 0.23037491
D41: 6 | E41: =S41 -> Drymill CCS Fermentation Exhaust | L41: =SUM(I41:K41) -> 0 | S41: {=_xlfn.XLOOKUP(D41, CT:CT, CU:DH)} -> Drymill CCS Fermentation Exhaust | T41: Biomass_Corn | U41: 0 | V41: 0.085342825 | W41: 3.104338 | X41: 1.0133975 | Y41: 1.7588667 | Z41: 0.35768767 | AA41: 0.68601739 | AB41: 0.15290642 | AC41: 0.032434696 | AD41: 45179.42 | AE41: 201481.25 | AF41: -25.28 | AR41: =B41 -> 0 | AS41: =C41 -> 0 | AT41: =SUM(AW41:BI41)+BK41+BL41 -> #DIV/0! | AU41: =SUM(AW41:BI41)+BN41+BO41 -> #DIV/0! | AV41: =AT41-AU41 -> #DIV/0! | AW41: =F41/L41*AO41 -> #DIV/0! | AX41: =G41/L41*AN41 -> #DIV/0! | AY41: =BS41 -> #DIV/0! | AZ41: =H41/L41 -> #DIV/0! | BA41: =BR41 -> #DIV/0! | BB41: =BT41 -> #DIV/0! | BC41: =BU41 -> #DIV/0! | BD41: =O41/L41/(0.9*8760) -> #DIV/0! | BE41: =BV41 -> #DIV/0! | BF41: =P41/L41/(0.9*8760) -> #DIV/0! | BG41: =BW41 -> #DIV/0! | BH41: =Q41/L41 -> #DIV/0! | BI41: =BX41 -> #DIV/0! | BJ41: =SUM(CK41:CP41)-CG41 -> -0.170671 | BK41: =((AH41+AI41)*-1*CL41)/L41 -> #DIV/0! | BL41: =BJ41*AH41 -> 0 | BM41: =(CK41+CM41+CN41+CO41+CP41-CG41)/L41 -> #DIV/0! | BN41: =(CL41*AI41*-1)/L41 -> #DIV/0! | BO41: =BM41*AH41 -> #DIV/0! | BQ41: =S41 -> Drymill CCS Fermentation Exhaust | BR41: =U41/W41/L41*AN41*-1 -> #DIV/0! | BS41: =V41/W41/L41*AN41 -> #DIV/0! | BT41: {=_xlfn.IFS(T41="Biomass_Corn", 1/W41/L41*AM41, T41="Biomass_Agri", 1/W41/L41*AL41, T41="Biomass_Wood", 1/W41/L41*AK41, T41="Biomass_Herb", 1/W41/L41*AJ41)} -> #DIV/0! | BU41: =X41/W41/L41*AP41 -> #DIV/0! | BV41: =AB41/W41/L41/(0.9*8760) -> #DIV/0! | BW41: =AC41/W41/L41/(0.9*8760) -> #DIV/0! | BX41: =AF41/W41/L41 -> #DIV/0! | BZ41: 0.24095893 | CA41: 0.24182836 | CB41: 0.24025514 | CC41: =Y41 -> 1.7588667 | CD41: 0.18289084 | CE41: 0.23037491 | CG41: =CC41/W41 -> 0.56658349 | CH41: =IF(X41=0, 0, CD41*X41/W41) -> 0.059703911 | CI41: =CE41 -> 0.23037491 | CK41: =(AA41+AC41)/W41 -> 0.23143488 | CL41: =(Z41+AB41)/W41 -> 0.16447761 | CM41: =BZ41*I41 -> 0 | CN41: =CA41*J41 -> 0 | CO41: =CB41*K41 -> 0 | CP41: =(N41) -> 0 | CR41: =SUM(CG41:CH41)-SUM(CK41:CP41) -> 0.23037491
D42: 6 | E42: =S42 -> Drymill CCS Fermentation Exhaust | L42: =SUM(I42:K42) -> 0 | S42: {=_xlfn.XLOOKUP(D42, CT:CT, CU:DH)} -> Drymill CCS Fermentation Exhaust | T42: Biomass_Corn | U42: 0 | V42: 0.085342825 | W42: 3.104338 | X42: 1.0133975 | Y42: 1.7588667 | Z42: 0.35768767 | AA42: 0.68601739 | AB42: 0.15290642 | AC42: 0.032434696 | AD42: 45179.42 | AE42: 201481.25 | AF42: -25.28 | AR42: =B42 -> 0 | AS42: =C42 -> 0 | AT42: =SUM(AW42:BI42)+BK42+BL42 -> #DIV/0! | AU42: =SUM(AW42:BI42)+BN42+BO42 -> #DIV/0! | AV42: =AT42-AU42 -> #DIV/0! | AW42: =F42/L42*AO42 -> #DIV/0! | AX42: =G42/L42*AN42 -> #DIV/0! | AY42: =BS42 -> #DIV/0! | AZ42: =H42/L42 -> #DIV/0! | BA42: =BR42 -> #DIV/0! | BB42: =BT42 -> #DIV/0! | BC42: =BU42 -> #DIV/0! | BD42: =O42/L42/(0.9*8760) -> #DIV/0! | BE42: =BV42 -> #DIV/0! | BF42: =P42/L42/(0.9*8760) -> #DIV/0! | BG42: =BW42 -> #DIV/0! | BH42: =Q42/L42 -> #DIV/0! | BI42: =BX42 -> #DIV/0! | BJ42: =SUM(CK42:CP42)-CG42 -> -0.170671 | BK42: =((AH42+AI42)*-1*CL42)/L42 -> #DIV/0! | BL42: =BJ42*AH42 -> 0 | BM42: =(CK42+CM42+CN42+CO42+CP42-CG42)/L42 -> #DIV/0! | BN42: =(CL42*AI42*-1)/L42 -> #DIV/0! | BO42: =BM42*AH42 -> #DIV/0! | BQ42: =S42 -> Drymill CCS Fermentation Exhaust | BR42: =U42/W42/L42*AN42*-1 -> #DIV/0! | BS42: =V42/W42/L42*AN42 -> #DIV/0! | BT42: {=_xlfn.IFS(T42="Biomass_Corn", 1/W42/L42*AM42, T42="Biomass_Agri", 1/W42/L42*AL42, T42="Biomass_Wood", 1/W42/L42*AK42, T42="Biomass_Herb", 1/W42/L42*AJ42)} -> #DIV/0! | BU42: =X42/W42/L42*AP42 -> #DIV/0! | BV42: =AB42/W42/L42/(0.9*8760) -> #DIV/0! | BW42: =AC42/W42/L42/(0.9*8760) -> #DIV/0! | BX42: =AF42/W42/L42 -> #DIV/0! | BZ42: 0.24095893 | CA42: 0.24182836 | CB42: 0.24025514 | CC42: =Y42 -> 1.7588667 | CD42: 0.18289084 | CE42: 0.23037491 | CG42: =CC42/W42 -> 0.56658349 | CH42: =IF(X42=0, 0, CD42*X42/W42) -> 0.059703911 | CI42: =CE42 -> 0.23037491 | CK42: =(AA42+AC42)/W42 -> 0.23143488 | CL42: =(Z42+AB42)/W42 -> 0.16447761 | CM42: =BZ42*I42 -> 0 | CN42: =CA42*J42 -> 0 | CO42: =CB42*K42 -> 0 | CP42: =(N42) -> 0 | CR42: =SUM(CG42:CH42)-SUM(CK42:CP42) -> 0.23037491
